{
  "version": 8,
  "blockIdVersion": 11,
  "anchorX": 0,
  "anchorY": 0,
  "anchorZ": 0,
  "blocks": [
    {
      "x": -10,
      "y": 0,
      "z": -10,
      "name": "Rock_Marble_Brick"
    },
    {
      "x": -10,
      "y": 1,
      "z": -10,
      "name": "Rock_Marble_Brick"
    },
    {
      "x": -10,
      "y": 0,
      "z": -9,
      "name": "Rock_Marble_Brick"
    },
    {
      "x": -10,
      "y": 1,
      "z": -9,
      "name": "Rock_Marble_Brick"
    },
    {
      "x": -10,
      "y": 0,
      "z": -8,
      "name": "Rock_Marble_Brick"
    },
    {
      "x": -10,
      "y": 1,
      "z": -8,
      "name": "Rock_Marble_Brick"
    },
    {
      "x": -10,
      "y": 0,
      "z": -7,
      "name": "Rock_Marble_Brick"
    },
    {
      "x": -10,
      "y": 1,
      "z": -7,
      "name": "Rock_Marble_Brick"
    },
    {
      "x": -10,
      "y": 0,
      "z": -6,
      "name": "Rock_Marble_Brick"
    },
    {
      "x": -10,
      "y": 1,
      "z": -6,
      "name": "Rock_Marble_Brick"
    },
    {
      "x": -10,
      "y": 0,
      "z": -5,
      "name": "Rock_Marble_Brick"
    },
    {
      "x": -10,
      "y": 1,
      "z": -5,
      "name": "Rock_Marble_Brick"
    },
    {
      "x": -10,
      "y": 0,
      "z": -4,
      "name": "Rock_Marble_Brick"
    },
    {
      "x": -10,
      "y": 1,
      "z": -4,
      "name": "Rock_Marble_Brick"
    },
    {
      "x": -10,
      "y": 0,
      "z": -3,
      "name": "Rock_Marble_Brick"
    },
    {
      "x": -10,
      "y": 1,
      "z": -3,
      "name": "Rock_Marble_Brick"
    },
    {
      "x": -10,
      "y": 0,
      "z": -2,
      "name": "Rock_Marble_Brick"
    },
    {
      "x": -10,
      "y": 1,
      "z": -2,
      "name": "Rock_Marble_Brick"
    },
    {
      "x": -10,
      "y": 0,
      "z": -1,
      "name": "Rock_Marble_Brick"
    },
    {
      "x": -10,
      "y": 1,
      "z": -1,
      "name": "Rock_Marble_Brick"
    },
    {
      "x": -10,
      "y": 0,
      "z": 0,
      "name": "Rock_Marble_Brick"
    },
    {
      "x": -10,
      "y": 1,
      "z": 0,
      "name": "Rock_Marble_Brick"
    },
    {
      "x": -10,
      "y": 0,
      "z": 1,
      "name": "Rock_Marble_Brick"
    },
    {
      "x": -10,
      "y": 1,
      "z": 1,
      "name": "Rock_Marble_Brick"
    },
    {
      "x": -10,
      "y": 0,
      "z": 2,
      "name": "Rock_Marble_Brick"
    },
    {
      "x": -10,
      "y": 1,
      "z": 2,
      "name": "Rock_Marble_Brick"
    },
    {
      "x": -10,
      "y": 0,
      "z": 3,
      "name": "Rock_Marble_Brick"
    },
    {
      "x": -10,
      "y": 1,
      "z": 3,
      "name": "Rock_Marble_Brick"
    },
    {
      "x": -10,
      "y": 0,
      "z": 4,
      "name": "Rock_Marble_Brick"
    },
    {
      "x": -10,
      "y": 1,
      "z": 4,
      "name": "Rock_Marble_Brick"
    },
    {
      "x": -10,
      "y": 0,
      "z": 5,
      "name": "Rock_Marble_Brick"
    },
    {
      "x": -10,
      "y": 1,
      "z": 5,
      "name": "Rock_Marble_Brick"
    },
    {
      "x": -10,
      "y": 0,
      "z": 6,
      "name": "Rock_Marble_Brick"
    },
    {
      "x": -10,
      "y": 1,
      "z": 6,
      "name": "Rock_Marble_Brick"
    },
    {
      "x": -10,
      "y": 0,
      "z": 7,
      "name": "Rock_Marble_Brick"
    },
    {
      "x": -10,
      "y": 1,
      "z": 7,
      "name": "Rock_Marble_Brick"
    },
    {
      "x": -10,
      "y": 0,
      "z": 8,
      "name": "Rock_Marble_Brick"
    },
    {
      "x": -10,
      "y": 1,
      "z": 8,
      "name": "Rock_Marble_Brick"
    },
    {
      "x": -10,
      "y": 0,
      "z": 9,
      "name": "Rock_Marble_Brick"
    },
    {
      "x": -10,
      "y": 1,
      "z": 9,
      "name": "Rock_Marble_Brick"
    },
    {
      "x": -10,
      "y": 0,
      "z": 10,
      "name": "Rock_Marble_Brick_Decorative"
    },
    {
      "x": -10,
      "y": 1,
      "z": 10,
      "name": "Rock_Marble_Brick_Decorative"
    },
    {
      "x": -9,
      "y": 0,
      "z": -10,
      "name": "Rock_Marble_Brick"
    },
    {
      "x": -9,
      "y": 1,
      "z": -10,
      "name": "Rock_Marble_Brick"
    },
    {
      "x": -9,
      "y": 0,
      "z": -9,
      "name": "Rock_Marble_Brick"
    },
    {
      "x": -9,
      "y": 1,
      "z": -9,
      "name": "BlueLED"
    },
    {
      "x": -9,
      "y": 0,
      "z": -8,
      "name": "Rock_Marble_Brick"
    },
    {
      "x": -9,
      "y": 1,
      "z": -8,
      "name": "BlueLED"
    },
    {
      "x": -9,
      "y": 0,
      "z": -7,
      "name": "Rock_Marble_Brick"
    },
    {
      "x": -9,
      "y": 1,
      "z": -7,
      "name": "BlueLED"
    },
    {
      "x": -9,
      "y": 0,
      "z": -6,
      "name": "Rock_Marble_Brick"
    },
    {
      "x": -9,
      "y": 1,
      "z": -6,
      "name": "BlueLED"
    },
    {
      "x": -9,
      "y": 9,
      "z": -6,
      "name": "Furniture_Temple_Light_Lantern_Ceiling"
    },
    {
      "x": -9,
      "y": 10,
      "z": -6,
      "name": "Rock_Marble_Brick_Decorative"
    },
    {
      "x": -9,
      "y": 0,
      "z": -5,
      "name": "Rock_Marble_Brick"
    },
    {
      "x": -9,
      "y": 1,
      "z": -5,
      "name": "BlueLED"
    },
    {
      "x": -9,
      "y": 0,
      "z": -4,
      "name": "Rock_Marble_Brick"
    },
    {
      "x": -9,
      "y": 1,
      "z": -4,
      "name": "BlueLED"
    },
    {
      "x": -9,
      "y": 0,
      "z": -3,
      "name": "Rock_Marble_Brick"
    },
    {
      "x": -9,
      "y": 1,
      "z": -3,
      "name": "BlueLED"
    },
    {
      "x": -9,
      "y": 0,
      "z": -2,
      "name": "Rock_Marble_Brick"
    },
    {
      "x": -9,
      "y": 1,
      "z": -2,
      "name": "BlueLED"
    },
    {
      "x": -9,
      "y": 0,
      "z": -1,
      "name": "Rock_Marble_Brick"
    },
    {
      "x": -9,
      "y": 1,
      "z": -1,
      "name": "BlueLED"
    },
    {
      "x": -9,
      "y": 0,
      "z": 0,
      "name": "Rock_Marble_Brick"
    },
    {
      "x": -9,
      "y": 1,
      "z": 0,
      "name": "BlueLED"
    },
    {
      "x": -9,
      "y": 0,
      "z": 1,
      "name": "Rock_Marble_Brick"
    },
    {
      "x": -9,
      "y": 1,
      "z": 1,
      "name": "BlueLED"
    },
    {
      "x": -9,
      "y": 9,
      "z": 1,
      "name": "Furniture_Temple_Light_Lantern_Ceiling"
    },
    {
      "x": -9,
      "y": 10,
      "z": 1,
      "name": "Rock_Marble_Brick_Decorative"
    },
    {
      "x": -9,
      "y": 0,
      "z": 2,
      "name": "Rock_Marble_Brick"
    },
    {
      "x": -9,
      "y": 1,
      "z": 2,
      "name": "BlueLED"
    },
    {
      "x": -9,
      "y": 0,
      "z": 3,
      "name": "Rock_Marble_Brick"
    },
    {
      "x": -9,
      "y": 1,
      "z": 3,
      "name": "Rock_Marble_Brick"
    },
    {
      "x": -9,
      "y": 0,
      "z": 4,
      "name": "Rock_Marble_Brick"
    },
    {
      "x": -9,
      "y": 1,
      "z": 4,
      "name": "Rock_Marble_Brick"
    },
    {
      "x": -9,
      "y": 0,
      "z": 5,
      "name": "Rock_Marble_Brick"
    },
    {
      "x": -9,
      "y": 1,
      "z": 5,
      "name": "Rock_Marble_Brick"
    },
    {
      "x": -9,
      "y": 0,
      "z": 6,
      "name": "Rock_Marble_Brick"
    },
    {
      "x": -9,
      "y": 1,
      "z": 6,
      "name": "Rock_Marble_Brick"
    },
    {
      "x": -9,
      "y": 0,
      "z": 7,
      "name": "Rock_Marble_Brick"
    },
    {
      "x": -9,
      "y": 1,
      "z": 7,
      "name": "Rock_Marble_Brick"
    },
    {
      "x": -9,
      "y": 0,
      "z": 8,
      "name": "Rock_Marble_Brick"
    },
    {
      "x": -9,
      "y": 1,
      "z": 8,
      "name": "Rock_Marble_Brick"
    },
    {
      "x": -9,
      "y": 0,
      "z": 9,
      "name": "Rock_Marble_Brick"
    },
    {
      "x": -9,
      "y": 1,
      "z": 9,
      "name": "Rock_Marble_Brick"
    },
    {
      "x": -9,
      "y": 0,
      "z": 10,
      "name": "Rock_Marble_Brick"
    },
    {
      "x": -9,
      "y": 1,
      "z": 10,
      "name": "Rock_Marble_Brick"
    },
    {
      "x": -8,
      "y": 0,
      "z": -10,
      "name": "Rock_Marble_Brick"
    },
    {
      "x": -8,
      "y": 1,
      "z": -10,
      "name": "Rock_Marble_Brick"
    },
    {
      "x": -8,
      "y": 0,
      "z": -9,
      "name": "Rock_Marble_Brick"
    },
    {
      "x": -8,
      "y": 1,
      "z": -9,
      "name": "BlueLED"
    },
    {
      "x": -8,
      "y": 0,
      "z": -8,
      "name": "Rock_Marble_Brick"
    },
    {
      "x": -8,
      "y": 1,
      "z": -8,
      "name": "Rock_Marble_Brick"
    },
    {
      "x": -8,
      "y": 6,
      "z": -8,
      "name": "*Rock_Marble_Brick_Roof_Shallow_State_Definitions_Corner_Left",
      "rotation": 2
    },
    {
      "x": -8,
      "y": 0,
      "z": -7,
      "name": "Rock_Marble_Brick"
    },
    {
      "x": -8,
      "y": 1,
      "z": -7,
      "name": "Rock_Marble_Brick"
    },
    {
      "x": -8,
      "y": 5,
      "z": -7,
      "name": "Rock_Marble_Brick_Beam",
      "rotation": 5
    },
    {
      "x": -8,
      "y": 6,
      "z": -7,
      "name": "*Rock_Marble_Brick_Roof_Shallow_State_Definitions_Corner_Left",
      "filler": 32,
      "rotation": 2
    },
    {
      "x": -8,
      "y": 0,
      "z": -6,
      "name": "Rock_Marble_Brick"
    },
    {
      "x": -8,
      "y": 1,
      "z": -6,
      "name": "Rock_Marble_Brick"
    },
    {
      "x": -8,
      "y": 6,
      "z": -6,
      "name": "Rock_Marble_Brick_Roof_Shallow",
      "rotation": 3
    },
    {
      "x": -8,
      "y": 10,
      "z": -6,
      "name": "Rock_Marble_Brick_Beam",
      "rotation": 5
    },
    {
      "x": -8,
      "y": 0,
      "z": -5,
      "name": "Rock_Marble_Brick"
    },
    {
      "x": -8,
      "y": 1,
      "z": -5,
      "name": "Rock_Marble_Brick"
    },
    {
      "x": -8,
      "y": 6,
      "z": -5,
      "name": "Rock_Marble_Brick_Roof_Shallow",
      "rotation": 3
    },
    {
      "x": -8,
      "y": 0,
      "z": -4,
      "name": "Rock_Marble_Brick"
    },
    {
      "x": -8,
      "y": 1,
      "z": -4,
      "name": "Rock_Marble_Brick"
    },
    {
      "x": -8,
      "y": 6,
      "z": -4,
      "name": "Rock_Marble_Brick_Roof_Shallow",
      "rotation": 3
    },
    {
      "x": -8,
      "y": 0,
      "z": -3,
      "name": "Rock_Marble_Brick"
    },
    {
      "x": -8,
      "y": 1,
      "z": -3,
      "name": "Rock_Marble_Brick"
    },
    {
      "x": -8,
      "y": 6,
      "z": -3,
      "name": "Rock_Marble_Brick_Roof_Shallow",
      "rotation": 3
    },
    {
      "x": -8,
      "y": 0,
      "z": -2,
      "name": "Rock_Marble_Brick"
    },
    {
      "x": -8,
      "y": 1,
      "z": -2,
      "name": "Rock_Marble_Brick"
    },
    {
      "x": -8,
      "y": 6,
      "z": -2,
      "name": "Rock_Marble_Brick_Roof_Shallow",
      "rotation": 3
    },
    {
      "x": -8,
      "y": 0,
      "z": -1,
      "name": "Rock_Marble_Brick"
    },
    {
      "x": -8,
      "y": 1,
      "z": -1,
      "name": "Rock_Marble_Brick"
    },
    {
      "x": -8,
      "y": 6,
      "z": -1,
      "name": "Rock_Marble_Brick_Roof_Shallow",
      "rotation": 3
    },
    {
      "x": -8,
      "y": 0,
      "z": 0,
      "name": "Rock_Marble_Brick"
    },
    {
      "x": -8,
      "y": 1,
      "z": 0,
      "name": "Rock_Marble_Brick"
    },
    {
      "x": -8,
      "y": 6,
      "z": 0,
      "name": "Rock_Marble_Brick_Roof_Shallow",
      "rotation": 3
    },
    {
      "x": -8,
      "y": 0,
      "z": 1,
      "name": "Rock_Marble_Brick"
    },
    {
      "x": -8,
      "y": 1,
      "z": 1,
      "name": "Rock_Marble_Brick"
    },
    {
      "x": -8,
      "y": 6,
      "z": 1,
      "name": "Rock_Marble_Brick_Roof_Shallow",
      "rotation": 3
    },
    {
      "x": -8,
      "y": 10,
      "z": 1,
      "name": "Rock_Marble_Brick_Beam",
      "rotation": 5
    },
    {
      "x": -8,
      "y": 0,
      "z": 2,
      "name": "Rock_Marble_Brick"
    },
    {
      "x": -8,
      "y": 1,
      "z": 2,
      "name": "Rock_Marble_Brick"
    },
    {
      "x": -8,
      "y": 5,
      "z": 2,
      "name": "Rock_Marble_Brick_Beam",
      "rotation": 5
    },
    {
      "x": -8,
      "y": 6,
      "z": 2,
      "name": "*Rock_Marble_Brick_Roof_Shallow_State_Definitions_Corner_Left",
      "filler": 992,
      "rotation": 3
    },
    {
      "x": -8,
      "y": 0,
      "z": 3,
      "name": "Rock_Marble_Brick"
    },
    {
      "x": -8,
      "y": 1,
      "z": 3,
      "name": "Rock_Marble_Brick"
    },
    {
      "x": -8,
      "y": 6,
      "z": 3,
      "name": "*Rock_Marble_Brick_Roof_Shallow_State_Definitions_Corner_Left",
      "rotation": 3
    },
    {
      "x": -8,
      "y": 0,
      "z": 4,
      "name": "Rock_Marble_Brick"
    },
    {
      "x": -8,
      "y": 1,
      "z": 4,
      "name": "Rock_Marble_Brick"
    },
    {
      "x": -8,
      "y": 0,
      "z": 5,
      "name": "Rock_Marble_Brick"
    },
    {
      "x": -8,
      "y": 1,
      "z": 5,
      "name": "Rock_Marble_Brick"
    },
    {
      "x": -8,
      "y": 0,
      "z": 6,
      "name": "Rock_Marble_Brick"
    },
    {
      "x": -8,
      "y": 1,
      "z": 6,
      "name": "Rock_Marble_Brick"
    },
    {
      "x": -8,
      "y": 0,
      "z": 7,
      "name": "Rock_Marble_Brick"
    },
    {
      "x": -8,
      "y": 1,
      "z": 7,
      "name": "Rock_Marble_Brick"
    },
    {
      "x": -8,
      "y": 0,
      "z": 8,
      "name": "Rock_Marble_Brick"
    },
    {
      "x": -8,
      "y": 1,
      "z": 8,
      "name": "Rock_Marble_Brick"
    },
    {
      "x": -8,
      "y": 2,
      "z": 8,
      "name": "Rock_Marble_Brick_Pillar_Base"
    },
    {
      "x": -8,
      "y": 3,
      "z": 8,
      "name": "Rock_Marble_Brick_Pillar_Middle"
    },
    {
      "x": -8,
      "y": 4,
      "z": 8,
      "name": "Rock_Marble_Brick_Pillar_Middle"
    },
    {
      "x": -8,
      "y": 5,
      "z": 8,
      "name": "Furniture_Temple_Light_Statue"
    },
    {
      "x": -8,
      "y": 6,
      "z": 8,
      "name": "Furniture_Temple_Light_Statue",
      "filler": 1024
    },
    {
      "x": -8,
      "y": 7,
      "z": 8,
      "name": "Furniture_Temple_Light_Statue",
      "filler": 2048
    },
    {
      "x": -8,
      "y": 0,
      "z": 9,
      "name": "Rock_Marble_Brick"
    },
    {
      "x": -8,
      "y": 1,
      "z": 9,
      "name": "Rock_Marble_Brick"
    },
    {
      "x": -8,
      "y": 2,
      "z": 9,
      "name": "Furniture_Temple_Light_Brazier"
    },
    {
      "x": -8,
      "y": 0,
      "z": 10,
      "name": "Rock_Marble_Brick"
    },
    {
      "x": -8,
      "y": 1,
      "z": 10,
      "name": "Rock_Marble_Brick_Ornate"
    },
    {
      "x": -7,
      "y": 0,
      "z": -10,
      "name": "Rock_Marble_Brick"
    },
    {
      "x": -7,
      "y": 1,
      "z": -10,
      "name": "Rock_Marble_Brick"
    },
    {
      "x": -7,
      "y": 0,
      "z": -9,
      "name": "Rock_Marble_Brick"
    },
    {
      "x": -7,
      "y": 1,
      "z": -9,
      "name": "BlueLED"
    },
    {
      "x": -7,
      "y": 0,
      "z": -8,
      "name": "Rock_Marble_Brick"
    },
    {
      "x": -7,
      "y": 1,
      "z": -8,
      "name": "Rock_Marble_Brick"
    },
    {
      "x": -7,
      "y": 5,
      "z": -8,
      "name": "Rock_Marble_Brick_Beam",
      "rotation": 4
    },
    {
      "x": -7,
      "y": 6,
      "z": -8,
      "name": "*Rock_Marble_Brick_Roof_Shallow_State_Definitions_Corner_Left",
      "filler": 1,
      "rotation": 2
    },
    {
      "x": -7,
      "y": 0,
      "z": -7,
      "name": "Rock_Marble_Brick"
    },
    {
      "x": -7,
      "y": 1,
      "z": -7,
      "name": "Rock_Marble_Brick"
    },
    {
      "x": -7,
      "y": 2,
      "z": -7,
      "name": "Rock_Marble_Brick_Decorative"
    },
    {
      "x": -7,
      "y": 3,
      "z": -7,
      "name": "Rock_Marble_Brick_Decorative"
    },
    {
      "x": -7,
      "y": 4,
      "z": -7,
      "name": "Rock_Marble_Brick_Decorative"
    },
    {
      "x": -7,
      "y": 5,
      "z": -7,
      "name": "Rock_Marble_Brick_Decorative"
    },
    {
      "x": -7,
      "y": 6,
      "z": -7,
      "name": "*Rock_Marble_Brick_Roof_Shallow_State_Definitions_Corner_Left",
      "filler": 33,
      "rotation": 2
    },
    {
      "x": -7,
      "y": 12,
      "z": -7,
      "name": "*Rock_Marble_Brick_Roof_Shallow_State_Definitions_Corner_Left",
      "rotation": 2
    },
    {
      "x": -7,
      "y": 0,
      "z": -6,
      "name": "Rock_Marble_Brick"
    },
    {
      "x": -7,
      "y": 1,
      "z": -6,
      "name": "Rock_Marble_Brick"
    },
    {
      "x": -7,
      "y": 2,
      "z": -6,
      "name": "Rock_Marble_Brick_Smooth"
    },
    {
      "x": -7,
      "y": 3,
      "z": -6,
      "name": "Rock_Marble_Brick_Decorative"
    },
    {
      "x": -7,
      "y": 4,
      "z": -6,
      "name": "Rock_Marble_Brick_Smooth"
    },
    {
      "x": -7,
      "y": 5,
      "z": -6,
      "name": "Rock_Marble_Brick_Wall",
      "rotation": 1
    },
    {
      "x": -7,
      "y": 6,
      "z": -6,
      "name": "Rock_Marble_Brick_Roof_Shallow",
      "filler": 1,
      "rotation": 3
    },
    {
      "x": -7,
      "y": 10,
      "z": -6,
      "name": "Rock_Marble_Brick_Beam",
      "rotation": 5
    },
    {
      "x": -7,
      "y": 12,
      "z": -6,
      "name": "*Rock_Marble_Brick_Roof_Shallow_State_Definitions_Corner_Left",
      "filler": 32,
      "rotation": 2
    },
    {
      "x": -7,
      "y": 0,
      "z": -5,
      "name": "Rock_Marble_Brick"
    },
    {
      "x": -7,
      "y": 1,
      "z": -5,
      "name": "Rock_Marble_Brick"
    },
    {
      "x": -7,
      "y": 2,
      "z": -5,
      "name": "Rock_Marble_Brick_Smooth"
    },
    {
      "x": -7,
      "y": 3,
      "z": -5,
      "name": "Rock_Marble_Brick_Smooth"
    },
    {
      "x": -7,
      "y": 4,
      "z": -5,
      "name": "Rock_Marble_Brick_Smooth"
    },
    {
      "x": -7,
      "y": 5,
      "z": -5,
      "name": "Rock_Marble_Brick_Wall",
      "rotation": 1
    },
    {
      "x": -7,
      "y": 6,
      "z": -5,
      "name": "Rock_Marble_Brick_Roof_Shallow",
      "filler": 1,
      "rotation": 3
    },
    {
      "x": -7,
      "y": 12,
      "z": -5,
      "name": "Rock_Marble_Brick_Roof_Shallow",
      "rotation": 3
    },
    {
      "x": -7,
      "y": 0,
      "z": -4,
      "name": "Rock_Marble_Brick"
    },
    {
      "x": -7,
      "y": 1,
      "z": -4,
      "name": "Rock_Marble_Brick"
    },
    {
      "x": -7,
      "y": 2,
      "z": -4,
      "name": "Rock_Marble_Brick_Smooth"
    },
    {
      "x": -7,
      "y": 3,
      "z": -4,
      "name": "Rock_Marble_Brick_Smooth"
    },
    {
      "x": -7,
      "y": 4,
      "z": -4,
      "name": "Rock_Marble_Brick_Smooth"
    },
    {
      "x": -7,
      "y": 5,
      "z": -4,
      "name": "Rock_Marble_Brick_Wall",
      "rotation": 1
    },
    {
      "x": -7,
      "y": 6,
      "z": -4,
      "name": "Rock_Marble_Brick_Roof_Shallow",
      "filler": 1,
      "rotation": 3
    },
    {
      "x": -7,
      "y": 12,
      "z": -4,
      "name": "Rock_Marble_Brick_Roof_Shallow",
      "rotation": 3
    },
    {
      "x": -7,
      "y": 0,
      "z": -3,
      "name": "Rock_Marble_Brick"
    },
    {
      "x": -7,
      "y": 1,
      "z": -3,
      "name": "Rock_Marble_Brick"
    },
    {
      "x": -7,
      "y": 2,
      "z": -3,
      "name": "Rock_Marble_Brick_Smooth"
    },
    {
      "x": -7,
      "y": 3,
      "z": -3,
      "name": "Rock_Marble_Brick_Smooth"
    },
    {
      "x": -7,
      "y": 4,
      "z": -3,
      "name": "Rock_Marble_Brick_Smooth"
    },
    {
      "x": -7,
      "y": 5,
      "z": -3,
      "name": "Rock_Marble_Brick_Wall",
      "rotation": 1
    },
    {
      "x": -7,
      "y": 6,
      "z": -3,
      "name": "Rock_Marble_Brick_Roof_Shallow",
      "filler": 1,
      "rotation": 3
    },
    {
      "x": -7,
      "y": 12,
      "z": -3,
      "name": "Rock_Marble_Brick_Roof_Shallow",
      "rotation": 3
    },
    {
      "x": -7,
      "y": 0,
      "z": -2,
      "name": "Rock_Marble_Brick"
    },
    {
      "x": -7,
      "y": 1,
      "z": -2,
      "name": "Rock_Marble_Brick"
    },
    {
      "x": -7,
      "y": 2,
      "z": -2,
      "name": "Rock_Marble_Brick_Smooth"
    },
    {
      "x": -7,
      "y": 3,
      "z": -2,
      "name": "Rock_Marble_Brick_Smooth"
    },
    {
      "x": -7,
      "y": 4,
      "z": -2,
      "name": "Rock_Marble_Brick_Smooth"
    },
    {
      "x": -7,
      "y": 5,
      "z": -2,
      "name": "Rock_Marble_Brick_Wall",
      "rotation": 1
    },
    {
      "x": -7,
      "y": 6,
      "z": -2,
      "name": "Rock_Marble_Brick_Roof_Shallow",
      "filler": 1,
      "rotation": 3
    },
    {
      "x": -7,
      "y": 12,
      "z": -2,
      "name": "Rock_Marble_Brick_Roof_Shallow",
      "rotation": 3
    },
    {
      "x": -7,
      "y": 0,
      "z": -1,
      "name": "Rock_Marble_Brick"
    },
    {
      "x": -7,
      "y": 1,
      "z": -1,
      "name": "Rock_Marble_Brick"
    },
    {
      "x": -7,
      "y": 2,
      "z": -1,
      "name": "Rock_Marble_Brick_Smooth"
    },
    {
      "x": -7,
      "y": 3,
      "z": -1,
      "name": "Rock_Marble_Brick_Smooth"
    },
    {
      "x": -7,
      "y": 4,
      "z": -1,
      "name": "Rock_Marble_Brick_Smooth"
    },
    {
      "x": -7,
      "y": 5,
      "z": -1,
      "name": "Rock_Marble_Brick_Wall",
      "rotation": 1
    },
    {
      "x": -7,
      "y": 6,
      "z": -1,
      "name": "Rock_Marble_Brick_Roof_Shallow",
      "filler": 1,
      "rotation": 3
    },
    {
      "x": -7,
      "y": 12,
      "z": -1,
      "name": "Rock_Marble_Brick_Roof_Shallow",
      "rotation": 3
    },
    {
      "x": -7,
      "y": 0,
      "z": 0,
      "name": "Rock_Marble_Brick"
    },
    {
      "x": -7,
      "y": 1,
      "z": 0,
      "name": "Rock_Marble_Brick"
    },
    {
      "x": -7,
      "y": 2,
      "z": 0,
      "name": "Rock_Marble_Brick_Smooth"
    },
    {
      "x": -7,
      "y": 3,
      "z": 0,
      "name": "Rock_Marble_Brick_Smooth"
    },
    {
      "x": -7,
      "y": 4,
      "z": 0,
      "name": "Rock_Marble_Brick_Smooth"
    },
    {
      "x": -7,
      "y": 5,
      "z": 0,
      "name": "Rock_Marble_Brick_Wall",
      "rotation": 1
    },
    {
      "x": -7,
      "y": 6,
      "z": 0,
      "name": "Rock_Marble_Brick_Roof_Shallow",
      "filler": 1,
      "rotation": 3
    },
    {
      "x": -7,
      "y": 12,
      "z": 0,
      "name": "Rock_Marble_Brick_Roof_Shallow",
      "rotation": 3
    },
    {
      "x": -7,
      "y": 0,
      "z": 1,
      "name": "Rock_Marble_Brick"
    },
    {
      "x": -7,
      "y": 1,
      "z": 1,
      "name": "Rock_Marble_Brick"
    },
    {
      "x": -7,
      "y": 2,
      "z": 1,
      "name": "Rock_Marble_Brick_Smooth"
    },
    {
      "x": -7,
      "y": 3,
      "z": 1,
      "name": "Rock_Marble_Brick_Decorative"
    },
    {
      "x": -7,
      "y": 4,
      "z": 1,
      "name": "Rock_Marble_Brick_Smooth"
    },
    {
      "x": -7,
      "y": 5,
      "z": 1,
      "name": "Rock_Marble_Brick_Wall",
      "rotation": 1
    },
    {
      "x": -7,
      "y": 6,
      "z": 1,
      "name": "Rock_Marble_Brick_Roof_Shallow",
      "filler": 1,
      "rotation": 3
    },
    {
      "x": -7,
      "y": 10,
      "z": 1,
      "name": "Rock_Marble_Brick_Beam",
      "rotation": 5
    },
    {
      "x": -7,
      "y": 12,
      "z": 1,
      "name": "*Rock_Marble_Brick_Roof_Shallow_State_Definitions_Corner_Left",
      "filler": 992,
      "rotation": 3
    },
    {
      "x": -7,
      "y": 0,
      "z": 2,
      "name": "Rock_Marble_Brick"
    },
    {
      "x": -7,
      "y": 1,
      "z": 2,
      "name": "Rock_Marble_Brick"
    },
    {
      "x": -7,
      "y": 2,
      "z": 2,
      "name": "Rock_Marble_Brick_Decorative"
    },
    {
      "x": -7,
      "y": 3,
      "z": 2,
      "name": "Rock_Marble_Brick_Decorative"
    },
    {
      "x": -7,
      "y": 4,
      "z": 2,
      "name": "Rock_Marble_Brick_Decorative"
    },
    {
      "x": -7,
      "y": 5,
      "z": 2,
      "name": "Rock_Marble_Brick_Decorative"
    },
    {
      "x": -7,
      "y": 6,
      "z": 2,
      "name": "*Rock_Marble_Brick_Roof_Shallow_State_Definitions_Corner_Left",
      "filler": 993,
      "rotation": 3
    },
    {
      "x": -7,
      "y": 12,
      "z": 2,
      "name": "*Rock_Marble_Brick_Roof_Shallow_State_Definitions_Corner_Left",
      "rotation": 3
    },
    {
      "x": -7,
      "y": 0,
      "z": 3,
      "name": "Rock_Marble_Brick"
    },
    {
      "x": -7,
      "y": 1,
      "z": 3,
      "name": "Rock_Marble_Brick"
    },
    {
      "x": -7,
      "y": 5,
      "z": 3,
      "name": "Rock_Marble_Brick_Beam",
      "rotation": 4
    },
    {
      "x": -7,
      "y": 6,
      "z": 3,
      "name": "*Rock_Marble_Brick_Roof_Shallow_State_Definitions_Corner_Left",
      "filler": 1,
      "rotation": 3
    },
    {
      "x": -7,
      "y": 0,
      "z": 4,
      "name": "Rock_Marble_Brick"
    },
    {
      "x": -7,
      "y": 1,
      "z": 4,
      "name": "Rock_Marble_Brick"
    },
    {
      "x": -7,
      "y": 6,
      "z": 4,
      "name": "*Furniture_Temple_Light_Trapdoor_State_Definitions_OpenDoorOut",
      "rotation": 2
    },
    {
      "x": -7,
      "y": 0,
      "z": 5,
      "name": "Rock_Marble_Brick"
    },
    {
      "x": -7,
      "y": 1,
      "z": 5,
      "name": "Rock_Marble_Brick"
    },
    {
      "x": -7,
      "y": 6,
      "z": 5,
      "name": "Rock_Marble_Brick_Smooth"
    },
    {
      "x": -7,
      "y": 0,
      "z": 6,
      "name": "Rock_Marble_Brick"
    },
    {
      "x": -7,
      "y": 1,
      "z": 6,
      "name": "Rock_Marble_Brick"
    },
    {
      "x": -7,
      "y": 6,
      "z": 6,
      "name": "*Furniture_Temple_Light_Trapdoor_State_Definitions_OpenDoorOut"
    },
    {
      "x": -7,
      "y": 0,
      "z": 7,
      "name": "Rock_Marble_Brick"
    },
    {
      "x": -7,
      "y": 1,
      "z": 7,
      "name": "Rock_Marble_Brick"
    },
    {
      "x": -7,
      "y": 0,
      "z": 8,
      "name": "Rock_Marble_Brick"
    },
    {
      "x": -7,
      "y": 1,
      "z": 8,
      "name": "Rock_Marble_Brick"
    },
    {
      "x": -7,
      "y": 0,
      "z": 9,
      "name": "Rock_Marble_Brick"
    },
    {
      "x": -7,
      "y": 1,
      "z": 9,
      "name": "Rock_Marble_Brick"
    },
    {
      "x": -7,
      "y": 0,
      "z": 10,
      "name": "Rock_Marble_Brick"
    },
    {
      "x": -7,
      "y": 1,
      "z": 10,
      "name": "Rock_Marble_Brick"
    },
    {
      "x": -6,
      "y": 0,
      "z": -10,
      "name": "Rock_Marble_Brick"
    },
    {
      "x": -6,
      "y": 1,
      "z": -10,
      "name": "Rock_Marble_Brick"
    },
    {
      "x": -6,
      "y": 0,
      "z": -9,
      "name": "Rock_Marble_Brick"
    },
    {
      "x": -6,
      "y": 1,
      "z": -9,
      "name": "BlueLED"
    },
    {
      "x": -6,
      "y": 9,
      "z": -9,
      "name": "Furniture_Temple_Light_Lantern_Ceiling"
    },
    {
      "x": -6,
      "y": 10,
      "z": -9,
      "name": "Rock_Marble_Brick_Decorative"
    },
    {
      "x": -6,
      "y": 0,
      "z": -8,
      "name": "Rock_Marble_Brick"
    },
    {
      "x": -6,
      "y": 1,
      "z": -8,
      "name": "Rock_Marble_Brick"
    },
    {
      "x": -6,
      "y": 6,
      "z": -8,
      "name": "Rock_Marble_Brick_Roof_Shallow",
      "rotation": 2
    },
    {
      "x": -6,
      "y": 10,
      "z": -8,
      "name": "Rock_Marble_Brick_Beam",
      "rotation": 4
    },
    {
      "x": -6,
      "y": 0,
      "z": -7,
      "name": "Rock_Marble_Brick"
    },
    {
      "x": -6,
      "y": 1,
      "z": -7,
      "name": "Rock_Marble_Brick"
    },
    {
      "x": -6,
      "y": 2,
      "z": -7,
      "name": "Rock_Marble_Brick_Smooth"
    },
    {
      "x": -6,
      "y": 3,
      "z": -7,
      "name": "Rock_Marble_Brick_Decorative"
    },
    {
      "x": -6,
      "y": 4,
      "z": -7,
      "name": "Rock_Marble_Brick_Smooth"
    },
    {
      "x": -6,
      "y": 5,
      "z": -7,
      "name": "Rock_Marble_Brick_Wall"
    },
    {
      "x": -6,
      "y": 6,
      "z": -7,
      "name": "Rock_Marble_Brick_Roof_Shallow",
      "filler": 32,
      "rotation": 2
    },
    {
      "x": -6,
      "y": 10,
      "z": -7,
      "name": "Rock_Marble_Brick_Beam",
      "rotation": 4
    },
    {
      "x": -6,
      "y": 12,
      "z": -7,
      "name": "*Rock_Marble_Brick_Roof_Shallow_State_Definitions_Corner_Left",
      "filler": 1,
      "rotation": 2
    },
    {
      "x": -6,
      "y": 0,
      "z": -6,
      "name": "Rock_Marble_Brick"
    },
    {
      "x": -6,
      "y": 1,
      "z": -6,
      "name": "Rock_Marble_Brick"
    },
    {
      "x": -6,
      "y": 7,
      "z": -6,
      "name": "Rock_Marble_Brick_Decorative"
    },
    {
      "x": -6,
      "y": 8,
      "z": -6,
      "name": "Rock_Marble_Brick_Smooth"
    },
    {
      "x": -6,
      "y": 9,
      "z": -6,
      "name": "Rock_Marble_Brick_Smooth"
    },
    {
      "x": -6,
      "y": 10,
      "z": -6,
      "name": "Rock_Marble_Brick_Smooth"
    },
    {
      "x": -6,
      "y": 11,
      "z": -6,
      "name": "Rock_Marble_Brick_Decorative"
    },
    {
      "x": -6,
      "y": 12,
      "z": -6,
      "name": "*Rock_Marble_Brick_Roof_Shallow_State_Definitions_Corner_Left",
      "filler": 33,
      "rotation": 2
    },
    {
      "x": -6,
      "y": 13,
      "z": -6,
      "name": "*Rock_Marble_Brick_Roof_Shallow_State_Definitions_Corner_Right",
      "rotation": 3
    },
    {
      "x": -6,
      "y": 0,
      "z": -5,
      "name": "Rock_Marble_Brick"
    },
    {
      "x": -6,
      "y": 1,
      "z": -5,
      "name": "Rock_Marble_Brick"
    },
    {
      "x": -6,
      "y": 7,
      "z": -5,
      "name": "Rock_Marble_Brick_Decorative"
    },
    {
      "x": -6,
      "y": 8,
      "z": -5,
      "name": "Rock_Marble_Brick_Smooth"
    },
    {
      "x": -6,
      "y": 9,
      "z": -5,
      "name": "Rock_Marble_Brick_Smooth"
    },
    {
      "x": -6,
      "y": 10,
      "z": -5,
      "name": "Rock_Marble_Brick_Smooth"
    },
    {
      "x": -6,
      "y": 11,
      "z": -5,
      "name": "Rock_Marble_Brick_Wall",
      "rotation": 1
    },
    {
      "x": -6,
      "y": 12,
      "z": -5,
      "name": "Rock_Marble_Brick_Roof_Shallow",
      "filler": 1,
      "rotation": 3
    },
    {
      "x": -6,
      "y": 13,
      "z": -5,
      "name": "*Rock_Marble_Brick_Roof_Shallow_State_Definitions_Corner_Right",
      "filler": 32,
      "rotation": 3
    },
    {
      "x": -6,
      "y": 0,
      "z": -4,
      "name": "Rock_Marble_Brick"
    },
    {
      "x": -6,
      "y": 1,
      "z": -4,
      "name": "Rock_Marble_Brick"
    },
    {
      "x": -6,
      "y": 7,
      "z": -4,
      "name": "Rock_Marble_Brick_Decorative"
    },
    {
      "x": -6,
      "y": 8,
      "z": -4,
      "name": "Rock_Marble_Brick_Smooth"
    },
    {
      "x": -6,
      "y": 9,
      "z": -4,
      "name": "Rock_Marble_Brick_Smooth"
    },
    {
      "x": -6,
      "y": 10,
      "z": -4,
      "name": "Rock_Marble_Brick_Smooth"
    },
    {
      "x": -6,
      "y": 11,
      "z": -4,
      "name": "Rock_Marble_Brick_Wall",
      "rotation": 1
    },
    {
      "x": -6,
      "y": 12,
      "z": -4,
      "name": "Rock_Marble_Brick_Roof_Shallow",
      "filler": 1,
      "rotation": 3
    },
    {
      "x": -6,
      "y": 13,
      "z": -4,
      "name": "Rock_Marble_Brick_Roof_Shallow",
      "rotation": 3
    },
    {
      "x": -6,
      "y": 0,
      "z": -3,
      "name": "Rock_Marble_Brick"
    },
    {
      "x": -6,
      "y": 1,
      "z": -3,
      "name": "Rock_Marble_Brick"
    },
    {
      "x": -6,
      "y": 7,
      "z": -3,
      "name": "Rock_Marble_Brick_Decorative"
    },
    {
      "x": -6,
      "y": 8,
      "z": -3,
      "name": "Rock_Marble_Brick_Smooth"
    },
    {
      "x": -6,
      "y": 9,
      "z": -3,
      "name": "Rock_Marble_Brick_Smooth"
    },
    {
      "x": -6,
      "y": 10,
      "z": -3,
      "name": "Rock_Marble_Brick_Smooth"
    },
    {
      "x": -6,
      "y": 11,
      "z": -3,
      "name": "Rock_Marble_Brick_Wall",
      "rotation": 1
    },
    {
      "x": -6,
      "y": 12,
      "z": -3,
      "name": "Rock_Marble_Brick_Roof_Shallow",
      "filler": 1,
      "rotation": 3
    },
    {
      "x": -6,
      "y": 13,
      "z": -3,
      "name": "Rock_Marble_Brick_Roof_Shallow",
      "rotation": 3
    },
    {
      "x": -6,
      "y": 0,
      "z": -2,
      "name": "Rock_Marble_Brick"
    },
    {
      "x": -6,
      "y": 1,
      "z": -2,
      "name": "Rock_Marble_Brick"
    },
    {
      "x": -6,
      "y": 7,
      "z": -2,
      "name": "Rock_Marble_Brick_Decorative"
    },
    {
      "x": -6,
      "y": 8,
      "z": -2,
      "name": "Rock_Marble_Brick_Smooth"
    },
    {
      "x": -6,
      "y": 9,
      "z": -2,
      "name": "Rock_Marble_Brick_Smooth"
    },
    {
      "x": -6,
      "y": 10,
      "z": -2,
      "name": "Rock_Marble_Brick_Smooth"
    },
    {
      "x": -6,
      "y": 11,
      "z": -2,
      "name": "Rock_Marble_Brick_Wall",
      "rotation": 1
    },
    {
      "x": -6,
      "y": 12,
      "z": -2,
      "name": "Rock_Marble_Brick_Roof_Shallow",
      "filler": 1,
      "rotation": 3
    },
    {
      "x": -6,
      "y": 13,
      "z": -2,
      "name": "Rock_Marble_Brick_Roof_Shallow",
      "rotation": 3
    },
    {
      "x": -6,
      "y": 0,
      "z": -1,
      "name": "Rock_Marble_Brick"
    },
    {
      "x": -6,
      "y": 1,
      "z": -1,
      "name": "Rock_Marble_Brick"
    },
    {
      "x": -6,
      "y": 7,
      "z": -1,
      "name": "Rock_Marble_Brick_Decorative"
    },
    {
      "x": -6,
      "y": 8,
      "z": -1,
      "name": "Rock_Marble_Brick_Smooth"
    },
    {
      "x": -6,
      "y": 9,
      "z": -1,
      "name": "Rock_Marble_Brick_Smooth"
    },
    {
      "x": -6,
      "y": 10,
      "z": -1,
      "name": "Rock_Marble_Brick_Smooth"
    },
    {
      "x": -6,
      "y": 11,
      "z": -1,
      "name": "Rock_Marble_Brick_Wall",
      "rotation": 1
    },
    {
      "x": -6,
      "y": 12,
      "z": -1,
      "name": "Rock_Marble_Brick_Roof_Shallow",
      "filler": 1,
      "rotation": 3
    },
    {
      "x": -6,
      "y": 13,
      "z": -1,
      "name": "Rock_Marble_Brick_Roof_Shallow",
      "rotation": 3
    },
    {
      "x": -6,
      "y": 0,
      "z": 0,
      "name": "Rock_Marble_Brick"
    },
    {
      "x": -6,
      "y": 1,
      "z": 0,
      "name": "Rock_Marble_Brick"
    },
    {
      "x": -6,
      "y": 7,
      "z": 0,
      "name": "Rock_Marble_Brick_Decorative"
    },
    {
      "x": -6,
      "y": 8,
      "z": 0,
      "name": "Rock_Marble_Brick_Smooth"
    },
    {
      "x": -6,
      "y": 9,
      "z": 0,
      "name": "Rock_Marble_Brick_Smooth"
    },
    {
      "x": -6,
      "y": 10,
      "z": 0,
      "name": "Rock_Marble_Brick_Smooth"
    },
    {
      "x": -6,
      "y": 11,
      "z": 0,
      "name": "Rock_Marble_Brick_Wall",
      "rotation": 1
    },
    {
      "x": -6,
      "y": 12,
      "z": 0,
      "name": "Rock_Marble_Brick_Roof_Shallow",
      "filler": 1,
      "rotation": 3
    },
    {
      "x": -6,
      "y": 13,
      "z": 0,
      "name": "*Rock_Marble_Brick_Roof_Shallow_State_Definitions_Corner_Right",
      "filler": 992
    },
    {
      "x": -6,
      "y": 0,
      "z": 1,
      "name": "Rock_Marble_Brick"
    },
    {
      "x": -6,
      "y": 1,
      "z": 1,
      "name": "Rock_Marble_Brick"
    },
    {
      "x": -6,
      "y": 7,
      "z": 1,
      "name": "Rock_Marble_Brick_Decorative"
    },
    {
      "x": -6,
      "y": 8,
      "z": 1,
      "name": "Rock_Marble_Brick_Smooth"
    },
    {
      "x": -6,
      "y": 9,
      "z": 1,
      "name": "Rock_Marble_Brick_Smooth"
    },
    {
      "x": -6,
      "y": 10,
      "z": 1,
      "name": "Rock_Marble_Brick_Smooth"
    },
    {
      "x": -6,
      "y": 11,
      "z": 1,
      "name": "Rock_Marble_Brick_Decorative"
    },
    {
      "x": -6,
      "y": 12,
      "z": 1,
      "name": "*Rock_Marble_Brick_Roof_Shallow_State_Definitions_Corner_Left",
      "filler": 993,
      "rotation": 3
    },
    {
      "x": -6,
      "y": 13,
      "z": 1,
      "name": "*Rock_Marble_Brick_Roof_Shallow_State_Definitions_Corner_Right"
    },
    {
      "x": -6,
      "y": 0,
      "z": 2,
      "name": "Rock_Marble_Brick"
    },
    {
      "x": -6,
      "y": 1,
      "z": 2,
      "name": "Rock_Marble_Brick"
    },
    {
      "x": -6,
      "y": 2,
      "z": 2,
      "name": "Rock_Marble_Brick_Smooth"
    },
    {
      "x": -6,
      "y": 3,
      "z": 2,
      "name": "Rock_Marble_Brick_Decorative"
    },
    {
      "x": -6,
      "y": 4,
      "z": 2,
      "name": "Rock_Marble_Brick_Smooth"
    },
    {
      "x": -6,
      "y": 5,
      "z": 2,
      "name": "Rock_Marble_Brick_Wall"
    },
    {
      "x": -6,
      "y": 6,
      "z": 2,
      "name": "Rock_Marble_Brick_Roof_Shallow",
      "filler": 992
    },
    {
      "x": -6,
      "y": 10,
      "z": 2,
      "name": "Rock_Marble_Brick_Beam",
      "rotation": 4
    },
    {
      "x": -6,
      "y": 12,
      "z": 2,
      "name": "*Rock_Marble_Brick_Roof_Shallow_State_Definitions_Corner_Left",
      "filler": 1,
      "rotation": 3
    },
    {
      "x": -6,
      "y": 0,
      "z": 3,
      "name": "Rock_Marble_Brick"
    },
    {
      "x": -6,
      "y": 1,
      "z": 3,
      "name": "Rock_Marble_Brick"
    },
    {
      "x": -6,
      "y": 6,
      "z": 3,
      "name": "Rock_Marble_Brick_Roof_Shallow"
    },
    {
      "x": -6,
      "y": 10,
      "z": 3,
      "name": "Rock_Marble_Brick_Beam",
      "rotation": 4
    },
    {
      "x": -6,
      "y": 0,
      "z": 4,
      "name": "Rock_Marble_Brick"
    },
    {
      "x": -6,
      "y": 1,
      "z": 4,
      "name": "Rock_Marble_Brick"
    },
    {
      "x": -6,
      "y": 9,
      "z": 4,
      "name": "Furniture_Temple_Light_Lantern_Ceiling"
    },
    {
      "x": -6,
      "y": 10,
      "z": 4,
      "name": "Rock_Marble_Brick_Decorative"
    },
    {
      "x": -6,
      "y": 0,
      "z": 5,
      "name": "Rock_Marble_Brick"
    },
    {
      "x": -6,
      "y": 1,
      "z": 5,
      "name": "Rock_Marble_Brick"
    },
    {
      "x": -6,
      "y": 6,
      "z": 5,
      "name": "Rock_Marble_Brick_Smooth"
    },
    {
      "x": -6,
      "y": 0,
      "z": 6,
      "name": "Rock_Marble_Brick"
    },
    {
      "x": -6,
      "y": 1,
      "z": 6,
      "name": "Rock_Marble_Brick"
    },
    {
      "x": -6,
      "y": 0,
      "z": 7,
      "name": "Rock_Marble_Brick"
    },
    {
      "x": -6,
      "y": 1,
      "z": 7,
      "name": "Rock_Marble_Brick"
    },
    {
      "x": -6,
      "y": 0,
      "z": 8,
      "name": "Rock_Marble_Brick"
    },
    {
      "x": -6,
      "y": 1,
      "z": 8,
      "name": "Rock_Marble_Brick"
    },
    {
      "x": -6,
      "y": 0,
      "z": 9,
      "name": "Rock_Marble_Brick"
    },
    {
      "x": -6,
      "y": 1,
      "z": 9,
      "name": "Rock_Marble_Brick"
    },
    {
      "x": -6,
      "y": 0,
      "z": 10,
      "name": "Rock_Marble_Brick_Decorative"
    },
    {
      "x": -6,
      "y": 1,
      "z": 10,
      "name": "Rock_Marble_Brick_Decorative"
    },
    {
      "x": -5,
      "y": 0,
      "z": -10,
      "name": "Rock_Marble_Brick"
    },
    {
      "x": -5,
      "y": 1,
      "z": -10,
      "name": "Rock_Marble_Brick"
    },
    {
      "x": -5,
      "y": 0,
      "z": -9,
      "name": "Rock_Marble_Brick"
    },
    {
      "x": -5,
      "y": 1,
      "z": -9,
      "name": "BlueLED"
    },
    {
      "x": -5,
      "y": 0,
      "z": -8,
      "name": "Rock_Marble_Brick"
    },
    {
      "x": -5,
      "y": 1,
      "z": -8,
      "name": "Rock_Marble_Brick"
    },
    {
      "x": -5,
      "y": 6,
      "z": -8,
      "name": "Rock_Marble_Brick_Roof_Shallow",
      "rotation": 2
    },
    {
      "x": -5,
      "y": 0,
      "z": -7,
      "name": "Rock_Marble_Brick"
    },
    {
      "x": -5,
      "y": 1,
      "z": -7,
      "name": "Rock_Marble_Brick"
    },
    {
      "x": -5,
      "y": 2,
      "z": -7,
      "name": "Rock_Marble_Brick_Smooth"
    },
    {
      "x": -5,
      "y": 3,
      "z": -7,
      "name": "Rock_Marble_Brick_Smooth"
    },
    {
      "x": -5,
      "y": 4,
      "z": -7,
      "name": "Rock_Marble_Brick_Smooth"
    },
    {
      "x": -5,
      "y": 5,
      "z": -7,
      "name": "Rock_Marble_Brick_Wall"
    },
    {
      "x": -5,
      "y": 6,
      "z": -7,
      "name": "Rock_Marble_Brick_Roof_Shallow",
      "filler": 32,
      "rotation": 2
    },
    {
      "x": -5,
      "y": 12,
      "z": -7,
      "name": "Rock_Marble_Brick_Roof_Shallow",
      "rotation": 2
    },
    {
      "x": -5,
      "y": 0,
      "z": -6,
      "name": "Rock_Marble_Brick"
    },
    {
      "x": -5,
      "y": 1,
      "z": -6,
      "name": "Rock_Marble_Brick"
    },
    {
      "x": -5,
      "y": 7,
      "z": -6,
      "name": "Rock_Marble_Brick_Decorative"
    },
    {
      "x": -5,
      "y": 8,
      "z": -6,
      "name": "Rock_Marble_Brick_Smooth"
    },
    {
      "x": -5,
      "y": 9,
      "z": -6,
      "name": "Rock_Marble_Brick_Smooth"
    },
    {
      "x": -5,
      "y": 10,
      "z": -6,
      "name": "Rock_Marble_Brick_Smooth"
    },
    {
      "x": -5,
      "y": 11,
      "z": -6,
      "name": "Rock_Marble_Brick_Wall"
    },
    {
      "x": -5,
      "y": 12,
      "z": -6,
      "name": "Rock_Marble_Brick_Roof_Shallow",
      "filler": 32,
      "rotation": 2
    },
    {
      "x": -5,
      "y": 13,
      "z": -6,
      "name": "*Rock_Marble_Brick_Roof_Shallow_State_Definitions_Corner_Right",
      "filler": 1,
      "rotation": 3
    },
    {
      "x": -5,
      "y": 0,
      "z": -5,
      "name": "Rock_Marble_Brick"
    },
    {
      "x": -5,
      "y": 1,
      "z": -5,
      "name": "Rock_Marble_Brick"
    },
    {
      "x": -5,
      "y": 2,
      "z": -5,
      "name": "Furniture_Temple_Light_Brazier"
    },
    {
      "x": -5,
      "y": 7,
      "z": -5,
      "name": "Rock_Marble_Brick_Decorative"
    },
    {
      "x": -5,
      "y": 13,
      "z": -5,
      "name": "*Rock_Marble_Brick_Roof_Shallow_State_Definitions_Corner_Right",
      "filler": 33,
      "rotation": 3
    },
    {
      "x": -5,
      "y": 14,
      "z": -5,
      "name": "*Rock_Marble_Brick_Roof_Shallow_State_Definitions_Corner_Right",
      "rotation": 3
    },
    {
      "x": -5,
      "y": 0,
      "z": -4,
      "name": "Rock_Marble_Brick"
    },
    {
      "x": -5,
      "y": 1,
      "z": -4,
      "name": "Rock_Marble_Brick"
    },
    {
      "x": -5,
      "y": 7,
      "z": -4,
      "name": "Rock_Marble_Brick_Decorative"
    },
    {
      "x": -5,
      "y": 13,
      "z": -4,
      "name": "Rock_Marble_Brick_Roof_Shallow",
      "filler": 1,
      "rotation": 3
    },
    {
      "x": -5,
      "y": 14,
      "z": -4,
      "name": "*Rock_Marble_Brick_Roof_Shallow_State_Definitions_Corner_Right",
      "filler": 32,
      "rotation": 3
    },
    {
      "x": -5,
      "y": 0,
      "z": -3,
      "name": "Rock_Marble_Brick"
    },
    {
      "x": -5,
      "y": 1,
      "z": -3,
      "name": "Rock_Marble_Brick"
    },
    {
      "x": -5,
      "y": 7,
      "z": -3,
      "name": "Rock_Marble_Brick_Decorative"
    },
    {
      "x": -5,
      "y": 13,
      "z": -3,
      "name": "Rock_Marble_Brick_Roof_Shallow",
      "filler": 1,
      "rotation": 3
    },
    {
      "x": -5,
      "y": 14,
      "z": -3,
      "name": "Rock_Marble_Brick_Roof_Shallow",
      "rotation": 3
    },
    {
      "x": -5,
      "y": 0,
      "z": -2,
      "name": "Rock_Marble_Brick"
    },
    {
      "x": -5,
      "y": 1,
      "z": -2,
      "name": "Rock_Marble_Brick"
    },
    {
      "x": -5,
      "y": 7,
      "z": -2,
      "name": "Rock_Marble_Brick_Decorative"
    },
    {
      "x": -5,
      "y": 13,
      "z": -2,
      "name": "Rock_Marble_Brick_Roof_Shallow",
      "filler": 1,
      "rotation": 3
    },
    {
      "x": -5,
      "y": 14,
      "z": -2,
      "name": "Rock_Marble_Brick_Roof_Shallow",
      "rotation": 3
    },
    {
      "x": -5,
      "y": 0,
      "z": -1,
      "name": "Rock_Marble_Brick"
    },
    {
      "x": -5,
      "y": 1,
      "z": -1,
      "name": "Rock_Marble_Brick"
    },
    {
      "x": -5,
      "y": 7,
      "z": -1,
      "name": "Rock_Marble_Brick_Decorative"
    },
    {
      "x": -5,
      "y": 13,
      "z": -1,
      "name": "Rock_Marble_Brick_Roof_Shallow",
      "filler": 1,
      "rotation": 3
    },
    {
      "x": -5,
      "y": 14,
      "z": -1,
      "name": "*Rock_Marble_Brick_Roof_Shallow_State_Definitions_Corner_Right",
      "filler": 992
    },
    {
      "x": -5,
      "y": 0,
      "z": 0,
      "name": "Rock_Marble_Brick"
    },
    {
      "x": -5,
      "y": 1,
      "z": 0,
      "name": "Rock_Marble_Brick"
    },
    {
      "x": -5,
      "y": 2,
      "z": 0,
      "name": "Furniture_Temple_Light_Brazier"
    },
    {
      "x": -5,
      "y": 7,
      "z": 0,
      "name": "Rock_Marble_Brick_Decorative"
    },
    {
      "x": -5,
      "y": 13,
      "z": 0,
      "name": "*Rock_Marble_Brick_Roof_Shallow_State_Definitions_Corner_Right",
      "filler": 993
    },
    {
      "x": -5,
      "y": 14,
      "z": 0,
      "name": "*Rock_Marble_Brick_Roof_Shallow_State_Definitions_Corner_Right"
    },
    {
      "x": -5,
      "y": 0,
      "z": 1,
      "name": "Rock_Marble_Brick"
    },
    {
      "x": -5,
      "y": 1,
      "z": 1,
      "name": "Rock_Marble_Brick"
    },
    {
      "x": -5,
      "y": 7,
      "z": 1,
      "name": "Rock_Marble_Brick_Decorative"
    },
    {
      "x": -5,
      "y": 8,
      "z": 1,
      "name": "Rock_Marble_Brick_Smooth"
    },
    {
      "x": -5,
      "y": 9,
      "z": 1,
      "name": "BlueLED"
    },
    {
      "x": -5,
      "y": 10,
      "z": 1,
      "name": "Rock_Marble_Brick_Smooth"
    },
    {
      "x": -5,
      "y": 11,
      "z": 1,
      "name": "Rock_Marble_Brick_Wall"
    },
    {
      "x": -5,
      "y": 12,
      "z": 1,
      "name": "Rock_Marble_Brick_Roof_Shallow",
      "filler": 992
    },
    {
      "x": -5,
      "y": 13,
      "z": 1,
      "name": "*Rock_Marble_Brick_Roof_Shallow_State_Definitions_Corner_Right",
      "filler": 1
    },
    {
      "x": -5,
      "y": 0,
      "z": 2,
      "name": "Rock_Marble_Brick"
    },
    {
      "x": -5,
      "y": 1,
      "z": 2,
      "name": "Rock_Marble_Brick"
    },
    {
      "x": -5,
      "y": 2,
      "z": 2,
      "name": "Rock_Marble_Brick_Smooth"
    },
    {
      "x": -5,
      "y": 3,
      "z": 2,
      "name": "Rock_Marble_Brick_Smooth"
    },
    {
      "x": -5,
      "y": 4,
      "z": 2,
      "name": "Rock_Marble_Brick_Smooth"
    },
    {
      "x": -5,
      "y": 5,
      "z": 2,
      "name": "Rock_Marble_Brick_Wall"
    },
    {
      "x": -5,
      "y": 6,
      "z": 2,
      "name": "Rock_Marble_Brick_Roof_Shallow",
      "filler": 992
    },
    {
      "x": -5,
      "y": 12,
      "z": 2,
      "name": "Rock_Marble_Brick_Roof_Shallow"
    },
    {
      "x": -5,
      "y": 0,
      "z": 3,
      "name": "Rock_Marble_Brick"
    },
    {
      "x": -5,
      "y": 1,
      "z": 3,
      "name": "Rock_Marble_Brick"
    },
    {
      "x": -5,
      "y": 6,
      "z": 3,
      "name": "Rock_Marble_Brick_Roof_Shallow"
    },
    {
      "x": -5,
      "y": 0,
      "z": 4,
      "name": "Rock_Marble_Brick"
    },
    {
      "x": -5,
      "y": 1,
      "z": 4,
      "name": "Rock_Marble_Brick"
    },
    {
      "x": -5,
      "y": 0,
      "z": 5,
      "name": "Rock_Marble_Brick"
    },
    {
      "x": -5,
      "y": 1,
      "z": 5,
      "name": "Rock_Marble_Brick"
    },
    {
      "x": -5,
      "y": 2,
      "z": 5,
      "name": "Rock_Marble_Brick_Pillar_Base"
    },
    {
      "x": -5,
      "y": 3,
      "z": 5,
      "name": "Rock_Marble_Brick_Pillar_Middle"
    },
    {
      "x": -5,
      "y": 4,
      "z": 5,
      "name": "Rock_Marble_Brick_Pillar_Middle"
    },
    {
      "x": -5,
      "y": 5,
      "z": 5,
      "name": "Rock_Marble_Brick_Pillar_Middle"
    },
    {
      "x": -5,
      "y": 6,
      "z": 5,
      "name": "Rock_Marble_Brick_Pillar_Base",
      "rotation": 8
    },
    {
      "x": -5,
      "y": 7,
      "z": 5,
      "name": "Rock_Marble_Brick_Decorative"
    },
    {
      "x": -5,
      "y": 0,
      "z": 6,
      "name": "Rock_Marble_Brick"
    },
    {
      "x": -5,
      "y": 1,
      "z": 6,
      "name": "Rock_Marble_Brick"
    },
    {
      "x": -5,
      "y": 0,
      "z": 7,
      "name": "Rock_Marble_Brick"
    },
    {
      "x": -5,
      "y": 1,
      "z": 7,
      "name": "Rock_Marble_Brick"
    },
    {
      "x": -5,
      "y": 0,
      "z": 8,
      "name": "Rock_Marble_Brick"
    },
    {
      "x": -5,
      "y": 1,
      "z": 8,
      "name": "Rock_Marble_Brick_Stairs"
    },
    {
      "x": -5,
      "y": 0,
      "z": 9,
      "name": "Rock_Marble_Brick"
    },
    {
      "x": -5,
      "y": 0,
      "z": 10,
      "name": "Rock_Marble_Brick_Stairs"
    },
    {
      "x": -4,
      "y": 0,
      "z": -10,
      "name": "Rock_Marble_Brick"
    },
    {
      "x": -4,
      "y": 1,
      "z": -10,
      "name": "Rock_Marble_Brick"
    },
    {
      "x": -4,
      "y": 0,
      "z": -9,
      "name": "Rock_Marble_Brick"
    },
    {
      "x": -4,
      "y": 1,
      "z": -9,
      "name": "BlueLED"
    },
    {
      "x": -4,
      "y": 0,
      "z": -8,
      "name": "Rock_Marble_Brick"
    },
    {
      "x": -4,
      "y": 1,
      "z": -8,
      "name": "Rock_Marble_Brick"
    },
    {
      "x": -4,
      "y": 6,
      "z": -8,
      "name": "Rock_Marble_Brick_Roof_Shallow",
      "rotation": 2
    },
    {
      "x": -4,
      "y": 0,
      "z": -7,
      "name": "Rock_Marble_Brick"
    },
    {
      "x": -4,
      "y": 1,
      "z": -7,
      "name": "Rock_Marble_Brick"
    },
    {
      "x": -4,
      "y": 2,
      "z": -7,
      "name": "Rock_Marble_Brick_Smooth"
    },
    {
      "x": -4,
      "y": 3,
      "z": -7,
      "name": "Rock_Marble_Brick_Smooth"
    },
    {
      "x": -4,
      "y": 4,
      "z": -7,
      "name": "Rock_Marble_Brick_Smooth"
    },
    {
      "x": -4,
      "y": 5,
      "z": -7,
      "name": "Rock_Marble_Brick_Wall"
    },
    {
      "x": -4,
      "y": 6,
      "z": -7,
      "name": "Rock_Marble_Brick_Roof_Shallow",
      "filler": 32,
      "rotation": 2
    },
    {
      "x": -4,
      "y": 12,
      "z": -7,
      "name": "Rock_Marble_Brick_Roof_Shallow",
      "rotation": 2
    },
    {
      "x": -4,
      "y": 0,
      "z": -6,
      "name": "Rock_Marble_Brick"
    },
    {
      "x": -4,
      "y": 1,
      "z": -6,
      "name": "Rock_Marble_Brick"
    },
    {
      "x": -4,
      "y": 7,
      "z": -6,
      "name": "Rock_Marble_Brick_Decorative"
    },
    {
      "x": -4,
      "y": 8,
      "z": -6,
      "name": "Rock_Marble_Brick_Smooth"
    },
    {
      "x": -4,
      "y": 9,
      "z": -6,
      "name": "Rock_Marble_Brick_Smooth"
    },
    {
      "x": -4,
      "y": 10,
      "z": -6,
      "name": "Rock_Marble_Brick_Smooth"
    },
    {
      "x": -4,
      "y": 11,
      "z": -6,
      "name": "Rock_Marble_Brick_Wall"
    },
    {
      "x": -4,
      "y": 12,
      "z": -6,
      "name": "Rock_Marble_Brick_Roof_Shallow",
      "filler": 32,
      "rotation": 2
    },
    {
      "x": -4,
      "y": 13,
      "z": -6,
      "name": "Rock_Marble_Brick_Roof_Shallow",
      "rotation": 2
    },
    {
      "x": -4,
      "y": 0,
      "z": -5,
      "name": "Rock_Marble_Brick"
    },
    {
      "x": -4,
      "y": 1,
      "z": -5,
      "name": "Rock_Marble_Brick"
    },
    {
      "x": -4,
      "y": 7,
      "z": -5,
      "name": "Rock_Marble_Brick_Decorative"
    },
    {
      "x": -4,
      "y": 13,
      "z": -5,
      "name": "Rock_Marble_Brick_Roof_Shallow",
      "filler": 32,
      "rotation": 2
    },
    {
      "x": -4,
      "y": 14,
      "z": -5,
      "name": "*Rock_Marble_Brick_Roof_Shallow_State_Definitions_Corner_Right",
      "filler": 1,
      "rotation": 3
    },
    {
      "x": -4,
      "y": 0,
      "z": -4,
      "name": "Rock_Marble_Brick"
    },
    {
      "x": -4,
      "y": 1,
      "z": -4,
      "name": "Rock_Marble_Brick"
    },
    {
      "x": -4,
      "y": 7,
      "z": -4,
      "name": "Rock_Marble_Brick_Decorative"
    },
    {
      "x": -4,
      "y": 14,
      "z": -4,
      "name": "*Rock_Marble_Brick_Roof_Shallow_State_Definitions_Corner_Right",
      "filler": 33,
      "rotation": 3
    },
    {
      "x": -4,
      "y": 15,
      "z": -4,
      "name": "*Rock_Marble_Brick_Roof_Shallow_State_Definitions_Corner_Left",
      "rotation": 2
    },
    {
      "x": -4,
      "y": 0,
      "z": -3,
      "name": "Rock_Marble_Brick"
    },
    {
      "x": -4,
      "y": 1,
      "z": -3,
      "name": "Rock_Marble_Brick"
    },
    {
      "x": -4,
      "y": 7,
      "z": -3,
      "name": "Rock_Marble_Brick_Decorative"
    },
    {
      "x": -4,
      "y": 14,
      "z": -3,
      "name": "Rock_Marble_Brick_Roof_Shallow",
      "filler": 1,
      "rotation": 3
    },
    {
      "x": -4,
      "y": 15,
      "z": -3,
      "name": "*Rock_Marble_Brick_Roof_Shallow_State_Definitions_Corner_Left",
      "filler": 32,
      "rotation": 2
    },
    {
      "x": -4,
      "y": 0,
      "z": -2,
      "name": "Rock_Marble_Brick"
    },
    {
      "x": -4,
      "y": 1,
      "z": -2,
      "name": "Rock_Marble_Brick"
    },
    {
      "x": -4,
      "y": 7,
      "z": -2,
      "name": "Rock_Marble_Brick_Decorative"
    },
    {
      "x": -4,
      "y": 14,
      "z": -2,
      "name": "Rock_Marble_Brick_Roof_Shallow",
      "filler": 1,
      "rotation": 3
    },
    {
      "x": -4,
      "y": 15,
      "z": -2,
      "name": "*Rock_Marble_Brick_Roof_Shallow_State_Definitions_Corner_Left",
      "filler": 992,
      "rotation": 3
    },
    {
      "x": -4,
      "y": 0,
      "z": -1,
      "name": "Rock_Marble_Brick"
    },
    {
      "x": -4,
      "y": 1,
      "z": -1,
      "name": "Rock_Marble_Brick"
    },
    {
      "x": -4,
      "y": 7,
      "z": -1,
      "name": "Rock_Marble_Brick_Decorative"
    },
    {
      "x": -4,
      "y": 14,
      "z": -1,
      "name": "*Rock_Marble_Brick_Roof_Shallow_State_Definitions_Corner_Right",
      "filler": 993
    },
    {
      "x": -4,
      "y": 15,
      "z": -1,
      "name": "*Rock_Marble_Brick_Roof_Shallow_State_Definitions_Corner_Left",
      "rotation": 3
    },
    {
      "x": -4,
      "y": 0,
      "z": 0,
      "name": "Rock_Marble_Brick"
    },
    {
      "x": -4,
      "y": 1,
      "z": 0,
      "name": "Rock_Marble_Brick"
    },
    {
      "x": -4,
      "y": 7,
      "z": 0,
      "name": "Rock_Marble_Brick_Decorative"
    },
    {
      "x": -4,
      "y": 13,
      "z": 0,
      "name": "Rock_Marble_Brick_Roof_Shallow",
      "filler": 992
    },
    {
      "x": -4,
      "y": 14,
      "z": 0,
      "name": "*Rock_Marble_Brick_Roof_Shallow_State_Definitions_Corner_Right",
      "filler": 1
    },
    {
      "x": -4,
      "y": 0,
      "z": 1,
      "name": "Rock_Marble_Brick"
    },
    {
      "x": -4,
      "y": 1,
      "z": 1,
      "name": "Rock_Marble_Brick"
    },
    {
      "x": -4,
      "y": 7,
      "z": 1,
      "name": "Rock_Marble_Brick_Decorative"
    },
    {
      "x": -4,
      "y": 8,
      "z": 1,
      "name": "Rock_Marble_Brick_Smooth"
    },
    {
      "x": -4,
      "y": 9,
      "z": 1,
      "name": "BlueLED"
    },
    {
      "x": -4,
      "y": 10,
      "z": 1,
      "name": "Rock_Marble_Brick_Smooth"
    },
    {
      "x": -4,
      "y": 11,
      "z": 1,
      "name": "Rock_Marble_Brick_Wall"
    },
    {
      "x": -4,
      "y": 12,
      "z": 1,
      "name": "Rock_Marble_Brick_Roof_Shallow",
      "filler": 992
    },
    {
      "x": -4,
      "y": 13,
      "z": 1,
      "name": "Rock_Marble_Brick_Roof_Shallow"
    },
    {
      "x": -4,
      "y": 0,
      "z": 2,
      "name": "Rock_Marble_Brick"
    },
    {
      "x": -4,
      "y": 1,
      "z": 2,
      "name": "Rock_Marble_Brick"
    },
    {
      "x": -4,
      "y": 2,
      "z": 2,
      "name": "Rock_Marble_Brick_Smooth"
    },
    {
      "x": -4,
      "y": 3,
      "z": 2,
      "name": "Rock_Marble_Brick_Smooth"
    },
    {
      "x": -4,
      "y": 4,
      "z": 2,
      "name": "Rock_Marble_Brick_Smooth"
    },
    {
      "x": -4,
      "y": 5,
      "z": 2,
      "name": "Rock_Marble_Brick_Wall"
    },
    {
      "x": -4,
      "y": 6,
      "z": 2,
      "name": "Rock_Marble_Brick_Roof_Shallow",
      "filler": 992
    },
    {
      "x": -4,
      "y": 12,
      "z": 2,
      "name": "Rock_Marble_Brick_Roof_Shallow"
    },
    {
      "x": -4,
      "y": 0,
      "z": 3,
      "name": "Rock_Marble_Brick"
    },
    {
      "x": -4,
      "y": 1,
      "z": 3,
      "name": "Rock_Marble_Brick"
    },
    {
      "x": -4,
      "y": 6,
      "z": 3,
      "name": "Rock_Marble_Brick_Roof_Shallow"
    },
    {
      "x": -4,
      "y": 0,
      "z": 4,
      "name": "Rock_Marble_Brick"
    },
    {
      "x": -4,
      "y": 1,
      "z": 4,
      "name": "Rock_Marble_Brick"
    },
    {
      "x": -4,
      "y": 7,
      "z": 4,
      "name": "*Furniture_Temple_Light_Trapdoor_State_Definitions_OpenDoorOut",
      "rotation": 2
    },
    {
      "x": -4,
      "y": 0,
      "z": 5,
      "name": "Rock_Marble_Brick"
    },
    {
      "x": -4,
      "y": 1,
      "z": 5,
      "name": "Rock_Marble_Brick"
    },
    {
      "x": -4,
      "y": 7,
      "z": 5,
      "name": "Rock_Marble_Brick"
    },
    {
      "x": -4,
      "y": 8,
      "z": 5,
      "name": "Rock_Marble_Brick_Roof_Flat",
      "rotation": 3
    },
    {
      "x": -4,
      "y": 0,
      "z": 6,
      "name": "Rock_Marble_Brick"
    },
    {
      "x": -4,
      "y": 1,
      "z": 6,
      "name": "Rock_Marble_Brick"
    },
    {
      "x": -4,
      "y": 7,
      "z": 6,
      "name": "*Furniture_Temple_Light_Trapdoor_State_Definitions_OpenDoorOut"
    },
    {
      "x": -4,
      "y": 0,
      "z": 7,
      "name": "Rock_Marble_Brick"
    },
    {
      "x": -4,
      "y": 1,
      "z": 7,
      "name": "Rock_Marble_Brick"
    },
    {
      "x": -4,
      "y": 0,
      "z": 8,
      "name": "Rock_Marble_Brick"
    },
    {
      "x": -4,
      "y": 1,
      "z": 8,
      "name": "Rock_Marble_Brick_Stairs"
    },
    {
      "x": -4,
      "y": 0,
      "z": 9,
      "name": "Rock_Marble_Brick"
    },
    {
      "x": -4,
      "y": 0,
      "z": 10,
      "name": "Rock_Marble_Brick_Stairs"
    },
    {
      "x": -3,
      "y": 0,
      "z": -10,
      "name": "Rock_Marble_Brick"
    },
    {
      "x": -3,
      "y": 1,
      "z": -10,
      "name": "Rock_Marble_Brick"
    },
    {
      "x": -3,
      "y": 0,
      "z": -9,
      "name": "Rock_Marble_Brick"
    },
    {
      "x": -3,
      "y": 1,
      "z": -9,
      "name": "BlueLED"
    },
    {
      "x": -3,
      "y": 0,
      "z": -8,
      "name": "Rock_Marble_Brick"
    },
    {
      "x": -3,
      "y": 1,
      "z": -8,
      "name": "Rock_Marble_Brick"
    },
    {
      "x": -3,
      "y": 6,
      "z": -8,
      "name": "Rock_Marble_Brick_Roof_Shallow",
      "rotation": 2
    },
    {
      "x": -3,
      "y": 0,
      "z": -7,
      "name": "Rock_Marble_Brick"
    },
    {
      "x": -3,
      "y": 1,
      "z": -7,
      "name": "Rock_Marble_Brick"
    },
    {
      "x": -3,
      "y": 2,
      "z": -7,
      "name": "Rock_Marble_Brick_Smooth"
    },
    {
      "x": -3,
      "y": 3,
      "z": -7,
      "name": "Rock_Marble_Brick_Smooth"
    },
    {
      "x": -3,
      "y": 4,
      "z": -7,
      "name": "Rock_Marble_Brick_Smooth"
    },
    {
      "x": -3,
      "y": 5,
      "z": -7,
      "name": "Rock_Marble_Brick_Wall"
    },
    {
      "x": -3,
      "y": 6,
      "z": -7,
      "name": "Rock_Marble_Brick_Roof_Shallow",
      "filler": 32,
      "rotation": 2
    },
    {
      "x": -3,
      "y": 12,
      "z": -7,
      "name": "Rock_Marble_Brick_Roof_Shallow",
      "rotation": 2
    },
    {
      "x": -3,
      "y": 0,
      "z": -6,
      "name": "Rock_Marble_Brick"
    },
    {
      "x": -3,
      "y": 1,
      "z": -6,
      "name": "Rock_Marble_Brick"
    },
    {
      "x": -3,
      "y": 7,
      "z": -6,
      "name": "Rock_Marble_Brick_Decorative"
    },
    {
      "x": -3,
      "y": 8,
      "z": -6,
      "name": "Rock_Marble_Brick_Smooth"
    },
    {
      "x": -3,
      "y": 9,
      "z": -6,
      "name": "Rock_Marble_Brick_Smooth"
    },
    {
      "x": -3,
      "y": 10,
      "z": -6,
      "name": "Rock_Marble_Brick_Smooth"
    },
    {
      "x": -3,
      "y": 11,
      "z": -6,
      "name": "Rock_Marble_Brick_Wall"
    },
    {
      "x": -3,
      "y": 12,
      "z": -6,
      "name": "Rock_Marble_Brick_Roof_Shallow",
      "filler": 32,
      "rotation": 2
    },
    {
      "x": -3,
      "y": 13,
      "z": -6,
      "name": "Rock_Marble_Brick_Roof_Shallow",
      "rotation": 2
    },
    {
      "x": -3,
      "y": 0,
      "z": -5,
      "name": "Rock_Marble_Brick"
    },
    {
      "x": -3,
      "y": 1,
      "z": -5,
      "name": "Rock_Marble_Brick"
    },
    {
      "x": -3,
      "y": 7,
      "z": -5,
      "name": "Rock_Marble_Brick_Decorative"
    },
    {
      "x": -3,
      "y": 13,
      "z": -5,
      "name": "Rock_Marble_Brick_Roof_Shallow",
      "filler": 32,
      "rotation": 2
    },
    {
      "x": -3,
      "y": 14,
      "z": -5,
      "name": "Rock_Marble_Brick_Roof_Shallow",
      "rotation": 2
    },
    {
      "x": -3,
      "y": 0,
      "z": -4,
      "name": "Rock_Marble_Brick"
    },
    {
      "x": -3,
      "y": 1,
      "z": -4,
      "name": "Rock_Marble_Brick"
    },
    {
      "x": -3,
      "y": 7,
      "z": -4,
      "name": "Rock_Marble_Brick_Decorative"
    },
    {
      "x": -3,
      "y": 14,
      "z": -4,
      "name": "Rock_Marble_Brick_Roof_Shallow",
      "filler": 32,
      "rotation": 2
    },
    {
      "x": -3,
      "y": 15,
      "z": -4,
      "name": "*Rock_Marble_Brick_Roof_Shallow_State_Definitions_Corner_Left",
      "filler": 1,
      "rotation": 2
    },
    {
      "x": -3,
      "y": 0,
      "z": -3,
      "name": "Rock_Marble_Brick"
    },
    {
      "x": -3,
      "y": 1,
      "z": -3,
      "name": "Rock_Marble_Brick"
    },
    {
      "x": -3,
      "y": 7,
      "z": -3,
      "name": "Rock_Marble_Brick_Decorative"
    },
    {
      "x": -3,
      "y": 15,
      "z": -3,
      "name": "*Rock_Marble_Brick_Roof_Shallow_State_Definitions_Corner_Left",
      "filler": 33,
      "rotation": 2
    },
    {
      "x": -3,
      "y": 0,
      "z": -2,
      "name": "Rock_Marble_Brick"
    },
    {
      "x": -3,
      "y": 1,
      "z": -2,
      "name": "Rock_Marble_Brick"
    },
    {
      "x": -3,
      "y": 7,
      "z": -2,
      "name": "Rock_Marble_Brick_Decorative"
    },
    {
      "x": -3,
      "y": 15,
      "z": -2,
      "name": "*Rock_Marble_Brick_Roof_Shallow_State_Definitions_Corner_Left",
      "filler": 993,
      "rotation": 3
    },
    {
      "x": -3,
      "y": 0,
      "z": -1,
      "name": "Rock_Marble_Brick"
    },
    {
      "x": -3,
      "y": 1,
      "z": -1,
      "name": "Rock_Marble_Brick"
    },
    {
      "x": -3,
      "y": 7,
      "z": -1,
      "name": "Rock_Marble_Brick_Decorative"
    },
    {
      "x": -3,
      "y": 14,
      "z": -1,
      "name": "Rock_Marble_Brick_Roof_Shallow",
      "filler": 992
    },
    {
      "x": -3,
      "y": 15,
      "z": -1,
      "name": "*Rock_Marble_Brick_Roof_Shallow_State_Definitions_Corner_Left",
      "filler": 1,
      "rotation": 3
    },
    {
      "x": -3,
      "y": 0,
      "z": 0,
      "name": "Rock_Marble_Brick"
    },
    {
      "x": -3,
      "y": 1,
      "z": 0,
      "name": "Rock_Marble_Brick"
    },
    {
      "x": -3,
      "y": 7,
      "z": 0,
      "name": "Rock_Marble_Brick_Decorative"
    },
    {
      "x": -3,
      "y": 13,
      "z": 0,
      "name": "Rock_Marble_Brick_Roof_Shallow",
      "filler": 992
    },
    {
      "x": -3,
      "y": 14,
      "z": 0,
      "name": "Rock_Marble_Brick_Roof_Shallow"
    },
    {
      "x": -3,
      "y": 0,
      "z": 1,
      "name": "Rock_Marble_Brick"
    },
    {
      "x": -3,
      "y": 1,
      "z": 1,
      "name": "Rock_Marble_Brick"
    },
    {
      "x": -3,
      "y": 7,
      "z": 1,
      "name": "Rock_Marble_Brick_Decorative"
    },
    {
      "x": -3,
      "y": 8,
      "z": 1,
      "name": "Rock_Marble_Brick_Smooth"
    },
    {
      "x": -3,
      "y": 9,
      "z": 1,
      "name": "BlueLED"
    },
    {
      "x": -3,
      "y": 10,
      "z": 1,
      "name": "Rock_Marble_Brick_Smooth"
    },
    {
      "x": -3,
      "y": 11,
      "z": 1,
      "name": "Rock_Marble_Brick_Wall"
    },
    {
      "x": -3,
      "y": 12,
      "z": 1,
      "name": "Rock_Marble_Brick_Roof_Shallow",
      "filler": 992
    },
    {
      "x": -3,
      "y": 13,
      "z": 1,
      "name": "Rock_Marble_Brick_Roof_Shallow"
    },
    {
      "x": -3,
      "y": 0,
      "z": 2,
      "name": "Rock_Marble_Brick"
    },
    {
      "x": -3,
      "y": 1,
      "z": 2,
      "name": "Rock_Marble_Brick"
    },
    {
      "x": -3,
      "y": 2,
      "z": 2,
      "name": "Rock_Marble_Brick_Smooth"
    },
    {
      "x": -3,
      "y": 3,
      "z": 2,
      "name": "Rock_Marble_Brick_Smooth"
    },
    {
      "x": -3,
      "y": 4,
      "z": 2,
      "name": "Rock_Marble_Brick_Smooth"
    },
    {
      "x": -3,
      "y": 5,
      "z": 2,
      "name": "Rock_Marble_Brick_Wall"
    },
    {
      "x": -3,
      "y": 6,
      "z": 2,
      "name": "Rock_Marble_Brick_Roof_Shallow",
      "filler": 992
    },
    {
      "x": -3,
      "y": 12,
      "z": 2,
      "name": "Rock_Marble_Brick_Roof_Shallow"
    },
    {
      "x": -3,
      "y": 0,
      "z": 3,
      "name": "Rock_Marble_Brick"
    },
    {
      "x": -3,
      "y": 1,
      "z": 3,
      "name": "Rock_Marble_Brick"
    },
    {
      "x": -3,
      "y": 6,
      "z": 3,
      "name": "Rock_Marble_Brick_Roof_Shallow"
    },
    {
      "x": -3,
      "y": 0,
      "z": 4,
      "name": "Rock_Marble_Brick"
    },
    {
      "x": -3,
      "y": 1,
      "z": 4,
      "name": "Rock_Marble_Brick"
    },
    {
      "x": -3,
      "y": 7,
      "z": 4,
      "name": "*Furniture_Temple_Light_Trapdoor_State_Definitions_OpenDoorOut",
      "rotation": 2
    },
    {
      "x": -3,
      "y": 0,
      "z": 5,
      "name": "Rock_Marble_Brick"
    },
    {
      "x": -3,
      "y": 1,
      "z": 5,
      "name": "Rock_Marble_Brick"
    },
    {
      "x": -3,
      "y": 6,
      "z": 5,
      "name": "Furniture_Temple_Light_Lantern_Ceiling"
    },
    {
      "x": -3,
      "y": 7,
      "z": 5,
      "name": "Rock_Marble_Brick"
    },
    {
      "x": -3,
      "y": 8,
      "z": 5,
      "name": "Rock_Marble_Brick_Roof_Flat",
      "rotation": 3
    },
    {
      "x": -3,
      "y": 0,
      "z": 6,
      "name": "Rock_Marble_Brick"
    },
    {
      "x": -3,
      "y": 1,
      "z": 6,
      "name": "Rock_Marble_Brick"
    },
    {
      "x": -3,
      "y": 7,
      "z": 6,
      "name": "*Furniture_Temple_Light_Trapdoor_State_Definitions_OpenDoorOut"
    },
    {
      "x": -3,
      "y": 0,
      "z": 7,
      "name": "Rock_Marble_Brick"
    },
    {
      "x": -3,
      "y": 1,
      "z": 7,
      "name": "Rock_Marble_Brick"
    },
    {
      "x": -3,
      "y": 0,
      "z": 8,
      "name": "Rock_Marble_Brick"
    },
    {
      "x": -3,
      "y": 1,
      "z": 8,
      "name": "Rock_Marble_Brick_Stairs"
    },
    {
      "x": -3,
      "y": 0,
      "z": 9,
      "name": "Rock_Marble_Brick"
    },
    {
      "x": -3,
      "y": 0,
      "z": 10,
      "name": "Rock_Marble_Brick_Stairs"
    },
    {
      "x": -2,
      "y": 0,
      "z": -10,
      "name": "Rock_Marble_Brick"
    },
    {
      "x": -2,
      "y": 1,
      "z": -10,
      "name": "Rock_Marble_Brick"
    },
    {
      "x": -2,
      "y": 0,
      "z": -9,
      "name": "Rock_Marble_Brick"
    },
    {
      "x": -2,
      "y": 1,
      "z": -9,
      "name": "BlueLED"
    },
    {
      "x": -2,
      "y": 0,
      "z": -8,
      "name": "Rock_Marble_Brick"
    },
    {
      "x": -2,
      "y": 1,
      "z": -8,
      "name": "Rock_Marble_Brick"
    },
    {
      "x": -2,
      "y": 6,
      "z": -8,
      "name": "Rock_Marble_Brick_Roof_Shallow",
      "rotation": 2
    },
    {
      "x": -2,
      "y": 0,
      "z": -7,
      "name": "Rock_Marble_Brick"
    },
    {
      "x": -2,
      "y": 1,
      "z": -7,
      "name": "Rock_Marble_Brick"
    },
    {
      "x": -2,
      "y": 2,
      "z": -7,
      "name": "Rock_Marble_Brick_Smooth"
    },
    {
      "x": -2,
      "y": 3,
      "z": -7,
      "name": "Rock_Marble_Brick_Smooth"
    },
    {
      "x": -2,
      "y": 4,
      "z": -7,
      "name": "Rock_Marble_Brick_Smooth"
    },
    {
      "x": -2,
      "y": 5,
      "z": -7,
      "name": "Rock_Marble_Brick_Wall"
    },
    {
      "x": -2,
      "y": 6,
      "z": -7,
      "name": "Rock_Marble_Brick_Roof_Shallow",
      "filler": 32,
      "rotation": 2
    },
    {
      "x": -2,
      "y": 12,
      "z": -7,
      "name": "Rock_Marble_Brick_Roof_Shallow",
      "rotation": 2
    },
    {
      "x": -2,
      "y": 0,
      "z": -6,
      "name": "Rock_Marble_Brick"
    },
    {
      "x": -2,
      "y": 1,
      "z": -6,
      "name": "Rock_Marble_Brick"
    },
    {
      "x": -2,
      "y": 7,
      "z": -6,
      "name": "Rock_Marble_Brick_Decorative"
    },
    {
      "x": -2,
      "y": 8,
      "z": -6,
      "name": "Rock_Marble_Brick_Smooth"
    },
    {
      "x": -2,
      "y": 9,
      "z": -6,
      "name": "Rock_Marble_Brick_Smooth"
    },
    {
      "x": -2,
      "y": 10,
      "z": -6,
      "name": "Rock_Marble_Brick_Smooth"
    },
    {
      "x": -2,
      "y": 11,
      "z": -6,
      "name": "Rock_Marble_Brick_Wall"
    },
    {
      "x": -2,
      "y": 12,
      "z": -6,
      "name": "Rock_Marble_Brick_Roof_Shallow",
      "filler": 32,
      "rotation": 2
    },
    {
      "x": -2,
      "y": 13,
      "z": -6,
      "name": "Rock_Marble_Brick_Roof_Shallow",
      "rotation": 2
    },
    {
      "x": -2,
      "y": 0,
      "z": -5,
      "name": "Rock_Marble_Brick"
    },
    {
      "x": -2,
      "y": 1,
      "z": -5,
      "name": "Rock_Marble_Brick"
    },
    {
      "x": -2,
      "y": 7,
      "z": -5,
      "name": "Rock_Marble_Brick_Decorative"
    },
    {
      "x": -2,
      "y": 13,
      "z": -5,
      "name": "Rock_Marble_Brick_Roof_Shallow",
      "filler": 32,
      "rotation": 2
    },
    {
      "x": -2,
      "y": 14,
      "z": -5,
      "name": "Rock_Marble_Brick_Roof_Shallow",
      "rotation": 2
    },
    {
      "x": -2,
      "y": 0,
      "z": -4,
      "name": "Rock_Marble_Brick"
    },
    {
      "x": -2,
      "y": 1,
      "z": -4,
      "name": "Rock_Marble_Brick"
    },
    {
      "x": -2,
      "y": 7,
      "z": -4,
      "name": "Rock_Marble_Brick_Decorative"
    },
    {
      "x": -2,
      "y": 14,
      "z": -4,
      "name": "Rock_Marble_Brick_Roof_Shallow",
      "filler": 32,
      "rotation": 2
    },
    {
      "x": -2,
      "y": 15,
      "z": -4,
      "name": "Rock_Marble_Brick_Roof_Shallow",
      "rotation": 2
    },
    {
      "x": -2,
      "y": 0,
      "z": -3,
      "name": "Rock_Marble_Brick"
    },
    {
      "x": -2,
      "y": 1,
      "z": -3,
      "name": "Rock_Marble_Brick"
    },
    {
      "x": -2,
      "y": 7,
      "z": -3,
      "name": "Rock_Marble_Brick_Decorative"
    },
    {
      "x": -2,
      "y": 15,
      "z": -3,
      "name": "Rock_Marble_Brick_Roof_Shallow",
      "filler": 32,
      "rotation": 2
    },
    {
      "x": -2,
      "y": 0,
      "z": -2,
      "name": "Rock_Marble_Brick"
    },
    {
      "x": -2,
      "y": 1,
      "z": -2,
      "name": "Rock_Marble_Brick"
    },
    {
      "x": -2,
      "y": 7,
      "z": -2,
      "name": "Rock_Marble_Brick_Decorative"
    },
    {
      "x": -2,
      "y": 15,
      "z": -2,
      "name": "Rock_Marble_Brick_Roof_Shallow",
      "filler": 992
    },
    {
      "x": -2,
      "y": 0,
      "z": -1,
      "name": "Rock_Marble_Brick"
    },
    {
      "x": -2,
      "y": 1,
      "z": -1,
      "name": "Rock_Marble_Brick"
    },
    {
      "x": -2,
      "y": 7,
      "z": -1,
      "name": "Rock_Marble_Brick_Decorative"
    },
    {
      "x": -2,
      "y": 14,
      "z": -1,
      "name": "Rock_Marble_Brick_Roof_Shallow",
      "filler": 992
    },
    {
      "x": -2,
      "y": 15,
      "z": -1,
      "name": "Rock_Marble_Brick_Roof_Shallow"
    },
    {
      "x": -2,
      "y": 0,
      "z": 0,
      "name": "Rock_Marble_Brick"
    },
    {
      "x": -2,
      "y": 1,
      "z": 0,
      "name": "Rock_Marble_Brick"
    },
    {
      "x": -2,
      "y": 7,
      "z": 0,
      "name": "Rock_Marble_Brick_Decorative"
    },
    {
      "x": -2,
      "y": 13,
      "z": 0,
      "name": "Rock_Marble_Brick_Roof_Shallow",
      "filler": 992
    },
    {
      "x": -2,
      "y": 14,
      "z": 0,
      "name": "Rock_Marble_Brick_Roof_Shallow"
    },
    {
      "x": -2,
      "y": 0,
      "z": 1,
      "name": "Rock_Marble_Brick"
    },
    {
      "x": -2,
      "y": 1,
      "z": 1,
      "name": "Rock_Marble_Brick"
    },
    {
      "x": -2,
      "y": 7,
      "z": 1,
      "name": "Rock_Marble_Brick_Decorative"
    },
    {
      "x": -2,
      "y": 8,
      "z": 1,
      "name": "Rock_Marble_Brick_Smooth"
    },
    {
      "x": -2,
      "y": 9,
      "z": 1,
      "name": "BlueLED"
    },
    {
      "x": -2,
      "y": 10,
      "z": 1,
      "name": "Rock_Marble_Brick_Smooth"
    },
    {
      "x": -2,
      "y": 11,
      "z": 1,
      "name": "Rock_Marble_Brick_Wall"
    },
    {
      "x": -2,
      "y": 12,
      "z": 1,
      "name": "Rock_Marble_Brick_Roof_Shallow",
      "filler": 992
    },
    {
      "x": -2,
      "y": 13,
      "z": 1,
      "name": "Rock_Marble_Brick_Roof_Shallow"
    },
    {
      "x": -2,
      "y": 0,
      "z": 2,
      "name": "Rock_Marble_Brick"
    },
    {
      "x": -2,
      "y": 1,
      "z": 2,
      "name": "Rock_Marble_Brick"
    },
    {
      "x": -2,
      "y": 2,
      "z": 2,
      "name": "Rock_Marble_Brick_Smooth"
    },
    {
      "x": -2,
      "y": 3,
      "z": 2,
      "name": "Rock_Marble_Brick_Decorative"
    },
    {
      "x": -2,
      "y": 4,
      "z": 2,
      "name": "Rock_Marble_Brick_Smooth"
    },
    {
      "x": -2,
      "y": 5,
      "z": 2,
      "name": "Rock_Marble_Brick_Wall"
    },
    {
      "x": -2,
      "y": 6,
      "z": 2,
      "name": "Rock_Marble_Brick_Roof_Shallow",
      "filler": 992
    },
    {
      "x": -2,
      "y": 12,
      "z": 2,
      "name": "Rock_Marble_Brick_Roof_Shallow"
    },
    {
      "x": -2,
      "y": 0,
      "z": 3,
      "name": "Rock_Marble_Brick"
    },
    {
      "x": -2,
      "y": 1,
      "z": 3,
      "name": "Rock_Marble_Brick"
    },
    {
      "x": -2,
      "y": 6,
      "z": 3,
      "name": "Rock_Marble_Brick_Roof_Shallow"
    },
    {
      "x": -2,
      "y": 0,
      "z": 4,
      "name": "Rock_Marble_Brick"
    },
    {
      "x": -2,
      "y": 1,
      "z": 4,
      "name": "Rock_Marble_Brick"
    },
    {
      "x": -2,
      "y": 0,
      "z": 5,
      "name": "Rock_Marble_Brick"
    },
    {
      "x": -2,
      "y": 1,
      "z": 5,
      "name": "Rock_Marble_Brick"
    },
    {
      "x": -2,
      "y": 8,
      "z": 5,
      "name": "Rock_Marble_Brick"
    },
    {
      "x": -2,
      "y": 0,
      "z": 6,
      "name": "Rock_Marble_Brick"
    },
    {
      "x": -2,
      "y": 1,
      "z": 6,
      "name": "Rock_Marble_Brick"
    },
    {
      "x": -2,
      "y": 0,
      "z": 7,
      "name": "Rock_Marble_Brick"
    },
    {
      "x": -2,
      "y": 1,
      "z": 7,
      "name": "Rock_Marble_Brick"
    },
    {
      "x": -2,
      "y": 0,
      "z": 8,
      "name": "Rock_Marble_Brick"
    },
    {
      "x": -2,
      "y": 1,
      "z": 8,
      "name": "Rock_Marble_Brick_Stairs"
    },
    {
      "x": -2,
      "y": 0,
      "z": 9,
      "name": "Rock_Marble_Brick"
    },
    {
      "x": -2,
      "y": 0,
      "z": 10,
      "name": "Rock_Marble_Brick_Stairs"
    },
    {
      "x": -1,
      "y": 0,
      "z": -10,
      "name": "Rock_Marble_Brick"
    },
    {
      "x": -1,
      "y": 1,
      "z": -10,
      "name": "Rock_Marble_Brick"
    },
    {
      "x": -1,
      "y": 0,
      "z": -9,
      "name": "Rock_Marble_Brick"
    },
    {
      "x": -1,
      "y": 1,
      "z": -9,
      "name": "BlueLED"
    },
    {
      "x": -1,
      "y": 0,
      "z": -8,
      "name": "Rock_Marble_Brick"
    },
    {
      "x": -1,
      "y": 1,
      "z": -8,
      "name": "Rock_Marble_Brick"
    },
    {
      "x": -1,
      "y": 6,
      "z": -8,
      "name": "Rock_Marble_Brick_Roof_Shallow",
      "rotation": 2
    },
    {
      "x": -1,
      "y": 0,
      "z": -7,
      "name": "Rock_Marble_Brick"
    },
    {
      "x": -1,
      "y": 1,
      "z": -7,
      "name": "Rock_Marble_Brick"
    },
    {
      "x": -1,
      "y": 2,
      "z": -7,
      "name": "Rock_Marble_Brick_Smooth"
    },
    {
      "x": -1,
      "y": 3,
      "z": -7,
      "name": "Rock_Marble_Brick_Smooth"
    },
    {
      "x": -1,
      "y": 4,
      "z": -7,
      "name": "Rock_Marble_Brick_Smooth"
    },
    {
      "x": -1,
      "y": 5,
      "z": -7,
      "name": "Rock_Marble_Brick_Wall"
    },
    {
      "x": -1,
      "y": 6,
      "z": -7,
      "name": "Rock_Marble_Brick_Roof_Shallow",
      "filler": 32,
      "rotation": 2
    },
    {
      "x": -1,
      "y": 12,
      "z": -7,
      "name": "Rock_Marble_Brick_Roof_Shallow",
      "rotation": 2
    },
    {
      "x": -1,
      "y": 0,
      "z": -6,
      "name": "Rock_Marble_Brick"
    },
    {
      "x": -1,
      "y": 1,
      "z": -6,
      "name": "Rock_Marble_Brick"
    },
    {
      "x": -1,
      "y": 7,
      "z": -6,
      "name": "Rock_Marble_Brick_Decorative"
    },
    {
      "x": -1,
      "y": 8,
      "z": -6,
      "name": "Rock_Marble_Brick_Smooth"
    },
    {
      "x": -1,
      "y": 9,
      "z": -6,
      "name": "Rock_Marble_Brick_Smooth"
    },
    {
      "x": -1,
      "y": 10,
      "z": -6,
      "name": "Rock_Marble_Brick_Smooth"
    },
    {
      "x": -1,
      "y": 11,
      "z": -6,
      "name": "Rock_Marble_Brick_Wall"
    },
    {
      "x": -1,
      "y": 12,
      "z": -6,
      "name": "Rock_Marble_Brick_Roof_Shallow",
      "filler": 32,
      "rotation": 2
    },
    {
      "x": -1,
      "y": 13,
      "z": -6,
      "name": "Rock_Marble_Brick_Roof_Shallow",
      "rotation": 2
    },
    {
      "x": -1,
      "y": 0,
      "z": -5,
      "name": "Rock_Marble_Brick"
    },
    {
      "x": -1,
      "y": 1,
      "z": -5,
      "name": "Rock_Marble_Brick"
    },
    {
      "x": -1,
      "y": 7,
      "z": -5,
      "name": "Rock_Marble_Brick_Decorative"
    },
    {
      "x": -1,
      "y": 13,
      "z": -5,
      "name": "Rock_Marble_Brick_Roof_Shallow",
      "filler": 32,
      "rotation": 2
    },
    {
      "x": -1,
      "y": 14,
      "z": -5,
      "name": "Rock_Marble_Brick_Roof_Shallow",
      "rotation": 2
    },
    {
      "x": -1,
      "y": 0,
      "z": -4,
      "name": "Rock_Marble_Brick"
    },
    {
      "x": -1,
      "y": 1,
      "z": -4,
      "name": "Rock_Marble_Brick"
    },
    {
      "x": -1,
      "y": 7,
      "z": -4,
      "name": "Rock_Marble_Brick_Decorative"
    },
    {
      "x": -1,
      "y": 14,
      "z": -4,
      "name": "Rock_Marble_Brick_Roof_Shallow",
      "filler": 32,
      "rotation": 2
    },
    {
      "x": -1,
      "y": 15,
      "z": -4,
      "name": "Rock_Marble_Brick_Roof_Shallow",
      "rotation": 2
    },
    {
      "x": -1,
      "y": 0,
      "z": -3,
      "name": "Rock_Marble_Brick"
    },
    {
      "x": -1,
      "y": 1,
      "z": -3,
      "name": "Rock_Marble_Brick"
    },
    {
      "x": -1,
      "y": 7,
      "z": -3,
      "name": "Rock_Marble_Brick_Decorative"
    },
    {
      "x": -1,
      "y": 15,
      "z": -3,
      "name": "Rock_Marble_Brick_Roof_Shallow",
      "filler": 32,
      "rotation": 2
    },
    {
      "x": -1,
      "y": 0,
      "z": -2,
      "name": "Rock_Marble_Brick"
    },
    {
      "x": -1,
      "y": 1,
      "z": -2,
      "name": "Rock_Marble_Brick"
    },
    {
      "x": -1,
      "y": 7,
      "z": -2,
      "name": "Rock_Marble_Brick_Decorative"
    },
    {
      "x": -1,
      "y": 15,
      "z": -2,
      "name": "Rock_Marble_Brick_Roof_Shallow",
      "filler": 992
    },
    {
      "x": -1,
      "y": 0,
      "z": -1,
      "name": "Rock_Marble_Brick"
    },
    {
      "x": -1,
      "y": 1,
      "z": -1,
      "name": "Rock_Marble_Brick"
    },
    {
      "x": -1,
      "y": 7,
      "z": -1,
      "name": "Rock_Marble_Brick_Decorative"
    },
    {
      "x": -1,
      "y": 14,
      "z": -1,
      "name": "Rock_Marble_Brick_Roof_Shallow",
      "filler": 992
    },
    {
      "x": -1,
      "y": 15,
      "z": -1,
      "name": "Rock_Marble_Brick_Roof_Shallow"
    },
    {
      "x": -1,
      "y": 0,
      "z": 0,
      "name": "Rock_Marble_Brick"
    },
    {
      "x": -1,
      "y": 1,
      "z": 0,
      "name": "Rock_Marble_Brick"
    },
    {
      "x": -1,
      "y": 7,
      "z": 0,
      "name": "Rock_Marble_Brick_Decorative"
    },
    {
      "x": -1,
      "y": 13,
      "z": 0,
      "name": "Rock_Marble_Brick_Roof_Shallow",
      "filler": 992
    },
    {
      "x": -1,
      "y": 14,
      "z": 0,
      "name": "Rock_Marble_Brick_Roof_Shallow"
    },
    {
      "x": -1,
      "y": 0,
      "z": 1,
      "name": "Rock_Marble_Brick"
    },
    {
      "x": -1,
      "y": 1,
      "z": 1,
      "name": "Rock_Marble_Brick"
    },
    {
      "x": -1,
      "y": 7,
      "z": 1,
      "name": "Rock_Marble_Brick_Decorative"
    },
    {
      "x": -1,
      "y": 8,
      "z": 1,
      "name": "Rock_Marble_Brick_Smooth"
    },
    {
      "x": -1,
      "y": 9,
      "z": 1,
      "name": "BlueLED"
    },
    {
      "x": -1,
      "y": 10,
      "z": 1,
      "name": "Rock_Marble_Brick_Smooth"
    },
    {
      "x": -1,
      "y": 11,
      "z": 1,
      "name": "Rock_Marble_Brick_Wall"
    },
    {
      "x": -1,
      "y": 12,
      "z": 1,
      "name": "Rock_Marble_Brick_Roof_Shallow",
      "filler": 992
    },
    {
      "x": -1,
      "y": 13,
      "z": 1,
      "name": "Rock_Marble_Brick_Roof_Shallow"
    },
    {
      "x": -1,
      "y": 0,
      "z": 2,
      "name": "Rock_Marble_Brick"
    },
    {
      "x": -1,
      "y": 1,
      "z": 2,
      "name": "Rock_Marble_Brick"
    },
    {
      "x": -1,
      "y": 2,
      "z": 2,
      "name": "*Furniture_Temple_Light_Door_Medilum_State_Definitions_CloseDoorIn"
    },
    {
      "x": -1,
      "y": 3,
      "z": 2,
      "name": "*Furniture_Temple_Light_Door_Medilum_State_Definitions_CloseDoorIn",
      "filler": 1024
    },
    {
      "x": -1,
      "y": 4,
      "z": 2,
      "name": "*Furniture_Temple_Light_Door_Medilum_State_Definitions_CloseDoorIn",
      "filler": 2048
    },
    {
      "x": -1,
      "y": 5,
      "z": 2,
      "name": "Rock_Marble_Brick_Wall"
    },
    {
      "x": -1,
      "y": 6,
      "z": 2,
      "name": "Rock_Marble_Brick_Roof_Shallow",
      "filler": 992
    },
    {
      "x": -1,
      "y": 12,
      "z": 2,
      "name": "Rock_Marble_Brick_Roof_Shallow"
    },
    {
      "x": -1,
      "y": 0,
      "z": 3,
      "name": "Rock_Marble_Brick"
    },
    {
      "x": -1,
      "y": 1,
      "z": 3,
      "name": "Rock_Marble_Brick"
    },
    {
      "x": -1,
      "y": 6,
      "z": 3,
      "name": "Rock_Marble_Brick_Roof_Shallow"
    },
    {
      "x": -1,
      "y": 0,
      "z": 4,
      "name": "Rock_Marble_Brick"
    },
    {
      "x": -1,
      "y": 1,
      "z": 4,
      "name": "Rock_Marble_Brick"
    },
    {
      "x": -1,
      "y": 8,
      "z": 4,
      "name": "*Furniture_Temple_Light_Trapdoor_State_Definitions_OpenDoorOut",
      "rotation": 2
    },
    {
      "x": -1,
      "y": 0,
      "z": 5,
      "name": "Rock_Marble_Brick"
    },
    {
      "x": -1,
      "y": 1,
      "z": 5,
      "name": "Rock_Marble_Brick"
    },
    {
      "x": -1,
      "y": 8,
      "z": 5,
      "name": "Rock_Marble_Brick"
    },
    {
      "x": -1,
      "y": 9,
      "z": 5,
      "name": "Rock_Marble_Brick_Roof_Flat",
      "rotation": 3
    },
    {
      "x": -1,
      "y": 0,
      "z": 6,
      "name": "Rock_Marble_Brick"
    },
    {
      "x": -1,
      "y": 1,
      "z": 6,
      "name": "Rock_Marble_Brick"
    },
    {
      "x": -1,
      "y": 8,
      "z": 6,
      "name": "*Furniture_Temple_Light_Trapdoor_State_Definitions_OpenDoorOut"
    },
    {
      "x": -1,
      "y": 0,
      "z": 7,
      "name": "Rock_Marble_Brick"
    },
    {
      "x": -1,
      "y": 1,
      "z": 7,
      "name": "Rock_Marble_Brick"
    },
    {
      "x": -1,
      "y": 0,
      "z": 8,
      "name": "Rock_Marble_Brick"
    },
    {
      "x": -1,
      "y": 1,
      "z": 8,
      "name": "Rock_Marble_Brick_Stairs"
    },
    {
      "x": -1,
      "y": 0,
      "z": 9,
      "name": "Rock_Marble_Brick"
    },
    {
      "x": -1,
      "y": 0,
      "z": 10,
      "name": "Rock_Marble_Brick_Stairs"
    },
    {
      "x": 0,
      "y": 0,
      "z": -10,
      "name": "Rock_Marble_Brick"
    },
    {
      "x": 0,
      "y": 1,
      "z": -10,
      "name": "Rock_Marble_Brick"
    },
    {
      "x": 0,
      "y": 0,
      "z": -9,
      "name": "Rock_Marble_Brick"
    },
    {
      "x": 0,
      "y": 1,
      "z": -9,
      "name": "BlueLED"
    },
    {
      "x": 0,
      "y": 0,
      "z": -8,
      "name": "Rock_Marble_Brick"
    },
    {
      "x": 0,
      "y": 1,
      "z": -8,
      "name": "Rock_Marble_Brick"
    },
    {
      "x": 0,
      "y": 6,
      "z": -8,
      "name": "Rock_Marble_Brick_Roof_Shallow",
      "rotation": 2
    },
    {
      "x": 0,
      "y": 0,
      "z": -7,
      "name": "Rock_Marble_Brick"
    },
    {
      "x": 0,
      "y": 1,
      "z": -7,
      "name": "Rock_Marble_Brick"
    },
    {
      "x": 0,
      "y": 2,
      "z": -7,
      "name": "Rock_Marble_Brick_Smooth"
    },
    {
      "x": 0,
      "y": 3,
      "z": -7,
      "name": "Rock_Marble_Brick_Smooth"
    },
    {
      "x": 0,
      "y": 4,
      "z": -7,
      "name": "Rock_Marble_Brick_Smooth"
    },
    {
      "x": 0,
      "y": 5,
      "z": -7,
      "name": "Rock_Marble_Brick_Wall"
    },
    {
      "x": 0,
      "y": 6,
      "z": -7,
      "name": "Rock_Marble_Brick_Roof_Shallow",
      "filler": 32,
      "rotation": 2
    },
    {
      "x": 0,
      "y": 12,
      "z": -7,
      "name": "Rock_Marble_Brick_Roof_Shallow",
      "rotation": 2
    },
    {
      "x": 0,
      "y": 0,
      "z": -6,
      "name": "Rock_Marble_Brick"
    },
    {
      "x": 0,
      "y": 1,
      "z": -6,
      "name": "Rock_Marble_Brick"
    },
    {
      "x": 0,
      "y": 7,
      "z": -6,
      "name": "Rock_Marble_Brick_Decorative"
    },
    {
      "x": 0,
      "y": 8,
      "z": -6,
      "name": "Rock_Marble_Brick_Smooth"
    },
    {
      "x": 0,
      "y": 9,
      "z": -6,
      "name": "Rock_Marble_Brick_Smooth"
    },
    {
      "x": 0,
      "y": 10,
      "z": -6,
      "name": "Rock_Marble_Brick_Smooth"
    },
    {
      "x": 0,
      "y": 11,
      "z": -6,
      "name": "Rock_Marble_Brick_Wall"
    },
    {
      "x": 0,
      "y": 12,
      "z": -6,
      "name": "Rock_Marble_Brick_Roof_Shallow",
      "filler": 32,
      "rotation": 2
    },
    {
      "x": 0,
      "y": 13,
      "z": -6,
      "name": "Rock_Marble_Brick_Roof_Shallow",
      "rotation": 2
    },
    {
      "x": 0,
      "y": 0,
      "z": -5,
      "name": "Rock_Marble_Brick"
    },
    {
      "x": 0,
      "y": 1,
      "z": -5,
      "name": "Rock_Marble_Brick"
    },
    {
      "x": 0,
      "y": 7,
      "z": -5,
      "name": "Rock_Marble_Brick_Decorative"
    },
    {
      "x": 0,
      "y": 8,
      "z": -5,
      "name": "Rock_Marble_Brick_Wall",
      "rotation": 1
    },
    {
      "x": 0,
      "y": 9,
      "z": -5,
      "name": "Rock_Marble_Brick_Decorative"
    },
    {
      "x": 0,
      "y": 10,
      "z": -5,
      "name": "Rock_Marble_Brick_Wall",
      "rotation": 1
    },
    {
      "x": 0,
      "y": 11,
      "z": -5,
      "name": "Rock_Marble_Brick_Decorative"
    },
    {
      "x": 0,
      "y": 12,
      "z": -5,
      "name": "Rock_Marble_Brick_Wall",
      "rotation": 1
    },
    {
      "x": 0,
      "y": 13,
      "z": -5,
      "name": "Rock_Marble_Brick_Roof_Shallow",
      "filler": 32,
      "rotation": 2
    },
    {
      "x": 0,
      "y": 14,
      "z": -5,
      "name": "Rock_Marble_Brick_Roof_Shallow",
      "rotation": 2
    },
    {
      "x": 0,
      "y": 0,
      "z": -4,
      "name": "Rock_Marble_Brick"
    },
    {
      "x": 0,
      "y": 1,
      "z": -4,
      "name": "Rock_Marble_Brick"
    },
    {
      "x": 0,
      "y": 7,
      "z": -4,
      "name": "Rock_Marble_Brick_Decorative"
    },
    {
      "x": 0,
      "y": 8,
      "z": -4,
      "name": "Rock_Marble_Brick_Wall",
      "rotation": 1
    },
    {
      "x": 0,
      "y": 9,
      "z": -4,
      "name": "Rock_Marble_Brick_Decorative"
    },
    {
      "x": 0,
      "y": 10,
      "z": -4,
      "name": "Rock_Marble_Brick_Wall",
      "rotation": 1
    },
    {
      "x": 0,
      "y": 11,
      "z": -4,
      "name": "Rock_Marble_Brick_Decorative"
    },
    {
      "x": 0,
      "y": 12,
      "z": -4,
      "name": "Rock_Marble_Brick_Wall",
      "rotation": 1
    },
    {
      "x": 0,
      "y": 13,
      "z": -4,
      "name": "Rock_Marble_Brick_Decorative"
    },
    {
      "x": 0,
      "y": 14,
      "z": -4,
      "name": "Rock_Marble_Brick_Roof_Shallow",
      "filler": 32,
      "rotation": 2
    },
    {
      "x": 0,
      "y": 15,
      "z": -4,
      "name": "Rock_Marble_Brick_Roof_Shallow",
      "rotation": 2
    },
    {
      "x": 0,
      "y": 0,
      "z": -3,
      "name": "Rock_Marble_Brick"
    },
    {
      "x": 0,
      "y": 1,
      "z": -3,
      "name": "Rock_Marble_Brick"
    },
    {
      "x": 0,
      "y": 7,
      "z": -3,
      "name": "Rock_Marble_Brick_Decorative"
    },
    {
      "x": 0,
      "y": 8,
      "z": -3,
      "name": "Rock_Marble_Brick_Wall",
      "rotation": 1
    },
    {
      "x": 0,
      "y": 9,
      "z": -3,
      "name": "Rock_Marble_Brick_Decorative"
    },
    {
      "x": 0,
      "y": 10,
      "z": -3,
      "name": "Rock_Marble_Brick_Wall",
      "rotation": 1
    },
    {
      "x": 0,
      "y": 11,
      "z": -3,
      "name": "Rock_Marble_Brick_Decorative"
    },
    {
      "x": 0,
      "y": 12,
      "z": -3,
      "name": "Rock_Marble_Brick_Wall",
      "rotation": 1
    },
    {
      "x": 0,
      "y": 13,
      "z": -3,
      "name": "Rock_Marble_Brick_Decorative"
    },
    {
      "x": 0,
      "y": 14,
      "z": -3,
      "name": "Rock_Marble_Brick_Wall",
      "rotation": 1
    },
    {
      "x": 0,
      "y": 15,
      "z": -3,
      "name": "Rock_Marble_Brick_Roof_Shallow",
      "filler": 32,
      "rotation": 2
    },
    {
      "x": 0,
      "y": 0,
      "z": -2,
      "name": "Rock_Marble_Brick"
    },
    {
      "x": 0,
      "y": 1,
      "z": -2,
      "name": "Rock_Marble_Brick"
    },
    {
      "x": 0,
      "y": 7,
      "z": -2,
      "name": "Rock_Marble_Brick_Decorative"
    },
    {
      "x": 0,
      "y": 15,
      "z": -2,
      "name": "Rock_Marble_Brick_Roof_Shallow",
      "filler": 992
    },
    {
      "x": 0,
      "y": 0,
      "z": -1,
      "name": "Rock_Marble_Brick"
    },
    {
      "x": 0,
      "y": 1,
      "z": -1,
      "name": "Rock_Marble_Brick"
    },
    {
      "x": 0,
      "y": 7,
      "z": -1,
      "name": "Rock_Marble_Brick_Decorative"
    },
    {
      "x": 0,
      "y": 14,
      "z": -1,
      "name": "Rock_Marble_Brick_Roof_Shallow",
      "filler": 992
    },
    {
      "x": 0,
      "y": 15,
      "z": -1,
      "name": "Rock_Marble_Brick_Roof_Shallow"
    },
    {
      "x": 0,
      "y": 0,
      "z": 0,
      "name": "Rock_Marble_Brick"
    },
    {
      "x": 0,
      "y": 1,
      "z": 0,
      "name": "Rock_Marble_Brick"
    },
    {
      "x": 0,
      "y": 7,
      "z": 0,
      "name": "Rock_Marble_Brick_Decorative"
    },
    {
      "x": 0,
      "y": 13,
      "z": 0,
      "name": "Rock_Marble_Brick_Roof_Shallow",
      "filler": 992
    },
    {
      "x": 0,
      "y": 14,
      "z": 0,
      "name": "Rock_Marble_Brick_Roof_Shallow"
    },
    {
      "x": 0,
      "y": 0,
      "z": 1,
      "name": "Rock_Marble_Brick"
    },
    {
      "x": 0,
      "y": 1,
      "z": 1,
      "name": "Rock_Marble_Brick"
    },
    {
      "x": 0,
      "y": 7,
      "z": 1,
      "name": "Rock_Marble_Brick_Decorative"
    },
    {
      "x": 0,
      "y": 8,
      "z": 1,
      "name": "Rock_Marble_Brick_Smooth"
    },
    {
      "x": 0,
      "y": 9,
      "z": 1,
      "name": "BlueLED"
    },
    {
      "x": 0,
      "y": 10,
      "z": 1,
      "name": "Rock_Marble_Brick_Smooth"
    },
    {
      "x": 0,
      "y": 11,
      "z": 1,
      "name": "Rock_Marble_Brick_Wall"
    },
    {
      "x": 0,
      "y": 12,
      "z": 1,
      "name": "Rock_Marble_Brick_Roof_Shallow",
      "filler": 992
    },
    {
      "x": 0,
      "y": 13,
      "z": 1,
      "name": "Rock_Marble_Brick_Roof_Shallow"
    },
    {
      "x": 0,
      "y": 0,
      "z": 2,
      "name": "Rock_Marble_Brick"
    },
    {
      "x": 0,
      "y": 1,
      "z": 2,
      "name": "Rock_Marble_Brick"
    },
    {
      "x": 0,
      "y": 2,
      "z": 2,
      "name": "*Furniture_Temple_Light_Door_Medilum_State_Definitions_CloseDoorIn",
      "filler": 1
    },
    {
      "x": 0,
      "y": 3,
      "z": 2,
      "name": "*Furniture_Temple_Light_Door_Medilum_State_Definitions_CloseDoorIn",
      "filler": 1025
    },
    {
      "x": 0,
      "y": 4,
      "z": 2,
      "name": "*Furniture_Temple_Light_Door_Medilum_State_Definitions_CloseDoorIn",
      "filler": 2049
    },
    {
      "x": 0,
      "y": 5,
      "z": 2,
      "name": "Rock_Marble_Brick_Wall"
    },
    {
      "x": 0,
      "y": 6,
      "z": 2,
      "name": "Rock_Marble_Brick_Roof_Shallow",
      "filler": 992
    },
    {
      "x": 0,
      "y": 12,
      "z": 2,
      "name": "Rock_Marble_Brick_Roof_Shallow"
    },
    {
      "x": 0,
      "y": 0,
      "z": 3,
      "name": "Rock_Marble_Brick"
    },
    {
      "x": 0,
      "y": 1,
      "z": 3,
      "name": "Rock_Marble_Brick"
    },
    {
      "x": 0,
      "y": 6,
      "z": 3,
      "name": "Rock_Marble_Brick_Roof_Shallow"
    },
    {
      "x": 0,
      "y": 0,
      "z": 4,
      "name": "Rock_Marble_Brick"
    },
    {
      "x": 0,
      "y": 1,
      "z": 4,
      "name": "Rock_Marble_Brick"
    },
    {
      "x": 0,
      "y": 8,
      "z": 4,
      "name": "*Furniture_Temple_Light_Trapdoor_State_Definitions_OpenDoorOut",
      "rotation": 2
    },
    {
      "x": 0,
      "y": 0,
      "z": 5,
      "name": "Rock_Marble_Brick"
    },
    {
      "x": 0,
      "y": 1,
      "z": 5,
      "name": "Rock_Marble_Brick"
    },
    {
      "x": 0,
      "y": 7,
      "z": 5,
      "name": "Furniture_Temple_Light_Lantern_Ceiling"
    },
    {
      "x": 0,
      "y": 8,
      "z": 5,
      "name": "Rock_Marble_Brick"
    },
    {
      "x": 0,
      "y": 9,
      "z": 5,
      "name": "Rock_Marble_Brick_Roof_Flat",
      "rotation": 3
    },
    {
      "x": 0,
      "y": 0,
      "z": 6,
      "name": "Rock_Marble_Brick"
    },
    {
      "x": 0,
      "y": 1,
      "z": 6,
      "name": "Rock_Marble_Brick"
    },
    {
      "x": 0,
      "y": 8,
      "z": 6,
      "name": "*Furniture_Temple_Light_Trapdoor_State_Definitions_OpenDoorOut"
    },
    {
      "x": 0,
      "y": 0,
      "z": 7,
      "name": "Rock_Marble_Brick"
    },
    {
      "x": 0,
      "y": 1,
      "z": 7,
      "name": "Rock_Marble_Brick"
    },
    {
      "x": 0,
      "y": 0,
      "z": 8,
      "name": "Rock_Marble_Brick"
    },
    {
      "x": 0,
      "y": 1,
      "z": 8,
      "name": "Rock_Marble_Brick_Stairs"
    },
    {
      "x": 0,
      "y": 0,
      "z": 9,
      "name": "Rock_Marble_Brick"
    },
    {
      "x": 0,
      "y": 0,
      "z": 10,
      "name": "Rock_Marble_Brick_Stairs"
    },
    {
      "x": 1,
      "y": 0,
      "z": -10,
      "name": "Rock_Marble_Brick"
    },
    {
      "x": 1,
      "y": 1,
      "z": -10,
      "name": "Rock_Marble_Brick"
    },
    {
      "x": 1,
      "y": 0,
      "z": -9,
      "name": "Rock_Marble_Brick"
    },
    {
      "x": 1,
      "y": 1,
      "z": -9,
      "name": "BlueLED"
    },
    {
      "x": 1,
      "y": 0,
      "z": -8,
      "name": "Rock_Marble_Brick"
    },
    {
      "x": 1,
      "y": 1,
      "z": -8,
      "name": "Rock_Marble_Brick"
    },
    {
      "x": 1,
      "y": 6,
      "z": -8,
      "name": "Rock_Marble_Brick_Roof_Shallow",
      "rotation": 2
    },
    {
      "x": 1,
      "y": 0,
      "z": -7,
      "name": "Rock_Marble_Brick"
    },
    {
      "x": 1,
      "y": 1,
      "z": -7,
      "name": "Rock_Marble_Brick"
    },
    {
      "x": 1,
      "y": 2,
      "z": -7,
      "name": "Rock_Marble_Brick_Smooth"
    },
    {
      "x": 1,
      "y": 3,
      "z": -7,
      "name": "Rock_Marble_Brick_Smooth"
    },
    {
      "x": 1,
      "y": 4,
      "z": -7,
      "name": "Rock_Marble_Brick_Smooth"
    },
    {
      "x": 1,
      "y": 5,
      "z": -7,
      "name": "Rock_Marble_Brick_Wall"
    },
    {
      "x": 1,
      "y": 6,
      "z": -7,
      "name": "Rock_Marble_Brick_Roof_Shallow",
      "filler": 32,
      "rotation": 2
    },
    {
      "x": 1,
      "y": 12,
      "z": -7,
      "name": "Rock_Marble_Brick_Roof_Shallow",
      "rotation": 2
    },
    {
      "x": 1,
      "y": 0,
      "z": -6,
      "name": "Rock_Marble_Brick"
    },
    {
      "x": 1,
      "y": 1,
      "z": -6,
      "name": "Rock_Marble_Brick"
    },
    {
      "x": 1,
      "y": 7,
      "z": -6,
      "name": "Rock_Marble_Brick_Decorative"
    },
    {
      "x": 1,
      "y": 8,
      "z": -6,
      "name": "Rock_Marble_Brick_Smooth"
    },
    {
      "x": 1,
      "y": 9,
      "z": -6,
      "name": "Rock_Marble_Brick_Smooth"
    },
    {
      "x": 1,
      "y": 10,
      "z": -6,
      "name": "Rock_Marble_Brick_Smooth"
    },
    {
      "x": 1,
      "y": 11,
      "z": -6,
      "name": "Rock_Marble_Brick_Wall"
    },
    {
      "x": 1,
      "y": 12,
      "z": -6,
      "name": "Rock_Marble_Brick_Roof_Shallow",
      "filler": 32,
      "rotation": 2
    },
    {
      "x": 1,
      "y": 13,
      "z": -6,
      "name": "Rock_Marble_Brick_Roof_Shallow",
      "rotation": 2
    },
    {
      "x": 1,
      "y": 0,
      "z": -5,
      "name": "Rock_Marble_Brick"
    },
    {
      "x": 1,
