{
  "version": 8,
  "blockIdVersion": 11,
  "anchorX": 0,
  "anchorY": 0,
  "anchorZ": 0,
  "blocks": [
    {
      "x": -7,
      "y": 0,
      "z": -5,
      "name": "Rock_Ledge_Brick_Smooth"
    },
    {
      "x": -7,
      "y": 1,
      "z": -5,
      "name": "Empty"
    },
    {
      "x": -7,
      "y": 2,
      "z": -5,
      "name": "Empty"
    },
    {
      "x": -7,
      "y": 3,
      "z": -5,
      "name": "Empty"
    },
    {
      "x": -7,
      "y": 4,
      "z": -5,
      "name": "Empty"
    },
    {
      "x": -7,
      "y": 5,
      "z": -5,
      "name": "Empty"
    },
    {
      "x": -7,
      "y": 6,
      "z": -5,
      "name": "Empty"
    },
    {
      "x": -7,
      "y": 7,
      "z": -5,
      "name": "Empty"
    },
    {
      "x": -7,
      "y": 8,
      "z": -5,
      "name": "Empty"
    },
    {
      "x": -7,
      "y": 9,
      "z": -5,
      "name": "Empty"
    },
    {
      "x": -7,
      "y": 10,
      "z": -5,
      "name": "Empty"
    },
    {
      "x": -7,
      "y": 11,
      "z": -5,
      "name": "Empty"
    },
    {
      "x": -7,
      "y": 12,
      "z": -5,
      "name": "Empty"
    },
    {
      "x": -7,
      "y": 13,
      "z": -5,
      "name": "Empty"
    },
    {
      "x": -7,
      "y": 14,
      "z": -5,
      "name": "Empty"
    },
    {
      "x": -7,
      "y": 15,
      "z": -5,
      "name": "Empty"
    },
    {
      "x": -7,
      "y": 16,
      "z": -5,
      "name": "Empty"
    },
    {
      "x": -7,
      "y": 17,
      "z": -5,
      "name": "Empty"
    },
    {
      "x": -7,
      "y": 18,
      "z": -5,
      "name": "Empty"
    },
    {
      "x": -7,
      "y": 19,
      "z": -5,
      "name": "Empty"
    },
    {
      "x": -7,
      "y": 20,
      "z": -5,
      "name": "Empty"
    },
    {
      "x": -7,
      "y": 21,
      "z": -5,
      "name": "Empty"
    },
    {
      "x": -7,
      "y": 0,
      "z": -4,
      "name": "Rock_Ledge_Brick_Smooth"
    },
    {
      "x": -7,
      "y": 1,
      "z": -4,
      "name": "Empty"
    },
    {
      "x": -7,
      "y": 2,
      "z": -4,
      "name": "Empty"
    },
    {
      "x": -7,
      "y": 3,
      "z": -4,
      "name": "Empty"
    },
    {
      "x": -7,
      "y": 4,
      "z": -4,
      "name": "Empty"
    },
    {
      "x": -7,
      "y": 5,
      "z": -4,
      "name": "Empty"
    },
    {
      "x": -7,
      "y": 6,
      "z": -4,
      "name": "Empty"
    },
    {
      "x": -7,
      "y": 7,
      "z": -4,
      "name": "Empty"
    },
    {
      "x": -7,
      "y": 8,
      "z": -4,
      "name": "Empty"
    },
    {
      "x": -7,
      "y": 9,
      "z": -4,
      "name": "Empty"
    },
    {
      "x": -7,
      "y": 10,
      "z": -4,
      "name": "Empty"
    },
    {
      "x": -7,
      "y": 11,
      "z": -4,
      "name": "Empty"
    },
    {
      "x": -7,
      "y": 12,
      "z": -4,
      "name": "Empty"
    },
    {
      "x": -7,
      "y": 13,
      "z": -4,
      "name": "Empty"
    },
    {
      "x": -7,
      "y": 14,
      "z": -4,
      "name": "Empty"
    },
    {
      "x": -7,
      "y": 15,
      "z": -4,
      "name": "Empty"
    },
    {
      "x": -7,
      "y": 16,
      "z": -4,
      "name": "Empty"
    },
    {
      "x": -7,
      "y": 17,
      "z": -4,
      "name": "Empty"
    },
    {
      "x": -7,
      "y": 18,
      "z": -4,
      "name": "Empty"
    },
    {
      "x": -7,
      "y": 19,
      "z": -4,
      "name": "Empty"
    },
    {
      "x": -7,
      "y": 20,
      "z": -4,
      "name": "Empty"
    },
    {
      "x": -7,
      "y": 21,
      "z": -4,
      "name": "Empty"
    },
    {
      "x": -7,
      "y": 0,
      "z": -3,
      "name": "Rock_Ledge_Brick_Smooth"
    },
    {
      "x": -7,
      "y": 1,
      "z": -3,
      "name": "Rock_Ledge_Brick_Smooth"
    },
    {
      "x": -7,
      "y": 2,
      "z": -3,
      "name": "Rock_Ledge_Brick_Smooth"
    },
    {
      "x": -7,
      "y": 3,
      "z": -3,
      "name": "Rock_Ledge_Brick_Smooth"
    },
    {
      "x": -7,
      "y": 4,
      "z": -3,
      "name": "Rock_Ledge_Brick_Smooth"
    },
    {
      "x": -7,
      "y": 5,
      "z": -3,
      "name": "Rock_Ledge_Brick_Smooth"
    },
    {
      "x": -7,
      "y": 6,
      "z": -3,
      "name": "Rock_Ledge_Brick_Smooth"
    },
    {
      "x": -7,
      "y": 7,
      "z": -3,
      "name": "Rock_Ledge_Brick_Smooth"
    },
    {
      "x": -7,
      "y": 8,
      "z": -3,
      "name": "Rock_Ledge_Brick_Smooth"
    },
    {
      "x": -7,
      "y": 9,
      "z": -3,
      "name": "Rock_Ledge_Brick_Smooth"
    },
    {
      "x": -7,
      "y": 10,
      "z": -3,
      "name": "Rock_Ledge_Brick_Smooth"
    },
    {
      "x": -7,
      "y": 11,
      "z": -3,
      "name": "Rock_Ledge_Brick_Smooth"
    },
    {
      "x": -7,
      "y": 12,
      "z": -3,
      "name": "Rock_Ledge_Brick_Smooth"
    },
    {
      "x": -7,
      "y": 13,
      "z": -3,
      "name": "Rock_Ledge_Brick_Smooth"
    },
    {
      "x": -7,
      "y": 14,
      "z": -3,
      "name": "Rock_Ledge_Brick_Smooth"
    },
    {
      "x": -7,
      "y": 15,
      "z": -3,
      "name": "Rock_Ledge_Brick_Smooth"
    },
    {
      "x": -7,
      "y": 16,
      "z": -3,
      "name": "Rock_Ledge_Brick_Smooth"
    },
    {
      "x": -7,
      "y": 17,
      "z": -3,
      "name": "Rock_Ledge_Brick_Smooth"
    },
    {
      "x": -7,
      "y": 18,
      "z": -3,
      "name": "Rock_Ledge_Brick_Smooth"
    },
    {
      "x": -7,
      "y": 19,
      "z": -3,
      "name": "Empty"
    },
    {
      "x": -7,
      "y": 20,
      "z": -3,
      "name": "Empty"
    },
    {
      "x": -7,
      "y": 21,
      "z": -3,
      "name": "Empty"
    },
    {
      "x": -7,
      "y": 22,
      "z": -3,
      "name": "Rock_Ledge_Brick_Smooth"
    },
    {
      "x": -7,
      "y": 0,
      "z": -2,
      "name": "Rock_Ledge_Brick_Smooth"
    },
    {
      "x": -7,
      "y": 1,
      "z": -2,
      "name": "Rock_Ledge_Brick_Smooth"
    },
    {
      "x": -7,
      "y": 2,
      "z": -2,
      "name": "Rock_Ledge_Brick_Smooth"
    },
    {
      "x": -7,
      "y": 3,
      "z": -2,
      "name": "Rock_Ledge_Brick_Smooth"
    },
    {
      "x": -7,
      "y": 4,
      "z": -2,
      "name": "Rock_Ledge_Brick_Smooth"
    },
    {
      "x": -7,
      "y": 5,
      "z": -2,
      "name": "Rock_Ledge_Brick_Smooth"
    },
    {
      "x": -7,
      "y": 6,
      "z": -2,
      "name": "Rock_Ledge_Brick_Smooth"
    },
    {
      "x": -7,
      "y": 7,
      "z": -2,
      "name": "Rock_Ledge_Brick_Smooth"
    },
    {
      "x": -7,
      "y": 8,
      "z": -2,
      "name": "Rock_Ledge_Brick_Smooth"
    },
    {
      "x": -7,
      "y": 9,
      "z": -2,
      "name": "Rock_Ledge_Brick_Smooth"
    },
    {
      "x": -7,
      "y": 10,
      "z": -2,
      "name": "Rock_Ledge_Brick_Smooth"
    },
    {
      "x": -7,
      "y": 11,
      "z": -2,
      "name": "Rock_Ledge_Brick_Smooth"
    },
    {
      "x": -7,
      "y": 12,
      "z": -2,
      "name": "Rock_Ledge_Brick_Smooth"
    },
    {
      "x": -7,
      "y": 13,
      "z": -2,
      "name": "Rock_Ledge_Brick_Smooth"
    },
    {
      "x": -7,
      "y": 14,
      "z": -2,
      "name": "Rock_Ledge_Brick_Smooth"
    },
    {
      "x": -7,
      "y": 15,
      "z": -2,
      "name": "Rock_Ledge_Brick_Smooth"
    },
    {
      "x": -7,
      "y": 16,
      "z": -2,
      "name": "Rock_Ledge_Brick_Smooth"
    },
    {
      "x": -7,
      "y": 17,
      "z": -2,
      "name": "Rock_Ledge_Brick_Smooth"
    },
    {
      "x": -7,
      "y": 18,
      "z": -2,
      "name": "Rock_Ledge_Brick_Smooth"
    },
    {
      "x": -7,
      "y": 19,
      "z": -2,
      "name": "Rock_Ledge_Brick_Smooth"
    },
    {
      "x": -7,
      "y": 20,
      "z": -2,
      "name": "Rock_Ledge_Brick_Smooth"
    },
    {
      "x": -7,
      "y": 21,
      "z": -2,
      "name": "Rock_Ledge_Brick_Smooth"
    },
    {
      "x": -7,
      "y": 22,
      "z": -2,
      "name": "Rock_Ledge_Brick_Smooth"
    },
    {
      "x": -7,
      "y": 0,
      "z": -1,
      "name": "Rock_Ledge_Brick_Smooth"
    },
    {
      "x": -7,
      "y": 1,
      "z": -1,
      "name": "Rock_Ledge_Brick_Smooth"
    },
    {
      "x": -7,
      "y": 2,
      "z": -1,
      "name": "Rock_Ledge_Brick_Smooth"
    },
    {
      "x": -7,
      "y": 3,
      "z": -1,
      "name": "Rock_Ledge_Brick_Smooth"
    },
    {
      "x": -7,
      "y": 4,
      "z": -1,
      "name": "Rock_Ledge_Brick_Smooth"
    },
    {
      "x": -7,
      "y": 5,
      "z": -1,
      "name": "Rock_Ledge_Brick_Smooth"
    },
    {
      "x": -7,
      "y": 6,
      "z": -1,
      "name": "Rock_Ledge_Brick_Smooth"
    },
    {
      "x": -7,
      "y": 7,
      "z": -1,
      "name": "Rock_Ledge_Brick_Smooth"
    },
    {
      "x": -7,
      "y": 8,
      "z": -1,
      "name": "Rock_Ledge_Brick_Smooth"
    },
    {
      "x": -7,
      "y": 9,
      "z": -1,
      "name": "Rock_Ledge_Brick_Smooth"
    },
    {
      "x": -7,
      "y": 10,
      "z": -1,
      "name": "Rock_Ledge_Brick_Smooth"
    },
    {
      "x": -7,
      "y": 11,
      "z": -1,
      "name": "Rock_Ledge_Brick_Smooth"
    },
    {
      "x": -7,
      "y": 12,
      "z": -1,
      "name": "Rock_Ledge_Brick_Smooth"
    },
    {
      "x": -7,
      "y": 13,
      "z": -1,
      "name": "Rock_Ledge_Brick_Smooth"
    },
    {
      "x": -7,
      "y": 14,
      "z": -1,
      "name": "Rock_Ledge_Brick_Smooth"
    },
    {
      "x": -7,
      "y": 15,
      "z": -1,
      "name": "Rock_Ledge_Brick_Smooth"
    },
    {
      "x": -7,
      "y": 16,
      "z": -1,
      "name": "Rock_Ledge_Brick_Smooth"
    },
    {
      "x": -7,
      "y": 17,
      "z": -1,
      "name": "Rock_Ledge_Brick_Smooth"
    },
    {
      "x": -7,
      "y": 18,
      "z": -1,
      "name": "Rock_Ledge_Brick_Smooth"
    },
    {
      "x": -7,
      "y": 19,
      "z": -1,
      "name": "Empty"
    },
    {
      "x": -7,
      "y": 20,
      "z": -1,
      "name": "Empty"
    },
    {
      "x": -7,
      "y": 21,
      "z": -1,
      "name": "Empty"
    },
    {
      "x": -7,
      "y": 22,
      "z": -1,
      "name": "Rock_Ledge_Brick_Smooth"
    },
    {
      "x": -7,
      "y": 0,
      "z": 0,
      "name": "Rock_Ledge_Brick_Smooth"
    },
    {
      "x": -7,
      "y": 1,
      "z": 0,
      "name": "Furniture_Robot_Door",
      "rotation": 3
    },
    {
      "x": -7,
      "y": 2,
      "z": 0,
      "name": "Furniture_Robot_Door",
      "filler": 1024,
      "rotation": 3
    },
    {
      "x": -7,
      "y": 3,
      "z": 0,
      "name": "Rock_Ledge_Brick_Smooth"
    },
    {
      "x": -7,
      "y": 4,
      "z": 0,
      "name": "Rock_Ledge_Brick_Smooth"
    },
    {
      "x": -7,
      "y": 5,
      "z": 0,
      "name": "Rock_Ledge_Brick_Smooth"
    },
    {
      "x": -7,
      "y": 6,
      "z": 0,
      "name": "Rock_Ledge_Brick_Smooth"
    },
    {
      "x": -7,
      "y": 7,
      "z": 0,
      "name": "Rock_Ledge_Brick_Smooth"
    },
    {
      "x": -7,
      "y": 8,
      "z": 0,
      "name": "Rock_Ledge_Brick_Smooth"
    },
    {
      "x": -7,
      "y": 9,
      "z": 0,
      "name": "Rock_Ledge_Brick_Smooth"
    },
    {
      "x": -7,
      "y": 10,
      "z": 0,
      "name": "Rock_Ledge_Brick_Smooth"
    },
    {
      "x": -7,
      "y": 11,
      "z": 0,
      "name": "Rock_Ledge_Brick_Smooth"
    },
    {
      "x": -7,
      "y": 12,
      "z": 0,
      "name": "Rock_Ledge_Brick_Smooth"
    },
    {
      "x": -7,
      "y": 13,
      "z": 0,
      "name": "Rock_Ledge_Brick_Smooth"
    },
    {
      "x": -7,
      "y": 14,
      "z": 0,
      "name": "Rock_Ledge_Brick_Smooth"
    },
    {
      "x": -7,
      "y": 15,
      "z": 0,
      "name": "Rock_Ledge_Brick_Smooth"
    },
    {
      "x": -7,
      "y": 16,
      "z": 0,
      "name": "Rock_Ledge_Brick_Smooth"
    },
    {
      "x": -7,
      "y": 17,
      "z": 0,
      "name": "Rock_Ledge_Brick_Smooth"
    },
    {
      "x": -7,
      "y": 18,
      "z": 0,
      "name": "Rock_Ledge_Brick_Smooth"
    },
    {
      "x": -7,
      "y": 19,
      "z": 0,
      "name": "Empty"
    },
    {
      "x": -7,
      "y": 20,
      "z": 0,
      "name": "Empty"
    },
    {
      "x": -7,
      "y": 21,
      "z": 0,
      "name": "Empty"
    },
    {
      "x": -7,
      "y": 22,
      "z": 0,
      "name": "Rock_Ledge_Brick_Smooth"
    },
    {
      "x": -7,
      "y": 0,
      "z": 1,
      "name": "Rock_Ledge_Brick_Smooth"
    },
    {
      "x": -7,
      "y": 1,
      "z": 1,
      "name": "Rock_Ledge_Brick_Smooth"
    },
    {
      "x": -7,
      "y": 2,
      "z": 1,
      "name": "Rock_Ledge_Brick_Smooth"
    },
    {
      "x": -7,
      "y": 3,
      "z": 1,
      "name": "Rock_Ledge_Brick_Smooth"
    },
    {
      "x": -7,
      "y": 4,
      "z": 1,
      "name": "Rock_Ledge_Brick_Smooth"
    },
    {
      "x": -7,
      "y": 5,
      "z": 1,
      "name": "Rock_Ledge_Brick_Smooth"
    },
    {
      "x": -7,
      "y": 6,
      "z": 1,
      "name": "Rock_Ledge_Brick_Smooth"
    },
    {
      "x": -7,
      "y": 7,
      "z": 1,
      "name": "Rock_Ledge_Brick_Smooth"
    },
    {
      "x": -7,
      "y": 8,
      "z": 1,
      "name": "Rock_Ledge_Brick_Smooth"
    },
    {
      "x": -7,
      "y": 9,
      "z": 1,
      "name": "Rock_Ledge_Brick_Smooth"
    },
    {
      "x": -7,
      "y": 10,
      "z": 1,
      "name": "Rock_Ledge_Brick_Smooth"
    },
    {
      "x": -7,
      "y": 11,
      "z": 1,
      "name": "Rock_Ledge_Brick_Smooth"
    },
    {
      "x": -7,
      "y": 12,
      "z": 1,
      "name": "Rock_Ledge_Brick_Smooth"
    },
    {
      "x": -7,
      "y": 13,
      "z": 1,
      "name": "Rock_Ledge_Brick_Smooth"
    },
    {
      "x": -7,
      "y": 14,
      "z": 1,
      "name": "Rock_Ledge_Brick_Smooth"
    },
    {
      "x": -7,
      "y": 15,
      "z": 1,
      "name": "Rock_Ledge_Brick_Smooth"
    },
    {
      "x": -7,
      "y": 16,
      "z": 1,
      "name": "Rock_Ledge_Brick_Smooth"
    },
    {
      "x": -7,
      "y": 17,
      "z": 1,
      "name": "Rock_Ledge_Brick_Smooth"
    },
    {
      "x": -7,
      "y": 18,
      "z": 1,
      "name": "Rock_Ledge_Brick_Smooth"
    },
    {
      "x": -7,
      "y": 19,
      "z": 1,
      "name": "Empty"
    },
    {
      "x": -7,
      "y": 20,
      "z": 1,
      "name": "Empty"
    },
    {
      "x": -7,
      "y": 21,
      "z": 1,
      "name": "Empty"
    },
    {
      "x": -7,
      "y": 22,
      "z": 1,
      "name": "Rock_Ledge_Brick_Smooth"
    },
    {
      "x": -7,
      "y": 0,
      "z": 2,
      "name": "Rock_Ledge_Brick_Smooth"
    },
    {
      "x": -7,
      "y": 1,
      "z": 2,
      "name": "Rock_Ledge_Brick_Smooth"
    },
    {
      "x": -7,
      "y": 2,
      "z": 2,
      "name": "Rock_Ledge_Brick_Smooth"
    },
    {
      "x": -7,
      "y": 3,
      "z": 2,
      "name": "Rock_Ledge_Brick_Smooth"
    },
    {
      "x": -7,
      "y": 4,
      "z": 2,
      "name": "Rock_Ledge_Brick_Smooth"
    },
    {
      "x": -7,
      "y": 5,
      "z": 2,
      "name": "Rock_Ledge_Brick_Smooth"
    },
    {
      "x": -7,
      "y": 6,
      "z": 2,
      "name": "Rock_Ledge_Brick_Smooth"
    },
    {
      "x": -7,
      "y": 7,
      "z": 2,
      "name": "Rock_Ledge_Brick_Smooth"
    },
    {
      "x": -7,
      "y": 8,
      "z": 2,
      "name": "Rock_Ledge_Brick_Smooth"
    },
    {
      "x": -7,
      "y": 9,
      "z": 2,
      "name": "Rock_Ledge_Brick_Smooth"
    },
    {
      "x": -7,
      "y": 10,
      "z": 2,
      "name": "Rock_Ledge_Brick_Smooth"
    },
    {
      "x": -7,
      "y": 11,
      "z": 2,
      "name": "Rock_Ledge_Brick_Smooth"
    },
    {
      "x": -7,
      "y": 12,
      "z": 2,
      "name": "Rock_Ledge_Brick_Smooth"
    },
    {
      "x": -7,
      "y": 13,
      "z": 2,
      "name": "Rock_Ledge_Brick_Smooth"
    },
    {
      "x": -7,
      "y": 14,
      "z": 2,
      "name": "Rock_Ledge_Brick_Smooth"
    },
    {
      "x": -7,
      "y": 15,
      "z": 2,
      "name": "Rock_Ledge_Brick_Smooth"
    },
    {
      "x": -7,
      "y": 16,
      "z": 2,
      "name": "Rock_Ledge_Brick_Smooth"
    },
    {
      "x": -7,
      "y": 17,
      "z": 2,
      "name": "Rock_Ledge_Brick_Smooth"
    },
    {
      "x": -7,
      "y": 18,
      "z": 2,
      "name": "Rock_Ledge_Brick_Smooth"
    },
    {
      "x": -7,
      "y": 19,
      "z": 2,
      "name": "Rock_Ledge_Brick_Smooth"
    },
    {
      "x": -7,
      "y": 20,
      "z": 2,
      "name": "Rock_Ledge_Brick_Smooth"
    },
    {
      "x": -7,
      "y": 21,
      "z": 2,
      "name": "Rock_Ledge_Brick_Smooth"
    },
    {
      "x": -7,
      "y": 22,
      "z": 2,
      "name": "Rock_Ledge_Brick_Smooth"
    },
    {
      "x": -7,
      "y": 0,
      "z": 3,
      "name": "Rock_Ledge_Brick_Smooth"
    },
    {
      "x": -7,
      "y": 1,
      "z": 3,
      "name": "Rock_Ledge_Brick_Smooth"
    },
    {
      "x": -7,
      "y": 2,
      "z": 3,
      "name": "Rock_Ledge_Brick_Smooth"
    },
    {
      "x": -7,
      "y": 3,
      "z": 3,
      "name": "Rock_Ledge_Brick_Smooth"
    },
    {
      "x": -7,
      "y": 4,
      "z": 3,
      "name": "Rock_Ledge_Brick_Smooth"
    },
    {
      "x": -7,
      "y": 5,
      "z": 3,
      "name": "Rock_Ledge_Brick_Smooth"
    },
    {
      "x": -7,
      "y": 6,
      "z": 3,
      "name": "Rock_Ledge_Brick_Smooth"
    },
    {
      "x": -7,
      "y": 7,
      "z": 3,
      "name": "Rock_Ledge_Brick_Smooth"
    },
    {
      "x": -7,
      "y": 8,
      "z": 3,
      "name": "Rock_Ledge_Brick_Smooth"
    },
    {
      "x": -7,
      "y": 9,
      "z": 3,
      "name": "Rock_Ledge_Brick_Smooth"
    },
    {
      "x": -7,
      "y": 10,
      "z": 3,
      "name": "Rock_Ledge_Brick_Smooth"
    },
    {
      "x": -7,
      "y": 11,
      "z": 3,
      "name": "Rock_Ledge_Brick_Smooth"
    },
    {
      "x": -7,
      "y": 12,
      "z": 3,
      "name": "Rock_Ledge_Brick_Smooth"
    },
    {
      "x": -7,
      "y": 13,
      "z": 3,
      "name": "Rock_Ledge_Brick_Smooth"
    },
    {
      "x": -7,
      "y": 14,
      "z": 3,
      "name": "Rock_Ledge_Brick_Smooth"
    },
    {
      "x": -7,
      "y": 15,
      "z": 3,
      "name": "Rock_Ledge_Brick_Smooth"
    },
    {
      "x": -7,
      "y": 16,
      "z": 3,
      "name": "Rock_Ledge_Brick_Smooth"
    },
    {
      "x": -7,
      "y": 17,
      "z": 3,
      "name": "Rock_Ledge_Brick_Smooth"
    },
    {
      "x": -7,
      "y": 18,
      "z": 3,
      "name": "Rock_Ledge_Brick_Smooth"
    },
    {
      "x": -7,
      "y": 19,
      "z": 3,
      "name": "Empty"
    },
    {
      "x": -7,
      "y": 20,
      "z": 3,
      "name": "Empty"
    },
    {
      "x": -7,
      "y": 21,
      "z": 3,
      "name": "Empty"
    },
    {
      "x": -7,
      "y": 22,
      "z": 3,
      "name": "Rock_Ledge_Brick_Smooth"
    },
    {
      "x": -7,
      "y": 0,
      "z": 4,
      "name": "Rock_Ledge_Brick_Smooth"
    },
    {
      "x": -7,
      "y": 1,
      "z": 4,
      "name": "Empty"
    },
    {
      "x": -7,
      "y": 2,
      "z": 4,
      "name": "Empty"
    },
    {
      "x": -7,
      "y": 3,
      "z": 4,
      "name": "Empty"
    },
    {
      "x": -7,
      "y": 4,
      "z": 4,
      "name": "Empty"
    },
    {
      "x": -7,
      "y": 5,
      "z": 4,
      "name": "Empty"
    },
    {
      "x": -7,
      "y": 6,
      "z": 4,
      "name": "Empty"
    },
    {
      "x": -7,
      "y": 7,
      "z": 4,
      "name": "Empty"
    },
    {
      "x": -7,
      "y": 8,
      "z": 4,
      "name": "Empty"
    },
    {
      "x": -7,
      "y": 9,
      "z": 4,
      "name": "Empty"
    },
    {
      "x": -7,
      "y": 10,
      "z": 4,
      "name": "Empty"
    },
    {
      "x": -7,
      "y": 11,
      "z": 4,
      "name": "Empty"
    },
    {
      "x": -7,
      "y": 12,
      "z": 4,
      "name": "Empty"
    },
    {
      "x": -7,
      "y": 13,
      "z": 4,
      "name": "Empty"
    },
    {
      "x": -7,
      "y": 14,
      "z": 4,
      "name": "Empty"
    },
    {
      "x": -7,
      "y": 15,
      "z": 4,
      "name": "Empty"
    },
    {
      "x": -7,
      "y": 16,
      "z": 4,
      "name": "Empty"
    },
    {
      "x": -7,
      "y": 17,
      "z": 4,
      "name": "Empty"
    },
    {
      "x": -7,
      "y": 18,
      "z": 4,
      "name": "Empty"
    },
    {
      "x": -7,
      "y": 19,
      "z": 4,
      "name": "Empty"
    },
    {
      "x": -7,
      "y": 20,
      "z": 4,
      "name": "Empty"
    },
    {
      "x": -7,
      "y": 21,
      "z": 4,
      "name": "Empty"
    },
    {
      "x": -7,
      "y": 0,
      "z": 5,
      "name": "Rock_Ledge_Brick_Smooth"
    },
    {
      "x": -7,
      "y": 1,
      "z": 5,
      "name": "Empty"
    },
    {
      "x": -7,
      "y": 2,
      "z": 5,
      "name": "Empty"
    },
    {
      "x": -7,
      "y": 3,
      "z": 5,
      "name": "Empty"
    },
    {
      "x": -7,
      "y": 4,
      "z": 5,
      "name": "Empty"
    },
    {
      "x": -7,
      "y": 5,
      "z": 5,
      "name": "Empty"
    },
    {
      "x": -7,
      "y": 6,
      "z": 5,
      "name": "Empty"
    },
    {
      "x": -7,
      "y": 7,
      "z": 5,
      "name": "Empty"
    },
    {
      "x": -7,
      "y": 8,
      "z": 5,
      "name": "Empty"
    },
    {
      "x": -7,
      "y": 9,
      "z": 5,
      "name": "Empty"
    },
    {
      "x": -7,
      "y": 10,
      "z": 5,
      "name": "Empty"
    },
    {
      "x": -7,
      "y": 11,
      "z": 5,
      "name": "Empty"
    },
    {
      "x": -7,
      "y": 12,
      "z": 5,
      "name": "Empty"
    },
    {
      "x": -7,
      "y": 13,
      "z": 5,
      "name": "Empty"
    },
    {
      "x": -7,
      "y": 14,
      "z": 5,
      "name": "Empty"
    },
    {
      "x": -7,
      "y": 15,
      "z": 5,
      "name": "Empty"
    },
    {
      "x": -7,
      "y": 16,
      "z": 5,
      "name": "Empty"
    },
    {
      "x": -7,
      "y": 17,
      "z": 5,
      "name": "Empty"
    },
    {
      "x": -7,
      "y": 18,
      "z": 5,
      "name": "Empty"
    },
    {
      "x": -7,
      "y": 19,
      "z": 5,
      "name": "Empty"
    },
    {
      "x": -7,
      "y": 20,
      "z": 5,
      "name": "Empty"
    },
    {
      "x": -7,
      "y": 21,
      "z": 5,
      "name": "Empty"
    },
    {
      "x": -7,
      "y": 0,
      "z": 6,
      "name": "Empty"
    },
    {
      "x": -7,
      "y": 1,
      "z": 6,
      "name": "Empty"
    },
    {
      "x": -7,
      "y": 2,
      "z": 6,
      "name": "Empty"
    },
    {
      "x": -7,
      "y": 3,
      "z": 6,
      "name": "Empty"
    },
    {
      "x": -7,
      "y": 4,
      "z": 6,
      "name": "Empty"
    },
    {
      "x": -7,
      "y": 5,
      "z": 6,
      "name": "Empty"
    },
    {
      "x": -7,
      "y": 6,
      "z": 6,
      "name": "Empty"
    },
    {
      "x": -7,
      "y": 7,
      "z": 6,
      "name": "Empty"
    },
    {
      "x": -7,
      "y": 8,
      "z": 6,
      "name": "Empty"
    },
    {
      "x": -7,
      "y": 9,
      "z": 6,
      "name": "Empty"
    },
    {
      "x": -7,
      "y": 10,
      "z": 6,
      "name": "Empty"
    },
    {
      "x": -7,
      "y": 11,
      "z": 6,
      "name": "Empty"
    },
    {
      "x": -7,
      "y": 12,
      "z": 6,
      "name": "Empty"
    },
    {
      "x": -7,
      "y": 13,
      "z": 6,
      "name": "Empty"
    },
    {
      "x": -7,
      "y": 14,
      "z": 6,
      "name": "Empty"
    },
    {
      "x": -7,
      "y": 15,
      "z": 6,
      "name": "Empty"
    },
    {
      "x": -7,
      "y": 16,
      "z": 6,
      "name": "Empty"
    },
    {
      "x": -7,
      "y": 17,
      "z": 6,
      "name": "Empty"
    },
    {
      "x": -7,
      "y": 18,
      "z": 6,
      "name": "Empty"
    },
    {
      "x": -7,
      "y": 19,
      "z": 6,
      "name": "Empty"
    },
    {
      "x": -7,
      "y": 20,
      "z": 6,
      "name": "Empty"
    },
    {
      "x": -7,
      "y": 21,
      "z": 6,
      "name": "Empty"
    },
    {
      "x": -6,
      "y": 0,
      "z": -6,
      "name": "Rock_Ledge_Brick_Smooth"
    },
    {
      "x": -6,
      "y": 0,
      "z": -5,
      "name": "Rock_Ledge_Brick_Smooth"
    },
    {
      "x": -6,
      "y": 1,
      "z": -5,
      "name": "Empty"
    },
    {
      "x": -6,
      "y": 2,
      "z": -5,
      "name": "Empty"
    },
    {
      "x": -6,
      "y": 3,
      "z": -5,
      "name": "Empty"
    },
    {
      "x": -6,
      "y": 4,
      "z": -5,
      "name": "Empty"
    },
    {
      "x": -6,
      "y": 5,
      "z": -5,
      "name": "Empty"
    },
    {
      "x": -6,
      "y": 6,
      "z": -5,
      "name": "Empty"
    },
    {
      "x": -6,
      "y": 7,
      "z": -5,
      "name": "Empty"
    },
    {
      "x": -6,
      "y": 8,
      "z": -5,
      "name": "Empty"
    },
    {
      "x": -6,
      "y": 9,
      "z": -5,
      "name": "Empty"
    },
    {
      "x": -6,
      "y": 10,
      "z": -5,
      "name": "Empty"
    },
    {
      "x": -6,
      "y": 11,
      "z": -5,
      "name": "Empty"
    },
    {
      "x": -6,
      "y": 12,
      "z": -5,
      "name": "Empty"
    },
    {
      "x": -6,
      "y": 13,
      "z": -5,
      "name": "Empty"
    },
    {
      "x": -6,
      "y": 14,
      "z": -5,
      "name": "Empty"
    },
    {
      "x": -6,
      "y": 15,
      "z": -5,
      "name": "Empty"
    },
    {
      "x": -6,
      "y": 16,
      "z": -5,
      "name": "Empty"
    },
    {
      "x": -6,
      "y": 17,
      "z": -5,
      "name": "Empty"
    },
    {
      "x": -6,
      "y": 18,
      "z": -5,
      "name": "Empty"
    },
    {
      "x": -6,
      "y": 19,
      "z": -5,
      "name": "Empty"
    },
    {
      "x": -6,
      "y": 20,
      "z": -5,
      "name": "Empty"
    },
    {
      "x": -6,
      "y": 21,
      "z": -5,
      "name": "Empty"
    },
    {
      "x": -6,
      "y": 0,
      "z": -4,
      "name": "Rock_Ledge_Brick_Smooth"
    },
    {
      "x": -6,
      "y": 1,
      "z": -4,
      "name": "Rock_Ledge_Brick_Smooth"
    },
    {
      "x": -6,
      "y": 2,
      "z": -4,
      "name": "Rock_Ledge_Brick_Smooth"
    },
    {
      "x": -6,
      "y": 3,
      "z": -4,
      "name": "Rock_Ledge_Brick_Smooth"
    },
    {
      "x": -6,
      "y": 4,
      "z": -4,
      "name": "Rock_Ledge_Brick_Smooth"
    },
    {
      "x": -6,
      "y": 5,
      "z": -4,
      "name": "Rock_Ledge_Brick_Smooth"
    },
    {
      "x": -6,
      "y": 6,
      "z": -4,
      "name": "Rock_Ledge_Brick_Smooth"
    },
    {
      "x": -6,
      "y": 7,
      "z": -4,
      "name": "Rock_Ledge_Brick_Smooth"
    },
    {
      "x": -6,
      "y": 8,
      "z": -4,
      "name": "Rock_Ledge_Brick_Smooth"
    },
    {
      "x": -6,
      "y": 9,
      "z": -4,
      "name": "Rock_Ledge_Brick_Smooth"
    },
    {
      "x": -6,
      "y": 10,
      "z": -4,
      "name": "Rock_Ledge_Brick_Smooth"
    },
    {
      "x": -6,
      "y": 11,
      "z": -4,
      "name": "Rock_Ledge_Brick_Smooth"
    },
    {
      "x": -6,
      "y": 12,
      "z": -4,
      "name": "Rock_Ledge_Brick_Smooth"
    },
    {
      "x": -6,
      "y": 13,
      "z": -4,
      "name": "Rock_Ledge_Brick_Smooth"
    },
    {
      "x": -6,
      "y": 14,
      "z": -4,
      "name": "Rock_Ledge_Brick_Smooth"
    },
    {
      "x": -6,
      "y": 15,
      "z": -4,
      "name": "Rock_Ledge_Brick_Smooth"
    },
    {
      "x": -6,
      "y": 16,
      "z": -4,
      "name": "Rock_Ledge_Brick_Smooth"
    },
    {
      "x": -6,
      "y": 17,
      "z": -4,
      "name": "Rock_Ledge_Brick_Smooth"
    },
    {
      "x": -6,
      "y": 18,
      "z": -4,
      "name": "Empty"
    },
    {
      "x": -6,
      "y": 19,
      "z": -4,
      "name": "Empty"
    },
    {
      "x": -6,
      "y": 20,
      "z": -4,
      "name": "Empty"
    },
    {
      "x": -6,
      "y": 21,
      "z": -4,
      "name": "Empty"
    },
    {
      "x": -6,
      "y": 22,
      "z": -4,
      "name": "Rock_Ledge_Brick_Smooth"
    },
    {
      "x": -6,
      "y": 0,
      "z": -3,
      "name": "Rock_Ledge_Brick_Smooth"
    },
    {
      "x": -6,
      "y": 1,
      "z": -3,
      "name": "YellowLED",
      "support": 15
    },
    {
      "x": -6,
      "y": 2,
      "z": -3,
      "name": "YellowLED",
      "support": 15
    },
    {
      "x": -6,
      "y": 3,
      "z": -3,
      "name": "YellowLED",
      "support": 15
    },
    {
      "x": -6,
      "y": 4,
      "z": -3,
      "name": "YellowLED",
      "support": 15
    },
    {
      "x": -6,
      "y": 5,
      "z": -3,
      "name": "YellowLED",
      "support": 15
    },
    {
      "x": -6,
      "y": 6,
      "z": -3,
      "name": "YellowLED",
      "support": 15
    },
    {
      "x": -6,
      "y": 7,
      "z": -3,
      "name": "YellowLED",
      "support": 15
    },
    {
      "x": -6,
      "y": 8,
      "z": -3,
      "name": "YellowLED",
      "support": 15
    },
    {
      "x": -6,
      "y": 9,
      "z": -3,
      "name": "YellowLED",
      "support": 15
    },
    {
      "x": -6,
      "y": 10,
      "z": -3,
      "name": "YellowLED",
      "support": 15
    },
    {
      "x": -6,
      "y": 11,
      "z": -3,
      "name": "YellowLED",
      "support": 15
    },
    {
      "x": -6,
      "y": 12,
      "z": -3,
      "name": "YellowLED",
      "support": 15
    },
    {
      "x": -6,
      "y": 13,
      "z": -3,
      "name": "YellowLED",
      "support": 15
    },
    {
      "x": -6,
      "y": 14,
      "z": -3,
      "name": "YellowLED",
      "support": 15
    },
    {
      "x": -6,
      "y": 15,
      "z": -3,
      "name": "YellowLED",
      "support": 15
    },
    {
      "x": -6,
      "y": 16,
      "z": -3,
      "name": "YellowLED",
      "support": 15
    },
    {
      "x": -6,
      "y": 17,
      "z": -3,
      "name": "YellowLED",
      "support": 15
    },
    {
      "x": -6,
      "y": 18,
      "z": -3,
      "name": "Rock_Ledge_Brick_Smooth"
    },
    {
      "x": -6,
      "y": 19,
      "z": -3,
      "name": "Rock_Ledge_Brick_Smooth"
    },
    {
      "x": -6,
      "y": 20,
      "z": -3,
      "name": "Rock_Ledge_Brick_Smooth"
    },
    {
      "x": -6,
      "y": 21,
      "z": -3,
      "name": "Rock_Ledge_Brick_Smooth"
    },
    {
      "x": -6,
      "y": 22,
      "z": -3,
      "name": "Rock_Ledge_Brick_Smooth"
    },
    {
      "x": -6,
      "y": 0,
      "z": -2,
      "name": "Rock_Ledge_Brick_Smooth"
    },
    {
      "x": -6,
      "y": 1,
      "z": -2,
      "name": "YellowLED",
      "support": 15
    },
    {
      "x": -6,
      "y": 2,
      "z": -2,
      "name": "YellowLED",
      "support": 15
    },
    {
      "x": -6,
      "y": 3,
      "z": -2,
      "name": "YellowLED",
      "support": 15
    },
    {
      "x": -6,
      "y": 4,
      "z": -2,
      "name": "YellowLED",
      "support": 15
    },
    {
      "x": -6,
      "y": 5,
      "z": -2,
      "name": "YellowLED",
      "support": 15
    },
    {
      "x": -6,
      "y": 6,
      "z": -2,
      "name": "YellowLED",
      "support": 15
    },
    {
      "x": -6,
      "y": 7,
      "z": -2,
      "name": "YellowLED",
      "support": 15
    },
    {
      "x": -6,
      "y": 8,
      "z": -2,
      "name": "YellowLED",
      "support": 15
    },
    {
      "x": -6,
      "y": 9,
      "z": -2,
      "name": "YellowLED",
      "support": 15
    },
    {
      "x": -6,
      "y": 10,
      "z": -2,
      "name": "YellowLED",
      "support": 15
    },
    {
      "x": -6,
      "y": 11,
      "z": -2,
      "name": "YellowLED",
      "support": 15
    },
    {
      "x": -6,
      "y": 12,
      "z": -2,
      "name": "YellowLED",
      "support": 15
    },
    {
      "x": -6,
      "y": 13,
      "z": -2,
      "name": "YellowLED",
      "support": 15
    },
    {
      "x": -6,
      "y": 14,
      "z": -2,
      "name": "YellowLED",
      "support": 15
    },
    {
      "x": -6,
      "y": 15,
      "z": -2,
      "name": "YellowLED",
      "support": 15
    },
    {
      "x": -6,
      "y": 16,
      "z": -2,
      "name": "YellowLED",
      "support": 15
    },
    {
      "x": -6,
      "y": 17,
      "z": -2,
      "name": "YellowLED",
      "support": 15
    },
    {
      "x": -6,
      "y": 18,
      "z": -2,
      "name": "Rock_Ledge_Brick_Smooth"
    },
    {
      "x": -6,
      "y": 19,
      "z": -2,
      "name": "Rock_Ledge_Brick_Smooth"
    },
    {
      "x": -6,
      "y": 20,
      "z": -2,
      "name": "Rock_Ledge_Brick_Smooth"
    },
    {
      "x": -6,
      "y": 21,
      "z": -2,
      "name": "Rock_Ledge_Brick_Smooth"
    },
    {
      "x": -6,
      "y": 22,
      "z": -2,
      "name": "Rock_Ledge_Brick_Smooth"
    },
    {
      "x": -6,
      "y": 0,
      "z": -1,
      "name": "Rock_Ledge_Brick_Smooth"
    },
    {
      "x": -6,
      "y": 1,
      "z": -1,
      "name": "Empty"
    },
    {
      "x": -6,
      "y": 2,
      "z": -1,
      "name": "Empty"
    },
    {
      "x": -6,
      "y": 3,
      "z": -1,
      "name": "Empty"
    },
    {
      "x": -6,
      "y": 4,
      "z": -1,
      "name": "YellowLED",
      "support": 15
    },
    {
      "x": -6,
      "y": 5,
      "z": -1,
      "name": "YellowLED",
      "support": 15
    },
    {
      "x": -6,
      "y": 6,
      "z": -1,
      "name": "YellowLED",
      "support": 15
    },
    {
      "x": -6,
      "y": 7,
      "z": -1,
      "name": "YellowLED",
      "support": 15
    },
    {
      "x": -6,
      "y": 8,
      "z": -1,
      "name": "YellowLED",
      "support": 15
    },
    {
      "x": -6,
      "y": 9,
      "z": -1,
      "name": "YellowLED",
      "support": 15
    },
    {
      "x": -6,
      "y": 10,
      "z": -1,
      "name": "YellowLED",
      "support": 15
    },
    {
      "x": -6,
      "y": 11,
      "z": -1,
      "name": "YellowLED",
      "support": 15
    },
    {
      "x": -6,
      "y": 12,
      "z": -1,
      "name": "YellowLED",
      "support": 15
    },
    {
      "x": -6,
      "y": 13,
      "z": -1,
      "name": "YellowLED",
      "support": 15
    },
    {
      "x": -6,
      "y": 14,
      "z": -1,
      "name": "YellowLED",
      "support": 15
    },
    {
      "x": -6,
      "y": 15,
      "z": -1,
      "name": "YellowLED",
      "support": 15
    },
    {
      "x": -6,
      "y": 16,
      "z": -1,
      "name": "YellowLED",
      "support": 15
    },
    {
      "x": -6,
      "y": 17,
      "z": -1,
      "name": "YellowLED",
      "support": 15
    },
    {
      "x": -6,
      "y": 18,
      "z": -1,
      "name": "Rock_Ledge_Brick_Smooth"
    },
    {
      "x": -6,
      "y": 19,
      "z": -1,
      "name": "Empty"
    },
    {
      "x": -6,
      "y": 20,
      "z": -1,
      "name": "Empty"
    },
    {
      "x": -6,
      "y": 21,
      "z": -1,
      "name": "Empty"
    },
    {
      "x": -6,
      "y": 22,
      "z": -1,
      "name": "Rock_Ledge_Brick_Smooth"
    },
    {
      "x": -6,
      "y": 0,
      "z": 0,
      "name": "Rock_Ledge_Brick_Smooth"
    },
    {
      "x": -6,
      "y": 1,
      "z": 0,
      "name": "Empty"
    },
    {
      "x": -6,
      "y": 2,
      "z": 0,
      "name": "Empty"
    },
    {
      "x": -6,
      "y": 3,
      "z": 0,
      "name": "Empty"
    },
    {
      "x": -6,
      "y": 4,
      "z": 0,
      "name": "YellowLED",
      "support": 15
    },
    {
      "x": -6,
      "y": 5,
      "z": 0,
      "name": "YellowLED",
      "support": 15
    },
    {
      "x": -6,
      "y": 6,
      "z": 0,
      "name": "YellowLED",
      "support": 15
    },
    {
      "x": -6,
      "y": 7,
      "z": 0,
      "name": "YellowLED",
      "support": 15
    },
    {
      "x": -6,
      "y": 8,
      "z": 0,
      "name": "YellowLED",
      "support": 15
    },
    {
      "x": -6,
      "y": 9,
      "z": 0,
      "name": "YellowLED",
      "support": 15
    },
    {
      "x": -6,
      "y": 10,
      "z": 0,
      "name": "YellowLED",
      "support": 15
    },
    {
      "x": -6,
      "y": 11,
      "z": 0,
      "name": "YellowLED",
      "support": 15
    },
    {
      "x": -6,
      "y": 12,
      "z": 0,
      "name": "YellowLED",
      "support": 15
    },
    {
      "x": -6,
      "y": 13,
      "z": 0,
      "name": "YellowLED",
      "support": 15
    },
    {
      "x": -6,
      "y": 14,
      "z": 0,
      "name": "YellowLED",
      "support": 15
    },
    {
      "x": -6,
      "y": 15,
      "z": 0,
      "name": "YellowLED",
      "support": 15
    },
    {
      "x": -6,
      "y": 16,
      "z": 0,
      "name": "YellowLED",
      "support": 15
    },
    {
      "x": -6,
      "y": 17,
      "z": 0,
      "name": "YellowLED",
      "support": 15
    },
    {
      "x": -6,
      "y": 18,
      "z": 0,
      "name": "Rock_Ledge_Brick_Smooth"
    },
    {
      "x": -6,
      "y": 19,
      "z": 0,
      "name": "Empty"
    },
    {
      "x": -6,
      "y": 20,
      "z": 0,
      "name": "Empty"
    },
    {
      "x": -6,
      "y": 21,
      "z": 0,
      "name": "Empty"
    },
    {
      "x": -6,
      "y": 22,
      "z": 0,
      "name": "Rock_Ledge_Brick_Smooth"
    },
    {
      "x": -6,
      "y": 0,
      "z": 1,
      "name": "Rock_Ledge_Brick_Smooth"
    },
    {
      "x": -6,
      "y": 1,
      "z": 1,
      "name": "Empty"
    },
    {
      "x": -6,
      "y": 2,
      "z": 1,
      "name": "Empty"
    },
    {
      "x": -6,
      "y": 3,
      "z": 1,
      "name": "Empty"
    },
    {
      "x": -6,
      "y": 4,
      "z": 1,
      "name": "YellowLED",
      "support": 15
    },
    {
      "x": -6,
      "y": 5,
      "z": 1,
      "name": "YellowLED",
      "support": 15
    },
    {
      "x": -6,
      "y": 6,
      "z": 1,
      "name": "YellowLED",
      "support": 15
    },
    {
      "x": -6,
      "y": 7,
      "z": 1,
      "name": "YellowLED",
      "support": 15
    },
    {
      "x": -6,
      "y": 8,
      "z": 1,
      "name": "YellowLED",
      "support": 15
    },
    {
      "x": -6,
      "y": 9,
      "z": 1,
      "name": "YellowLED",
      "support": 15
    },
    {
      "x": -6,
      "y": 10,
      "z": 1,
      "name": "YellowLED",
      "support": 15
    },
    {
      "x": -6,
      "y": 11,
      "z": 1,
      "name": "YellowLED",
      "support": 15
    },
    {
      "x": -6,
      "y": 12,
      "z": 1,
      "name": "YellowLED",
      "support": 15
    },
    {
      "x": -6,
      "y": 13,
      "z": 1,
      "name": "YellowLED",
      "support": 15
    },
    {
      "x": -6,
      "y": 14,
      "z": 1,
      "name": "YellowLED",
      "support": 15
    },
    {
      "x": -6,
      "y": 15,
      "z": 1,
      "name": "YellowLED",
      "support": 15
    },
    {
      "x": -6,
      "y": 16,
      "z": 1,
      "name": "YellowLED",
      "support": 15
    },
    {
      "x": -6,
      "y": 17,
      "z": 1,
      "name": "YellowLED",
      "support": 15
    },
    {
      "x": -6,
      "y": 18,
      "z": 1,
      "name": "Rock_Ledge_Brick_Smooth"
    },
    {
      "x": -6,
      "y": 19,
      "z": 1,
      "name": "Empty"
    },
    {
      "x": -6,
      "y": 20,
      "z": 1,
      "name": "Empty"
    },
    {
      "x": -6,
      "y": 21,
      "z": 1,
      "name": "Empty"
    },
    {
      "x": -6,
      "y": 22,
      "z": 1,
      "name": "Rock_Ledge_Brick_Smooth"
    },
    {
      "x": -6,
      "y": 0,
      "z": 2,
      "name": "Rock_Ledge_Brick_Smooth"
    },
    {
      "x": -6,
      "y": 1,
      "z": 2,
      "name": "YellowLED",
      "support": 15
    },
    {
      "x": -6,
      "y": 2,
      "z": 2,
      "name": "YellowLED",
      "support": 15
    },
    {
      "x": -6,
      "y": 3,
      "z": 2,
      "name": "YellowLED",
      "support": 15
    },
    {
      "x": -6,
      "y": 4,
      "z": 2,
      "name": "YellowLED",
      "support": 15
    },
    {
      "x": -6,
      "y": 5,
      "z": 2,
      "name": "YellowLED",
      "support": 15
    },
    {
      "x": -6,
      "y": 6,
      "z": 2,
      "name": "YellowLED",
      "support": 15
    },
    {
      "x": -6,
      "y": 7,
      "z": 2,
      "name": "YellowLED",
      "support": 15
    },
    {
      "x": -6,
      "y": 8,
      "z": 2,
      "name": "YellowLED",
      "support": 15
    },
    {
      "x": -6,
      "y": 9,
      "z": 2,
      "name": "YellowLED",
      "support": 15
    },
    {
      "x": -6,
      "y": 10,
      "z": 2,
      "name": "YellowLED",
      "support": 15
    },
    {
      "x": -6,
      "y": 11,
      "z": 2,
      "name": "YellowLED",
      "support": 15
    },
    {
      "x": -6,
      "y": 12,
      "z": 2,
      "name": "YellowLED",
      "support": 15
    },
    {
      "x": -6,
      "y": 13,
      "z": 2,
      "name": "YellowLED",
      "support": 15
    },
    {
      "x": -6,
      "y": 14,
      "z": 2,
      "name": "YellowLED",
      "support": 15
    },
    {
      "x": -6,
      "y": 15,
      "z": 2,
      "name": "YellowLED",
      "support": 15
    },
    {
      "x": -6,
      "y": 16,
      "z": 2,
      "name": "YellowLED",
      "support": 15
    },
    {
      "x": -6,
      "y": 17,
      "z": 2,
      "name": "YellowLED",
      "support": 15
    },
    {
      "x": -6,
      "y": 18,
      "z": 2,
      "name": "Rock_Ledge_Brick_Smooth"
    },
    {
      "x": -6,
      "y": 19,
      "z": 2,
      "name": "Rock_Ledge_Brick_Smooth"
    },
    {
      "x": -6,
      "y": 20,
      "z": 2,
      "name": "Rock_Ledge_Brick_Smooth"
    },
    {
      "x": -6,
      "y": 21,
      "z": 2,
      "name": "Rock_Ledge_Brick_Smooth"
    },
    {
      "x": -6,
      "y": 22,
      "z": 2,
      "name": "Rock_Ledge_Brick_Smooth"
    },
    {
      "x": -6,
      "y": 0,
      "z": 3,
      "name": "Rock_Ledge_Brick_Smooth"
    },
    {
      "x": -6,
      "y": 1,
      "z": 3,
      "name": "YellowLED",
      "support": 15
    },
    {
      "x": -6,
      "y": 2,
      "z": 3,
      "name": "YellowLED",
      "support": 15
    },
    {
      "x": -6,
      "y": 3,
      "z": 3,
      "name": "YellowLED",
      "support": 15
    },
    {
      "x": -6,
      "y": 4,
      "z": 3,
      "name": "YellowLED",
      "support": 15
    },
    {
      "x": -6,
      "y": 5,
      "z": 3,
      "name": "YellowLED",
      "support": 15
    },
    {
      "x": -6,
      "y": 6,
      "z": 3,
      "name": "YellowLED",
      "support": 15
    },
    {
      "x": -6,
      "y": 7,
      "z": 3,
      "name": "YellowLED",
      "support": 15
    },
    {
      "x": -6,
      "y": 8,
      "z": 3,
      "name": "YellowLED",
      "support": 15
    },
    {
      "x": -6,
      "y": 9,
      "z": 3,
      "name": "YellowLED",
      "support": 15
    },
    {
      "x": -6,
      "y": 10,
      "z": 3,
      "name": "YellowLED",
      "support": 15
    },
    {
      "x": -6,
      "y": 11,
      "z": 3,
      "name": "YellowLED",
      "support": 15
    },
    {
      "x": -6,
      "y": 12,
      "z": 3,
      "name": "YellowLED",
      "support": 15
    },
    {
      "x": -6,
      "y": 13,
      "z": 3,
      "name": "YellowLED",
      "support": 15
    },
    {
      "x": -6,
      "y": 14,
      "z": 3,
      "name": "YellowLED",
      "support": 15
    },
    {
      "x": -6,
      "y": 15,
      "z": 3,
      "name": "YellowLED",
      "support": 15
    },
    {
      "x": -6,
      "y": 16,
      "z": 3,
      "name": "YellowLED",
      "support": 15
    },
    {
      "x": -6,
      "y": 17,
      "z": 3,
      "name": "YellowLED",
      "support": 15
    },
    {
      "x": -6,
      "y": 18,
      "z": 3,
      "name": "Rock_Ledge_Brick_Smooth"
    },
    {
      "x": -6,
      "y": 19,
      "z": 3,
      "name": "Rock_Ledge_Brick_Smooth"
    },
    {
      "x": -6,
      "y": 20,
      "z": 3,
      "name": "Rock_Ledge_Brick_Smooth"
    },
    {
      "x": -6,
      "y": 21,
      "z": 3,
      "name": "Rock_Ledge_Brick_Smooth"
    },
    {
      "x": -6,
      "y": 22,
      "z": 3,
      "name": "Rock_Ledge_Brick_Smooth"
    },
    {
      "x": -6,
      "y": 0,
      "z": 4,
      "name": "Rock_Ledge_Brick_Smooth"
    },
    {
      "x": -6,
      "y": 1,
      "z": 4,
      "name": "Rock_Ledge_Brick_Smooth"
    },
    {
      "x": -6,
      "y": 2,
      "z": 4,
      "name": "Rock_Ledge_Brick_Smooth"
    },
    {
      "x": -6,
      "y": 3,
      "z": 4,
      "name": "Rock_Ledge_Brick_Smooth"
    },
    {
      "x": -6,
      "y": 4,
      "z": 4,
      "name": "Rock_Ledge_Brick_Smooth"
    },
    {
      "x": -6,
      "y": 5,
      "z": 4,
      "name": "Rock_Ledge_Brick_Smooth"
    },
    {
      "x": -6,
      "y": 6,
      "z": 4,
      "name": "Rock_Ledge_Brick_Smooth"
    },
    {
      "x": -6,
      "y": 7,
      "z": 4,
      "name": "Rock_Ledge_Brick_Smooth"
    },
    {
      "x": -6,
      "y": 8,
      "z": 4,
      "name": "Rock_Ledge_Brick_Smooth"
    },
    {
      "x": -6,
      "y": 9,
      "z": 4,
      "name": "Rock_Ledge_Brick_Smooth"
    },
    {
      "x": -6,
      "y": 10,
      "z": 4,
      "name": "Rock_Ledge_Brick_Smooth"
    },
    {
      "x": -6,
      "y": 11,
      "z": 4,
      "name": "Rock_Ledge_Brick_Smooth"
    },
    {
      "x": -6,
      "y": 12,
      "z": 4,
      "name": "Rock_Ledge_Brick_Smooth"
    },
    {
      "x": -6,
      "y": 13,
      "z": 4,
      "name": "Rock_Ledge_Brick_Smooth"
    },
    {
      "x": -6,
      "y": 14,
      "z": 4,
      "name": "Rock_Ledge_Brick_Smooth"
    },
    {
      "x": -6,
      "y": 15,
      "z": 4,
      "name": "Rock_Ledge_Brick_Smooth"
    },
    {
      "x": -6,
      "y": 16,
      "z": 4,
      "name": "Rock_Ledge_Brick_Smooth"
    },
    {
      "x": -6,
      "y": 17,
      "z": 4,
      "name": "Rock_Ledge_Brick_Smooth"
    },
    {
      "x": -6,
      "y": 18,
      "z": 4,
      "name": "Empty"
    },
    {
      "x": -6,
      "y": 19,
      "z": 4,
      "name": "Empty"
    },
    {
      "x": -6,
      "y": 20,
      "z": 4,
      "name": "Empty"
    },
    {
      "x": -6,
      "y": 21,
      "z": 4,
      "name": "Empty"
    },
    {
      "x": -6,
      "y": 22,
      "z": 4,
      "name": "Rock_Ledge_Brick_Smooth"
    },
    {
      "x": -6,
      "y": 0,
      "z": 5,
      "name": "Rock_Ledge_Brick_Smooth"
    },
    {
      "x": -6,
      "y": 1,
      "z": 5,
      "name": "Empty"
    },
    {
      "x": -6,
      "y": 2,
      "z": 5,
      "name": "Empty"
    },
    {
      "x": -6,
      "y": 3,
      "z": 5,
      "name": "Empty"
    },
    {
      "x": -6,
      "y": 4,
      "z": 5,
      "name": "Empty"
    },
    {
      "x": -6,
      "y": 5,
      "z": 5,
      "name": "Empty"
    },
    {
      "x": -6,
      "y": 6,
      "z": 5,
      "name": "Empty"
    },
    {
      "x": -6,
      "y": 7,
      "z": 5,
      "name": "Empty"
    },
    {
      "x": -6,
      "y": 8,
      "z": 5,
      "name": "Empty"
    },
    {
      "x": -6,
      "y": 9,
      "z": 5,
      "name": "Empty"
    },
    {
      "x": -6,
      "y": 10,
      "z": 5,
      "name": "Empty"
    },
    {
      "x": -6,
      "y": 11,
      "z": 5,
      "name": "Empty"
    },
    {
      "x": -6,
      "y": 12,
      "z": 5,
      "name": "Empty"
    },
    {
      "x": -6,
      "y": 13,
      "z": 5,
      "name": "Empty"
    },
    {
      "x": -6,
      "y": 14,
      "z": 5,
      "name": "Empty"
    },
    {
      "x": -6,
      "y": 15,
      "z": 5,
      "name": "Empty"
    },
    {
      "x": -6,
      "y": 16,
      "z": 5,
      "name": "Empty"
    },
    {
      "x": -6,
      "y": 17,
      "z": 5,
      "name": "Empty"
    },
    {
      "x": -6,
      "y": 18,
      "z": 5,
      "name": "Empty"
    },
    {
      "x": -6,
      "y": 19,
      "z": 5,
      "name": "Empty"
    },
    {
      "x": -6,
      "y": 20,
      "z": 5,
      "name": "Empty"
    },
    {
      "x": -6,
      "y": 21,
      "z": 5,
      "name": "Empty"
    },
    {
      "x": -6,
      "y": 0,
      "z": 6,
      "name": "Rock_Ledge_Brick_Smooth"
    },
    {
      "x": -6,
      "y": 1,
      "z": 6,
      "name": "Empty"
    },
    {
      "x": -6,
      "y": 2,
      "z": 6,
      "name": "Empty"
    },
    {
      "x": -6,
      "y": 3,
      "z": 6,
      "name": "Empty"
    },
    {
      "x": -6,
      "y": 4,
      "z": 6,
      "name": "Empty"
    },
    {
      "x": -6,
      "y": 5,
      "z": 6,
      "name": "Empty"
    },
    {
      "x": -6,
      "y": 6,
      "z": 6,
      "name": "Empty"
    },
    {
      "x": -6,
      "y": 7,
      "z": 6,
      "name": "Empty"
    },
    {
      "x": -6,
      "y": 8,
      "z": 6,
      "name": "Empty"
    },
    {
      "x": -6,
      "y": 9,
      "z": 6,
      "name": "Empty"
    },
    {
      "x": -6,
      "y": 10,
      "z": 6,
      "name": "Empty"
    },
    {
      "x": -6,
      "y": 11,
      "z": 6,
      "name": "Empty"
    },
    {
      "x": -6,
      "y": 12,
      "z": 6,
      "name": "Empty"
    },
    {
      "x": -6,
      "y": 13,
      "z": 6,
      "name": "Empty"
    },
    {
      "x": -6,
      "y": 14,
      "z": 6,
      "name": "Empty"
    },
    {
      "x": -6,
      "y": 15,
      "z": 6,
      "name": "Empty"
    },
    {
      "x": -6,
      "y": 16,
      "z": 6,
      "name": "Empty"
    },
    {
      "x": -6,
      "y": 17,
      "z": 6,
      "name": "Empty"
    },
    {
      "x": -6,
      "y": 18,
      "z": 6,
      "name": "Empty"
    },
    {
      "x": -6,
      "y": 19,
      "z": 6,
      "name": "Empty"
    },
    {
      "x": -6,
      "y": 20,
      "z": 6,
      "name": "Empty"
    },
    {
      "x": -6,
      "y": 21,
      "z": 6,
      "name": "Empty"
    },
    {
      "x": -5,
      "y": 0,
      "z": -6,
      "name": "Rock_Ledge_Brick_Smooth"
    },
    {
      "x": -5,
      "y": 0,
      "z": -5,
      "name": "Rock_Ledge_Brick_Smooth"
    },
    {
      "x": -5,
      "y": 1,
      "z": -5,
      "name": "Empty"
    },
    {
      "x": -5,
      "y": 2,
      "z": -5,
      "name": "Empty"
    },
    {
      "x": -5,
      "y": 3,
      "z": -5,
      "name": "Empty"
    },
    {
      "x": -5,
      "y": 4,
      "z": -5,
      "name": "Empty"
    },
    {
      "x": -5,
      "y": 5,
      "z": -5,
      "name": "Empty"
    },
    {
      "x": -5,
      "y": 6,
      "z": -5,
      "name": "Empty"
    },
    {
      "x": -5,
      "y": 7,
      "z": -5,
      "name": "Empty"
    },
    {
      "x": -5,
      "y": 8,
      "z": -5,
      "name": "Empty"
    },
    {
      "x": -5,
      "y": 9,
      "z": -5,
      "name": "Empty"
    },
    {
      "x": -5,
      "y": 10,
      "z": -5,
      "name": "Empty"
    },
    {
      "x": -5,
      "y": 11,
      "z": -5,
      "name": "Empty"
    },
    {
      "x": -5,
      "y": 12,
      "z": -5,
      "name": "Empty"
    },
    {
      "x": -5,
      "y": 13,
      "z": -5,
      "name": "Empty"
    },
    {
      "x": -5,
      "y": 14,
      "z": -5,
      "name": "Empty"
    },
    {
      "x": -5,
      "y": 15,
      "z": -5,
      "name": "Empty"
    },
    {
      "x": -5,
      "y": 16,
      "z": -5,
      "name": "Empty"
    },
    {
      "x": -5,
      "y": 17,
      "z": -5,
      "name": "Empty"
    },
    {
      "x": -5,
      "y": 18,
      "z": -5,
      "name": "Empty"
    },
    {
      "x": -5,
      "y": 19,
      "z": -5,
      "name": "Empty"
    },
    {
      "x": -5,
      "y": 20,
      "z": -5,
      "name": "Empty"
    },
    {
      "x": -5,
      "y": 21,
      "z": -5,
      "name": "Empty"
    },
    {
      "x": -5,
      "y": 0,
      "z": -4,
      "name": "Rock_Ledge_Brick_Smooth"
    },
    {
      "x": -5,
      "y": 1,
      "z": -4,
      "name": "Rock_Ledge_Brick_Smooth"
    },
    {
      "x": -5,
      "y": 2,
      "z": -4,
      "name": "Rock_Ledge_Brick_Smooth"
    },
    {
      "x": -5,
      "y": 3,
      "z": -4,
      "name": "Rock_Ledge_Brick_Smooth"
    },
    {
      "x": -5,
      "y": 4,
      "z": -4,
      "name": "Rock_Ledge_Brick_Smooth"
    },
    {
      "x": -5,
      "y": 5,
      "z": -4,
      "name": "Rock_Ledge_Brick_Smooth"
    },
    {
      "x": -5,
      "y": 6,
      "z": -4,
      "name": "Rock_Ledge_Brick_Smooth"
    },
    {
      "x": -5,
      "y": 7,
      "z": -4,
      "name": "Rock_Ledge_Brick_Smooth"
    },
    {
      "x": -5,
      "y": 8,
      "z": -4,
      "name": "Rock_Ledge_Brick_Smooth"
    },
    {
      "x": -5,
      "y": 9,
      "z": -4,
      "name": "Rock_Ledge_Brick_Smooth"
    },
    {
      "x": -5,
      "y": 10,
      "z": -4,
      "name": "Rock_Ledge_Brick_Smooth"
    },
    {
      "x": -5,
      "y": 11,
      "z": -4,
      "name": "Rock_Ledge_Brick_Smooth"
    },
    {
      "x": -5,
      "y": 12,
      "z": -4,
      "name": "Rock_Ledge_Brick_Smooth"
    },
    {
      "x": -5,
      "y": 13,
      "z": -4,
      "name": "Rock_Ledge_Brick_Smooth"
    },
    {
      "x": -5,
      "y": 14,
      "z": -4,
      "name": "Rock_Ledge_Brick_Smooth"
    },
    {
      "x": -5,
      "y": 15,
      "z": -4,
      "name": "Rock_Ledge_Brick_Smooth"
    },
    {
      "x": -5,
      "y": 16,
      "z": -4,
      "name": "Rock_Ledge_Brick_Smooth"
    },
    {
      "x": -5,
      "y": 17,
      "z": -4,
      "name": "Rock_Ledge_Brick_Smooth"
    },
    {
      "x": -5,
      "y": 18,
      "z": -4,
      "name": "Empty"
    },
    {
      "x": -5,
      "y": 19,
      "z": -4,
      "name": "Empty"
    },
    {
      "x": -5,
      "y": 20,
      "z": -4,
      "name": "Empty"
    },
    {
      "x": -5,
      "y": 21,
      "z": -4,
      "name": "Empty"
    },
    {
      "x": -5,
      "y": 22,
      "z": -4,
      "name": "Rock_Ledge_Brick_Smooth"
    },
    {
      "x": -5,
      "y": 0,
      "z": -3,
      "name": "Rock_Ledge_Brick_Smooth"
    },
    {
      "x": -5,
      "y": 1,
      "z": -3,
      "name": "YellowLED",
      "support": 15
    },
    {
      "x": -5,
      "y": 2,
      "z": -3,
      "name": "YellowLED",
      "support": 15
    },
    {
      "x": -5,
      "y": 3,
      "z": -3,
      "name": "YellowLED",
      "support": 15
    },
    {
      "x": -5,
      "y": 4,
      "z": -3,
      "name": "YellowLED",
      "support": 15
    },
    {
      "x": -5,
      "y": 5,
      "z": -3,
      "name": "YellowLED",
      "support": 15
    },
    {
      "x": -5,
      "y": 6,
      "z": -3,
      "name": "YellowLED",
      "support": 15
    },
    {
      "x": -5,
      "y": 7,
      "z": -3,
      "name": "YellowLED",
      "support": 15
    },
    {
      "x": -5,
      "y": 8,
      "z": -3,
      "name": "YellowLED",
      "support": 15
    },
    {
      "x": -5,
      "y": 9,
      "z": -3,
      "name": "YellowLED",
      "support": 15
    },
    {
      "x": -5,
      "y": 10,
      "z": -3,
      "name": "YellowLED",
      "support": 15
    },
    {
      "x": -5,
      "y": 11,
      "z": -3,
      "name": "YellowLED",
      "support": 15
    },
    {
      "x": -5,
      "y": 12,
      "z": -3,
      "name": "YellowLED",
      "support": 15
    },
    {
      "x": -5,
      "y": 13,
      "z": -3,
      "name": "YellowLED",
      "support": 15
    },
    {
      "x": -5,
      "y": 14,
      "z": -3,
      "name": "YellowLED",
      "support": 15
    },
    {
      "x": -5,
      "y": 15,
      "z": -3,
      "name": "YellowLED",
      "support": 15
    },
    {
      "x": -5,
      "y": 16,
      "z": -3,
      "name": "YellowLED",
      "support": 15
    },
    {
      "x": -5,
      "y": 17,
      "z": -3,
      "name": "YellowLED",
      "support": 15
    },
    {
      "x": -5,
      "y": 18,
      "z": -3,
      "name": "Rock_Ledge_Brick_Smooth"
    },
    {
      "x": -5,
      "y": 19,
      "z": -3,
      "name": "Empty"
    },
    {
      "x": -5,
      "y": 20,
      "z": -3,
      "name": "Empty"
    },
    {
      "x": -5,
      "y": 21,
      "z": -3,
      "name": "Empty"
    },
    {
      "x": -5,
      "y": 22,
      "z": -3,
      "name": "Rock_Ledge_Brick_Smooth"
    },
    {
      "x": -5,
      "y": 0,
      "z": -2,
      "name": "Rock_Ledge_Brick_Smooth"
    },
    {
      "x": -5,
      "y": 1,
      "z": -2,
      "name": "Empty"
    },
    {
      "x": -5,
      "y": 2,
      "z": -2,
      "name": "Empty"
    },
    {
      "x": -5,
      "y": 3,
      "z": -2,
      "name": "Empty"
    },
    {
      "x": -5,
      "y": 4,
      "z": -2,
      "name": "Empty"
    },
    {
      "x": -5,
      "y": 5,
      "z": -2,
      "name": "Empty"
    },
    {
      "x": -5,
      "y": 6,
      "z": -2,
      "name": "Empty"
    },
    {
      "x": -5,
      "y": 7,
      "z": -2,
      "name": "Empty"
    },
    {
      "x": -5,
      "y": 8,
      "z": -2,
      "name": "Empty"
    },
    {
      "x": -5,
      "y": 9,
      "z": -2,
      "name": "Empty"
    },
    {
      "x": -5,
      "y": 10,
      "z": -2,
      "name": "Empty"
    },
    {
      "x": -5,
      "y": 11,
      "z": -2,
      "name": "Empty"
    },
    {
      "x": -5,
      "y": 12,
      "z": -2,
      "name": "Empty"
    },
    {
      "x": -5,
      "y": 13,
      "z": -2,
      "name": "Empty"
    },
    {
      "x": -5,
      "y": 14,
      "z": -2,
      "name": "Empty"
    },
    {
      "x": -5,
      "y": 15,
      "z": -2,
      "name": "Empty"
    },
    {
      "x": -5,
      "y": 16,
      "z": -2,
      "name": "Empty"
    },
    {
      "x": -5,
      "y": 17,
      "z": -2,
      "name": "YellowLED",
      "support": 15
    },
    {
      "x": -5,
      "y": 18,
      "z": -2,
      "name": "Rock_Ledge_Brick_Smooth"
    },
    {
      "x": -5,
      "y": 19,
      "z": -2,
      "name": "Rock_Ledge_Brick_Smooth"
    },
    {
      "x": -5,
      "y": 20,
      "z": -2,
      "name": "Rock_Ledge_Brick_Smooth"
    },
    {
      "x": -5,
      "y": 21,
      "z": -2,
      "name": "Rock_Ledge_Brick_Smooth"
    },
    {
      "x": -5,
      "y": 22,
      "z": -2,
      "name": "Rock_Ledge_Brick_Smooth"
    },
    {
      "x": -5,
      "y": 0,
      "z": -1,
      "name": "Rock_Ledge_Brick_Smooth"
    },
    {
      "x": -5,
      "y": 1,
      "z": -1,
      "name": "Empty"
    },
    {
      "x": -5,
      "y": 2,
      "z": -1,
      "name": "Empty"
    },
    {
      "x": -5,
      "y": 3,
      "z": -1,
      "name": "Empty"
    },
    {
      "x": -5,
      "y": 4,
      "z": -1,
      "name": "Empty"
    },
    {
      "x": -5,
      "y": 5,
      "z": -1,
      "name": "Empty"
    },
    {
      "x": -5,
      "y": 6,
      "z": -1,
      "name": "Empty"
    },
    {
      "x": -5,
      "y": 7,
      "z": -1,
      "name": "Empty"
    },
    {
      "x": -5,
      "y": 8,
      "z": -1,
      "name": "Empty"
    },
    {
      "x": -5,
      "y": 9,
      "z": -1,
      "name": "Empty"
    },
    {
      "x": -5,
      "y": 10,
      "z": -1,
      "name": "Empty"
    },
    {
      "x": -5,
      "y": 11,
      "z": -1,
      "name": "Empty"
    },
    {
      "x": -5,
      "y": 12,
      "z": -1,
      "name": "Empty"
    },
    {
      "x": -5,
      "y": 13,
      "z": -1,
      "name": "Empty"
    },
    {
      "x": -5,
      "y": 14,
      "z": -1,
      "name": "Empty"
    },
    {
      "x": -5,
      "y": 15,
      "z": -1,
      "name": "Empty"
    },
    {
      "x": -5,
      "y": 16,
      "z": -1,
      "name": "Empty"
    },
    {
      "x": -5,
      "y": 17,
      "z": -1,
      "name": "YellowLED",
      "support": 15
    },
    {
      "x": -5,
      "y": 18,
      "z": -1,
      "name": "Rock_Ledge_Brick_Smooth"
    },
    {
      "x": -5,
      "y": 19,
      "z": -1,
      "name": "Empty"
    },
    {
      "x": -5,
      "y": 20,
      "z": -1,
      "name": "Empty"
    },
    {
      "x": -5,
      "y": 21,
      "z": -1,
      "name": "Empty"
    },
    {
      "x": -5,
      "y": 22,
      "z": -1,
      "name": "Rock_Ledge_Brick_Smooth"
    },
    {
      "x": -5,
      "y": 0,
      "z": 0,
      "name": "Rock_Ledge_Brick_Smooth"
    },
    {
      "x": -5,
      "y": 1,
      "z": 0,
      "name": "Empty"
    },
    {
      "x": -5,
      "y": 2,
      "z": 0,
      "name": "Empty"
    },
    {
      "x": -5,
      "y": 3,
      "z": 0,
      "name": "Empty"
    },
    {
      "x": -5,
      "y": 4,
      "z": 0,
      "name": "Empty"
    },
    {
      "x": -5,
      "y": 5,
      "z": 0,
      "name": "Empty"
    },
    {
      "x": -5,
      "y": 6,
      "z": 0,
      "name": "Empty"
    },
    {
      "x": -5,
      "y": 7,
      "z": 0,
      "name": "Empty"
    },
    {
      "x": -5,
      "y": 8,
      "z": 0,
      "name": "Empty"
    },
    {
      "x": -5,
      "y": 9,
      "z": 0,
      "name": "Empty"
    },
    {
      "x": -5,
      "y": 10,
      "z": 0,
      "name": "Empty"
    },
    {
      "x": -5,
      "y": 11,
      "z": 0,
      "name": "Empty"
    },
    {
      "x": -5,
      "y": 12,
      "z": 0,
      "name": "Empty"
    },
    {
      "x": -5,
      "y": 13,
      "z": 0,
      "name": "Empty"
    },
    {
      "x": -5,
      "y": 14,
      "z": 0,
      "name": "Empty"
    },
    {
      "x": -5,
      "y": 15,
      "z": 0,
      "name": "Empty"
    },
    {
      "x": -5,
      "y": 16,
      "z": 0,
      "name": "Empty"
    },
    {
      "x": -5,
      "y": 17,
      "z": 0,
      "name": "YellowLED",
      "support": 15
    },
    {
      "x": -5,
      "y": 18,
      "z": 0,
      "name": "Rock_Ledge_Brick_Smooth"
    },
    {
      "x": -5,
      "y": 19,
      "z": 0,
      "name": "Empty"
    },
    {
      "x": -5,
      "y": 20,
      "z": 0,
      "name": "Empty"
    },
    {
      "x": -5,
      "y": 21,
      "z": 0,
      "name": "Empty"
    },
    {
      "x": -5,
      "y": 22,
      "z": 0,
      "name": "YellowLED",
      "support": 15
    },
    {
      "x": -5,
      "y": 0,
      "z": 1,
      "name": "Rock_Ledge_Brick_Smooth"
    },
    {
      "x": -5,
      "y": 1,
      "z": 1,
      "name": "Empty"
    },
    {
      "x": -5,
      "y": 2,
      "z": 1,
      "name": "Empty"
    },
    {
      "x": -5,
      "y": 3,
      "z": 1,
      "name": "Empty"
    },
    {
      "x": -5,
      "y": 4,
      "z": 1,
      "name": "Empty"
    },
    {
      "x": -5,
      "y": 5,
      "z": 1,
      "name": "Empty"
    },
    {
      "x": -5,
      "y": 6,
      "z": 1,
      "name": "Empty"
    },
    {
      "x": -5,
      "y": 7,
      "z": 1,
      "name": "Empty"
    },
    {
      "x": -5,
      "y": 8,
      "z": 1,
      "name": "Empty"
    },
    {
      "x": -5,
      "y": 9,
      "z": 1,
      "name": "Empty"
    },
    {
      "x": -5,
      "y": 10,
      "z": 1,
      "name": "Empty"
    },
    {
      "x": -5,
      "y": 11,
      "z": 1,
      "name": "Empty"
    },
    {
      "x": -5,
      "y": 12,
      "z": 1,
      "name": "Empty"
    },
    {
      "x": -5,
      "y": 13,
      "z": 1,
      "name": "Empty"
    },
    {
      "x": -5,
      "y": 14,
      "z": 1,
      "name": "Empty"
    },
    {
      "x": -5,
      "y": 15,
      "z": 1,
      "name": "Empty"
    },
    {
      "x": -5,
      "y": 16,
      "z": 1,
      "name": "Empty"
    },
    {
      "x": -5,
      "y": 17,
      "z": 1,
      "name": "YellowLED",
      "support": 15
    },
    {
      "x": -5,
      "y": 18,
      "z": 1,
      "name": "Rock_Ledge_Brick_Smooth"
    },
    {
      "x": -5,
      "y": 19,
      "z": 1,
      "name": "Empty"
    },
    {
      "x": -5,
      "y": 20,
      "z": 1,
      "name": "Empty"
    },
    {
      "x": -5,
      "y": 21,
      "z": 1,
      "name": "Empty"
    },
    {
      "x": -5,
      "y": 22,
      "z": 1,
      "name": "Rock_Ledge_Brick_Smooth"
    },
    {
      "x": -5,
      "y": 0,
      "z": 2,
      "name": "Rock_Ledge_Brick_Smooth"
    },
    {
      "x": -5,
      "y": 1,
      "z": 2,
      "name": "Empty"
    },
    {
      "x": -5,
      "y": 2,
      "z": 2,
      "name": "Empty"
    },
    {
      "x": -5,
      "y": 3,
      "z": 2,
      "name": "Empty"
    },
    {
      "x": -5,
      "y": 4,
      "z": 2,
      "name": "Empty"
    },
    {
      "x": -5,
      "y": 5,
      "z": 2,
      "name": "Empty"
    },
    {
      "x": -5,
      "y": 6,
      "z": 2,
      "name": "Empty"
    },
    {
      "x": -5,
      "y": 7,
      "z": 2,
      "name": "Empty"
    },
    {
      "x": -5,
      "y": 8,
      "z": 2,
      "name": "Empty"
    },
    {
      "x": -5,
      "y": 9,
      "z": 2,
      "name": "Empty"
    },
    {
      "x": -5,
      "y": 10,
      "z": 2,
      "name": "Empty"
    },
    {
      "x": -5,
      "y": 11,
      "z": 2,
      "name": "Empty"
    },
    {
      "x": -5,
      "y": 12,
      "z": 2,
      "name": "Empty"
    },
    {
      "x": -5,
      "y": 13,
      "z": 2,
      "name": "Empty"
    },
    {
      "x": -5,
      "y": 14,
      "z": 2,
      "name": "Empty"
    },
    {
      "x": -5,
      "y": 15,
      "z": 2,
      "name": "Empty"
    },
    {
      "x": -5,
      "y": 16,
      "z": 2,
      "name": "Empty"
    },
    {
      "x": -5,
      "y": 17,
      "z": 2,
      "name": "YellowLED",
      "support": 15
    },
    {
      "x": -5,
      "y": 18,
      "z": 2,
      "name": "Rock_Ledge_Brick_Smooth"
    },
    {
      "x": -5,
      "y": 19,
      "z": 2,
      "name": "Rock_Ledge_Brick_Smooth"
    },
    {
      "x": -5,
      "y": 20,
      "z": 2,
      "name": "Rock_Ledge_Brick_Smooth"
    },
    {
      "x": -5,
      "y": 21,
      "z": 2,
      "name": "Rock_Ledge_Brick_Smooth"
    },
    {
      "x": -5,
      "y": 22,
      "z": 2,
      "name": "Rock_Ledge_Brick_Smooth"
    },
    {
      "x": -5,
      "y": 0,
      "z": 3,
      "name": "Rock_Ledge_Brick_Smooth"
    },
    {
      "x": -5,
      "y": 1,
      "z": 3,
      "name": "YellowLED",
      "support": 15
    },
    {
      "x": -5,
      "y": 2,
      "z": 3,
      "name": "YellowLED",
      "support": 15
    },
    {
      "x": -5,
      "y": 3,
      "z": 3,
      "name": "YellowLED",
      "support": 15
    },
    {
      "x": -5,
      "y": 4,
      "z": 3,
      "name": "YellowLED",
      "support": 15
    },
    {
      "x": -5,
      "y": 5,
      "z": 3,
      "name": "YellowLED",
      "support": 15
    },
    {
      "x": -5,
      "y": 6,
      "z": 3,
      "name": "YellowLED",
      "support": 15
    },
    {
      "x": -5,
      "y": 7,
      "z": 3,
      "name": "YellowLED",
      "support": 15
    },
    {
      "x": -5,
      "y": 8,
      "z": 3,
      "name": "YellowLED",
      "support": 15
    },
    {
      "x": -5,
      "y": 9,
      "z": 3,
      "name": "YellowLED",
      "support": 15
    },
    {
      "x": -5,
      "y": 10,
      "z": 3,
      "name": "YellowLED",
      "support": 15
    },
    {
      "x": -5,
      "y": 11,
      "z": 3,
      "name": "YellowLED",
      "support": 15
    },
    {
      "x": -5,
      "y": 12,
      "z": 3,
      "name": "YellowLED",
      "support": 15
    },
    {
      "x": -5,
      "y": 13,
      "z": 3,
      "name": "YellowLED",
      "support": 15
    },
    {
      "x": -5,
      "y": 14,
      "z": 3,
      "name": "YellowLED",
      "support": 15
    },
    {
      "x": -5,
      "y": 15,
      "z": 3,
      "name": "YellowLED",
      "support": 15
    },
    {
      "x": -5,
      "y": 16,
      "z": 3,
      "name": "YellowLED",
      "support": 15
    },
    {
      "x": -5,
      "y": 17,
      "z": 3,
      "name": "YellowLED",
      "support": 15
    },
    {
      "x": -5,
      "y": 18,
      "z": 3,
      "name": "Rock_Ledge_Brick_Smooth"
    },
    {
      "x": -5,
      "y": 19,
      "z": 3,
      "name": "Empty"
    },
    {
      "x": -5,
      "y": 20,
      "z": 3,
      "name": "Empty"
    },
    {
      "x": -5,
      "y": 21,
      "z": 3,
      "name": "Empty"
    },
    {
      "x": -5,
      "y": 22,
      "z": 3,
      "name": "Rock_Ledge_Brick_Smooth"
    },
    {
      "x": -5,
      "y": 0,
      "z": 4,
      "name": "Rock_Ledge_Brick_Smooth"
    },
    {
      "x": -5,
      "y": 1,
      "z": 4,
      "name": "Rock_Ledge_Brick_Smooth"
    },
    {
      "x": -5,
      "y": 2,
      "z": 4,
      "name": "Rock_Ledge_Brick_Smooth"
    },
    {
      "x": -5,
      "y": 3,
      "z": 4,
      "name": "Rock_Ledge_Brick_Smooth"
    },
    {
      "x": -5,
      "y": 4,
      "z": 4,
      "name": "Rock_Ledge_Brick_Smooth"
    },
    {
      "x": -5,
      "y": 5,
      "z": 4,
      "name": "Rock_Ledge_Brick_Smooth"
    },
    {
      "x": -5,
      "y": 6,
      "z": 4,
      "name": "Rock_Ledge_Brick_Smooth"
    },
    {
      "x": -5,
      "y": 7,
      "z": 4,
      "name": "Rock_Ledge_Brick_Smooth"
    },
    {
      "x": -5,
      "y": 8,
      "z": 4,
      "name": "Rock_Ledge_Brick_Smooth"
    },
    {
      "x": -5,
      "y": 9,
      "z": 4,
      "name": "Rock_Ledge_Brick_Smooth"
    },
    {
      "x": -5,
      "y": 10,
      "z": 4,
      "name": "Rock_Ledge_Brick_Smooth"
    },
    {
      "x": -5,
      "y": 11,
      "z": 4,
      "name": "Rock_Ledge_Brick_Smooth"
    },
    {
      "x": -5,
      "y": 12,
      "z": 4,
      "name": "Rock_Ledge_Brick_Smooth"
    },
    {
      "x": -5,
      "y": 13,
      "z": 4,
      "name": "Rock_Ledge_Brick_Smooth"
    },
    {
      "x": -5,
      "y": 14,
      "z": 4,
      "name": "Rock_Ledge_Brick_Smooth"
    },
    {
      "x": -5,
      "y": 15,
      "z": 4,
      "name": "Rock_Ledge_Brick_Smooth"
    },
    {
      "x": -5,
      "y": 16,
      "z": 4,
      "name": "Rock_Ledge_Brick_Smooth"
    },
    {
      "x": -5,
      "y": 17,
      "z": 4,
      "name": "Rock_Ledge_Brick_Smooth"
    },
    {
      "x": -5,
      "y": 18,
      "z": 4,
      "name": "Empty"
    },
    {
      "x": -5,
      "y": 19,
      "z": 4,
      "name": "Empty"
    },
    {
      "x": -5,
      "y": 20,
      "z": 4,
      "name": "Empty"
    },
    {
      "x": -5,
      "y": 21,
      "z": 4,
      "name": "Empty"
    },
    {
      "x": -5,
      "y": 22,
      "z": 4,
      "name": "Rock_Ledge_Brick_Smooth"
    },
    {
      "x": -5,
      "y": 0,
      "z": 5,
      "name": "Rock_Ledge_Brick_Smooth"
    },
    {
      "x": -5,
      "y": 1,
      "z": 5,
      "name": "Empty"
    },
    {
      "x": -5,
      "y": 2,
      "z": 5,
      "name": "Empty"
    },
    {
      "x": -5,
      "y": 3,
      "z": 5,
      "name": "Empty"
    },
    {
      "x": -5,
      "y": 4,
      "z": 5,
      "name": "Empty"
    },
    {
      "x": -5,
      "y": 5,
      "z": 5,
      "name": "Empty"
    },
    {
      "x": -5,
      "y": 6,
      "z": 5,
      "name": "Empty"
    },
    {
      "x": -5,
      "y": 7,
      "z": 5,
      "name": "Empty"
    },
    {
      "x": -5,
      "y": 8,
      "z": 5,
      "name": "Empty"
    },
    {
      "x": -5,
      "y": 9,
      "z": 5,
      "name": "Empty"
    },
    {
      "x": -5,
      "y": 10,
      "z": 5,
      "name": "Empty"
    },
    {
      "x": -5,
      "y": 11,
      "z": 5,
      "name": "Empty"
    },
    {
      "x": -5,
      "y": 12,
      "z": 5,
      "name": "Empty"
    },
    {
      "x": -5,
      "y": 13,
      "z": 5,
      "name": "Empty"
    },
    {
      "x": -5,
      "y": 14,
      "z": 5,
      "name": "Empty"
    },
    {
      "x": -5,
      "y": 15,
      "z": 5,
      "name": "Empty"
    },
    {
      "x": -5,
      "y": 16,
      "z": 5,
      "name": "Empty"
    },
    {
      "x": -5,
      "y": 17,
      "z": 5,
      "name": "Empty"
    },
    {
      "x": -5,
      "y": 18,
      "z": 5,
      "name": "Empty"
    },
    {
      "x": -5,
      "y": 19,
      "z": 5,
      "name": "Empty"
    },
    {
      "x": -5,
      "y": 20,
      "z": 5,
      "name": "Empty"
    },
    {
      "x": -5,
      "y": 21,
      "z": 5,
      "name": "Empty"
    },
    {
      "x": -5,
      "y": 0,
      "z": 6,
      "name": "Rock_Ledge_Brick_Smooth"
    },
    {
      "x": -5,
      "y": 1,
      "z": 6,
      "name": "Empty"
    },
    {
      "x": -5,
      "y": 2,
      "z": 6,
      "name": "Empty"
    },
    {
      "x": -5,
      "y": 3,
      "z": 6,
      "name": "Empty"
    },
    {
      "x": -5,
      "y": 4,
      "z": 6,
      "name": "Empty"
    },
    {
      "x": -5,
      "y": 5,
      "z": 6,
      "name": "Empty"
    },
    {
      "x": -5,
      "y": 6,
      "z": 6,
      "name": "Empty"
    },
    {
      "x": -5,
      "y": 7,
      "z": 6,
      "name": "Empty"
    },
    {
      "x": -5,
      "y": 8,
      "z": 6,
      "name": "Empty"
    },
    {
      "x": -5,
      "y": 9,
      "z": 6,
      "name": "Empty"
    },
    {
      "x": -5,
      "y": 10,
      "z": 6,
      "name": "Empty"
    },
    {
      "x": -5,
      "y": 11,
      "z": 6,
      "name": "Empty"
    },
    {
      "x": -5,
      "y": 12,
      "z": 6,
      "name": "Empty"
    },
    {
      "x": -5,
      "y": 13,
      "z": 6,
      "name": "Empty"
    },
    {
      "x": -5,
      "y": 14,
      "z": 6,
      "name": "Empty"
    },
    {
      "x": -5,
      "y": 15,
      "z": 6,
      "name": "Empty"
    },
    {
      "x": -5,
      "y": 16,
      "z": 6,
      "name": "Empty"
    },
    {
      "x": -5,
      "y": 17,
      "z": 6,
      "name": "Empty"
    },
    {
      "x": -5,
      "y": 18,
      "z": 6,
      "name": "Empty"
    },
    {
      "x": -5,
      "y": 19,
      "z": 6,
      "name": "Empty"
    },
    {
      "x": -5,
      "y": 20,
      "z": 6,
      "name": "Empty"
    },
    {
      "x": -5,
      "y": 21,
      "z": 6,
      "name": "Empty"
    },
    {
      "x": -4,
      "y": 0,
      "z": -6,
      "name": "Rock_Ledge_Brick_Smooth"
    },
    {
      "x": -4,
      "y": 0,
      "z": -5,
      "name": "Rock_Ledge_Brick_Smooth"
    },
    {
      "x": -4,
      "y": 1,
      "z": -5,
      "name": "Empty"
    },
    {
      "x": -4,
      "y": 2,
      "z": -5,
      "name": "Empty"
    },
    {
      "x": -4,
      "y": 3,
      "z": -5,
      "name": "Empty"
    },
    {
      "x": -4,
      "y": 4,
      "z": -5,
      "name": "Empty"
    },
    {
      "x": -4,
      "y": 5,
      "z": -5,
      "name": "Empty"
    },
    {
      "x": -4,
      "y": 6,
      "z": -5,
      "name": "Empty"
    },
    {
      "x": -4,
      "y": 7,
      "z": -5,
      "name": "Empty"
    },
    {
      "x": -4,
      "y": 8,
      "z": -5,
      "name": "Empty"
    },
    {
      "x": -4,
      "y": 9,
      "z": -5,
      "name": "Empty"
    },
    {
      "x": -4,
      "y": 10,
      "z": -5,
      "name": "Empty"
    },
    {
      "x": -4,
      "y": 11,
      "z": -5,
      "name": "Empty"
    },
    {
      "x": -4,
      "y": 12,
      "z": -5,
      "name": "Empty"
    },
    {
      "x": -4,
      "y": 13,
      "z": -5,
      "name": "Empty"
    },
    {
      "x": -4,
      "y": 14,
      "z": -5,
      "name": "Empty"
    },
    {
      "x": -4,
      "y": 15,
      "z": -5,
      "name": "Empty"
    },
    {
      "x": -4,
      "y": 16,
      "z": -5,
      "name": "Empty"
    },
    {
      "x": -4,
      "y": 17,
      "z": -5,
      "name": "Empty"
    },
    {
      "x": -4,
      "y": 18,
      "z": -5,
      "name": "Empty"
    },
    {
      "x": -4,
      "y": 19,
      "z": -5,
      "name": "Empty"
    },
    {
      "x": -4,
      "y": 20,
      "z": -5,
      "name": "Empty"
    },
    {
      "x": -4,
      "y": 21,
      "z": -5,
      "name": "Empty"
    },
    {
      "x": -4,
      "y": 0,
      "z": -4,
      "name": "Rock_Ledge_Brick_Smooth"
    },
    {
      "x": -4,
      "y": 1,
      "z": -4,
      "name": "Rock_Ledge_Brick_Smooth"
    },
    {
      "x": -4,
      "y": 2,
      "z": -4,
      "name": "Rock_Ledge_Brick_Smooth"
    },
    {
      "x": -4,
      "y": 3,
      "z": -4,
      "name": "Rock_Ledge_Brick_Smooth"
    },
    {
      "x": -4,
      "y": 4,
      "z": -4,
      "name": "Rock_Ledge_Brick_Smooth"
    },
    {
      "x": -4,
      "y": 5,
      "z": -4,
      "name": "Rock_Ledge_Brick_Smooth"
    },
    {
      "x": -4,
      "y": 6,
      "z": -4,
      "name": "Rock_Ledge_Brick_Smooth"
    },
    {
      "x": -4,
      "y": 7,
      "z": -4,
      "name": "Rock_Ledge_Brick_Smooth"
    },
    {
      "x": -4,
      "y": 8,
      "z": -4,
      "name": "Rock_Ledge_Brick_Smooth"
    },
    {
      "x": -4,
      "y": 9,
      "z": -4,
      "name": "Rock_Ledge_Brick_Smooth"
    },
    {
      "x": -4,
      "y": 10,
      "z": -4,
      "name": "Rock_Ledge_Brick_Smooth"
    },
    {
      "x": -4,
      "y": 11,
      "z": -4,
      "name": "Rock_Ledge_Brick_Smooth"
    },
    {
      "x": -4,
      "y": 12,
      "z": -4,
      "name": "Rock_Ledge_Brick_Smooth"
    },
    {
      "x": -4,
      "y": 13,
      "z": -4,
      "name": "Rock_Ledge_Brick_Smooth"
    },
    {
      "x": -4,
      "y": 14,
      "z": -4,
      "name": "Rock_Ledge_Brick_Smooth"
    },
    {
      "x": -4,
      "y": 15,
      "z": -4,
      "name": "Rock_Ledge_Brick_Smooth"
    },
    {
      "x": -4,
      "y": 16,
      "z": -4,
      "name": "Rock_Ledge_Brick_Smooth"
    },
    {
      "x": -4,
      "y": 17,
      "z": -4,
      "name": "Rock_Ledge_Brick_Smooth"
    },
    {
      "x": -4,
      "y": 18,
      "z": -4,
      "name": "Empty"
    },
    {
      "x": -4,
      "y": 19,
      "z": -4,
      "name": "Empty"
    },
    {
      "x": -4,
      "y": 20,
      "z": -4,
      "name": "Empty"
    },
    {
      "x": -4,
      "y": 21,
      "z": -4,
      "name": "Empty"
    },
    {
      "x": -4,
      "y": 22,
      "z": -4,
      "name": "Rock_Ledge_Brick_Smooth"
    },
    {
      "x": -4,
      "y": 0,
      "z": -3,
      "name": "Rock_Ledge_Brick_Smooth"
    },
    {
      "x": -4,
      "y": 1,
      "z": -3,
      "name": "YellowLED",
      "support": 15
    },
    {
      "x": -4,
      "y": 2,
      "z": -3,
      "name": "YellowLED",
      "support": 15
    },
    {
      "x": -4,
      "y": 3,
      "z": -3,
      "name": "YellowLED",
      "support": 15
    },
    {
      "x": -4,
      "y": 4,
      "z": -3,
      "name": "YellowLED",
      "support": 15
    },
    {
      "x": -4,
      "y": 5,
      "z": -3,
      "name": "YellowLED",
      "support": 15
    },
    {
      "x": -4,
      "y": 6,
      "z": -3,
      "name": "YellowLED",
      "support": 15
    },
    {
      "x": -4,
      "y": 7,
      "z": -3,
      "name": "YellowLED",
      "support": 15
    },
    {
      "x": -4,
      "y": 8,
      "z": -3,
      "name": "YellowLED",
      "support": 15
    },
    {
      "x": -4,
      "y": 9,
      "z": -3,
      "name": "YellowLED",
      "support": 15
    },
    {
      "x": -4,
      "y": 10,
      "z": -3,
      "name": "YellowLED",
      "support": 15
    },
    {
      "x": -4,
      "y": 11,
      "z": -3,
      "name": "YellowLED",
      "support": 15
    },
    {
      "x": -4,
      "y": 12,
      "z": -3,
      "name": "YellowLED",
      "support": 15
    },
    {
      "x": -4,
      "y": 13,
      "z": -3,
      "name": "YellowLED",
      "support": 15
    },
    {
      "x": -4,
      "y": 14,
      "z": -3,
      "name": "YellowLED",
      "support": 15
    },
    {
      "x": -4,
      "y": 15,
      "z": -3,
      "name": "YellowLED",
      "support": 15
    },
    {
      "x": -4,
      "y": 16,
      "z": -3,
      "name": "YellowLED",
      "support": 15
    },
    {
      "x": -4,
      "y": 17,
      "z": -3,
      "name": "YellowLED",
      "support": 15
    },
    {
      "x": -4,
      "y": 18,
      "z": -3,
      "name": "Rock_Ledge_Brick_Smooth"
    },
    {
      "x": -4,
      "y": 19,
      "z": -3,
      "name": "Rock_Ledge_Brick_Smooth"
    },
    {
      "x": -4,
      "y": 20,
      "z": -3,
      "name": "Rock_Ledge_Brick_Smooth"
    },
    {
      "x": -4,
      "y": 21,
      "z": -3,
      "name": "Rock_Ledge_Brick_Smooth"
    },
    {
      "x": -4,
      "y": 22,
      "z": -3,
      "name": "Rock_Ledge_Brick_Smooth"
    },
    {
      "x": -4,
      "y": 0,
      "z": -2,
      "name": "Rock_Ledge_Brick_Smooth"
    },
    {
      "x": -4,
      "y": 1,
      "z": -2,
      "name": "Empty"
    },
    {
      "x": -4,
      "y": 2,
      "z": -2,
      "name": "Empty"
    },
    {
      "x": -4,
      "y": 3,
      "z": -2,
      "name": "Empty"
    },
    {
      "x": -4,
      "y": 4,
      "z": -2,
      "name": "Empty"
    },
    {
      "x": -4,
      "y": 5,
      "z": -2,
      "name": "Empty"
    },
    {
      "x": -4,
      "y": 6,
      "z": -2,
      "name": "Empty"
    },
    {
      "x": -4,
      "y": 7,
      "z": -2,
      "name": "Empty"
    },
    {
      "x": -4,
      "y": 8,
      "z": -2,
      "name": "Empty"
    },
    {
      "x": -4,
      "y": 9,
      "z": -2,
      "name": "Empty"
    },
    {
      "x": -4,
      "y": 10,
      "z": -2,
      "name": "Empty"
    },
    {
      "x": -4,
      "y": 11,
      "z": -2,
      "name": "Empty"
    },
    {
      "x": -4,
      "y": 12,
      "z": -2,
      "name": "Empty"
    },
    {
      "x": -4,
      "y": 13,
      "z": -2,
      "name": "Empty"
    },
    {
      "x": -4,
      "y": 14,
      "z": -2,
      "name": "Empty"
    },
    {
      "x": -4,
      "y": 15,
      "z": -2,
      "name": "Empty"
    },
    {
      "x": -4,
      "y": 16,
      "z": -2,
      "name": "Empty"
    },
    {
      "x": -4,
      "y": 17,
      "z": -2,
      "name": "YellowLED"
    },
    {
      "x": -4,
      "y": 18,
      "z": -2,
      "name": "Rock_Ledge_Brick_Smooth"
    },
    {
      "x": -4,
      "y": 19,
      "z": -2,
      "name": "Rock_Ledge_Brick_Smooth"
    },
    {
      "x": -4,
      "y": 20,
      "z": -2,
      "name": "Rock_Ledge_Brick_Smooth"
    },
    {
      "x": -4,
      "y": 21,
      "z": -2,
      "name": "Rock_Ledge_Brick_Smooth"
    },
    {
      "x": -4,
      "y": 22,
      "z": -2,
      "name": "Rock_Ledge_Brick_Smooth"
    },
    {
      "x": -4,
      "y": 0,
      "z": -1,
      "name": "Rock_Ledge_Brick_Smooth"
    },
    {
      "x": -4,
      "y": 1,
      "z": -1,
      "name": "Empty"
    },
    {
      "x": -4,
      "y": 2,
      "z": -1,
      "name": "Empty"
    },
    {
      "x": -4,
      "y": 3,
      "z": -1,
      "name": "Empty"
    },
    {
      "x": -4,
      "y": 4,
      "z": -1,
      "name": "Empty"
    },
    {
      "x": -4,
      "y": 5,
      "z": -1,
      "name": "Empty"
    },
    {
      "x": -4,
      "y": 6,
      "z": -1,
      "name": "Empty"
    },
    {
      "x": -4,
      "y": 7,
      "z": -1,
      "name": "Empty"
    },
    {
      "x": -4,
      "y": 8,
      "z": -1,
      "name": "Empty"
    },
    {
      "x": -4,
      "y": 9,
      "z": -1,
      "name": "Empty"
    },
    {
      "x": -4,
      "y": 10,
      "z": -1,
      "name": "Empty"
    },
    {
      "x": -4,
      "y": 11,
      "z": -1,
      "name": "Empty"
    },
    {
      "x": -4,
      "y": 12,
      "z": -1,
      "name": "Empty"
    },
    {
      "x": -4,
      "y": 13,
      "z": -1,
      "name": "Empty"
    },
    {
      "x": -4,
      "y": 14,
      "z": -1,
      "name": "Empty"
    },
    {
      "x": -4,
      "y": 15,
      "z": -1,
      "name": "Empty"
    },
    {
      "x": -4,
      "y": 16,
      "z": -1,
      "name": "Empty"
    },
    {
      "x": -4,
      "y": 17,
      "z": -1,
      "name": "YellowLED"
    },
    {
      "x": -4,
      "y": 18,
      "z": -1,
      "name": "Rock_Ledge_Brick_Smooth"
    },
    {
      "x": -4,
      "y": 19,
      "z": -1,
      "name": "Empty"
    },
    {
      "x": -4,
      "y": 20,
      "z": -1,
      "name": "Empty"
    },
    {
      "x": -4,
      "y": 21,
      "z": -1,
      "name": "Empty"
    },
    {
      "x": -4,
      "y": 22,
      "z": -1,
      "name": "Rock_Ledge_Brick_Smooth"
    },
    {
      "x": -4,
      "y": 0,
      "z": 0,
      "name": "Rock_Ledge_Brick_Smooth"
    },
    {
      "x": -4,
      "y": 1,
      "z": 0,
      "name": "Empty"
    },
    {
      "x": -4,
      "y": 2,
      "z": 0,
      "name": "Empty"
    },
    {
      "x": -4,
      "y": 3,
      "z": 0,
      "name": "Empty"
    },
    {
      "x": -4,
      "y": 4,
      "z": 0,
      "name": "Empty"
    },
    {
      "x": -4,
      "y": 5,
      "z": 0,
      "name": "Empty"
    },
    {
      "x": -4,
      "y": 6,
      "z": 0,
      "name": "Empty"
    },
    {
      "x": -4,
      "y": 7,
      "z": 0,
      "name": "Empty"
    },
    {
      "x": -4,
      "y": 8,
      "z": 0,
      "name": "Empty"
    },
    {
      "x": -4,
      "y": 9,
      "z": 0,
      "name": "Empty"
    },
    {
      "x": -4,
      "y": 10,
      "z": 0,
      "name": "Empty"
    },
    {
      "x": -4,
      "y": 11,
      "z": 0,
      "name": "Empty"
    },
    {
      "x": -4,
      "y": 12,
      "z": 0,
      "name": "Empty"
    },
    {
      "x": -4,
      "y": 13,
      "z": 0,
      "name": "Empty"
    },
    {
      "x": -4,
      "y": 14,
      "z": 0,
      "name": "Empty"
    },
    {
      "x": -4,
      "y": 15,
      "z": 0,
      "name": "Empty"
    },
    {
      "x": -4,
      "y": 16,
      "z": 0,
      "name": "Empty"
    },
    {
      "x": -4,
      "y": 17,
      "z": 0,
      "name": "YellowLED"
    },
    {
      "x": -4,
      "y": 18,
      "z": 0,
      "name": "Rock_Ledge_Brick_Smooth"
    },
    {
      "x": -4,
      "y": 19,
      "z": 0,
      "name": "Empty"
    },
    {
      "x": -4,
      "y": 20,
      "z": 0,
      "name": "Empty"
    },
    {
      "x": -4,
      "y": 21,
      "z": 0,
      "name": "Empty"
    },
    {
      "x": -4,
      "y": 22,
      "z": 0,
      "name": "Rock_Ledge_Brick_Smooth"
    },
    {
      "x": -4,
      "y": 0,
      "z": 1,
      "name": "Rock_Ledge_Brick_Smooth"
    },
    {
      "x": -4,
      "y": 1,
      "z": 1,
      "name": "Empty"
    },
    {
      "x": -4,
      "y": 2,
      "z": 1,
      "name": "Empty"
    },
    {
      "x": -4,
      "y": 3,
      "z": 1,
      "name": "Empty"
    },
    {
      "x": -4,
      "y": 4,
      "z": 1,
      "name": "Empty"
    },
    {
      "x": -4,
      "y": 5,
      "z": 1,
      "name": "Empty"
    },
    {
      "x": -4,
      "y": 6,
      "z": 1,
      "name": "Empty"
    },
    {
      "x": -4,
      "y": 7,
      "z": 1,
      "name": "Empty"
    },
    {
      "x": -4,
      "y": 8,
      "z": 1,
      "name": "Empty"
    },
    {
      "x": -4,
      "y": 9,
      "z": 1,
      "name": "Empty"
    },
    {
      "x": -4,
      "y": 10,
      "z": 1,
      "name": "Empty"
    },
    {
      "x": -4,
      "y": 11,
      "z": 1,
      "name": "Empty"
    },
    {
      "x": -4,
      "y": 12,
      "z": 1,
      "name": "Empty"
    },
    {
      "x": -4,
      "y": 13,
      "z": 1,
      "name": "Empty"
    },
    {
      "x": -4,
      "y": 14,
      "z": 1,
      "name": "Empty"
    },
    {
      "x": -4,
      "y": 15,
      "z": 1,
      "name": "Empty"
    },
    {
      "x": -4,
      "y": 16,
      "z": 1,
      "name": "Empty"
    },
    {
      "x": -4,
      "y": 17,
      "z": 1,
      "name": "YellowLED"
    },
    {
      "x": -4,
      "y": 18,
      "z": 1,
      "name": "Rock_Ledge_Brick_Smooth"
    },
    {
      "x": -4,
      "y": 19,
      "z": 1,
      "name": "Block_Spawner_Block",
      "components": {
        "Components": {
          "PlacedByInteraction": {
            "WhoPlacedUuid": {
              "$binary": "L6LzkYSjQOWrksT02Y12sg==",
              "$type": "04"
            }
          },
          "BlockSpawner": {
            "BlockSpawnerId": "RobotCity"
          }
        }
      },
      "rotation": 2
    },
    {
      "x": -4,
      "y": 20,
      "z": 1,
      "name": "Empty"
    },
    {
      "x": -4,
      "y": 21,
      "z": 1,
      "name": "Empty"
    },
    {
      "x": -4,
      "y": 22,
      "z": 1,
      "name": "Rock_Ledge_Brick_Smooth"
    },
    {
      "x": -4,
      "y": 0,
      "z": 2,
      "name": "Rock_Ledge_Brick_Smooth"
    },
    {
      "x": -4,
      "y": 1,
      "z": 2,
      "name": "Empty"
    },
    {
      "x": -4,
      "y": 2,
      "z": 2,
      "name": "Empty"
    },
    {
      "x": -4,
      "y": 3,
      "z": 2,
      "name": "Empty"
    },
    {
      "x": -4,
      "y": 4,
      "z": 2,
      "name": "Empty"
    },
    {
      "x": -4,
      "y": 5,
      "z": 2,
      "name": "Empty"
    },
    {
      "x": -4,
      "y": 6,
      "z": 2,
      "name": "Empty"
    },
    {
      "x": -4,
      "y": 7,
      "z": 2,
      "name": "Empty"
    },
    {
      "x": -4,
      "y": 8,
      "z": 2,
      "name": "Empty"
    },
    {
      "x": -4,
      "y": 9,
      "z": 2,
      "name": "Empty"
    },
    {
      "x": -4,
      "y": 10,
      "z": 2,
      "name": "Empty"
    },
    {
      "x": -4,
      "y": 11,
      "z": 2,
      "name": "Empty"
    },
    {
      "x": -4,
      "y": 12,
      "z": 2,
      "name": "Empty"
    },
    {
      "x": -4,
      "y": 13,
      "z": 2,
      "name": "Empty"
    },
    {
      "x": -4,
      "y": 14,
      "z": 2,
      "name": "Empty"
    },
    {
      "x": -4,
      "y": 15,
      "z": 2,
      "name": "Empty"
    },
    {
      "x": -4,
      "y": 16,
      "z": 2,
      "name": "Empty"
    },
    {
      "x": -4,
      "y": 17,
      "z": 2,
      "name": "YellowLED"
    },
    {
      "x": -4,
      "y": 18,
      "z": 2,
      "name": "Rock_Ledge_Brick_Smooth"
    },
    {
      "x": -4,
      "y": 19,
      "z": 2,
      "name": "Rock_Ledge_Brick_Smooth"
    },
    {
      "x": -4,
      "y": 20,
      "z": 2,
      "name": "Rock_Ledge_Brick_Smooth"
    },
    {
      "x": -4,
      "y": 21,
      "z": 2,
      "name": "Rock_Ledge_Brick_Smooth"
    },
    {
      "x": -4,
      "y": 22,
      "z": 2,
      "name": "Rock_Ledge_Brick_Smooth"
    },
    {
      "x": -4,
      "y": 0,
      "z": 3,
      "name": "Rock_Ledge_Brick_Smooth"
    },
    {
      "x": -4,
      "y": 1,
      "z": 3,
      "name": "YellowLED",
      "support": 15
    },
    {
      "x": -4,
      "y": 2,
      "z": 3,
      "name": "YellowLED",
      "support": 15
    },
    {
      "x": -4,
      "y": 3,
      "z": 3,
      "name": "YellowLED",
      "support": 15
    },
    {
      "x": -4,
      "y": 4,
      "z": 3,
      "name": "YellowLED",
      "support": 15
    },
    {
      "x": -4,
      "y": 5,
      "z": 3,
      "name": "YellowLED",
      "support": 15
    },
    {
      "x": -4,
      "y": 6,
      "z": 3,
      "name": "YellowLED",
      "support": 15
    },
    {
      "x": -4,
      "y": 7,
      "z": 3,
      "name": "YellowLED",
      "support": 15
    },
    {
      "x": -4,
      "y": 8,
      "z": 3,
      "name": "YellowLED",
      "support": 15
    },
    {
      "x": -4,
      "y": 9,
      "z": 3,
      "name": "YellowLED",
      "support": 15
    },
    {
      "x": -4,
      "y": 10,
      "z": 3,
      "name": "YellowLED",
      "support": 15
    },
    {
      "x": -4,
      "y": 11,
      "z": 3,
      "name": "YellowLED",
      "support": 15
    },
    {
      "x": -4,
      "y": 12,
      "z": 3,
      "name": "YellowLED",
      "support": 15
    },
    {
      "x": -4,
      "y": 13,
      "z": 3,
      "name": "YellowLED",
      "support": 15
    },
    {
      "x": -4,
      "y": 14,
      "z": 3,
      "name": "YellowLED",
      "support": 15
    },
    {
      "x": -4,
      "y": 15,
      "z": 3,
      "name": "YellowLED",
      "support": 15
    },
    {
      "x": -4,
      "y": 16,
      "z": 3,
      "name": "YellowLED",
      "support": 15
    },
    {
      "x": -4,
      "y": 17,
      "z": 3,
      "name": "YellowLED",
      "support": 15
    },
    {
      "x": -4,
      "y": 18,
      "z": 3,
      "name": "Rock_Ledge_Brick_Smooth"
    },
    {
      "x": -4,
      "y": 19,
      "z": 3,
      "name": "Rock_Ledge_Brick_Smooth"
    },
    {
      "x": -4,
      "y": 20,
      "z": 3,
      "name": "Rock_Ledge_Brick_Smooth"
    },
    {
      "x": -4,
      "y": 21,
      "z": 3,
      "name": "Rock_Ledge_Brick_Smooth"
    },
    {
      "x": -4,
      "y": 22,
      "z": 3,
      "name": "Rock_Ledge_Brick_Smooth"
    },
    {
      "x": -4,
      "y": 0,
      "z": 4,
      "name": "Rock_Ledge_Brick_Smooth"
    },
    {
      "x": -4,
      "y": 1,
      "z": 4,
      "name": "Rock_Ledge_Brick_Smooth"
    },
    {
      "x": -4,
      "y": 2,
      "z": 4,
      "name": "Rock_Ledge_Brick_Smooth"
    },
    {
      "x": -4,
      "y": 3,
      "z": 4,
      "name": "Rock_Ledge_Brick_Smooth"
    },
    {
      "x": -4,
      "y": 4,
      "z": 4,
      "name": "Rock_Ledge_Brick_Smooth"
    },
    {
      "x": -4,
      "y": 5,
      "z": 4,
      "name": "Rock_Ledge_Brick_Smooth"
    },
    {
      "x": -4,
      "y": 6,
      "z": 4,
      "name": "Rock_Ledge_Brick_Smooth"
    },
    {
      "x": -4,
      "y": 7,
      "z": 4,
      "name": "Rock_Ledge_Brick_Smooth"
    },
    {
      "x": -4,
      "y": 8,
      "z": 4,
      "name": "Rock_Ledge_Brick_Smooth"
    },
    {
      "x": -4,
      "y": 9,
      "z": 4,
      "name": "Rock_Ledge_Brick_Smooth"
    },
    {
      "x": -4,
      "y": 10,
      "z": 4,
      "name": "Rock_Ledge_Brick_Smooth"
    },
    {
      "x": -4,
      "y": 11,
      "z": 4,
      "name": "Rock_Ledge_Brick_Smooth"
    },
    {
      "x": -4,
      "y": 12,
      "z": 4,
      "name": "Rock_Ledge_Brick_Smooth"
    },
    {
      "x": -4,
      "y": 13,
      "z": 4,
      "name": "Rock_Ledge_Brick_Smooth"
    },
    {
      "x": -4,
      "y": 14,
      "z": 4,
      "name": "Rock_Ledge_Brick_Smooth"
    },
    {
      "x": -4,
      "y": 15,
      "z": 4,
      "name": "Rock_Ledge_Brick_Smooth"
    },
    {
      "x": -4,
      "y": 16,
      "z": 4,
      "name": "Rock_Ledge_Brick_Smooth"
    },
    {
      "x": -4,
      "y": 17,
      "z": 4,
      "name": "Rock_Ledge_Brick_Smooth"
    },
    {
      "x": -4,
      "y": 18,
      "z": 4,
      "name": "Empty"
    },
    {
      "x": -4,
      "y": 19,
      "z": 4,
      "name": "Empty"
    },
    {
      "x": -4,
      "y": 20,
      "z": 4,
      "name": "Empty"
    },
    {
      "x": -4,
      "y": 21,
      "z": 4,
      "name": "Empty"
    },
    {
      "x": -4,
      "y": 22,
      "z": 4,
      "name": "Rock_Ledge_Brick_Smooth"
    },
    {
      "x": -4,
      "y": 0,
      "z": 5,
      "name": "Rock_Ledge_Brick_Smooth"
    },
    {
      "x": -4,
      "y": 1,
      "z": 5,
      "name": "Empty"
    },
    {
      "x": -4,
      "y": 2,
      "z": 5,
      "name": "Empty"
    },
    {
      "x": -4,
      "y": 3,
      "z": 5,
      "name": "Empty"
    },
    {
      "x": -4,
      "y": 4,
      "z": 5,
      "name": "Empty"
    },
    {
      "x": -4,
      "y": 5,
      "z": 5,
      "name": "Empty"
    },
    {
      "x": -4,
      "y": 6,
      "z": 5,
      "name": "Empty"
    },
    {
      "x": -4,
      "y": 7,
      "z": 5,
      "name": "Empty"
    },
    {
      "x": -4,
      "y": 8,
      "z": 5,
      "name": "Empty"
    },
    {
      "x": -4,
      "y": 9,
      "z": 5,
      "name": "Empty"
    },
    {
      "x": -4,
      "y": 10,
      "z": 5,
      "name": "Empty"
    },
    {
      "x": -4,
      "y": 11,
      "z": 5,
      "name": "Empty"
    },
    {
      "x": -4,
      "y": 12,
      "z": 5,
      "name": "Empty"
    },
    {
      "x": -4,
      "y": 13,
      "z": 5,
      "name": "Empty"
    },
    {
      "x": -4,
      "y": 14,
      "z": 5,
      "name": "Empty"
    },
    {
      "x": -4,
      "y": 15,
      "z": 5,
      "name": "Empty"
    },
    {
      "x": -4,
      "y": 16,
      "z": 5,
      "name": "Empty"
    },
    {
      "x": -4,
      "y": 17,
      "z": 5,
      "name": "Empty"
    },
    {
      "x": -4,
      "y": 18,
      "z": 5,
      "name": "Empty"
    },
    {
      "x": -4,
      "y": 19,
      "z": 5,
      "name": "Empty"
    },
    {
      "x": -4,
      "y": 20,
      "z": 5,
      "name": "Empty"
    },
    {
      "x": -4,
      "y": 21,
      "z": 5,
      "name": "Empty"
    },
    {
      "x": -4,
      "y": 0,
      "z": 6,
      "name": "Rock_Ledge_Brick_Smooth"
    },
    {
      "x": -4,
      "y": 1,
      "z": 6,
      "name": "Empty"
    },
    {
      "x": -4,
      "y": 2,
      "z": 6,
      "name": "Empty"
    },
    {
      "x": -4,
      "y": 3,
      "z": 6,
      "name": "Empty"
    },
    {
      "x": -4,
      "y": 4,
      "z": 6,
      "name": "Empty"
    },
    {
      "x": -4,
      "y": 5,
      "z": 6,
      "name": "Empty"
    },
    {
      "x": -4,
      "y": 6,
      "z": 6,
      "name": "Empty"
    },
    {
      "x": -4,
      "y": 7,
      "z": 6,
      "name": "Empty"
    },
    {
      "x": -4,
      "y": 8,
      "z": 6,
      "name": "Empty"
    },
    {
      "x": -4,
      "y": 9,
      "z": 6,
      "name": "Empty"
    },
    {
      "x": -4,
      "y": 10,
      "z": 6,
      "name": "Empty"
    },
    {
      "x": -4,
      "y": 11,
      "z": 6,
      "name": "Empty"
    },
    {
      "x": -4,
      "y": 12,
      "z": 6,
      "name": "Empty"
    },
    {
      "x": -4,
      "y": 13,
      "z": 6,
      "name": "Empty"
    },
    {
      "x": -4,
      "y": 14,
      "z": 6,
      "name": "Empty"
    },
    {
      "x": -4,
      "y": 15,
      "z": 6,
      "name": "Empty"
    },
    {
      "x": -4,
      "y": 16,
      "z": 6,
      "name": "Empty"
    },
    {
      "x": -4,
      "y": 17,
      "z": 6,
      "name": "Empty"
    },
    {
      "x": -4,
      "y": 18,
      "z": 6,
      "name": "Empty"
    },
    {
      "x": -4,
      "y": 19,
      "z": 6,
      "name": "Empty"
    },
    {
      "x": -4,
      "y": 20,
      "z": 6,
      "name": "Empty"
    },
    {
      "x": -4,
      "y": 21,
      "z": 6,
      "name": "Empty"
    },
    {
      "x": -3,
      "y": 0,
      "z": -6,
      "name": "Rock_Ledge_Brick_Smooth"
    },
    {
      "x": -3,
      "y": 0,
      "z": -5,
      "name": "Rock_Ledge_Brick_Smooth"
    },
    {
      "x": -3,
      "y": 1,
      "z": -5,
      "name": "Rock_Ledge_Brick_Smooth"
    },
    {
      "x": -3,
      "y": 2,
      "z": -5,
      "name": "Rock_Ledge_Brick_Smooth"
    },
    {
      "x": -3,
      "y": 3,
      "z": -5,
      "name": "Rock_Ledge_Brick_Smooth"
    },
    {
      "x": -3,
      "y": 4,
      "z": -5,
      "name": "Rock_Ledge_Brick_Smooth"
    },
    {
      "x": -3,
      "y": 5,
      "z": -5,
      "name": "Rock_Ledge_Brick_Smooth"
    },
    {
      "x": -3,
      "y": 6,
      "z": -5,
      "name": "Rock_Ledge_Brick_Smooth"
    },
    {
      "x": -3,
      "y": 7,
      "z": -5,
      "name": "Rock_Ledge_Brick_Smooth"
    },
    {
      "x": -3,
      "y": 8,
      "z": -5,
      "name": "Rock_Ledge_Brick_Smooth"
    },
    {
      "x": -3,
      "y": 9,
      "z": -5,
      "name": "Rock_Ledge_Brick_Smooth"
    },
    {
      "x": -3,
      "y": 10,
      "z": -5,
      "name": "Rock_Ledge_Brick_Smooth"
    },
    {
      "x": -3,
      "y": 11,
      "z": -5,
      "name": "Rock_Ledge_Brick_Smooth"
    },
    {
      "x": -3,
      "y": 12,
      "z": -5,
      "name": "Rock_Ledge_Brick_Smooth"
    },
    {
      "x": -3,
      "y": 13,
      "z": -5,
      "name": "Rock_Ledge_Brick_Smooth"
    },
    {
      "x": -3,
      "y": 14,
      "z": -5,
      "name": "Rock_Ledge_Brick_Smooth"
    },
    {
      "x": -3,
      "y": 15,
      "z": -5,
      "name": "Rock_Ledge_Brick_Smooth"
    },
    {
      "x": -3,
      "y": 16,
      "z": -5,
      "name": "Rock_Ledge_Brick_Smooth"
    },
    {
      "x": -3,
      "y": 17,
      "z": -5,
      "name": "Rock_Ledge_Brick_Smooth"
    },
    {
      "x": -3,
      "y": 18,
      "z": -5,
