{
  "version": 8,
  "blockIdVersion": 11,
  "anchorX": 0,
  "anchorY": 0,
  "anchorZ": 0,
  "blocks": [
    {
      "x": -7,
      "y": 0,
      "z": -6,
      "name": "Rock_Ledge_Brick"
    },
    {
      "x": -7,
      "y": 0,
      "z": -5,
      "name": "Rock_Ledge_Brick"
    },
    {
      "x": -7,
      "y": 0,
      "z": -4,
      "name": "Rock_Ledge_Brick"
    },
    {
      "x": -7,
      "y": 0,
      "z": -3,
      "name": "Rock_Ledge_Brick"
    },
    {
      "x": -7,
      "y": 0,
      "z": -2,
      "name": "Rock_Ledge_Brick"
    },
    {
      "x": -7,
      "y": 0,
      "z": -1,
      "name": "Rock_Ledge_Brick"
    },
    {
      "x": -7,
      "y": 0,
      "z": 0,
      "name": "Rock_Ledge_Brick"
    },
    {
      "x": -7,
      "y": 0,
      "z": 1,
      "name": "Rock_Ledge_Brick"
    },
    {
      "x": -7,
      "y": 0,
      "z": 2,
      "name": "Rock_Ledge_Brick"
    },
    {
      "x": -7,
      "y": 0,
      "z": 3,
      "name": "Rock_Ledge_Brick"
    },
    {
      "x": -7,
      "y": 0,
      "z": 4,
      "name": "Rock_Ledge_Brick"
    },
    {
      "x": -7,
      "y": 0,
      "z": 5,
      "name": "Rock_Ledge_Brick"
    },
    {
      "x": -7,
      "y": 1,
      "z": 5,
      "name": "Deco_Iron_Bars",
      "rotation": 1
    },
    {
      "x": -7,
      "y": 0,
      "z": 6,
      "name": "Rock_Ledge_Brick"
    },
    {
      "x": -7,
      "y": 1,
      "z": 6,
      "name": "Deco_Iron_Bars_Corner",
      "rotation": 2
    },
    {
      "x": -6,
      "y": 0,
      "z": -6,
      "name": "Rock_Ledge_Brick"
    },
    {
      "x": -6,
      "y": 0,
      "z": -5,
      "name": "Rock_Ledge_Brick"
    },
    {
      "x": -6,
      "y": 0,
      "z": -4,
      "name": "Rock_Ledge_Brick"
    },
    {
      "x": -6,
      "y": 5,
      "z": -4,
      "name": "Rock_Ledge_Brick_Smooth"
    },
    {
      "x": -6,
      "y": 0,
      "z": -3,
      "name": "Rock_Ledge_Brick"
    },
    {
      "x": -6,
      "y": 1,
      "z": -3,
      "name": "Rock_Ledge_Brick_Smooth"
    },
    {
      "x": -6,
      "y": 2,
      "z": -3,
      "name": "Rock_Ledge_Brick_Smooth"
    },
    {
      "x": -6,
      "y": 3,
      "z": -3,
      "name": "Rock_Ledge_Brick_Smooth"
    },
    {
      "x": -6,
      "y": 4,
      "z": -3,
      "name": "Rock_Ledge_Brick_Smooth"
    },
    {
      "x": -6,
      "y": 5,
      "z": -3,
      "name": "Rock_Ledge_Brick_Smooth"
    },
    {
      "x": -6,
      "y": 0,
      "z": -2,
      "name": "Rock_Ledge_Brick"
    },
    {
      "x": -6,
      "y": 1,
      "z": -2,
      "name": "Rock_Ledge_Brick_Smooth"
    },
    {
      "x": -6,
      "y": 5,
      "z": -2,
      "name": "Rock_Ledge_Brick_Smooth"
    },
    {
      "x": -6,
      "y": 0,
      "z": -1,
      "name": "Rock_Ledge_Brick"
    },
    {
      "x": -6,
      "y": 1,
      "z": -1,
      "name": "Rock_Ledge_Brick_Smooth"
    },
    {
      "x": -6,
      "y": 5,
      "z": -1,
      "name": "Rock_Ledge_Brick_Smooth"
    },
    {
      "x": -6,
      "y": 0,
      "z": 0,
      "name": "Rock_Ledge_Brick"
    },
    {
      "x": -6,
      "y": 1,
      "z": 0,
      "name": "Rock_Ledge_Brick_Smooth"
    },
    {
      "x": -6,
      "y": 5,
      "z": 0,
      "name": "Rock_Ledge_Brick_Smooth"
    },
    {
      "x": -6,
      "y": 0,
      "z": 1,
      "name": "Rock_Ledge_Brick"
    },
    {
      "x": -6,
      "y": 1,
      "z": 1,
      "name": "Rock_Ledge_Brick_Smooth"
    },
    {
      "x": -6,
      "y": 5,
      "z": 1,
      "name": "Rock_Ledge_Brick_Smooth"
    },
    {
      "x": -6,
      "y": 0,
      "z": 2,
      "name": "Rock_Ledge_Brick"
    },
    {
      "x": -6,
      "y": 1,
      "z": 2,
      "name": "Rock_Ledge_Brick_Smooth"
    },
    {
      "x": -6,
      "y": 5,
      "z": 2,
      "name": "Rock_Ledge_Brick_Smooth"
    },
    {
      "x": -6,
      "y": 0,
      "z": 3,
      "name": "Rock_Ledge_Brick"
    },
    {
      "x": -6,
      "y": 1,
      "z": 3,
      "name": "Rock_Ledge_Brick_Smooth"
    },
    {
      "x": -6,
      "y": 5,
      "z": 3,
      "name": "Rock_Ledge_Brick_Smooth"
    },
    {
      "x": -6,
      "y": 0,
      "z": 4,
      "name": "Rock_Ledge_Brick"
    },
    {
      "x": -6,
      "y": 1,
      "z": 4,
      "name": "Rock_Ledge_Brick_Smooth"
    },
    {
      "x": -6,
      "y": 2,
      "z": 4,
      "name": "Rock_Ledge_Brick_Smooth"
    },
    {
      "x": -6,
      "y": 3,
      "z": 4,
      "name": "Rock_Ledge_Brick_Smooth"
    },
    {
      "x": -6,
      "y": 4,
      "z": 4,
      "name": "Rock_Ledge_Brick_Smooth"
    },
    {
      "x": -6,
      "y": 5,
      "z": 4,
      "name": "Rock_Ledge_Brick_Smooth"
    },
    {
      "x": -6,
      "y": 0,
      "z": 5,
      "name": "Rock_Ledge_Brick"
    },
    {
      "x": -6,
      "y": 0,
      "z": 6,
      "name": "Rock_Ledge_Brick"
    },
    {
      "x": -6,
      "y": 1,
      "z": 6,
      "name": "Deco_Iron_Bars"
    },
    {
      "x": -5,
      "y": 0,
      "z": -6,
      "name": "Rock_Ledge_Brick"
    },
    {
      "x": -5,
      "y": 5,
      "z": -6,
      "name": "Rock_Ledge_Brick_Smooth"
    },
    {
      "x": -5,
      "y": 0,
      "z": -5,
      "name": "Rock_Ledge_Brick"
    },
    {
      "x": -5,
      "y": 5,
      "z": -5,
      "name": "Rock_Ledge_Brick_Smooth"
    },
    {
      "x": -5,
      "y": 0,
      "z": -4,
      "name": "Rock_Ledge_Brick"
    },
    {
      "x": -5,
      "y": 5,
      "z": -4,
      "name": "Rock_Ledge_Brick_Smooth"
    },
    {
      "x": -5,
      "y": 0,
      "z": -3,
      "name": "Rock_Ledge_Brick"
    },
    {
      "x": -5,
      "y": 1,
      "z": -3,
      "name": "Rock_Ledge_Brick_Smooth"
    },
    {
      "x": -5,
      "y": 2,
      "z": -3,
      "name": "Rock_Ledge_Brick_Smooth"
    },
    {
      "x": -5,
      "y": 3,
      "z": -3,
      "name": "Rock_Ledge_Brick_Smooth"
    },
    {
      "x": -5,
      "y": 4,
      "z": -3,
      "name": "Rock_Ledge_Brick_Smooth"
    },
    {
      "x": -5,
      "y": 5,
      "z": -3,
      "name": "Rock_Ledge_Brick_Smooth"
    },
    {
      "x": -5,
      "y": 6,
      "z": -3,
      "name": "Rock_Ledge_Brick_Smooth"
    },
    {
      "x": -5,
      "y": 7,
      "z": -3,
      "name": "Rock_Ledge_Brick_Smooth"
    },
    {
      "x": -5,
      "y": 0,
      "z": -2,
      "name": "Rock_Ledge_Brick"
    },
    {
      "x": -5,
      "y": 2,
      "z": -2,
      "name": "Rock_Marble_Brick_Smooth"
    },
    {
      "x": -5,
      "y": 3,
      "z": -2,
      "name": "Rock_Marble_Brick_Smooth"
    },
    {
      "x": -5,
      "y": 4,
      "z": -2,
      "name": "Rock_Marble_Brick_Smooth"
    },
    {
      "x": -5,
      "y": 5,
      "z": -2,
      "name": "Rock_Ledge_Brick_Smooth"
    },
    {
      "x": -5,
      "y": 6,
      "z": -2,
      "name": "Rock_Ledge_Brick_Smooth"
    },
    {
      "x": -5,
      "y": 7,
      "z": -2,
      "name": "Rock_Ledge_Brick_Smooth"
    },
    {
      "x": -5,
      "y": 0,
      "z": -1,
      "name": "Rock_Ledge_Brick"
    },
    {
      "x": -5,
      "y": 2,
      "z": -1,
      "name": "Rock_Marble_Brick_Smooth"
    },
    {
      "x": -5,
      "y": 3,
      "z": -1,
      "name": "Rock_Marble_Brick_Smooth"
    },
    {
      "x": -5,
      "y": 4,
      "z": -1,
      "name": "Rock_Marble_Brick_Smooth"
    },
    {
      "x": -5,
      "y": 5,
      "z": -1,
      "name": "Rock_Ledge_Brick_Smooth"
    },
    {
      "x": -5,
      "y": 6,
      "z": -1,
      "name": "Rock_Ledge_Brick_Smooth"
    },
    {
      "x": -5,
      "y": 7,
      "z": -1,
      "name": "Rock_Ledge_Brick_Smooth"
    },
    {
      "x": -5,
      "y": 0,
      "z": 0,
      "name": "Rock_Ledge_Brick"
    },
    {
      "x": -5,
      "y": 2,
      "z": 0,
      "name": "Rock_Marble_Brick_Smooth"
    },
    {
      "x": -5,
      "y": 3,
      "z": 0,
      "name": "Rock_Marble_Brick_Smooth"
    },
    {
      "x": -5,
      "y": 4,
      "z": 0,
      "name": "Rock_Marble_Brick_Smooth"
    },
    {
      "x": -5,
      "y": 5,
      "z": 0,
      "name": "Rock_Ledge_Brick_Smooth"
    },
    {
      "x": -5,
      "y": 6,
      "z": 0,
      "name": "Rock_Ledge_Brick_Smooth"
    },
    {
      "x": -5,
      "y": 7,
      "z": 0,
      "name": "Rock_Ledge_Brick_Smooth"
    },
    {
      "x": -5,
      "y": 0,
      "z": 1,
      "name": "Rock_Ledge_Brick"
    },
    {
      "x": -5,
      "y": 2,
      "z": 1,
      "name": "Rock_Marble_Brick_Smooth"
    },
    {
      "x": -5,
      "y": 3,
      "z": 1,
      "name": "Rock_Marble_Brick_Smooth"
    },
    {
      "x": -5,
      "y": 4,
      "z": 1,
      "name": "Rock_Marble_Brick_Smooth"
    },
    {
      "x": -5,
      "y": 5,
      "z": 1,
      "name": "Rock_Ledge_Brick_Smooth"
    },
    {
      "x": -5,
      "y": 6,
      "z": 1,
      "name": "Rock_Ledge_Brick_Smooth"
    },
    {
      "x": -5,
      "y": 7,
      "z": 1,
      "name": "Rock_Ledge_Brick_Smooth"
    },
    {
      "x": -5,
      "y": 0,
      "z": 2,
      "name": "Rock_Ledge_Brick"
    },
    {
      "x": -5,
      "y": 2,
      "z": 2,
      "name": "Rock_Marble_Brick_Smooth"
    },
    {
      "x": -5,
      "y": 3,
      "z": 2,
      "name": "Rock_Marble_Brick_Smooth"
    },
    {
      "x": -5,
      "y": 4,
      "z": 2,
      "name": "Rock_Marble_Brick_Smooth"
    },
    {
      "x": -5,
      "y": 5,
      "z": 2,
      "name": "Rock_Ledge_Brick_Smooth"
    },
    {
      "x": -5,
      "y": 6,
      "z": 2,
      "name": "Rock_Ledge_Brick_Smooth"
    },
    {
      "x": -5,
      "y": 7,
      "z": 2,
      "name": "Rock_Ledge_Brick_Smooth"
    },
    {
      "x": -5,
      "y": 0,
      "z": 3,
      "name": "Rock_Ledge_Brick"
    },
    {
      "x": -5,
      "y": 2,
      "z": 3,
      "name": "Rock_Marble_Brick_Smooth"
    },
    {
      "x": -5,
      "y": 3,
      "z": 3,
      "name": "Rock_Marble_Brick_Smooth"
    },
    {
      "x": -5,
      "y": 4,
      "z": 3,
      "name": "Rock_Marble_Brick_Smooth"
    },
    {
      "x": -5,
      "y": 5,
      "z": 3,
      "name": "Rock_Ledge_Brick_Smooth"
    },
    {
      "x": -5,
      "y": 6,
      "z": 3,
      "name": "Rock_Ledge_Brick_Smooth"
    },
    {
      "x": -5,
      "y": 7,
      "z": 3,
      "name": "Rock_Ledge_Brick_Smooth"
    },
    {
      "x": -5,
      "y": 0,
      "z": 4,
      "name": "Rock_Ledge_Brick"
    },
    {
      "x": -5,
      "y": 1,
      "z": 4,
      "name": "Rock_Ledge_Brick_Smooth"
    },
    {
      "x": -5,
      "y": 2,
      "z": 4,
      "name": "Rock_Ledge_Brick_Smooth"
    },
    {
      "x": -5,
      "y": 3,
      "z": 4,
      "name": "Rock_Ledge_Brick_Smooth"
    },
    {
      "x": -5,
      "y": 4,
      "z": 4,
      "name": "Rock_Ledge_Brick_Smooth"
    },
    {
      "x": -5,
      "y": 5,
      "z": 4,
      "name": "Rock_Ledge_Brick_Smooth"
    },
    {
      "x": -5,
      "y": 0,
      "z": 5,
      "name": "Rock_Ledge_Brick"
    },
    {
      "x": -5,
      "y": 1,
      "z": 5,
      "name": "Soil_Clay_Smooth_Black"
    },
    {
      "x": -5,
      "y": 2,
      "z": 5,
      "name": "Soil_Clay_Smooth_Black"
    },
    {
      "x": -5,
      "y": 3,
      "z": 5,
      "name": "Soil_Clay_Smooth_Black"
    },
    {
      "x": -5,
      "y": 4,
      "z": 5,
      "name": "Soil_Clay_Smooth_Black"
    },
    {
      "x": -5,
      "y": 0,
      "z": 6,
      "name": "Rock_Ledge_Brick"
    },
    {
      "x": -5,
      "y": 1,
      "z": 6,
      "name": "Deco_Iron_Bars"
    },
    {
      "x": -4,
      "y": 0,
      "z": -6,
      "name": "Rock_Ledge_Brick"
    },
    {
      "x": -4,
      "y": 5,
      "z": -6,
      "name": "Rock_Ledge_Brick_Smooth"
    },
    {
      "x": -4,
      "y": 0,
      "z": -5,
      "name": "Rock_Ledge_Brick"
    },
    {
      "x": -4,
      "y": 1,
      "z": -5,
      "name": "Rock_Ledge_Brick_Smooth"
    },
    {
      "x": -4,
      "y": 2,
      "z": -5,
      "name": "Rock_Ledge_Brick_Smooth"
    },
    {
      "x": -4,
      "y": 3,
      "z": -5,
      "name": "Rock_Ledge_Brick_Smooth"
    },
    {
      "x": -4,
      "y": 4,
      "z": -5,
      "name": "Rock_Ledge_Brick_Smooth"
    },
    {
      "x": -4,
      "y": 5,
      "z": -5,
      "name": "Rock_Ledge_Brick_Smooth"
    },
    {
      "x": -4,
      "y": 6,
      "z": -5,
      "name": "Rock_Ledge_Brick_Smooth"
    },
    {
      "x": -4,
      "y": 7,
      "z": -5,
      "name": "Rock_Ledge_Brick_Smooth"
    },
    {
      "x": -4,
      "y": 0,
      "z": -4,
      "name": "Rock_Ledge_Brick"
    },
    {
      "x": -4,
      "y": 1,
      "z": -4,
      "name": "Rock_Ledge_Brick_Smooth"
    },
    {
      "x": -4,
      "y": 2,
      "z": -4,
      "name": "Rock_Ledge_Brick_Smooth"
    },
    {
      "x": -4,
      "y": 3,
      "z": -4,
      "name": "Rock_Ledge_Brick_Smooth"
    },
    {
      "x": -4,
      "y": 4,
      "z": -4,
      "name": "Rock_Ledge_Brick_Smooth"
    },
    {
      "x": -4,
      "y": 5,
      "z": -4,
      "name": "Rock_Ledge_Brick_Smooth"
    },
    {
      "x": -4,
      "y": 6,
      "z": -4,
      "name": "Rock_Ledge_Brick_Smooth"
    },
    {
      "x": -4,
      "y": 7,
      "z": -4,
      "name": "Rock_Ledge_Brick_Smooth"
    },
    {
      "x": -4,
      "y": 0,
      "z": -3,
      "name": "Rock_Ledge_Brick"
    },
    {
      "x": -4,
      "y": 1,
      "z": -3,
      "name": "Cloth_Block_Wool_White"
    },
    {
      "x": -4,
      "y": 2,
      "z": -3,
      "name": "Cloth_Block_Wool_White"
    },
    {
      "x": -4,
      "y": 3,
      "z": -3,
      "name": "Cloth_Block_Wool_White"
    },
    {
      "x": -4,
      "y": 4,
      "z": -3,
      "name": "Rock_Marble_Brick_Smooth"
    },
    {
      "x": -4,
      "y": 5,
      "z": -3,
      "name": "Rock_Marble_Brick_Smooth"
    },
    {
      "x": -4,
      "y": 6,
      "z": -3,
      "name": "Rock_Marble_Brick_Smooth"
    },
    {
      "x": -4,
      "y": 7,
      "z": -3,
      "name": "Rock_Ledge_Brick_Smooth"
    },
    {
      "x": -4,
      "y": 0,
      "z": -2,
      "name": "Rock_Ledge_Brick"
    },
    {
      "x": -4,
      "y": 1,
      "z": -2,
      "name": "Cloth_Block_Wool_White"
    },
    {
      "x": -4,
      "y": 2,
      "z": -2,
      "name": "Cloth_Block_Wool_White"
    },
    {
      "x": -4,
      "y": 3,
      "z": -2,
      "name": "Cloth_Block_Wool_White"
    },
    {
      "x": -4,
      "y": 4,
      "z": -2,
      "name": "Rock_Marble_Brick_Smooth"
    },
    {
      "x": -4,
      "y": 5,
      "z": -2,
      "name": "Rock_Marble_Brick_Smooth"
    },
    {
      "x": -4,
      "y": 6,
      "z": -2,
      "name": "Rock_Marble_Brick_Smooth"
    },
    {
      "x": -4,
      "y": 7,
      "z": -2,
      "name": "Rock_Ledge_Brick_Smooth"
    },
    {
      "x": -4,
      "y": 0,
      "z": -1,
      "name": "Rock_Ledge_Brick"
    },
    {
      "x": -4,
      "y": 1,
      "z": -1,
      "name": "Cloth_Block_Wool_White"
    },
    {
      "x": -4,
      "y": 2,
      "z": -1,
      "name": "Cloth_Block_Wool_White"
    },
    {
      "x": -4,
      "y": 3,
      "z": -1,
      "name": "Cloth_Block_Wool_White"
    },
    {
      "x": -4,
      "y": 4,
      "z": -1,
      "name": "Rock_Marble_Brick_Smooth"
    },
    {
      "x": -4,
      "y": 5,
      "z": -1,
      "name": "Rock_Marble_Brick_Smooth"
    },
    {
      "x": -4,
      "y": 6,
      "z": -1,
      "name": "Rock_Marble_Brick_Smooth"
    },
    {
      "x": -4,
      "y": 7,
      "z": -1,
      "name": "Rock_Ledge_Brick_Smooth"
    },
    {
      "x": -4,
      "y": 0,
      "z": 0,
      "name": "Rock_Ledge_Brick"
    },
    {
      "x": -4,
      "y": 1,
      "z": 0,
      "name": "Cloth_Block_Wool_White"
    },
    {
      "x": -4,
      "y": 2,
      "z": 0,
      "name": "Cloth_Block_Wool_White"
    },
    {
      "x": -4,
      "y": 3,
      "z": 0,
      "name": "Cloth_Block_Wool_White"
    },
    {
      "x": -4,
      "y": 4,
      "z": 0,
      "name": "Rock_Marble_Brick_Smooth"
    },
    {
      "x": -4,
      "y": 5,
      "z": 0,
      "name": "Rock_Marble_Brick_Smooth"
    },
    {
      "x": -4,
      "y": 6,
      "z": 0,
      "name": "Rock_Marble_Brick_Smooth"
    },
    {
      "x": -4,
      "y": 7,
      "z": 0,
      "name": "Rock_Ledge_Brick_Smooth"
    },
    {
      "x": -4,
      "y": 0,
      "z": 1,
      "name": "Rock_Ledge_Brick"
    },
    {
      "x": -4,
      "y": 1,
      "z": 1,
      "name": "Cloth_Block_Wool_White"
    },
    {
      "x": -4,
      "y": 2,
      "z": 1,
      "name": "Cloth_Block_Wool_White"
    },
    {
      "x": -4,
      "y": 3,
      "z": 1,
      "name": "Cloth_Block_Wool_White"
    },
    {
      "x": -4,
      "y": 4,
      "z": 1,
      "name": "Rock_Marble_Brick_Smooth"
    },
    {
      "x": -4,
      "y": 5,
      "z": 1,
      "name": "Rock_Marble_Brick_Smooth"
    },
    {
      "x": -4,
      "y": 6,
      "z": 1,
      "name": "Rock_Marble_Brick_Smooth"
    },
    {
      "x": -4,
      "y": 7,
      "z": 1,
      "name": "Rock_Ledge_Brick_Smooth"
    },
    {
      "x": -4,
      "y": 0,
      "z": 2,
      "name": "Rock_Ledge_Brick"
    },
    {
      "x": -4,
      "y": 1,
      "z": 2,
      "name": "Cloth_Block_Wool_White"
    },
    {
      "x": -4,
      "y": 2,
      "z": 2,
      "name": "Cloth_Block_Wool_White"
    },
    {
      "x": -4,
      "y": 3,
      "z": 2,
      "name": "Cloth_Block_Wool_White"
    },
    {
      "x": -4,
      "y": 4,
      "z": 2,
      "name": "Rock_Marble_Brick_Smooth"
    },
    {
      "x": -4,
      "y": 5,
      "z": 2,
      "name": "Rock_Marble_Brick_Smooth"
    },
    {
      "x": -4,
      "y": 6,
      "z": 2,
      "name": "Rock_Ledge_Brick_Smooth"
    },
    {
      "x": -4,
      "y": 7,
      "z": 2,
      "name": "Rock_Ledge_Brick_Smooth"
    },
    {
      "x": -4,
      "y": 0,
      "z": 3,
      "name": "Rock_Ledge_Brick"
    },
    {
      "x": -4,
      "y": 1,
      "z": 3,
      "name": "Cloth_Block_Wool_White"
    },
    {
      "x": -4,
      "y": 2,
      "z": 3,
      "name": "Cloth_Block_Wool_White"
    },
    {
      "x": -4,
      "y": 3,
      "z": 3,
      "name": "Cloth_Block_Wool_White"
    },
    {
      "x": -4,
      "y": 4,
      "z": 3,
      "name": "Rock_Marble_Brick_Smooth"
    },
    {
      "x": -4,
      "y": 5,
      "z": 3,
      "name": "Rock_Marble_Brick_Smooth"
    },
    {
      "x": -4,
      "y": 6,
      "z": 3,
      "name": "Rock_Ledge_Brick_Smooth"
    },
    {
      "x": -4,
      "y": 7,
      "z": 3,
      "name": "Rock_Ledge_Brick_Smooth"
    },
    {
      "x": -4,
      "y": 0,
      "z": 4,
      "name": "Rock_Ledge_Brick"
    },
    {
      "x": -4,
      "y": 1,
      "z": 4,
      "name": "Rock_Ledge_Brick_Smooth"
    },
    {
      "x": -4,
      "y": 2,
      "z": 4,
      "name": "Rock_Ledge_Brick_Smooth"
    },
    {
      "x": -4,
      "y": 3,
      "z": 4,
      "name": "Rock_Ledge_Brick_Smooth"
    },
    {
      "x": -4,
      "y": 4,
      "z": 4,
      "name": "Rock_Ledge_Brick_Smooth"
    },
    {
      "x": -4,
      "y": 5,
      "z": 4,
      "name": "Rock_Ledge_Brick_Smooth"
    },
    {
      "x": -4,
      "y": 0,
      "z": 5,
      "name": "Rock_Ledge_Brick"
    },
    {
      "x": -4,
      "y": 1,
      "z": 5,
      "name": "Soil_Clay_Smooth_Black"
    },
    {
      "x": -4,
      "y": 2,
      "z": 5,
      "name": "PinkLED"
    },
    {
      "x": -4,
      "y": 3,
      "z": 5,
      "name": "PinkLED"
    },
    {
      "x": -4,
      "y": 4,
      "z": 5,
      "name": "Soil_Clay_Smooth_Black"
    },
    {
      "x": -4,
      "y": 0,
      "z": 6,
      "name": "Rock_Ledge_Brick"
    },
    {
      "x": -4,
      "y": 1,
      "z": 6,
      "name": "Deco_Iron_Bars"
    },
    {
      "x": -3,
      "y": 0,
      "z": -6,
      "name": "Rock_Ledge_Brick"
    },
    {
      "x": -3,
      "y": 5,
      "z": -6,
      "name": "Rock_Ledge_Brick_Smooth"
    },
    {
      "x": -3,
      "y": 0,
      "z": -5,
      "name": "Rock_Ledge_Brick"
    },
    {
      "x": -3,
      "y": 1,
      "z": -5,
      "name": "*Furniture_Robot_Door_State_Definitions_CloseDoorOut"
    },
    {
      "x": -3,
      "y": 2,
      "z": -5,
      "name": "*Furniture_Robot_Door_State_Definitions_CloseDoorOut",
      "filler": 1024
    },
    {
      "x": -3,
      "y": 3,
      "z": -5,
      "name": "Rock_Ledge_Brick_Smooth"
    },
    {
      "x": -3,
      "y": 4,
      "z": -5,
      "name": "Rock_Ledge_Brick_Smooth"
    },
    {
      "x": -3,
      "y": 5,
      "z": -5,
      "name": "Rock_Ledge_Brick_Smooth"
    },
    {
      "x": -3,
      "y": 6,
      "z": -5,
      "name": "Rock_Ledge_Brick_Smooth"
    },
    {
      "x": -3,
      "y": 7,
      "z": -5,
      "name": "Rock_Ledge_Brick_Smooth"
    },
    {
      "x": -3,
      "y": 0,
      "z": -4,
      "name": "Rock_Ledge_Brick"
    },
    {
      "x": -3,
      "y": 3,
      "z": -4,
      "name": "Cloth_Block_Wool_White"
    },
    {
      "x": -3,
      "y": 4,
      "z": -4,
      "name": "Rock_Marble_Brick_Smooth"
    },
    {
      "x": -3,
      "y": 5,
      "z": -4,
      "name": "Rock_Ledge_Brick_Smooth"
    },
    {
      "x": -3,
      "y": 6,
      "z": -4,
      "name": "Rock_Ledge_Brick_Smooth"
    },
    {
      "x": -3,
      "y": 7,
      "z": -4,
      "name": "Rock_Ledge_Brick_Smooth"
    },
    {
      "x": -3,
      "y": 0,
      "z": -3,
      "name": "Rock_Ledge_Brick"
    },
    {
      "x": -3,
      "y": 4,
      "z": -3,
      "name": "Rock_Marble_Brick_Smooth"
    },
    {
      "x": -3,
      "y": 5,
      "z": -3,
      "name": "Rock_Marble_Brick_Smooth"
    },
    {
      "x": -3,
      "y": 6,
      "z": -3,
      "name": "Rock_Marble_Brick_Smooth"
    },
    {
      "x": -3,
      "y": 7,
      "z": -3,
      "name": "Rock_Ledge_Brick_Smooth"
    },
    {
      "x": -3,
      "y": 0,
      "z": -2,
      "name": "Rock_Ledge_Brick"
    },
    {
      "x": -3,
      "y": 4,
      "z": -2,
      "name": "Rock_Marble_Brick_Smooth"
    },
    {
      "x": -3,
      "y": 7,
      "z": -2,
      "name": "Rock_Ledge_Brick_Smooth"
    },
    {
      "x": -3,
      "y": 0,
      "z": -1,
      "name": "Rock_Ledge_Brick"
    },
    {
      "x": -3,
      "y": 4,
      "z": -1,
      "name": "Rock_Marble_Brick_Smooth"
    },
    {
      "x": -3,
      "y": 7,
      "z": -1,
      "name": "Rock_Ledge_Brick_Smooth"
    },
    {
      "x": -3,
      "y": 0,
      "z": 0,
      "name": "Rock_Ledge_Brick"
    },
    {
      "x": -3,
      "y": 4,
      "z": 0,
      "name": "Rock_Marble_Brick_Smooth"
    },
    {
      "x": -3,
      "y": 5,
      "z": 0,
      "name": "Block_Spawner_Block",
      "components": {
        "Components": {
          "PlacedByInteraction": {
            "WhoPlacedUuid": {
              "$binary": "L6LzkYSjQOWrksT02Y12sg==",
              "$type": "04"
            }
          },
          "BlockSpawner": {
            "BlockSpawnerId": "RobotCity"
          }
        }
      },
      "rotation": 1
    },
    {
      "x": -3,
      "y": 7,
      "z": 0,
      "name": "Rock_Ledge_Brick_Smooth"
    },
    {
      "x": -3,
      "y": 0,
      "z": 1,
      "name": "Rock_Ledge_Brick"
    },
    {
      "x": -3,
      "y": 1,
      "z": 1,
      "name": "Rock_Marble_Brick_Smooth"
    },
    {
      "x": -3,
      "y": 2,
      "z": 1,
      "name": "Deco_Treasure",
      "rotation": 1
    },
    {
      "x": -3,
      "y": 4,
      "z": 1,
      "name": "Rock_Marble_Brick_Smooth"
    },
    {
      "x": -3,
      "y": 7,
      "z": 1,
      "name": "Rock_Ledge_Brick_Smooth"
    },
    {
      "x": -3,
      "y": 0,
      "z": 2,
      "name": "Rock_Ledge_Brick"
    },
    {
      "x": -3,
      "y": 3,
      "z": 2,
      "name": "Furniture_Temple_Light_Shelf",
      "rotation": 2
    },
    {
      "x": -3,
      "y": 4,
      "z": 2,
      "name": "BlueLED"
    },
    {
      "x": -3,
      "y": 5,
      "z": 2,
      "name": "Rock_Marble_Brick_Smooth"
    },
    {
      "x": -3,
      "y": 6,
      "z": 2,
      "name": "Rock_Marble_Brick_Smooth"
    },
    {
      "x": -3,
      "y": 7,
      "z": 2,
      "name": "Rock_Ledge_Brick_Smooth"
    },
    {
      "x": -3,
      "y": 0,
      "z": 3,
      "name": "Rock_Ledge_Brick"
    },
    {
      "x": -3,
      "y": 1,
      "z": 3,
      "name": "Cloth_Block_Wool_White"
    },
    {
      "x": -3,
      "y": 2,
      "z": 3,
      "name": "Cloth_Block_Wool_White"
    },
    {
      "x": -3,
      "y": 3,
      "z": 3,
      "name": "Cloth_Block_Wool_White"
    },
    {
      "x": -3,
      "y": 4,
      "z": 3,
      "name": "Rock_Marble_Brick_Smooth"
    },
    {
      "x": -3,
      "y": 5,
      "z": 3,
      "name": "Rock_Marble_Brick_Smooth"
    },
    {
      "x": -3,
      "y": 6,
      "z": 3,
      "name": "Rock_Ledge_Brick_Smooth"
    },
    {
      "x": -3,
      "y": 7,
      "z": 3,
      "name": "Rock_Ledge_Brick_Smooth"
    },
    {
      "x": -3,
      "y": 0,
      "z": 4,
      "name": "Rock_Ledge_Brick"
    },
    {
      "x": -3,
      "y": 1,
      "z": 4,
      "name": "Rock_Ledge_Brick_Smooth"
    },
    {
      "x": -3,
      "y": 2,
      "z": 4,
      "name": "Rock_Ledge_Brick_Smooth"
    },
    {
      "x": -3,
      "y": 3,
      "z": 4,
      "name": "Rock_Ledge_Brick_Smooth"
    },
    {
      "x": -3,
      "y": 4,
      "z": 4,
      "name": "Rock_Ledge_Brick_Smooth"
    },
    {
      "x": -3,
      "y": 5,
      "z": 4,
      "name": "Rock_Ledge_Brick_Smooth"
    },
    {
      "x": -3,
      "y": 0,
      "z": 5,
      "name": "Rock_Ledge_Brick"
    },
    {
      "x": -3,
      "y": 1,
      "z": 5,
      "name": "Soil_Clay_Smooth_Black"
    },
    {
      "x": -3,
      "y": 2,
      "z": 5,
      "name": "PinkLED"
    },
    {
      "x": -3,
      "y": 3,
      "z": 5,
      "name": "PinkLED"
    },
    {
      "x": -3,
      "y": 4,
      "z": 5,
      "name": "Soil_Clay_Smooth_Black"
    },
    {
      "x": -3,
      "y": 0,
      "z": 6,
      "name": "Rock_Ledge_Brick"
    },
    {
      "x": -3,
      "y": 1,
      "z": 6,
      "name": "Deco_Iron_Bars"
    },
    {
      "x": -2,
      "y": 0,
      "z": -6,
      "name": "Rock_Ledge_Brick"
    },
    {
      "x": -2,
      "y": 5,
      "z": -6,
      "name": "Rock_Ledge_Brick_Smooth"
    },
    {
      "x": -2,
      "y": 0,
      "z": -5,
      "name": "Rock_Ledge_Brick"
    },
    {
      "x": -2,
      "y": 1,
      "z": -5,
      "name": "*Furniture_Robot_Door_State_Definitions_CloseDoorIn",
      "rotation": 2
    },
    {
      "x": -2,
      "y": 2,
      "z": -5,
      "name": "*Furniture_Robot_Door_State_Definitions_CloseDoorIn",
      "filler": 1024,
      "rotation": 2
    },
    {
      "x": -2,
      "y": 3,
      "z": -5,
      "name": "Rock_Ledge_Brick_Smooth"
    },
    {
      "x": -2,
      "y": 4,
      "z": -5,
      "name": "Rock_Ledge_Brick_Smooth"
    },
    {
      "x": -2,
      "y": 5,
      "z": -5,
      "name": "Rock_Ledge_Brick_Smooth"
    },
    {
      "x": -2,
      "y": 6,
      "z": -5,
      "name": "Rock_Ledge_Brick_Smooth"
    },
    {
      "x": -2,
      "y": 7,
      "z": -5,
      "name": "Rock_Ledge_Brick_Smooth"
    },
    {
      "x": -2,
      "y": 0,
      "z": -4,
      "name": "Rock_Ledge_Brick"
    },
    {
      "x": -2,
      "y": 3,
      "z": -4,
      "name": "Cloth_Block_Wool_White"
    },
    {
      "x": -2,
      "y": 4,
      "z": -4,
      "name": "Rock_Marble_Brick_Smooth"
    },
    {
      "x": -2,
      "y": 5,
      "z": -4,
      "name": "Rock_Marble_Brick_Smooth"
    },
    {
      "x": -2,
      "y": 6,
      "z": -4,
      "name": "Rock_Marble_Brick_Smooth"
    },
    {
      "x": -2,
      "y": 7,
      "z": -4,
      "name": "Rock_Ledge_Brick_Smooth"
    },
    {
      "x": -2,
      "y": 0,
      "z": -3,
      "name": "Rock_Ledge_Brick"
    },
    {
      "x": -2,
      "y": 4,
      "z": -3,
      "name": "Rock_Marble_Brick_Smooth"
    },
    {
      "x": -2,
      "y": 5,
      "z": -3,
      "name": "Rock_Marble_Brick_Smooth"
    },
    {
      "x": -2,
      "y": 6,
      "z": -3,
      "name": "Rock_Marble_Brick_Smooth"
    },
    {
      "x": -2,
      "y": 7,
      "z": -3,
      "name": "Rock_Ledge_Brick_Smooth"
    },
    {
      "x": -2,
      "y": 0,
      "z": -2,
      "name": "Rock_Ledge_Brick"
    },
    {
      "x": -2,
      "y": 4,
      "z": -2,
      "name": "Rock_Marble_Brick_Smooth"
    },
    {
      "x": -2,
      "y": 7,
      "z": -2,
      "name": "Rock_Ledge_Brick_Smooth"
    },
    {
      "x": -2,
      "y": 0,
      "z": -1,
      "name": "Rock_Ledge_Brick"
    },
    {
      "x": -2,
      "y": 4,
      "z": -1,
      "name": "Rock_Marble_Brick_Smooth"
    },
    {
      "x": -2,
      "y": 7,
      "z": -1,
      "name": "Rock_Ledge_Brick_Smooth"
    },
    {
      "x": -2,
      "y": 0,
      "z": 0,
      "name": "Rock_Ledge_Brick"
    },
    {
      "x": -2,
      "y": 4,
      "z": 0,
      "name": "Rock_Marble_Brick_Smooth"
    },
    {
      "x": -2,
      "y": 7,
      "z": 0,
      "name": "Rock_Ledge_Brick_Smooth"
    },
    {
      "x": -2,
      "y": 0,
      "z": 1,
      "name": "Rock_Ledge_Brick"
    },
    {
      "x": -2,
      "y": 1,
      "z": 1,
      "name": "Rock_Marble_Brick_Smooth"
    },
    {
      "x": -2,
      "y": 4,
      "z": 1,
      "name": "Rock_Marble_Brick_Smooth"
    },
    {
      "x": -2,
      "y": 7,
      "z": 1,
      "name": "Rock_Ledge_Brick_Smooth"
    },
    {
      "x": -2,
      "y": 0,
      "z": 2,
      "name": "Rock_Ledge_Brick"
    },
    {
      "x": -2,
      "y": 1,
      "z": 2,
      "name": "Furniture_Temple_Light_Stool",
      "components": {
        "Components": {}
      },
      "rotation": 2
    },
    {
      "x": -2,
      "y": 3,
      "z": 2,
      "name": "Furniture_Temple_Light_Shelf",
      "rotation": 2
    },
    {
      "x": -2,
      "y": 4,
      "z": 2,
      "name": "BlueLED"
    },
    {
      "x": -2,
      "y": 5,
      "z": 2,
      "name": "Rock_Marble_Brick_Smooth"
    },
    {
      "x": -2,
      "y": 6,
      "z": 2,
      "name": "Rock_Marble_Brick_Smooth"
    },
    {
      "x": -2,
      "y": 7,
      "z": 2,
      "name": "Rock_Ledge_Brick_Smooth"
    },
    {
      "x": -2,
      "y": 0,
      "z": 3,
      "name": "Rock_Ledge_Brick"
    },
    {
      "x": -2,
      "y": 1,
      "z": 3,
      "name": "Cloth_Block_Wool_White"
    },
    {
      "x": -2,
      "y": 2,
      "z": 3,
      "name": "Cloth_Block_Wool_White"
    },
    {
      "x": -2,
      "y": 3,
      "z": 3,
      "name": "Cloth_Block_Wool_White"
    },
    {
      "x": -2,
      "y": 4,
      "z": 3,
      "name": "Rock_Marble_Brick_Smooth"
    },
    {
      "x": -2,
      "y": 5,
      "z": 3,
      "name": "Rock_Marble_Brick_Smooth"
    },
    {
      "x": -2,
      "y": 6,
      "z": 3,
      "name": "Rock_Ledge_Brick_Smooth"
    },
    {
      "x": -2,
      "y": 7,
      "z": 3,
      "name": "Rock_Ledge_Brick_Smooth"
    },
    {
      "x": -2,
      "y": 0,
      "z": 4,
      "name": "Rock_Ledge_Brick"
    },
    {
      "x": -2,
      "y": 1,
      "z": 4,
      "name": "Rock_Ledge_Brick_Smooth"
    },
    {
      "x": -2,
      "y": 2,
      "z": 4,
      "name": "Rock_Ledge_Brick_Smooth"
    },
    {
      "x": -2,
      "y": 3,
      "z": 4,
      "name": "Rock_Ledge_Brick_Smooth"
    },
    {
      "x": -2,
      "y": 4,
      "z": 4,
      "name": "Rock_Ledge_Brick_Smooth"
    },
    {
      "x": -2,
      "y": 5,
      "z": 4,
      "name": "Rock_Ledge_Brick_Smooth"
    },
    {
      "x": -2,
      "y": 0,
      "z": 5,
      "name": "Rock_Ledge_Brick"
    },
    {
      "x": -2,
      "y": 1,
      "z": 5,
      "name": "Soil_Clay_Smooth_Black"
    },
    {
      "x": -2,
      "y": 2,
      "z": 5,
      "name": "PinkLED"
    },
    {
      "x": -2,
      "y": 3,
      "z": 5,
      "name": "PinkLED"
    },
    {
      "x": -2,
      "y": 4,
      "z": 5,
      "name": "Soil_Clay_Smooth_Black"
    },
    {
      "x": -2,
      "y": 0,
      "z": 6,
      "name": "Rock_Ledge_Brick"
    },
    {
      "x": -2,
      "y": 1,
      "z": 6,
      "name": "Deco_Iron_Bars"
    },
    {
      "x": -1,
      "y": 0,
      "z": -6,
      "name": "Rock_Ledge_Brick"
    },
    {
      "x": -1,
      "y": 5,
      "z": -6,
      "name": "Rock_Ledge_Brick_Smooth"
    },
    {
      "x": -1,
      "y": 0,
      "z": -5,
      "name": "Rock_Ledge_Brick"
    },
    {
      "x": -1,
      "y": 1,
      "z": -5,
      "name": "Rock_Ledge_Brick_Smooth"
    },
    {
      "x": -1,
      "y": 2,
      "z": -5,
      "name": "Rock_Ledge_Brick_Smooth"
    },
    {
      "x": -1,
      "y": 3,
      "z": -5,
      "name": "Rock_Ledge_Brick_Smooth"
    },
    {
      "x": -1,
      "y": 4,
      "z": -5,
      "name": "Rock_Ledge_Brick_Smooth"
    },
    {
      "x": -1,
      "y": 5,
      "z": -5,
      "name": "Rock_Ledge_Brick_Smooth"
    },
    {
      "x": -1,
      "y": 6,
      "z": -5,
      "name": "Rock_Ledge_Brick_Smooth"
    },
    {
      "x": -1,
      "y": 7,
      "z": -5,
      "name": "Rock_Ledge_Brick_Smooth"
    },
    {
      "x": -1,
      "y": 0,
      "z": -4,
      "name": "Rock_Ledge_Brick"
    },
    {
      "x": -1,
      "y": 1,
      "z": -4,
      "name": "Cloth_Block_Wool_White"
    },
    {
      "x": -1,
      "y": 2,
      "z": -4,
      "name": "Cloth_Block_Wool_White"
    },
    {
      "x": -1,
      "y": 3,
      "z": -4,
      "name": "Cloth_Block_Wool_White"
    },
    {
      "x": -1,
      "y": 4,
      "z": -4,
      "name": "Rock_Marble_Brick_Smooth"
    },
    {
      "x": -1,
      "y": 5,
      "z": -4,
      "name": "Rock_Marble_Brick_Smooth"
    },
    {
      "x": -1,
      "y": 6,
      "z": -4,
      "name": "Rock_Marble_Brick_Smooth"
    },
    {
      "x": -1,
      "y": 7,
      "z": -4,
      "name": "Rock_Ledge_Brick_Smooth"
    },
    {
      "x": -1,
      "y": 0,
      "z": -3,
      "name": "Rock_Ledge_Brick"
    },
    {
      "x": -1,
      "y": 1,
      "z": -3,
      "name": "Rock_Ledge_Brick_Wall",
      "rotation": 1
    },
    {
      "x": -1,
      "y": 2,
      "z": -3,
      "name": "Rock_Ledge_Brick_Wall",
      "rotation": 1
    },
    {
      "x": -1,
      "y": 3,
      "z": -3,
      "name": "Rock_Ledge_Brick_Wall",
      "rotation": 1
    },
    {
      "x": -1,
      "y": 4,
      "z": -3,
      "name": "Rock_Marble_Brick_Smooth"
    },
    {
      "x": -1,
      "y": 5,
      "z": -3,
      "name": "Rock_Marble_Brick_Smooth"
    },
    {
      "x": -1,
      "y": 6,
      "z": -3,
      "name": "Rock_Marble_Brick_Smooth"
    },
    {
      "x": -1,
      "y": 7,
      "z": -3,
      "name": "Rock_Ledge_Brick_Smooth"
    },
    {
      "x": -1,
      "y": 0,
      "z": -2,
      "name": "Rock_Ledge_Brick"
    },
    {
      "x": -1,
      "y": 1,
      "z": -2,
      "name": "Rock_Ledge_Brick_Wall",
      "rotation": 1
    },
    {
      "x": -1,
      "y": 2,
      "z": -2,
      "name": "Rock_Ledge_Brick_Wall",
      "rotation": 1
    },
    {
      "x": -1,
      "y": 3,
      "z": -2,
      "name": "Rock_Ledge_Brick_Wall",
      "rotation": 1
    },
    {
      "x": -1,
      "y": 4,
      "z": -2,
      "name": "Rock_Marble_Brick_Smooth"
    },
    {
      "x": -1,
      "y": 7,
      "z": -2,
      "name": "Rock_Ledge_Brick_Smooth"
    },
    {
      "x": -1,
      "y": 0,
      "z": -1,
      "name": "Rock_Ledge_Brick"
    },
    {
      "x": -1,
      "y": 4,
      "z": -1,
      "name": "Rock_Marble_Brick_Smooth"
    },
    {
      "x": -1,
      "y": 7,
      "z": -1,
      "name": "Rock_Ledge_Brick_Smooth"
    },
    {
      "x": -1,
      "y": 0,
      "z": 0,
      "name": "Rock_Ledge_Brick"
    },
    {
      "x": -1,
      "y": 4,
      "z": 0,
      "name": "Rock_Marble_Brick_Smooth"
    },
    {
      "x": -1,
      "y": 7,
      "z": 0,
      "name": "Rock_Ledge_Brick_Smooth"
    },
    {
      "x": -1,
      "y": 0,
      "z": 1,
      "name": "Rock_Ledge_Brick"
    },
    {
      "x": -1,
      "y": 1,
      "z": 1,
      "name": "*Furniture_Temple_Light_Trapdoor_State_Definitions_OpenDoorOut",
      "rotation": 3
    },
    {
      "x": -1,
      "y": 4,
      "z": 1,
      "name": "Rock_Marble_Brick_Smooth"
    },
    {
      "x": -1,
      "y": 7,
      "z": 1,
      "name": "Rock_Ledge_Brick_Smooth"
    },
    {
      "x": -1,
      "y": 0,
      "z": 2,
      "name": "Rock_Ledge_Brick"
    },
    {
      "x": -1,
      "y": 3,
      "z": 2,
      "name": "Furniture_Temple_Light_Shelf",
      "rotation": 2
    },
    {
      "x": -1,
      "y": 4,
      "z": 2,
      "name": "BlueLED"
    },
    {
      "x": -1,
      "y": 5,
      "z": 2,
      "name": "Rock_Marble_Brick_Smooth"
    },
    {
      "x": -1,
      "y": 6,
      "z": 2,
      "name": "Rock_Marble_Brick_Smooth"
    },
    {
      "x": -1,
      "y": 7,
      "z": 2,
      "name": "Rock_Ledge_Brick_Smooth"
    },
    {
      "x": -1,
      "y": 0,
      "z": 3,
      "name": "Rock_Ledge_Brick"
    },
    {
      "x": -1,
      "y": 1,
      "z": 3,
      "name": "Cloth_Block_Wool_White"
    },
    {
      "x": -1,
      "y": 2,
      "z": 3,
      "name": "Cloth_Block_Wool_White"
    },
    {
      "x": -1,
      "y": 3,
      "z": 3,
      "name": "Cloth_Block_Wool_White"
    },
    {
      "x": -1,
      "y": 4,
      "z": 3,
      "name": "Rock_Marble_Brick_Smooth"
    },
    {
      "x": -1,
      "y": 5,
      "z": 3,
      "name": "Rock_Marble_Brick_Smooth"
    },
    {
      "x": -1,
      "y": 6,
      "z": 3,
      "name": "Rock_Ledge_Brick_Smooth"
    },
    {
      "x": -1,
      "y": 7,
      "z": 3,
      "name": "Rock_Ledge_Brick_Smooth"
    },
    {
      "x": -1,
      "y": 0,
      "z": 4,
      "name": "Rock_Ledge_Brick"
    },
    {
      "x": -1,
      "y": 1,
      "z": 4,
      "name": "Rock_Ledge_Brick_Smooth"
    },
    {
      "x": -1,
      "y": 2,
      "z": 4,
      "name": "Rock_Ledge_Brick_Smooth"
    },
    {
      "x": -1,
      "y": 3,
      "z": 4,
      "name": "Rock_Ledge_Brick_Smooth"
    },
    {
      "x": -1,
      "y": 4,
      "z": 4,
      "name": "Rock_Ledge_Brick_Smooth"
    },
    {
      "x": -1,
      "y": 5,
      "z": 4,
      "name": "Rock_Ledge_Brick_Smooth"
    },
    {
      "x": -1,
      "y": 0,
      "z": 5,
      "name": "Rock_Ledge_Brick"
    },
    {
      "x": -1,
      "y": 1,
      "z": 5,
      "name": "Soil_Clay_Smooth_Black"
    },
    {
      "x": -1,
      "y": 2,
      "z": 5,
      "name": "PinkLED"
    },
    {
      "x": -1,
      "y": 3,
      "z": 5,
      "name": "PinkLED"
    },
    {
      "x": -1,
      "y": 4,
      "z": 5,
      "name": "Soil_Clay_Smooth_Black"
    },
    {
      "x": -1,
      "y": 0,
      "z": 6,
      "name": "Rock_Ledge_Brick"
    },
    {
      "x": -1,
      "y": 1,
      "z": 6,
      "name": "Deco_Iron_Bars"
    },
    {
      "x": 0,
      "y": 0,
      "z": -6,
      "name": "Rock_Ledge_Brick"
    },
    {
      "x": 0,
      "y": 1,
      "z": -6,
      "name": "Soil_Clay_Smooth_Black"
    },
    {
      "x": 0,
      "y": 2,
      "z": -6,
      "name": "Soil_Clay_Smooth_Black"
    },
    {
      "x": 0,
      "y": 3,
      "z": -6,
      "name": "Soil_Clay_Smooth_Black"
    },
    {
      "x": 0,
      "y": 4,
      "z": -6,
      "name": "Soil_Clay_Smooth_Black"
    },
    {
      "x": 0,
      "y": 5,
      "z": -6,
      "name": "Soil_Clay_Smooth_Black"
    },
    {
      "x": 0,
      "y": 6,
      "z": -6,
      "name": "Soil_Clay_Smooth_Black"
    },
    {
      "x": 0,
      "y": 7,
      "z": -6,
      "name": "Soil_Clay_Smooth_Black"
    },
    {
      "x": 0,
      "y": 0,
      "z": -5,
      "name": "Rock_Ledge_Brick"
    },
    {
      "x": 0,
      "y": 1,
      "z": -5,
      "name": "Rock_Ledge_Brick_Smooth"
    },
    {
      "x": 0,
      "y": 2,
      "z": -5,
      "name": "Rock_Marble_Brick_Smooth"
    },
    {
      "x": 0,
      "y": 3,
      "z": -5,
      "name": "Rock_Marble_Brick_Smooth"
    },
    {
      "x": 0,
      "y": 4,
      "z": -5,
      "name": "Rock_Marble_Brick_Smooth"
    },
    {
      "x": 0,
      "y": 5,
      "z": -5,
      "name": "Rock_Marble_Brick_Smooth"
    },
    {
      "x": 0,
      "y": 6,
      "z": -5,
      "name": "Rock_Marble_Brick_Smooth"
    },
    {
      "x": 0,
      "y": 7,
      "z": -5,
      "name": "Soil_Clay_Smooth_Black"
    },
    {
      "x": 0,
      "y": 0,
      "z": -4,
      "name": "Rock_Ledge_Brick"
    },
    {
      "x": 0,
      "y": 1,
      "z": -4,
      "name": "Cloth_Block_Wool_White"
    },
    {
      "x": 0,
      "y": 2,
      "z": -4,
      "name": "Cloth_Block_Wool_White"
    },
    {
      "x": 0,
      "y": 3,
      "z": -4,
      "name": "Cloth_Block_Wool_White"
    },
    {
      "x": 0,
      "y": 4,
      "z": -4,
      "name": "Rock_Marble_Brick_Smooth"
    },
    {
      "x": 0,
      "y": 5,
      "z": -4,
      "name": "Rock_Marble_Brick_Smooth"
    },
    {
      "x": 0,
      "y": 6,
      "z": -4,
      "name": "Rock_Marble_Brick_Smooth"
    },
    {
      "x": 0,
      "y": 7,
      "z": -4,
      "name": "Soil_Clay_Smooth_Black"
    },
    {
      "x": 0,
      "y": 0,
      "z": -3,
      "name": "Rock_Ledge_Brick"
    },
    {
      "x": 0,
      "y": 1,
      "z": -3,
      "name": "Furniture_Temple_Light_Bench",
      "rotation": 1
    },
    {
      "x": 0,
      "y": 3,
      "z": -3,
      "name": "Furniture_Temple_Light_Shelf"
    },
    {
      "x": 0,
      "y": 4,
      "z": -3,
      "name": "BlueLED"
    },
    {
      "x": 0,
      "y": 5,
      "z": -3,
      "name": "Rock_Marble_Brick_Smooth"
    },
    {
      "x": 0,
      "y": 6,
      "z": -3,
      "name": "Rock_Marble_Brick_Smooth"
    },
    {
      "x": 0,
      "y": 7,
      "z": -3,
      "name": "Soil_Clay_Smooth_Black"
    },
    {
      "x": 0,
      "y": 0,
      "z": -2,
      "name": "Rock_Ledge_Brick"
    },
    {
      "x": 0,
      "y": 1,
      "z": -2,
      "name": "Furniture_Temple_Light_Bench",
      "filler": 32,
      "rotation": 1
    },
    {
      "x": 0,
      "y": 4,
      "z": -2,
      "name": "Rock_Marble_Brick_Smooth"
    },
    {
      "x": 0,
      "y": 5,
      "z": -2,
      "name": "Block_Spawner_Block",
      "components": {
        "Components": {
          "PlacedByInteraction": {
            "WhoPlacedUuid": {
              "$binary": "L6LzkYSjQOWrksT02Y12sg==",
              "$type": "04"
            }
          },
          "BlockSpawner": {
            "BlockSpawnerId": "RobotCity"
          }
        }
      }
    },
    {
      "x": 0,
      "y": 7,
      "z": -2,
      "name": "Soil_Clay_Smooth_Black"
    },
    {
      "x": 0,
      "y": 0,
      "z": -1,
      "name": "Rock_Ledge_Brick"
    },
    {
      "x": 0,
      "y": 4,
      "z": -1,
      "name": "Rock_Marble_Brick_Smooth"
    },
    {
      "x": 0,
      "y": 7,
      "z": -1,
      "name": "Rock_Ledge_Brick_Smooth"
    },
    {
      "x": 0,
      "y": 0,
      "z": 0,
      "name": "Rock_Ledge_Brick"
    },
    {
      "x": 0,
      "y": 4,
      "z": 0,
      "name": "Rock_Marble_Brick_Smooth"
    },
    {
      "x": 0,
      "y": 7,
      "z": 0,
      "name": "Rock_Ledge_Brick_Smooth"
    },
    {
      "x": 0,
      "y": 0,
      "z": 1,
      "name": "Rock_Ledge_Brick"
    },
    {
      "x": 0,
      "y": 1,
      "z": 1,
      "name": "Cloth_Block_Wool_White"
    },
    {
      "x": 0,
      "y": 2,
      "z": 1,
      "name": "Cloth_Block_Wool_White"
    },
    {
      "x": 0,
      "y": 3,
      "z": 1,
      "name": "Cloth_Block_Wool_White"
    },
    {
      "x": 0,
      "y": 4,
      "z": 1,
      "name": "Rock_Marble_Brick_Smooth"
    },
    {
      "x": 0,
      "y": 7,
      "z": 1,
      "name": "Rock_Ledge_Brick_Smooth"
    },
    {
      "x": 0,
      "y": 0,
      "z": 2,
      "name": "Rock_Ledge_Brick"
    },
    {
      "x": 0,
      "y": 1,
      "z": 2,
      "name": "Cloth_Block_Wool_White"
    },
    {
      "x": 0,
      "y": 2,
      "z": 2,
      "name": "Cloth_Block_Wool_White"
    },
    {
      "x": 0,
      "y": 3,
      "z": 2,
      "name": "Cloth_Block_Wool_White"
    },
    {
      "x": 0,
      "y": 4,
      "z": 2,
      "name": "Rock_Marble_Brick_Smooth"
    },
    {
      "x": 0,
      "y": 5,
      "z": 2,
      "name": "Rock_Marble_Brick_Smooth"
    },
    {
      "x": 0,
      "y": 6,
      "z": 2,
      "name": "Rock_Marble_Brick_Smooth"
    },
    {
      "x": 0,
      "y": 7,
      "z": 2,
      "name": "Rock_Ledge_Brick_Smooth"
    },
    {
      "x": 0,
      "y": 0,
      "z": 3,
      "name": "Rock_Ledge_Brick"
    },
    {
      "x": 0,
      "y": 1,
      "z": 3,
      "name": "Cloth_Block_Wool_White"
    },
    {
      "x": 0,
      "y": 2,
      "z": 3,
      "name": "Cloth_Block_Wool_White"
    },
    {
      "x": 0,
      "y": 3,
      "z": 3,
      "name": "Cloth_Block_Wool_White"
    },
    {
      "x": 0,
      "y": 4,
      "z": 3,
      "name": "Rock_Marble_Brick_Smooth"
    },
    {
      "x": 0,
      "y": 5,
      "z": 3,
      "name": "Rock_Marble_Brick_Smooth"
    },
    {
      "x": 0,
      "y": 6,
      "z": 3,
      "name": "Rock_Ledge_Brick_Smooth"
    },
    {
      "x": 0,
      "y": 7,
      "z": 3,
      "name": "Rock_Ledge_Brick_Smooth"
    },
    {
      "x": 0,
      "y": 0,
      "z": 4,
      "name": "Rock_Ledge_Brick"
    },
    {
      "x": 0,
      "y": 1,
      "z": 4,
      "name": "Rock_Ledge_Brick_Smooth"
    },
    {
      "x": 0,
      "y": 2,
      "z": 4,
      "name": "Rock_Ledge_Brick_Smooth"
    },
    {
      "x": 0,
      "y": 3,
      "z": 4,
      "name": "Rock_Ledge_Brick_Smooth"
    },
    {
      "x": 0,
      "y": 4,
      "z": 4,
      "name": "Rock_Ledge_Brick_Smooth"
    },
    {
      "x": 0,
      "y": 5,
      "z": 4,
      "name": "Rock_Ledge_Brick_Smooth"
    },
    {
      "x": 0,
      "y": 0,
      "z": 5,
      "name": "Rock_Ledge_Brick"
    },
    {
      "x": 0,
      "y": 1,
      "z": 5,
      "name": "Soil_Clay_Smooth_Black"
    },
    {
      "x": 0,
      "y": 2,
      "z": 5,
      "name": "Soil_Clay_Smooth_Black"
    },
    {
      "x": 0,
      "y": 3,
      "z": 5,
      "name": "Soil_Clay_Smooth_Black"
    },
    {
      "x": 0,
      "y": 4,
      "z": 5,
      "name": "Soil_Clay_Smooth_Black"
    },
    {
      "x": 0,
      "y": 0,
      "z": 6,
      "name": "Rock_Ledge_Brick"
    },
    {
      "x": 0,
      "y": 1,
      "z": 6,
      "name": "Deco_Iron_Bars"
    },
    {
      "x": 1,
      "y": 0,
      "z": -6,
      "name": "Rock_Ledge_Brick"
    },
    {
      "x": 1,
      "y": 1,
      "z": -6,
      "name": "Soil_Clay_Smooth_Black"
    },
    {
      "x": 1,
      "y": 0,
      "z": -5,
      "name": "Rock_Ledge_Brick"
    },
    {
      "x": 1,
      "y": 1,
      "z": -5,
      "name": "Rock_Ledge_Brick_Smooth"
    },
    {
      "x": 1,
      "y": 2,
      "z": -5,
      "name": "PinkLED"
    },
    {
      "x": 1,
      "y": 3,
      "z": -5,
      "name": "PinkLED"
    },
    {
      "x": 1,
      "y": 4,
      "z": -5,
      "name": "PinkLED"
    },
    {
      "x": 1,
      "y": 5,
      "z": -5,
      "name": "PinkLED"
    },
    {
      "x": 1,
      "y": 6,
      "z": -5,
      "name": "PinkLED"
    },
    {
      "x": 1,
      "y": 0,
      "z": -4,
      "name": "Rock_Ledge_Brick"
    },
    {
      "x": 1,
      "y": 1,
      "z": -4,
      "name": "Cloth_Block_Wool_White"
    },
    {
      "x": 1,
      "y": 2,
      "z": -4,
      "name": "Cloth_Block_Wool_White"
    },
    {
      "x": 1,
      "y": 3,
      "z": -4,
      "name": "Cloth_Block_Wool_White"
    },
    {
      "x": 1,
      "y": 4,
      "z": -4,
      "name": "Rock_Marble_Brick_Smooth"
    },
    {
      "x": 1,
      "y": 5,
      "z": -4,
      "name": "Rock_Marble_Brick_Smooth"
    },
    {
      "x": 1,
      "y": 6,
      "z": -4,
      "name": "PinkLED"
    },
    {
      "x": 1,
      "y": 0,
      "z": -3,
      "name": "Rock_Ledge_Brick"
    },
    {
      "x": 1,
      "y": 1,
      "z": -3,
      "name": "Furniture_Temple_Light_Table",
      "filler": 992,
      "rotation": 1
    },
    {
      "x": 1,
      "y": 3,
      "z": -3,
      "name": "Furniture_Temple_Light_Shelf"
    },
    {
      "x": 1,
      "y": 4,
      "z": -3,
      "name": "BlueLED"
    },
    {
      "x": 1,
      "y": 5,
      "z": -3,
      "name": "Rock_Marble_Brick_Smooth"
    },
    {
      "x": 1,
      "y": 6,
      "z": -3,
      "name": "PinkLED"
    },
    {
      "x": 1,
      "y": 0,
      "z": -2,
      "name": "Rock_Ledge_Brick"
    },
    {
      "x": 1,
      "y": 1,
      "z": -2,
      "name": "Furniture_Temple_Light_Table",
      "rotation": 1
    },
    {
      "x": 1,
      "y": 4,
      "z": -2,
      "name": "Rock_Marble_Brick_Smooth"
    },
    {
      "x": 1,
      "y": 7,
      "z": -2,
      "name": "Soil_Clay_Smooth_Black"
    },
    {
      "x": 1,
      "y": 0,
      "z": -1,
      "name": "Rock_Ledge_Brick"
    },
    {
      "x": 1,
      "y": 4,
      "z": -1,
      "name": "Rock_Marble_Brick_Smooth"
    },
    {
      "x": 1,
      "y": 7,
      "z": -1,
      "name": "Rock_Ledge_Brick_Smooth"
    },
    {
      "x": 1,
      "y": 0,
      "z": 0,
      "name": "Rock_Ledge_Brick"
    },
    {
      "x": 1,
      "y": 1,
      "z": 0,
      "name": "Furniture_Temple_Light_Bench",
      "rotation": 2
    },
    {
      "x": 1,
      "y": 4,
      "z": 0,
      "name": "Rock_Marble_Brick_Smooth"
    },
    {
      "x": 1,
      "y": 7,
      "z": 0,
      "name": "Rock_Ledge_Brick_Smooth"
    },
    {
      "x": 1,
      "y": 0,
      "z": 1,
      "name": "Rock_Ledge_Brick"
    },
    {
      "x": 1,
      "y": 1,
      "z": 1,
      "name": "Cloth_Block_Wool_White"
    },
    {
      "x": 1,
      "y": 2,
      "z": 1,
      "name": "Cloth_Block_Wool_White"
    },
    {
      "x": 1,
      "y": 3,
      "z": 1,
      "name": "Cloth_Block_Wool_White"
    },
    {
      "x": 1,
      "y": 4,
      "z": 1,
      "name": "Rock_Marble_Brick_Smooth"
    },
    {
      "x": 1,
      "y": 7,
      "z": 1,
      "name": "Rock_Ledge_Brick_Smooth"
    },
    {
      "x": 1,
      "y": 0,
      "z": 2,
      "name": "Rock_Ledge_Brick"
    },
    {
      "x": 1,
      "y": 1,
      "z": 2,
      "name": "Rock_Ledge_Brick_Smooth"
    },
    {
      "x": 1,
      "y": 2,
      "z": 2,
      "name": "Rock_Ledge_Brick_Smooth"
    },
    {
      "x": 1,
      "y": 3,
      "z": 2,
      "name": "Rock_Ledge_Brick_Smooth"
    },
    {
      "x": 1,
      "y": 4,
      "z": 2,
      "name": "Rock_Marble_Brick_Smooth"
    },
    {
      "x": 1,
      "y": 5,
      "z": 2,
      "name": "Rock_Marble_Brick_Smooth"
    },
    {
      "x": 1,
      "y": 6,
      "z": 2,
      "name": "Rock_Marble_Brick_Smooth"
    },
    {
      "x": 1,
      "y": 7,
      "z": 2,
      "name": "Rock_Ledge_Brick_Smooth"
    },
    {
      "x": 1,
      "y": 0,
      "z": 3,
      "name": "Rock_Ledge_Brick"
    },
    {
      "x": 1,
      "y": 1,
      "z": 3,
      "name": "Rock_Ledge_Brick_Smooth"
    },
    {
      "x": 1,
      "y": 2,
      "z": 3,
      "name": "Rock_Ledge_Brick_Smooth"
    },
    {
      "x": 1,
      "y": 3,
      "z": 3,
      "name": "Rock_Ledge_Brick_Smooth"
    },
    {
      "x": 1,
      "y": 4,
      "z": 3,
      "name": "Rock_Ledge_Brick_Smooth"
    },
    {
      "x": 1,
      "y": 5,
      "z": 3,
      "name": "Rock_Ledge_Brick_Smooth"
    },
    {
      "x": 1,
      "y": 6,
      "z": 3,
      "name": "Rock_Ledge_Brick_Smooth"
    },
    {
      "x": 1,
      "y": 7,
      "z": 3,
      "name": "Rock_Ledge_Brick_Smooth"
    },
    {
      "x": 1,
      "y": 0,
      "z": 4,
      "name": "Rock_Ledge_Brick"
    },
    {
      "x": 1,
      "y": 1,
      "z": 4,
      "name": "Rock_Ledge_Brick_Smooth"
    },
    {
      "x": 1,
      "y": 2,
      "z": 4,
      "name": "Rock_Ledge_Brick_Smooth"
    },
    {
      "x": 1,
      "y": 3,
      "z": 4,
      "name": "Rock_Ledge_Brick_Smooth"
    },
    {
      "x": 1,
      "y": 4,
      "z": 4,
      "name": "Rock_Ledge_Brick_Smooth"
    },
    {
      "x": 1,
      "y": 5,
      "z": 4,
      "name": "Rock_Ledge_Brick_Smooth"
    },
    {
      "x": 1,
      "y": 0,
      "z": 5,
      "name": "Rock_Ledge_Brick"
    },
    {
      "x": 1,
      "y": 0,
      "z": 6,
      "name": "Rock_Ledge_Brick"
    },
    {
      "x": 1,
      "y": 1,
      "z": 6,
      "name": "Deco_Iron_Bars"
    },
    {
      "x": 2,
      "y": 0,
      "z": -6,
      "name": "Rock_Ledge_Brick"
    },
    {
      "x": 2,
      "y": 1,
      "z": -6,
      "name": "Soil_Clay_Smooth_Black"
    },
    {
      "x": 2,
      "y": 2,
      "z": -6,
      "name": "Soil_Clay_Smooth_Black"
    },
    {
      "x": 2,
      "y": 3,
      "z": -6,
      "name": "Soil_Clay_Smooth_Black"
    },
    {
      "x": 2,
      "y": 4,
      "z": -6,
      "name": "Soil_Clay_Smooth_Black"
    },
    {
      "x": 2,
      "y": 5,
      "z": -6,
      "name": "Soil_Clay_Smooth_Black"
    },
    {
      "x": 2,
      "y": 6,
      "z": -6,
      "name": "Soil_Clay_Smooth_Black"
    },
    {
      "x": 2,
      "y": 7,
      "z": -6,
      "name": "Soil_Clay_Smooth_Black"
    },
    {
      "x": 2,
      "y": 0,
      "z": -5,
      "name": "Rock_Ledge_Brick"
    },
    {
      "x": 2,
      "y": 1,
      "z": -5,
      "name": "Rock_Ledge_Brick_Smooth"
    },
    {
      "x": 2,
      "y": 2,
      "z": -5,
      "name": "Rock_Ledge_Brick_Smooth"
    },
    {
      "x": 2,
      "y": 3,
      "z": -5,
      "name": "Rock_Ledge_Brick_Smooth"
    },
    {
      "x": 2,
      "y": 4,
      "z": -5,
      "name": "Rock_Ledge_Brick_Smooth"
    },
    {
      "x": 2,
      "y": 5,
      "z": -5,
      "name": "Rock_Ledge_Brick_Smooth"
    },
    {
      "x": 2,
      "y": 6,
      "z": -5,
      "name": "Rock_Marble_Brick_Smooth"
    },
    {
      "x": 2,
      "y": 7,
      "z": -5,
      "name": "Soil_Clay_Smooth_Black"
    },
    {
      "x": 2,
      "y": 0,
      "z": -4,
      "name": "Rock_Ledge_Brick"
    },
    {
      "x": 2,
      "y": 1,
      "z": -4,
      "name": "Cloth_Block_Wool_White"
    },
    {
      "x": 2,
      "y": 2,
      "z": -4,
      "name": "Cloth_Block_Wool_White"
    },
    {
      "x": 2,
      "y": 3,
      "z": -4,
      "name": "Cloth_Block_Wool_White"
    },
    {
      "x": 2,
      "y": 4,
      "z": -4,
      "name": "Rock_Marble_Brick_Smooth"
    },
    {
      "x": 2,
      "y": 5,
      "z": -4,
      "name": "Rock_Marble_Brick_Smooth"
    },
    {
      "x": 2,
      "y": 6,
      "z": -4,
      "name": "Rock_Marble_Brick_Smooth"
    },
    {
      "x": 2,
      "y": 7,
      "z": -4,
      "name": "Soil_Clay_Smooth_Black"
    },
    {
      "x": 2,
      "y": 0,
      "z": -3,
      "name": "Rock_Ledge_Brick"
    },
    {
      "x": 2,
      "y": 1,
      "z": -3,
      "name": "Furniture_Temple_Light_Table",
      "filler": 993,
      "rotation": 1
    },
    {
      "x": 2,
      "y": 2,
      "z": -3,
      "name": "Block_Spawner_Block",
      "components": {
        "Components": {
          "PlacedByInteraction": {
            "WhoPlacedUuid": {
              "$binary": "L6LzkYSjQOWrksT02Y12sg==",
              "$type": "04"
            }
          },
          "BlockSpawner": {
            "BlockSpawnerId": "RobotCity"
          }
        }
      }
    },
    {
      "x": 2,
      "y": 3,
      "z": -3,
      "name": "Furniture_Temple_Light_Shelf"
    },
    {
      "x": 2,
      "y": 4,
      "z": -3,
      "name": "BlueLED"
    },
    {
      "x": 2,
      "y": 5,
      "z": -3,
      "name": "Rock_Marble_Brick_Smooth"
    },
    {
      "x": 2,
      "y": 6,
      "z": -3,
      "name": "Rock_Marble_Brick_Smooth"
    },
    {
      "x": 2,
      "y": 7,
      "z": -3,
      "name": "Soil_Clay_Smooth_Black"
    },
    {
      "x": 2,
      "y": 0,
      "z": -2,
      "name": "Rock_Ledge_Brick"
    },
    {
      "x": 2,
      "y": 1,
      "z": -2,
      "name": "Furniture_Temple_Light_Table",
      "filler": 1,
      "rotation": 1
    },
    {
      "x": 2,
      "y": 4,
      "z": -2,
      "name": "Rock_Marble_Brick_Smooth"
    },
    {
      "x": 2,
      "y": 7,
      "z": -2,
      "name": "Soil_Clay_Smooth_Black"
    },
    {
      "x": 2,
      "y": 0,
      "z": -1,
      "name": "Rock_Ledge_Brick"
    },
    {
      "x": 2,
      "y": 4,
      "z": -1,
      "name": "Rock_Marble_Brick_Smooth"
    },
    {
      "x": 2,
      "y": 7,
      "z": -1,
      "name": "Rock_Ledge_Brick_Smooth"
    },
    {
      "x": 2,
      "y": 0,
      "z": 0,
      "name": "Rock_Ledge_Brick"
    },
    {
      "x": 2,
      "y": 1,
      "z": 0,
      "name": "Furniture_Temple_Light_Bench",
      "filler": 1,
      "rotation": 2
    },
    {
      "x": 2,
      "y": 4,
      "z": 0,
      "name": "Rock_Marble_Brick_Smooth"
    },
    {
      "x": 2,
      "y": 7,
      "z": 0,
      "name": "Rock_Ledge_Brick_Smooth"
    },
    {
      "x": 2,
      "y": 0,
      "z": 1,
      "name": "Rock_Ledge_Brick"
    },
    {
      "x": 2,
      "y": 1,
      "z": 1,
      "name": "Cloth_Block_Wool_White"
    },
    {
      "x": 2,
      "y": 2,
      "z": 1,
      "name": "Cloth_Block_Wool_White"
    },
    {
      "x": 2,
      "y": 3,
      "z": 1,
      "name": "Cloth_Block_Wool_White"
    },
    {
      "x": 2,
      "y": 4,
      "z": 1,
      "name": "Rock_Marble_Brick_Smooth"
    },
    {
      "x": 2,
      "y": 7,
      "z": 1,
      "name": "Rock_Ledge_Brick_Smooth"
    },
    {
      "x": 2,
      "y": 0,
      "z": 2,
      "name": "Rock_Ledge_Brick"
    },
    {
      "x": 2,
      "y": 1,
      "z": 2,
      "name": "Rock_Ledge_Brick_Smooth"
    },
    {
      "x": 2,
      "y": 2,
      "z": 2,
      "name": "Rock_Ledge_Brick_Smooth"
    },
    {
      "x": 2,
      "y": 3,
      "z": 2,
      "name": "Rock_Ledge_Brick_Smooth"
    },
    {
      "x": 2,
      "y": 4,
      "z": 2,
      "name": "Rock_Marble_Brick_Smooth"
    },
    {
      "x": 2,
      "y": 5,
      "z": 2,
      "name": "Rock_Marble_Brick_Smooth"
    },
    {
      "x": 2,
      "y": 6,
      "z": 2,
      "name": "Rock_Marble_Brick_Smooth"
    },
    {
      "x": 2,
      "y": 7,
      "z": 2,
      "name": "Rock_Ledge_Brick_Smooth"
    },
    {
      "x": 2,
      "y": 0,
      "z": 3,
      "name": "Rock_Ledge_Brick"
    },
    {
      "x": 2,
      "y": 1,
      "z": 3,
      "name": "Rock_Ledge_Brick_Smooth"
    },
    {
      "x": 2,
      "y": 2,
      "z": 3,
      "name": "Rock_Ledge_Brick_Smooth"
    },
    {
      "x": 2,
      "y": 3,
      "z": 3,
      "name": "Rock_Ledge_Brick_Smooth"
    },
    {
      "x": 2,
      "y": 4,
      "z": 3,
      "name": "Rock_Ledge_Brick_Smooth"
    },
    {
      "x": 2,
      "y": 5,
      "z": 3,
      "name": "Rock_Ledge_Brick_Smooth"
    },
    {
      "x": 2,
      "y": 6,
      "z": 3,
      "name": "Rock_Ledge_Brick_Smooth"
    },
    {
      "x": 2,
      "y": 7,
      "z": 3,
      "name": "Rock_Ledge_Brick_Smooth"
    },
    {
      "x": 2,
      "y": 0,
      "z": 4,
      "name": "Rock_Ledge_Brick"
    },
    {
      "x": 2,
      "y": 5,
      "z": 4,
      "name": "Rock_Ledge_Brick_Smooth"
    },
    {
      "x": 2,
      "y": 0,
      "z": 5,
      "name": "Rock_Ledge_Brick"
    },
    {
      "x": 2,
      "y": 1,
      "z": 5,
      "name": "Deco_Iron_Bars_Corner",
      "rotation": 1
    },
    {
      "x": 2,
      "y": 0,
      "z": 6,
      "name": "Rock_Ledge_Brick"
    },
    {
      "x": 2,
      "y": 1,
      "z": 6,
      "name": "Deco_Iron_Bars_Corner",
      "rotation": 3
    },
    {
      "x": 3,
      "y": 0,
      "z": -6,
      "name": "Rock_Ledge_Brick"
    },
    {
      "x": 3,
      "y": 5,
      "z": -6,
      "name": "Rock_Ledge_Brick_Smooth"
    },
    {
      "x": 3,
      "y": 0,
      "z": -5,
      "name": "Rock_Ledge_Brick"
    },
    {
      "x": 3,
      "y": 1,
      "z": -5,
      "name": "Rock_Ledge_Brick_Smooth"
    },
    {
      "x": 3,
      "y": 2,
      "z": -5,
      "name": "Rock_Ledge_Brick_Smooth"
    },
    {
      "x": 3,
      "y": 3,
      "z": -5,
      "name": "Rock_Ledge_Brick_Smooth"
    },
    {
      "x": 3,
      "y": 4,
      "z": -5,
      "name": "Rock_Ledge_Brick_Smooth"
    },
    {
      "x": 3,
      "y": 5,
      "z": -5,
      "name": "Rock_Ledge_Brick_Smooth"
    },
    {
      "x": 3,
      "y": 6,
      "z": -5,
      "name": "Rock_Ledge_Brick_Smooth"
    },
    {
      "x": 3,
      "y": 7,
      "z": -5,
      "name": "Rock_Ledge_Brick_Smooth"
    },
    {
      "x": 3,
      "y": 0,
      "z": -4,
      "name": "Rock_Ledge_Brick"
    },
    {
      "x": 3,
      "y": 1,
      "z": -4,
      "name": "Cloth_Block_Wool_White"
    },
    {
      "x": 3,
      "y": 2,
      "z": -4,
      "name": "Cloth_Block_Wool_White"
    },
    {
      "x": 3,
      "y": 3,
      "z": -4,
      "name": "Cloth_Block_Wool_White"
    },
    {
      "x": 3,
      "y": 4,
      "z": -4,
      "name": "Rock_Marble_Brick_Smooth"
    },
    {
      "x": 3,
      "y": 5,
      "z": -4,
      "name": "Rock_Marble_Brick_Smooth"
    },
    {
      "x": 3,
      "y": 6,
      "z": -4,
      "name": "Rock_Marble_Brick_Smooth"
    },
    {
      "x": 3,
      "y": 7,
      "z": -4,
      "name": "Rock_Ledge_Brick_Smooth"
    },
    {
      "x": 3,
      "y": 0,
      "z": -3,
      "name": "Rock_Ledge_Brick"
    },
    {
      "x": 3,
      "y": 1,
      "z": -3,
      "name": "Furniture_Temple_Light_Bench",
      "filler": 992,
      "rotation": 3
    },
    {
      "x": 3,
      "y": 3,
      "z": -3,
      "name": "Furniture_Temple_Light_Shelf"
    },
    {
      "x": 3,
      "y": 4,
      "z": -3,
      "name": "BlueLED"
    },
    {
      "x": 3,
      "y": 5,
      "z": -3,
      "name": "Rock_Marble_Brick_Smooth"
    },
    {
      "x": 3,
      "y": 6,
      "z": -3,
      "name": "Rock_Marble_Brick_Smooth"
    },
    {
      "x": 3,
      "y": 7,
      "z": -3,
      "name": "Rock_Ledge_Brick_Smooth"
    },
    {
      "x": 3,
      "y": 0,
      "z": -2,
      "name": "Rock_Ledge_Brick"
    },
    {
      "x": 3,
      "y": 1,
      "z": -2,
      "name": "Furniture_Temple_Light_Bench",
      "components": {
        "Components": {}
      },
      "rotation": 3
    },
    {
      "x": 3,
      "y": 4,
      "z": -2,
      "name": "Rock_Marble_Brick_Smooth"
    },
    {
      "x": 3,
      "y": 7,
      "z": -2,
      "name": "Rock_Ledge_Brick_Smooth"
    },
    {
      "x": 3,
      "y": 0,
      "z": -1,
      "name": "Rock_Ledge_Brick"
    },
    {
      "x": 3,
      "y": 4,
      "z": -1,
      "name": "Rock_Marble_Brick_Smooth"
    },
    {
      "x": 3,
      "y": 7,
      "z": -1,
      "name": "Rock_Ledge_Brick_Smooth"
    },
    {
      "x": 3,
      "y": 0,
      "z": 0,
      "name": "Rock_Ledge_Brick"
    },
    {
      "x": 3,
      "y": 4,
      "z": 0,
      "name": "Rock_Marble_Brick_Smooth"
    },
    {
      "x": 3,
      "y": 7,
      "z": 0,
      "name": "Rock_Ledge_Brick_Smooth"
    },
    {
      "x": 3,
      "y": 0,
      "z": 1,
      "name": "Rock_Ledge_Brick"
    },
    {
      "x": 3,
      "y": 1,
      "z": 1,
      "name": "Cloth_Block_Wool_White"
    },
    {
      "x": 3,
      "y": 2,
      "z": 1,
      "name": "Cloth_Block_Wool_White"
    },
    {
      "x": 3,
      "y": 3,
      "z": 1,
      "name": "Cloth_Block_Wool_White"
    },
    {
      "x": 3,
      "y": 4,
      "z": 1,
      "name": "Rock_Marble_Brick_Smooth"
    },
    {
      "x": 3,
      "y": 7,
      "z": 1,
      "name": "Rock_Ledge_Brick_Smooth"
    },
    {
      "x": 3,
      "y": 0,
      "z": 2,
      "name": "Rock_Ledge_Brick"
    },
    {
      "x": 3,
      "y": 1,
      "z": 2,
      "name": "Rock_Marble_Brick_Smooth"
    },
    {
      "x": 3,
      "y": 2,
      "z": 2,
      "name": "Rock_Marble_Brick_Smooth"
    },
    {
      "x": 3,
      "y": 3,
      "z": 2,
      "name": "Rock_Marble_Brick_Smooth"
    },
    {
      "x": 3,
      "y": 4,
      "z": 2,
      "name": "Rock_Marble_Brick_Smooth"
    },
    {
      "x": 3,
      "y": 5,
      "z": 2,
      "name": "Rock_Marble_Brick_Smooth"
    },
    {
      "x": 3,
      "y": 6,
      "z": 2,
      "name": "Rock_Marble_Brick_Smooth"
    },
    {
      "x": 3,
      "y": 7,
      "z": 2,
      "name": "Rock_Ledge_Brick_Smooth"
    },
    {
      "x": 3,
      "y": 0,
      "z": 3,
      "name": "Rock_Ledge_Brick"
    },
    {
      "x": 3,
      "y": 1,
      "z": 3,
      "name": "Rock_Ledge_Brick_Smooth"
    },
    {
      "x": 3,
      "y": 4,
      "z": 3,
      "name": "Rock_Ledge_Brick_Smooth"
    },
    {
      "x": 3,
      "y": 5,
      "z": 3,
      "name": "Rock_Ledge_Brick_Smooth"
    },
    {
      "x": 3,
      "y": 6,
      "z": 3,
      "name": "Rock_Ledge_Brick_Smooth"
    },
    {
      "x": 3,
      "y": 7,
      "z": 3,
      "name": "Rock_Ledge_Brick_Smooth"
    },
    {
      "x": 3,
      "y": 0,
      "z": 4,
      "name": "Rock_Ledge_Brick"
    },
    {
      "x": 3,
      "y": 5,
      "z": 4,
      "name": "Rock_Ledge_Brick_Smooth"
    },
    {
      "x": 3,
      "y": 0,
      "z": 5,
      "name": "Rock_Ledge_Brick"
    },
    {
      "x": 3,
      "y": 1,
      "z": 5,
      "name": "Deco_Iron_Bars"
    },
    {
      "x": 4,
      "y": 0,
      "z": -6,
      "name": "Rock_Ledge_Brick"
    },
    {
      "x": 4,
      "y": 5,
      "z": -6,
      "name": "Rock_Ledge_Brick_Smooth"
    },
    {
      "x": 4,
      "y": 0,
      "z": -5,
      "name": "Rock_Ledge_Brick"
    },
    {
      "x": 4,
      "y": 1,
      "z": -5,
      "name": "Rock_Ledge_Brick_Smooth"
    },
    {
      "x": 4,
      "y": 2,
      "z": -5,
      "name": "Rock_Ledge_Brick_Smooth"
    },
    {
      "x": 4,
      "y": 3,
      "z": -5,
      "name": "Rock_Ledge_Brick_Smooth"
    },
    {
      "x": 4,
      "y": 4,
      "z": -5,
      "name": "Rock_Ledge_Brick_Smooth"
    },
    {
      "x": 4,
      "y": 5,
      "z": -5,
      "name": "Rock_Ledge_Brick_Smooth"
    },
    {
      "x": 4,
      "y": 6,
      "z": -5,
      "name": "Rock_Ledge_Brick_Smooth"
    },
    {
      "x": 4,
      "y": 7,
      "z": -5,
      "name": "Rock_Ledge_Brick_Smooth"
    },
    {
      "x": 4,
      "y": 0,
      "z": -4,
      "name": "Rock_Ledge_Brick"
    },
    {
      "x": 4,
      "y": 1,
      "z": -4,
      "name": "Cloth_Block_Wool_White"
    },
    {
      "x": 4,
      "y": 2,
      "z": -4,
      "name": "Cloth_Block_Wool_White"
    },
    {
      "x": 4,
      "y": 3,
      "z": -4,
      "name": "Cloth_Block_Wool_White"
    },
    {
      "x": 4,
      "y": 4,
      "z": -4,
      "name": "Rock_Marble_Brick_Smooth"
    },
    {
      "x": 4,
      "y": 5,
      "z": -4,
      "name": "Rock_Marble_Brick_Smooth"
    },
    {
      "x": 4,
      "y": 6,
      "z": -4,
      "name": "Rock_Marble_Brick_Smooth"
    },
    {
      "x": 4,
      "y": 7,
      "z": -4,
      "name": "Rock_Ledge_Brick_Smooth"
    },
    {
      "x": 4,
      "y": 0,
      "z": -3,
      "name": "Rock_Ledge_Brick"
    },
    {
      "x": 4,
      "y": 1,
      "z": -3,
      "name": "Cloth_Block_Wool_White"
    },
    {
      "x": 4,
      "y": 2,
      "z": -3,
      "name": "Cloth_Block_Wool_White"
    },
    {
      "x": 4,
      "y": 3,
      "z": -3,
      "name": "Cloth_Block_Wool_White"
    },
    {
      "x": 4,
      "y": 4,
      "z": -3,
      "name": "Rock_Marble_Brick_Smooth"
    },
    {
      "x": 4,
      "y": 5,
      "z": -3,
      "name": "Rock_Marble_Brick_Smooth"
    },
    {
      "x": 4,
      "y": 6,
      "z": -3,
      "name": "Rock_Marble_Brick_Smooth"
    },
    {
      "x": 4,
      "y": 7,
      "z": -3,
      "name": "Rock_Ledge_Brick_Smooth"
    },
    {
      "x": 4,
      "y": 0,
      "z": -2,
      "name": "Rock_Ledge_Brick"
    },
    {
      "x": 4,
      "y": 1,
      "z": -2,
      "name": "Cloth_Block_Wool_White"
    },
    {
      "x": 4,
      "y": 2,
      "z": -2,
      "name": "Cloth_Block_Wool_White"
    },
    {
      "x": 4,
      "y": 3,
      "z": -2,
      "name": "Cloth_Block_Wool_White"
    },
    {
      "x": 4,
      "y": 4,
      "z": -2,
      "name": "Rock_Marble_Brick_Smooth"
    },
    {
      "x": 4,
      "y": 7,
      "z": -2,
      "name": "Rock_Ledge_Brick_Smooth"
    },
    {
      "x": 4,
      "y": 0,
      "z": -1,
      "name": "Rock_Ledge_Brick"
    },
    {
      "x": 4,
      "y": 1,
      "z": -1,
      "name": "Cloth_Block_Wool_White"
    },
    {
      "x": 4,
      "y": 2,
      "z": -1,
      "name": "Cloth_Block_Wool_White"
    },
    {
      "x": 4,
      "y": 3,
      "z": -1,
      "name": "Cloth_Block_Wool_White"
    },
    {
      "x": 4,
      "y": 4,
      "z": -1,
      "name": "Rock_Marble_Brick_Smooth"
    },
    {
      "x": 4,
      "y": 7,
      "z": -1,
      "name": "Rock_Ledge_Brick_Smooth"
    },
    {
      "x": 4,
      "y": 0,
      "z": 0,
      "name": "Rock_Ledge_Brick"
    },
    {
      "x": 4,
      "y": 1,
      "z": 0,
      "name": "*Furniture_Robot_Door_State_Definitions_CloseDoorOut",
      "rotation": 1
    },
    {
      "x": 4,
      "y": 2,
      "z": 0,
      "name": "*Furniture_Robot_Door_State_Definitions_CloseDoorOut",
      "filler": 1024,
      "rotation": 1
    },
    {
      "x": 4,
      "y": 3,
      "z": 0,
      "name": "Cloth_Block_Wool_White"
    },
    {
      "x": 4,
      "y": 4,
      "z": 0,
      "name": "Rock_Marble_Brick_Smooth"
    },
    {
      "x": 4,
      "y": 7,
      "z": 0,
      "name": "Rock_Ledge_Brick_Smooth"
    },
    {
      "x": 4,
      "y": 0,
      "z": 1,
      "name": "Rock_Ledge_Brick"
    },
    {
      "x": 4,
      "y": 1,
      "z": 1,
      "name": "Cloth_Block_Wool_White"
    },
    {
      "x": 4,
      "y": 2,
      "z": 1,
      "name": "Cloth_Block_Wool_White"
    },
    {
      "x": 4,
      "y": 3,
      "z": 1,
      "name": "Cloth_Block_Wool_White"
    },
    {
      "x": 4,
      "y": 4,
      "z": 1,
      "name": "Rock_Marble_Brick_Smooth"
    },
    {
      "x": 4,
      "y": 7,
      "z": 1,
      "name": "Rock_Ledge_Brick_Smooth"
    },
    {
      "x": 4,
      "y": 0,
      "z": 2,
      "name": "Rock_Ledge_Brick"
    },
    {
      "x": 4,
      "y": 1,
      "z": 2,
      "name": "Rock_Marble_Brick_Smooth"
    },
    {
      "x": 4,
      "y": 2,
      "z": 2,
      "name": "Rock_Marble_Brick_Smooth"
    },
    {
      "x": 4,
      "y": 3,
      "z": 2,
      "name": "Rock_Marble_Brick_Smooth"
    },
    {
      "x": 4,
      "y": 4,
      "z": 2,
      "name": "Rock_Marble_Brick_Smooth"
    },
    {
      "x": 4,
      "y": 5,
      "z": 2,
      "name": "Rock_Marble_Brick_Smooth"
    },
    {
      "x": 4,
      "y": 6,
      "z": 2,
      "name": "Rock_Marble_Brick_Smooth"
    },
    {
      "x": 4,
      "y": 7,
      "z": 2,
      "name": "Rock_Ledge_Brick_Smooth"
    },
    {
      "x": 4,
      "y": 0,
      "z": 3,
      "name": "Rock_Ledge_Brick"
    },
    {
      "x": 4,
      "y": 1,
      "z": 3,
      "name": "Rock_Ledge_Brick_Smooth"
    },
    {
      "x": 4,
      "y": 4,
      "z": 3,
      "name": "Rock_Ledge_Brick_Smooth"
    },
    {
      "x": 4,
      "y": 5,
      "z": 3,
      "name": "Rock_Ledge_Brick_Smooth"
    },
    {
      "x": 4,
      "y": 6,
      "z": 3,
      "name": "Rock_Ledge_Brick_Smooth"
    },
    {
      "x": 4,
      "y": 7,
      "z": 3,
      "name": "Rock_Ledge_Brick_Smooth"
    },
    {
      "x": 4,
      "y": 0,
      "z": 4,
      "name": "Rock_Ledge_Brick"
    },
    {
      "x": 4,
      "y": 5,
      "z": 4,
      "name": "Rock_Ledge_Brick_Smooth"
    },
    {
      "x": 4,
      "y": 0,
      "z": 5,
      "name": "Rock_Ledge_Brick"
    },
    {
      "x": 4,
      "y": 1,
      "z": 5,
      "name": "Deco_Iron_Bars"
    },
    {
      "x": 5,
      "y": 0,
      "z": -6,
      "name": "Rock_Ledge_Brick"
    },
    {
      "x": 5,
      "y": 5,
      "z": -6,
      "name": "Rock_Ledge_Brick_Smooth"
    },
    {
      "x": 5,
      "y": 0,
      "z": -5,
      "name": "Rock_Ledge_Brick"
    },
    {
      "x": 5,
      "y": 1,
      "z": -5,
      "name": "Rock_Ledge_Brick_Smooth"
    },
    {
      "x": 5,
      "y": 2,
      "z": -5,
      "name": "Rock_Ledge_Brick_Smooth"
    },
    {
      "x": 5,
      "y": 3,
      "z": -5,
      "name": "Rock_Ledge_Brick_Smooth"
    },
    {
      "x": 5,
      "y": 4,
      "z": -5,
      "name": "Rock_Ledge_Brick_Smooth"
    },
    {
      "x": 5,
      "y": 5,
      "z": -5,
      "name": "Rock_Ledge_Brick_Smooth"
    },
    {
      "x": 5,
      "y": 6,
      "z": -5,
      "name": "Rock_Ledge_Brick_Smooth"
    },
    {
      "x": 5,
      "y": 7,
      "z": -5,
      "name": "Rock_Ledge_Brick_Smooth"
    },
    {
      "x": 5,
      "y": 0,
      "z": -4,
      "name": "Rock_Ledge_Brick"
    },
    {
      "x": 5,
      "y": 1,
      "z": -4,
      "name": "Rock_Ledge_Brick_Smooth"
    },
    {
      "x": 5,
      "y": 2,
      "z": -4,
      "name": "Rock_Ledge_Brick_Smooth"
    },
    {
      "x": 5,
      "y": 3,
      "z": -4,
      "name": "Rock_Ledge_Brick_Smooth"
    },
    {
      "x": 5,
      "y": 4,
      "z": -4,
      "name": "Rock_Ledge_Brick_Smooth"
    },
    {
      "x": 5,
      "y": 5,
      "z": -4,
      "name": "Rock_Ledge_Brick_Smooth"
    },
    {
      "x": 5,
      "y": 6,
      "z": -4,
      "name": "Rock_Ledge_Brick_Smooth"
    },
    {
      "x": 5,
      "y": 7,
      "z": -4,
      "name": "Rock_Ledge_Brick_Smooth"
    },
    {
      "x": 5,
      "y": 0,
      "z": -3,
      "name": "Rock_Ledge_Brick"
    },
    {
      "x": 5,
      "y": 1,
      "z": -3,
      "name": "Rock_Ledge_Brick_Smooth"
    },
    {
      "x": 5,
      "y": 2,
      "z": -3,
      "name": "Rock_Ledge_Brick_Smooth"
    },
    {
      "x": 5,
      "y": 3,
      "z": -3,
      "name": "Rock_Ledge_Brick_Smooth"
    },
    {
      "x": 5,
      "y": 4,
      "z": -3,
      "name": "Rock_Ledge_Brick_Smooth"
    },
    {
      "x": 5,
      "y": 5,
      "z": -3,
      "name": "Rock_Marble_Brick_Smooth"
    },
    {
      "x": 5,
      "y": 6,
      "z": -3,
      "name": "Rock_Ledge_Brick_Smooth"
    },
    {
      "x": 5,
      "y": 7,
      "z": -3,
      "name": "Rock_Ledge_Brick_Smooth"
    },
    {
      "x": 5,
      "y": 0,
      "z": -2,
      "name": "Rock_Ledge_Brick"
    },
    {
      "x": 5,
      "y": 1,
      "z": -2,
      "name": "Furniture_Temple_Light_Ladder"
    },
    {
      "x": 5,
      "y": 2,
      "z": -2,
      "name": "Furniture_Temple_Light_Ladder"
    },
    {
      "x": 5,
      "y": 3,
      "z": -2,
      "name": "Furniture_Temple_Light_Ladder"
    },
    {
      "x": 5,
      "y": 4,
      "z": -2,
      "name": "Furniture_Temple_Light_Ladder"
    },
    {
      "x": 5,
      "y": 5,
      "z": -2,
      "name": "Furniture_Temple_Light_Ladder"
    },
    {
      "x": 5,
      "y": 6,
      "z": -2,
      "name": "Furniture_Temple_Light_Ladder"
    },
    {
      "x": 5,
      "y": 7,
      "z": -2,
      "name": "Rock_Ledge_Brick_Smooth"
    },
    {
      "x": 5,
      "y": 0,
      "z": -1,
      "name": "Rock_Ledge_Brick"
    },
    {
      "x": 5,
      "y": 4,
      "z": -1,
      "name": "Rock_Marble_Brick_Smooth_Half",
      "rotation": 6
    },
    {
      "x": 5,
      "y": 7,
      "z": -1,
      "name": "Rock_Ledge_Brick_Smooth"
    },
    {
      "x": 5,
      "y": 0,
      "z": 0,
      "name": "Rock_Ledge_Brick"
    },
    {
      "x": 5,
      "y": 4,
      "z": 0,
      "name": "Rock_Marble_Brick_Smooth"
    },
    {
      "x": 5,
      "y": 7,
      "z": 0,
      "name": "Rock_Ledge_Brick_Smooth"
    },
    {
      "x": 5,
      "y": 0,
      "z": 1,
      "name": "Rock_Ledge_Brick"
    },
    {
      "x": 5,
      "y": 4,
      "z": 1,
      "name": "Rock_Marble_Brick_Smooth"
    },
    {
      "x": 5,
      "y": 7,
      "z": 1,
      "name": "Rock_Ledge_Brick_Smooth"
    },
    {
      "x": 5,
      "y": 0,
      "z": 2,
      "name": "Rock_Ledge_Brick"
    },
    {
      "x": 5,
      "y": 1,
      "z": 2,
      "name": "Rock_Marble_Brick_Smooth"
    },
    {
      "x": 5,
      "y": 2,
      "z": 2,
      "name": "Rock_Marble_Brick_Smooth"
    },
    {
      "x": 5,
      "y": 3,
      "z": 2,
      "name": "Rock_Marble_Brick_Smooth"
    },
    {
      "x": 5,
      "y": 4,
      "z": 2,
      "name": "Rock_Marble_Brick_Smooth"
    },
    {
      "x": 5,
      "y": 5,
      "z": 2,
      "name": "Rock_Marble_Brick_Smooth"
    },
    {
      "x": 5,
      "y": 6,
      "z": 2,
      "name": "Rock_Marble_Brick_Smooth"
    },
    {
      "x": 5,
      "y": 7,
      "z": 2,
      "name": "Rock_Ledge_Brick_Smooth"
    },
    {
      "x": 5,
      "y": 0,
      "z": 3,
      "name": "Rock_Ledge_Brick"
    },
    {
      "x": 5,
      "y": 1,
      "z": 3,
      "name": "Rock_Ledge_Brick_Smooth"
    },
    {
      "x": 5,
      "y": 4,
      "z": 3,
      "name": "Rock_Ledge_Brick_Smooth"
    },
    {
      "x": 5,
      "y": 5,
      "z": 3,
      "name": "Rock_Ledge_Brick_Smooth"
    },
    {
      "x": 5,
      "y": 6,
      "z": 3,
      "name": "Rock_Ledge_Brick_Smooth"
    },
    {
      "x": 5,
      "y": 7,
      "z": 3,
      "name": "Rock_Ledge_Brick_Smooth"
    },
    {
      "x": 5,
      "y": 0,
      "z": 4,
      "name": "Rock_Ledge_Brick"
    },
    {
      "x": 5,
      "y": 5,
      "z": 4,
      "name": "Rock_Ledge_Brick_Smooth"
    },
    {
      "x": 5,
      "y": 0,
      "z": 5,
      "name": "Rock_Ledge_Brick"
    },
    {
      "x": 5,
      "y": 1,
      "z": 5,
      "name": "Deco_Iron_Bars"
    },
    {
      "x": 6,
      "y": 0,
      "z": -6,
      "name": "Rock_Ledge_Brick"
    },
    {
      "x": 6,
      "y": 5,
      "z": -6,
      "name": "Rock_Ledge_Brick_Smooth"
    },
    {
      "x": 6,
      "y": 0,
      "z": -5,
      "name": "Rock_Ledge_Brick"
    },
    {
      "x": 6,
      "y": 1,
      "z": -5,
      "name": "Soil_Clay_Smooth_Black"
    },
    {
      "x": 6,
      "y": 2,
      "z": -5,
      "name": "Soil_Clay_Smooth_Black"
    },
    {
      "x": 6,
      "y": 3,
      "z": -5,
      "name": "Soil_Clay_Smooth_Black"
    },
    {
      "x": 6,
      "y": 5,
      "z": -5,
      "name": "Rock_Ledge_Brick_Smooth"
    },
    {
      "x": 6,
      "y": 0,
      "z": -4,
      "name": "Rock_Ledge_Brick"
    },
    {
      "x": 6,
      "y": 1,
      "z": -4,
      "name": "Soil_Clay_Smooth_Black"
    },
    {
      "x": 6,
      "y": 2,
      "z": -4,
      "name": "PinkLED"
    },
    {
      "x": 6,
      "y": 3,
      "z": -4,
      "name": "Soil_Clay_Smooth_Black"
    },
    {
      "x": 6,
      "y": 5,
      "z": -4,
      "name": "Rock_Ledge_Brick_Smooth"
    },
    {
      "x": 6,
      "y": 0,
      "z": -3,
      "name": "Rock_Ledge_Brick"
    },
    {
      "x": 6,
      "y": 1,
      "z": -3,
      "name": "Soil_Clay_Smooth_Black"
    },
    {
      "x": 6,
      "y": 2,
      "z": -3,
      "name": "PinkLED"
    },
    {
      "x": 6,
      "y": 3,
      "z": -3,
      "name": "Soil_Clay_Smooth_Black"
    },
    {
      "x": 6,
      "y": 5,
      "z": -3,
      "name": "Rock_Ledge_Brick_Smooth"
    },
    {
      "x": 6,
      "y": 0,
      "z": -2,
      "name": "Rock_Ledge_Brick"
    },
    {
      "x": 6,
      "y": 1,
      "z": -2,
      "name": "Rock_Ledge_Brick_Smooth"
    },
    {
      "x": 6,
      "y": 2,
      "z": -2,
      "name": "Rock_Ledge_Brick_Smooth"
    },
    {
      "x": 6,
      "y": 3,
      "z": -2,
      "name": "Rock_Ledge_Brick_Smooth"
    },
    {
      "x": 6,
      "y": 4,
      "z": -2,
      "name": "Rock_Ledge_Brick_Smooth"
    },
    {
      "x": 6,
      "y": 5,
      "z": -2,
      "name": "Rock_Ledge_Brick_Smooth"
    },
    {
      "x": 6,
      "y": 6,
      "z": -2,
      "name": "Rock_Ledge_Brick_Smooth"
    },
    {
      "x": 6,
      "y": 7,
      "z": -2,
      "name": "Rock_Ledge_Brick_Smooth"
    },
    {
      "x": 6,
      "y": 0,
      "z": -1,
      "name": "Rock_Ledge_Brick"
    },
    {
      "x": 6,
      "y": 1,
      "z": -1,
      "name": "Furniture_Temple_Light_Shelf",
      "rotation": 3
    },
    {
      "x": 6,
      "y": 4,
      "z": -1,
      "name": "Rock_Marble_Brick_Smooth"
    },
    {
      "x": 6,
      "y": 5,
      "z": -1,
      "name": "Rock_Marble_Brick_Smooth"
    },
    {
      "x": 6,
      "y": 6,
      "z": -1,
      "name": "Rock_Marble_Brick_Smooth"
    },
    {
      "x": 6,
      "y": 7,
      "z": -1,
      "name": "Rock_Ledge_Brick_Smooth"
    },
    {
      "x": 6,
      "y": 0,
      "z": 0,
      "name": "Rock_Ledge_Brick"
    },
    {
      "x": 6,
      "y": 1,
      "z": 0,
      "name": "Furniture_Temple_Light_Shelf",
      "rotation": 3
    },
    {
      "x": 6,
      "y": 4,
      "z": 0,
      "name": "Rock_Marble_Brick_Smooth"
    },
    {
      "x": 6,
      "y": 5,
      "z": 0,
      "name": "Rock_Marble_Brick_Smooth"
    },
    {
      "x": 6,
      "y": 6,
      "z": 0,
      "name": "Rock_Marble_Brick_Smooth"
    },
    {
      "x": 6,
      "y": 7,
      "z": 0,
      "name": "Rock_Ledge_Brick_Smooth"
    },
    {
      "x": 6,
      "y": 0,
      "z": 1,
      "name": "Rock_Ledge_Brick"
    },
    {
      "x": 6,
      "y": 1,
      "z": 1,
      "name": "Furniture_Temple_Light_Shelf",
      "rotation": 3
    },
    {
      "x": 6,
      "y": 4,
      "z": 1,
      "name": "Rock_Marble_Brick_Smooth"
    },
    {
      "x": 6,
      "y": 5,
      "z": 1,
      "name": "Rock_Marble_Brick_Smooth"
    },
    {
      "x": 6,
      "y": 6,
      "z": 1,
      "name": "Rock_Marble_Brick_Smooth"
    },
    {
      "x": 6,
      "y": 7,
      "z": 1,
      "name": "Rock_Ledge_Brick_Smooth"
    },
    {
      "x": 6,
      "y": 0,
      "z": 2,
      "name": "Rock_Ledge_Brick"
    },
    {
      "x": 6,
      "y": 1,
      "z": 2,
      "name": "Rock_Marble_Brick_Smooth"
    },
    {
      "x": 6,
      "y": 2,
      "z": 2,
      "name": "Rock_Marble_Brick_Smooth"
    },
    {
      "x": 6,
      "y": 3,
      "z": 2,
      "name": "Rock_Marble_Brick_Smooth"
    },
    {
      "x": 6,
      "y": 4,
      "z": 2,
      "name": "Rock_Marble_Brick_Smooth"
    },
    {
      "x": 6,
      "y": 5,
      "z": 2,
      "name": "Rock_Marble_Brick_Smooth"
    },
    {
      "x": 6,
      "y": 6,
      "z": 2,
      "name": "Rock_Ledge_Brick_Smooth"
    },
    {
      "x": 6,
      "y": 7,
      "z": 2,
      "name": "Rock_Ledge_Brick_Smooth"
    },
    {
      "x": 6,
      "y": 0,
      "z": 3,
      "name": "Rock_Ledge_Brick"
    },
    {
      "x": 6,
      "y": 1,
      "z": 3,
      "name": "Rock_Ledge_Brick_Smooth"
    },
    {
      "x": 6,
      "y": 4,
      "z": 3,
      "name": "Rock_Ledge_Brick_Smooth"
    },
    {
      "x": 6,
      "y": 5,
      "z": 3,
      "name": "Rock_Ledge_Brick_Smooth"
    },
    {
      "x": 6,
      "y": 6,
      "z": 3,
      "name": "Rock_Ledge_Brick_Smooth"
    },
    {
      "x": 6,
      "y": 7,
      "z": 3,
      "name": "Rock_Ledge_Brick_Smooth"
    },
    {
      "x": 6,
      "y": 0,
      "z": 4,
      "name": "Rock_Ledge_Brick"
    },
    {
      "x": 6,
      "y": 5,
      "z": 4,
      "name": "Rock_Ledge_Brick_Smooth"
    },
    {
      "x": 6,
      "y": 0,
      "z": 5,
      "name": "Rock_Ledge_Brick"
    },
    {
      "x": 6,
      "y": 1,
      "z": 5,
      "name": "Deco_Iron_Bars"
    },
    {
      "x": 7,
      "y": 0,
      "z": -6,
      "name": "Rock_Ledge_Brick"
    },
    {
      "x": 7,
      "y": 0,
      "z": -5,
      "name": "Rock_Ledge_Brick"
    },
    {
      "x": 7,
      "y": 0,
      "z": -4,
      "name": "Rock_Ledge_Brick"
    },
    {
      "x": 7,
      "y": 0,
      "z": -3,
      "name": "Rock_Ledge_Brick"
    },
    {
      "x": 7,
      "y": 1,
      "z": -3,
      "name": "Soil_Clay_Smooth_Black"
    },
    {
      "x": 7,
      "y": 2,
      "z": -3,
      "name": "PinkLED"
    },
    {
      "x": 7,
      "y": 3,
      "z": -3,
      "name": "Soil_Clay_Smooth_Black"
    },
    {
      "x": 7,
      "y": 4,
      "z": -3,
      "name": "Soil_Clay_Smooth_Black"
    },
    {
      "x": 7,
      "y": 5,
      "z": -3,
      "name": "Soil_Clay_Smooth_Black"
    },
    {
      "x": 7,
      "y": 6,
      "z": -3,
      "name": "Soil_Clay_Smooth_Black"
    },
    {
      "x": 7,
      "y": 7,
      "z": -3,
      "name": "Soil_Clay_Smooth_Black"
    },
    {
      "x": 7,
      "y": 0,
      "z": -2,
      "name": "Rock_Ledge_Brick"
    },
    {
      "x": 7,
      "y": 1,
      "z": -2,
      "name": "PinkLED"
    },
    {
      "x": 7,
      "y": 2,
      "z": -2,
      "name": "PinkLED"
    },
    {
      "x": 7,
      "y": 3,
      "z": -2,
      "name": "PinkLED"
    },
    {
      "x": 7,
      "y": 4,
      "z": -2,
      "name": "PinkLED"
    },
    {
      "x": 7,
      "y": 5,
      "z": -2,
      "name": "PinkLED"
    },
    {
      "x": 7,
      "y": 6,
      "z": -2,
      "name": "PinkLED"
    },
    {
      "x": 7,
      "y": 7,
      "z": -2,
      "name": "Soil_Clay_Smooth_Black"
    },
    {
      "x": 7,
      "y": 0,
      "z": -1,
      "name": "Rock_Ledge_Brick"
    },
    {
      "x": 7,
      "y": 1,
      "z": -1,
      "name": "Soil_Clay_Smooth_Black"
    },
    {
      "x": 7,
      "y": 2,
      "z": -1,
      "name": "Soil_Clay_Smooth_Black"
    },
    {
      "x": 7,
      "y": 3,
      "z": -1,
      "name": "Soil_Clay_Smooth_Black"
    },
    {
      "x": 7,
      "y": 4,
      "z": -1,
      "name": "Soil_Clay_Smooth_Black"
    },
    {
      "x": 7,
      "y": 5,
      "z": -1,
      "name": "Soil_Clay_Smooth_Black"
    },
    {
      "x": 7,
      "y": 6,
      "z": -1,
      "name": "Soil_Clay_Smooth_Black"
    },
    {
      "x": 7,
      "y": 7,
      "z": -1,
      "name": "Soil_Clay_Smooth_Black"
    },
    {
      "x": 7,
      "y": 0,
      "z": 0,
      "name": "Rock_Ledge_Brick"
    },
    {
      "x": 7,
      "y": 1,
      "z": 0,
      "name": "Rock_Ledge_Brick_Smooth"
    },
    {
      "x": 7,
      "y": 2,
      "z": 0,
      "name": "Rock_Ledge_Brick_Smooth"
    },
    {
      "x": 7,
      "y": 3,
      "z": 0,
      "name": "Rock_Ledge_Brick_Smooth"
    },
    {
      "x": 7,
      "y": 4,
      "z": 0,
      "name": "Rock_Ledge_Brick_Smooth"
    },
    {
      "x": 7,
      "y": 5,
      "z": 0,
      "name": "Rock_Ledge_Brick_Smooth"
    },
    {
      "x": 7,
      "y": 6,
      "z": 0,
      "name": "Rock_Ledge_Brick_Smooth"
    },
    {
      "x": 7,
      "y": 7,
      "z": 0,
      "name": "Rock_Ledge_Brick_Smooth"
    },
    {
      "x": 7,
      "y": 0,
      "z": 1,
      "name": "Rock_Ledge_Brick"
    },
    {
      "x": 7,
      "y": 1,
      "z": 1,
      "name": "Rock_Ledge_Brick_Smooth"
    },
    {
      "x": 7,
      "y": 2,
      "z": 1,
      "name": "Rock_Ledge_Brick_Smooth"
    },
    {
      "x": 7,
      "y": 3,
      "z": 1,
      "name": "Rock_Ledge_Brick_Smooth"
    },
    {
      "x": 7,
      "y": 4,
      "z": 1,
      "name": "Rock_Ledge_Brick_Smooth"
    },
    {
      "x": 7,
      "y": 5,
      "z": 1,
      "name": "Rock_Ledge_Brick_Smooth"
    },
    {
      "x": 7,
      "y": 6,
      "z": 1,
      "name": "Rock_Ledge_Brick_Smooth"
    },
    {
      "x": 7,
      "y": 7,
      "z": 1,
      "name": "Rock_Ledge_Brick_Smooth"
    },
    {
      "x": 7,
      "y": 0,
      "z": 2,
      "name": "Rock_Ledge_Brick"
    },
    {
      "x": 7,
      "y": 1,
      "z": 2,
      "name": "Rock_Ledge_Brick_Smooth"
    },
    {
      "x": 7,
      "y": 2,
      "z": 2,
      "name": "Rock_Ledge_Brick_Smooth"
    },
    {
      "x": 7,
      "y": 3,
      "z": 2,
      "name": "Rock_Ledge_Brick_Smooth"
    },
    {
      "x": 7,
      "y": 4,
      "z": 2,
      "name": "Rock_Ledge_Brick_Smooth"
    },
    {
      "x": 7,
      "y": 5,
      "z": 2,
      "name": "Rock_Ledge_Brick_Smooth"
    },
    {
      "x": 7,
      "y": 6,
      "z": 2,
      "name": "Rock_Ledge_Brick_Smooth"
    },
    {
      "x": 7,
      "y": 7,
      "z": 2,
      "name": "Rock_Ledge_Brick_Smooth"
    },
    {
      "x": 7,
      "y": 0,
      "z": 3,
      "name": "Rock_Ledge_Brick"
    },
    {
      "x": 7,
      "y": 1,
      "z": 3,
      "name": "Rock_Ledge_Brick_Smooth"
    },
    {
      "x": 7,
      "y": 2,
      "z": 3,
      "name": "Rock_Ledge_Brick_Smooth"
    },
    {
      "x": 7,
      "y": 3,
      "z": 3,
      "name": "Rock_Ledge_Brick_Smooth"
    },
    {
      "x": 7,
      "y": 4,
      "z": 3,
      "name": "Rock_Ledge_Brick_Smooth"
    },
    {
      "x": 7,
      "y": 5,
      "z": 3,
      "name": "Rock_Ledge_Brick_Smooth"
    },
    {
      "x": 7,
      "y": 6,
      "z": 3,
      "name": "Rock_Ledge_Brick_Smooth"
    },
    {
      "x": 7,
      "y": 7,
      "z": 3,
      "name": "Rock_Ledge_Brick_Smooth"
    },
    {
      "x": 7,
      "y": 0,
      "z": 4,
      "name": "Rock_Ledge_Brick"
    },
    {
      "x": 7,
      "y": 5,
      "z": 4,
      "name": "Rock_Ledge_Brick_Smooth"
    },
    {
      "x": 7,
      "y": 0,
      "z": 5,
      "name": "Rock_Ledge_Brick"
    },
    {
      "x": 7,
      "y": 1,
      "z": 5,
      "name": "Deco_Iron_Bars"
    },
    {
      "x": 8,
      "y": 0,
      "z": -6,
      "name": "Rock_Ledge_Brick"
    },
    {
      "x": 8,
      "y": 0,
      "z": -5,
      "name": "Rock_Ledge_Brick"
    },
    {
      "x": 8,
      "y": 0,
      "z": -4,
      "name": "Rock_Ledge_Brick"
    },
    {
      "x": 8,
      "y": 0,
      "z": -3,
      "name": "Rock_Ledge_Brick"
    },
    {
      "x": 8,
      "y": 0,
      "z": -2,
      "name": "Rock_Ledge_Brick"
    },
    {
      "x": 8,
      "y": 0,
      "z": -1,
      "name": "Rock_Ledge_Brick"
    },
    {
      "x": 8,
      "y": 0,
      "z": 0,
      "name": "Rock_Ledge_Brick"
    },
    {
      "x": 8,
      "y": 5,
      "z": 0,
      "name": "Rock_Ledge_Brick_Smooth"
    },
    {
      "x": 8,
      "y": 0,
      "z": 1,
      "name": "Rock_Ledge_Brick"
    },
    {
      "x": 8,
      "y": 1,
      "z": 1,
      "name": "Deco_Iron_Bars",
      "rotation": 1
    },
    {
      "x": 8,
      "y": 5,
      "z": 1,
      "name": "Rock_Ledge_Brick_Smooth"
    },
    {
      "x": 8,
      "y": 0,
      "z": 2,
      "name": "Rock_Ledge_Brick"
    },
    {
      "x": 8,
      "y": 1,
      "z": 2,
      "name": "Deco_Iron_Bars",
      "rotation": 1
    },
    {
      "x": 8,
      "y": 5,
      "z": 2,
      "name": "Rock_Ledge_Brick_Smooth"
    },
    {
      "x": 8,
      "y": 0,
      "z": 3,
      "name": "Rock_Ledge_Brick"
    },
    {
      "x": 8,
      "y": 1,
      "z": 3,
      "name": "Deco_Iron_Bars",
      "rotation": 1
    },
    {
      "x": 8,
      "y": 5,
      "z": 3,
      "name": "Rock_Ledge_Brick_Smooth"
    },
    {
      "x": 8,
      "y": 0,
      "z": 4,
      "name": "Rock_Ledge_Brick"
    },
    {
      "x": 8,
      "y": 1,
      "z": 4,
      "name": "Deco_Iron_Bars",
      "rotation": 1
    },
    {
      "x": 8,
      "y": 5,
      "z": 4,
      "name": "Rock_Ledge_Brick_Smooth"
    },
    {
      "x": 8,
      "y": 0,
      "z": 5,
      "name": "Rock_Ledge_Brick"
    },
    {
      "x": 8,
      "y": 1,
      "z": 5,
      "name": "Deco_Iron_Bars_Corner",
      "rotation": 3
    }
  ]
}