{
  "version": 8,
  "blockIdVersion": 11,
  "anchorX": 0,
  "anchorY": 0,
  "anchorZ": 0,
  "blocks": [
    {
      "x": -7,
      "y": 8,
      "z": -5,
      "name": "Rock_Ledge_Brick_Smooth"
    },
    {
      "x": -7,
      "y": 8,
      "z": -4,
      "name": "Rock_Ledge_Brick_Smooth"
    },
    {
      "x": -7,
      "y": 8,
      "z": -3,
      "name": "Rock_Ledge_Brick_Smooth"
    },
    {
      "x": -7,
      "y": 8,
      "z": -2,
      "name": "Rock_Ledge_Brick_Smooth"
    },
    {
      "x": -7,
      "y": 8,
      "z": -1,
      "name": "Rock_Ledge_Brick_Smooth"
    },
    {
      "x": -7,
      "y": 8,
      "z": 0,
      "name": "Rock_Ledge_Brick_Smooth"
    },
    {
      "x": -7,
      "y": 8,
      "z": 1,
      "name": "Rock_Ledge_Brick_Smooth"
    },
    {
      "x": -7,
      "y": 8,
      "z": 2,
      "name": "Rock_Ledge_Brick_Smooth"
    },
    {
      "x": -7,
      "y": 8,
      "z": 3,
      "name": "Rock_Ledge_Brick_Smooth"
    },
    {
      "x": -7,
      "y": 8,
      "z": 4,
      "name": "Rock_Ledge_Brick_Smooth"
    },
    {
      "x": -7,
      "y": 8,
      "z": 5,
      "name": "Rock_Ledge_Brick_Smooth"
    },
    {
      "x": -7,
      "y": 8,
      "z": 6,
      "name": "Rock_Ledge_Brick_Smooth"
    },
    {
      "x": -6,
      "y": 8,
      "z": -5,
      "name": "Rock_Ledge_Brick_Smooth"
    },
    {
      "x": -6,
      "y": 0,
      "z": -4,
      "name": "Rock_Ledge_Brick"
    },
    {
      "x": -6,
      "y": 8,
      "z": -4,
      "name": "Rock_Ledge_Brick_Smooth"
    },
    {
      "x": -6,
      "y": 9,
      "z": -4,
      "name": "Rock_Ledge_Brick_Smooth"
    },
    {
      "x": -6,
      "y": 10,
      "z": -4,
      "name": "Rock_Ledge_Brick_Smooth"
    },
    {
      "x": -6,
      "y": 0,
      "z": -3,
      "name": "Rock_Ledge_Brick"
    },
    {
      "x": -6,
      "y": 8,
      "z": -3,
      "name": "Rock_Ledge_Brick_Smooth"
    },
    {
      "x": -6,
      "y": 9,
      "z": -3,
      "name": "Rock_Ledge_Brick_Smooth"
    },
    {
      "x": -6,
      "y": 10,
      "z": -3,
      "name": "Rock_Ledge_Brick_Smooth"
    },
    {
      "x": -6,
      "y": 0,
      "z": -2,
      "name": "Rock_Ledge_Brick"
    },
    {
      "x": -6,
      "y": 1,
      "z": -2,
      "name": "Rock_Ledge_Brick_Smooth"
    },
    {
      "x": -6,
      "y": 2,
      "z": -2,
      "name": "Rock_Ledge_Brick_Smooth"
    },
    {
      "x": -6,
      "y": 3,
      "z": -2,
      "name": "Rock_Ledge_Brick_Smooth"
    },
    {
      "x": -6,
      "y": 7,
      "z": -2,
      "name": "Rock_Ledge_Brick_Smooth"
    },
    {
      "x": -6,
      "y": 8,
      "z": -2,
      "name": "Rock_Ledge_Brick_Smooth"
    },
    {
      "x": -6,
      "y": 9,
      "z": -2,
      "name": "Rock_Ledge_Brick_Smooth"
    },
    {
      "x": -6,
      "y": 10,
      "z": -2,
      "name": "Rock_Ledge_Brick_Smooth"
    },
    {
      "x": -6,
      "y": 0,
      "z": -1,
      "name": "Rock_Ledge_Brick"
    },
    {
      "x": -6,
      "y": 1,
      "z": -1,
      "name": "Rock_Ledge_Brick_Smooth"
    },
    {
      "x": -6,
      "y": 2,
      "z": -1,
      "name": "Rock_Ledge_Brick_Smooth"
    },
    {
      "x": -6,
      "y": 3,
      "z": -1,
      "name": "Rock_Ledge_Brick_Smooth"
    },
    {
      "x": -6,
      "y": 7,
      "z": -1,
      "name": "Rock_Ledge_Brick_Smooth"
    },
    {
      "x": -6,
      "y": 8,
      "z": -1,
      "name": "Rock_Ledge_Brick_Smooth"
    },
    {
      "x": -6,
      "y": 9,
      "z": -1,
      "name": "Rock_Ledge_Brick_Smooth"
    },
    {
      "x": -6,
      "y": 10,
      "z": -1,
      "name": "Rock_Ledge_Brick_Smooth"
    },
    {
      "x": -6,
      "y": 0,
      "z": 0,
      "name": "Rock_Ledge_Brick"
    },
    {
      "x": -6,
      "y": 1,
      "z": 0,
      "name": "Rock_Ledge_Brick_Smooth"
    },
    {
      "x": -6,
      "y": 2,
      "z": 0,
      "name": "Rock_Ledge_Brick_Smooth"
    },
    {
      "x": -6,
      "y": 3,
      "z": 0,
      "name": "Rock_Ledge_Brick_Smooth"
    },
    {
      "x": -6,
      "y": 7,
      "z": 0,
      "name": "Rock_Ledge_Brick_Smooth"
    },
    {
      "x": -6,
      "y": 8,
      "z": 0,
      "name": "Rock_Ledge_Brick_Smooth"
    },
    {
      "x": -6,
      "y": 9,
      "z": 0,
      "name": "Rock_Ledge_Brick_Smooth"
    },
    {
      "x": -6,
      "y": 10,
      "z": 0,
      "name": "Rock_Ledge_Brick_Smooth"
    },
    {
      "x": -6,
      "y": 0,
      "z": 1,
      "name": "Rock_Ledge_Brick"
    },
    {
      "x": -6,
      "y": 1,
      "z": 1,
      "name": "Rock_Ledge_Brick_Smooth"
    },
    {
      "x": -6,
      "y": 2,
      "z": 1,
      "name": "Rock_Ledge_Brick_Smooth"
    },
    {
      "x": -6,
      "y": 3,
      "z": 1,
      "name": "Rock_Ledge_Brick_Smooth"
    },
    {
      "x": -6,
      "y": 7,
      "z": 1,
      "name": "Rock_Ledge_Brick_Smooth"
    },
    {
      "x": -6,
      "y": 8,
      "z": 1,
      "name": "Rock_Ledge_Brick_Smooth"
    },
    {
      "x": -6,
      "y": 9,
      "z": 1,
      "name": "Rock_Ledge_Brick_Smooth"
    },
    {
      "x": -6,
      "y": 10,
      "z": 1,
      "name": "Rock_Ledge_Brick_Smooth"
    },
    {
      "x": -6,
      "y": 0,
      "z": 2,
      "name": "Rock_Ledge_Brick"
    },
    {
      "x": -6,
      "y": 1,
      "z": 2,
      "name": "Rock_Ledge_Brick_Smooth"
    },
    {
      "x": -6,
      "y": 2,
      "z": 2,
      "name": "Rock_Ledge_Brick_Smooth"
    },
    {
      "x": -6,
      "y": 3,
      "z": 2,
      "name": "Rock_Ledge_Brick_Smooth"
    },
    {
      "x": -6,
      "y": 7,
      "z": 2,
      "name": "Rock_Ledge_Brick_Smooth"
    },
    {
      "x": -6,
      "y": 8,
      "z": 2,
      "name": "Rock_Ledge_Brick_Smooth"
    },
    {
      "x": -6,
      "y": 9,
      "z": 2,
      "name": "Rock_Ledge_Brick_Smooth"
    },
    {
      "x": -6,
      "y": 10,
      "z": 2,
      "name": "Rock_Ledge_Brick_Smooth"
    },
    {
      "x": -6,
      "y": 0,
      "z": 3,
      "name": "Rock_Ledge_Brick"
    },
    {
      "x": -6,
      "y": 1,
      "z": 3,
      "name": "Rock_Ledge_Brick_Smooth"
    },
    {
      "x": -6,
      "y": 2,
      "z": 3,
      "name": "Rock_Ledge_Brick_Smooth"
    },
    {
      "x": -6,
      "y": 3,
      "z": 3,
      "name": "Rock_Ledge_Brick_Smooth"
    },
    {
      "x": -6,
      "y": 7,
      "z": 3,
      "name": "Rock_Ledge_Brick_Smooth"
    },
    {
      "x": -6,
      "y": 8,
      "z": 3,
      "name": "Rock_Ledge_Brick_Smooth"
    },
    {
      "x": -6,
      "y": 9,
      "z": 3,
      "name": "Rock_Ledge_Brick_Smooth"
    },
    {
      "x": -6,
      "y": 10,
      "z": 3,
      "name": "Rock_Ledge_Brick_Smooth"
    },
    {
      "x": -6,
      "y": 0,
      "z": 4,
      "name": "Rock_Ledge_Brick"
    },
    {
      "x": -6,
      "y": 1,
      "z": 4,
      "name": "Rock_Ledge_Brick_Smooth"
    },
    {
      "x": -6,
      "y": 2,
      "z": 4,
      "name": "Rock_Ledge_Brick_Smooth"
    },
    {
      "x": -6,
      "y": 3,
      "z": 4,
      "name": "Rock_Ledge_Brick_Smooth"
    },
    {
      "x": -6,
      "y": 7,
      "z": 4,
      "name": "Rock_Ledge_Brick_Smooth"
    },
    {
      "x": -6,
      "y": 8,
      "z": 4,
      "name": "Rock_Ledge_Brick_Smooth"
    },
    {
      "x": -6,
      "y": 9,
      "z": 4,
      "name": "Rock_Ledge_Brick_Smooth"
    },
    {
      "x": -6,
      "y": 10,
      "z": 4,
      "name": "Rock_Ledge_Brick_Smooth"
    },
    {
      "x": -6,
      "y": 0,
      "z": 5,
      "name": "Rock_Ledge_Brick"
    },
    {
      "x": -6,
      "y": 1,
      "z": 5,
      "name": "Rock_Ledge_Brick_Smooth"
    },
    {
      "x": -6,
      "y": 2,
      "z": 5,
      "name": "Rock_Ledge_Brick_Smooth"
    },
    {
      "x": -6,
      "y": 3,
      "z": 5,
      "name": "Rock_Ledge_Brick_Smooth"
    },
    {
      "x": -6,
      "y": 4,
      "z": 5,
      "name": "Rock_Ledge_Brick_Smooth"
    },
    {
      "x": -6,
      "y": 5,
      "z": 5,
      "name": "Rock_Ledge_Brick_Smooth"
    },
    {
      "x": -6,
      "y": 6,
      "z": 5,
      "name": "Rock_Ledge_Brick_Smooth"
    },
    {
      "x": -6,
      "y": 7,
      "z": 5,
      "name": "Rock_Ledge_Brick_Smooth"
    },
    {
      "x": -6,
      "y": 8,
      "z": 5,
      "name": "Rock_Ledge_Brick_Smooth"
    },
    {
      "x": -6,
      "y": 9,
      "z": 5,
      "name": "Rock_Ledge_Brick_Smooth"
    },
    {
      "x": -6,
      "y": 10,
      "z": 5,
      "name": "Rock_Ledge_Brick_Smooth"
    },
    {
      "x": -6,
      "y": 0,
      "z": 6,
      "name": "Rock_Ledge_Brick"
    },
    {
      "x": -6,
      "y": 8,
      "z": 6,
      "name": "Rock_Ledge_Brick_Smooth"
    },
    {
      "x": -6,
      "y": 0,
      "z": 7,
      "name": "Rock_Ledge_Brick"
    },
    {
      "x": -5,
      "y": 8,
      "z": -5,
      "name": "Rock_Ledge_Brick_Smooth"
    },
    {
      "x": -5,
      "y": 0,
      "z": -4,
      "name": "Rock_Ledge_Brick"
    },
    {
      "x": -5,
      "y": 8,
      "z": -4,
      "name": "Rock_Ledge_Brick_Smooth"
    },
    {
      "x": -5,
      "y": 9,
      "z": -4,
      "name": "Rock_Ledge_Brick_Smooth"
    },
    {
      "x": -5,
      "y": 10,
      "z": -4,
      "name": "Rock_Ledge_Brick_Smooth"
    },
    {
      "x": -5,
      "y": 0,
      "z": -3,
      "name": "Rock_Ledge_Brick"
    },
    {
      "x": -5,
      "y": 8,
      "z": -3,
      "name": "Rock_Ledge_Brick_Smooth"
    },
    {
      "x": -5,
      "y": 10,
      "z": -3,
      "name": "Rock_Ledge_Brick_Smooth"
    },
    {
      "x": -5,
      "y": 0,
      "z": -2,
      "name": "Rock_Ledge_Brick"
    },
    {
      "x": -5,
      "y": 1,
      "z": -2,
      "name": "Rock_Ledge_Brick_Smooth"
    },
    {
      "x": -5,
      "y": 2,
      "z": -2,
      "name": "Rock_Ledge_Brick_Smooth"
    },
    {
      "x": -5,
      "y": 3,
      "z": -2,
      "name": "Rock_Ledge_Brick_Smooth"
    },
    {
      "x": -5,
      "y": 7,
      "z": -2,
      "name": "Rock_Ledge_Brick_Smooth"
    },
    {
      "x": -5,
      "y": 10,
      "z": -2,
      "name": "Rock_Ledge_Brick_Smooth"
    },
    {
      "x": -5,
      "y": 0,
      "z": -1,
      "name": "Rock_Ledge_Brick"
    },
    {
      "x": -5,
      "y": 1,
      "z": -1,
      "name": "Cloth_Block_Wool_White"
    },
    {
      "x": -5,
      "y": 2,
      "z": -1,
      "name": "Cloth_Block_Wool_White"
    },
    {
      "x": -5,
      "y": 3,
      "z": -1,
      "name": "Cloth_Block_Wool_White"
    },
    {
      "x": -5,
      "y": 4,
      "z": -1,
      "name": "Rock_Marble_Brick_Smooth"
    },
    {
      "x": -5,
      "y": 5,
      "z": -1,
      "name": "YellowLED"
    },
    {
      "x": -5,
      "y": 6,
      "z": -1,
      "name": "Rock_Marble_Brick_Smooth"
    },
    {
      "x": -5,
      "y": 10,
      "z": -1,
      "name": "Rock_Ledge_Brick_Smooth"
    },
    {
      "x": -5,
      "y": 0,
      "z": 0,
      "name": "Rock_Ledge_Brick"
    },
    {
      "x": -5,
      "y": 1,
      "z": 0,
      "name": "Cloth_Block_Wool_White"
    },
    {
      "x": -5,
      "y": 2,
      "z": 0,
      "name": "Cloth_Block_Wool_White"
    },
    {
      "x": -5,
      "y": 3,
      "z": 0,
      "name": "Cloth_Block_Wool_White"
    },
    {
      "x": -5,
      "y": 4,
      "z": 0,
      "name": "Rock_Marble_Brick_Smooth"
    },
    {
      "x": -5,
      "y": 5,
      "z": 0,
      "name": "YellowLED"
    },
    {
      "x": -5,
      "y": 6,
      "z": 0,
      "name": "Rock_Marble_Brick_Smooth"
    },
    {
      "x": -5,
      "y": 10,
      "z": 0,
      "name": "Rock_Ledge_Brick_Smooth"
    },
    {
      "x": -5,
      "y": 0,
      "z": 1,
      "name": "Rock_Ledge_Brick"
    },
    {
      "x": -5,
      "y": 1,
      "z": 1,
      "name": "Cloth_Block_Wool_White"
    },
    {
      "x": -5,
      "y": 2,
      "z": 1,
      "name": "Cloth_Block_Wool_White"
    },
    {
      "x": -5,
      "y": 3,
      "z": 1,
      "name": "Cloth_Block_Wool_White"
    },
    {
      "x": -5,
      "y": 4,
      "z": 1,
      "name": "Rock_Marble_Brick_Smooth"
    },
    {
      "x": -5,
      "y": 5,
      "z": 1,
      "name": "YellowLED"
    },
    {
      "x": -5,
      "y": 6,
      "z": 1,
      "name": "Rock_Marble_Brick_Smooth"
    },
    {
      "x": -5,
      "y": 10,
      "z": 1,
      "name": "Rock_Ledge_Brick_Smooth"
    },
    {
      "x": -5,
      "y": 0,
      "z": 2,
      "name": "Rock_Ledge_Brick"
    },
    {
      "x": -5,
      "y": 1,
      "z": 2,
      "name": "Cloth_Block_Wool_White"
    },
    {
      "x": -5,
      "y": 2,
      "z": 2,
      "name": "Cloth_Block_Wool_White"
    },
    {
      "x": -5,
      "y": 3,
      "z": 2,
      "name": "Cloth_Block_Wool_White"
    },
    {
      "x": -5,
      "y": 4,
      "z": 2,
      "name": "Rock_Marble_Brick_Smooth"
    },
    {
      "x": -5,
      "y": 5,
      "z": 2,
      "name": "YellowLED"
    },
    {
      "x": -5,
      "y": 6,
      "z": 2,
      "name": "Rock_Marble_Brick_Smooth"
    },
    {
      "x": -5,
      "y": 10,
      "z": 2,
      "name": "Rock_Ledge_Brick_Smooth"
    },
    {
      "x": -5,
      "y": 0,
      "z": 3,
      "name": "Rock_Ledge_Brick"
    },
    {
      "x": -5,
      "y": 1,
      "z": 3,
      "name": "Cloth_Block_Wool_White"
    },
    {
      "x": -5,
      "y": 2,
      "z": 3,
      "name": "Cloth_Block_Wool_White"
    },
    {
      "x": -5,
      "y": 3,
      "z": 3,
      "name": "Cloth_Block_Wool_White"
    },
    {
      "x": -5,
      "y": 4,
      "z": 3,
      "name": "Rock_Marble_Brick_Smooth"
    },
    {
      "x": -5,
      "y": 5,
      "z": 3,
      "name": "YellowLED"
    },
    {
      "x": -5,
      "y": 6,
      "z": 3,
      "name": "Rock_Marble_Brick_Smooth"
    },
    {
      "x": -5,
      "y": 10,
      "z": 3,
      "name": "Rock_Ledge_Brick_Smooth"
    },
    {
      "x": -5,
      "y": 0,
      "z": 4,
      "name": "Rock_Ledge_Brick"
    },
    {
      "x": -5,
      "y": 1,
      "z": 4,
      "name": "Cloth_Block_Wool_White"
    },
    {
      "x": -5,
      "y": 2,
      "z": 4,
      "name": "Cloth_Block_Wool_White"
    },
    {
      "x": -5,
      "y": 3,
      "z": 4,
      "name": "Cloth_Block_Wool_White"
    },
    {
      "x": -5,
      "y": 4,
      "z": 4,
      "name": "Rock_Marble_Brick_Smooth"
    },
    {
      "x": -5,
      "y": 5,
      "z": 4,
      "name": "YellowLED"
    },
    {
      "x": -5,
      "y": 6,
      "z": 4,
      "name": "Rock_Marble_Brick_Smooth"
    },
    {
      "x": -5,
      "y": 10,
      "z": 4,
      "name": "Rock_Ledge_Brick_Smooth"
    },
    {
      "x": -5,
      "y": 0,
      "z": 5,
      "name": "Rock_Ledge_Brick"
    },
    {
      "x": -5,
      "y": 1,
      "z": 5,
      "name": "Rock_Ledge_Brick_Smooth"
    },
    {
      "x": -5,
      "y": 2,
      "z": 5,
      "name": "Rock_Ledge_Brick_Smooth"
    },
    {
      "x": -5,
      "y": 3,
      "z": 5,
      "name": "Rock_Ledge_Brick_Smooth"
    },
    {
      "x": -5,
      "y": 4,
      "z": 5,
      "name": "Rock_Ledge_Brick_Smooth"
    },
    {
      "x": -5,
      "y": 5,
      "z": 5,
      "name": "Rock_Ledge_Brick"
    },
    {
      "x": -5,
      "y": 9,
      "z": 5,
      "name": "Rock_Ledge_Brick_Smooth"
    },
    {
      "x": -5,
      "y": 10,
      "z": 5,
      "name": "Rock_Ledge_Brick_Smooth"
    },
    {
      "x": -5,
      "y": 0,
      "z": 6,
      "name": "Rock_Ledge_Brick"
    },
    {
      "x": -5,
      "y": 5,
      "z": 6,
      "name": "Rock_Ledge_Brick_Smooth"
    },
    {
      "x": -5,
      "y": 6,
      "z": 6,
      "name": "Rock_Ledge_Brick_Smooth"
    },
    {
      "x": -5,
      "y": 7,
      "z": 6,
      "name": "Rock_Ledge_Brick_Stairs"
    },
    {
      "x": -5,
      "y": 8,
      "z": 6,
      "name": "Rock_Ledge_Brick_Smooth"
    },
    {
      "x": -5,
      "y": 0,
      "z": 7,
      "name": "Rock_Ledge_Brick"
    },
    {
      "x": -5,
      "y": 1,
      "z": 7,
      "name": "Rock_Ledge_Brick_Pillar_Base"
    },
    {
      "x": -5,
      "y": 2,
      "z": 7,
      "name": "Rock_Ledge_Brick_Pillar_Base",
      "rotation": 8
    },
    {
      "x": -5,
      "y": 3,
      "z": 7,
      "name": "Rock_Ledge_Brick_Pillar_Base"
    },
    {
      "x": -5,
      "y": 4,
      "z": 7,
      "name": "Rock_Ledge_Brick_Pillar_Base",
      "rotation": 8
    },
    {
      "x": -5,
      "y": 5,
      "z": 7,
      "name": "Rock_Ledge_Brick_Smooth"
    },
    {
      "x": -4,
      "y": 8,
      "z": -5,
      "name": "Rock_Ledge_Brick_Smooth"
    },
    {
      "x": -4,
      "y": 0,
      "z": -4,
      "name": "Rock_Ledge_Brick"
    },
    {
      "x": -4,
      "y": 8,
      "z": -4,
      "name": "Rock_Ledge_Brick_Smooth"
    },
    {
      "x": -4,
      "y": 9,
      "z": -4,
      "name": "Rock_Ledge_Brick_Smooth"
    },
    {
      "x": -4,
      "y": 10,
      "z": -4,
      "name": "Rock_Ledge_Brick_Smooth"
    },
    {
      "x": -4,
      "y": 0,
      "z": -3,
      "name": "Rock_Ledge_Brick"
    },
    {
      "x": -4,
      "y": 8,
      "z": -3,
      "name": "Rock_Ledge_Brick_Smooth"
    },
    {
      "x": -4,
      "y": 10,
      "z": -3,
      "name": "Rock_Ledge_Brick_Smooth"
    },
    {
      "x": -4,
      "y": 0,
      "z": -2,
      "name": "Rock_Ledge_Brick"
    },
    {
      "x": -4,
      "y": 1,
      "z": -2,
      "name": "*Furniture_Temple_Light_Door_State_Definitions_CloseDoorIn"
    },
    {
      "x": -4,
      "y": 2,
      "z": -2,
      "name": "*Furniture_Temple_Light_Door_State_Definitions_CloseDoorIn",
      "filler": 1024
    },
    {
      "x": -4,
      "y": 3,
      "z": -2,
      "name": "Rock_Ledge_Brick_Smooth"
    },
    {
      "x": -4,
      "y": 7,
      "z": -2,
      "name": "Rock_Ledge_Brick_Smooth"
    },
    {
      "x": -4,
      "y": 10,
      "z": -2,
      "name": "Rock_Ledge_Brick_Smooth"
    },
    {
      "x": -4,
      "y": 0,
      "z": -1,
      "name": "Rock_Ledge_Brick"
    },
    {
      "x": -4,
      "y": 4,
      "z": -1,
      "name": "Rock_Marble_Brick_Smooth"
    },
    {
      "x": -4,
      "y": 5,
      "z": -1,
      "name": "YellowLED"
    },
    {
      "x": -4,
      "y": 6,
      "z": -1,
      "name": "Rock_Marble_Brick_Smooth"
    },
    {
      "x": -4,
      "y": 10,
      "z": -1,
      "name": "Rock_Ledge_Brick_Smooth"
    },
    {
      "x": -4,
      "y": 0,
      "z": 0,
      "name": "Rock_Ledge_Brick"
    },
    {
      "x": -4,
      "y": 4,
      "z": 0,
      "name": "Rock_Marble_Brick_Smooth"
    },
    {
      "x": -4,
      "y": 5,
      "z": 0,
      "name": "Rock_Ledge_Brick"
    },
    {
      "x": -4,
      "y": 6,
      "z": 0,
      "name": "Cloth_Block_Wool_White"
    },
    {
      "x": -4,
      "y": 7,
      "z": 0,
      "name": "Cloth_Block_Wool_White"
    },
    {
      "x": -4,
      "y": 8,
      "z": 0,
      "name": "Cloth_Block_Wool_White"
    },
    {
      "x": -4,
      "y": 10,
      "z": 0,
      "name": "Rock_Ledge_Brick_Smooth"
    },
    {
      "x": -4,
      "y": 0,
      "z": 1,
      "name": "Rock_Ledge_Brick"
    },
    {
      "x": -4,
      "y": 1,
      "z": 1,
      "name": "Furniture_Temple_Light_Stool",
      "rotation": 1
    },
    {
      "x": -4,
      "y": 4,
      "z": 1,
      "name": "Rock_Marble_Brick_Smooth"
    },
    {
      "x": -4,
      "y": 5,
      "z": 1,
      "name": "Rock_Ledge_Brick"
    },
    {
      "x": -4,
      "y": 6,
      "z": 1,
      "name": "Cloth_Block_Wool_White"
    },
    {
      "x": -4,
      "y": 7,
      "z": 1,
      "name": "Cloth_Block_Wool_White"
    },
    {
      "x": -4,
      "y": 8,
      "z": 1,
      "name": "Cloth_Block_Wool_White"
    },
    {
      "x": -4,
      "y": 10,
      "z": 1,
      "name": "Rock_Ledge_Brick_Smooth"
    },
    {
      "x": -4,
      "y": 0,
      "z": 2,
      "name": "Rock_Ledge_Brick"
    },
    {
      "x": -4,
      "y": 1,
      "z": 2,
      "name": "Furniture_Temple_Light_Table",
      "filler": 992,
      "rotation": 1
    },
    {
      "x": -4,
      "y": 4,
      "z": 2,
      "name": "Rock_Marble_Brick_Smooth"
    },
    {
      "x": -4,
      "y": 5,
      "z": 2,
      "name": "Rock_Ledge_Brick"
    },
    {
      "x": -4,
      "y": 6,
      "z": 2,
      "name": "Cloth_Block_Wool_White"
    },
    {
      "x": -4,
      "y": 7,
      "z": 2,
      "name": "Cloth_Block_Wool_White"
    },
    {
      "x": -4,
      "y": 8,
      "z": 2,
      "name": "Cloth_Block_Wool_White"
    },
    {
      "x": -4,
      "y": 10,
      "z": 2,
      "name": "Rock_Ledge_Brick_Smooth"
    },
    {
      "x": -4,
      "y": 0,
      "z": 3,
      "name": "Rock_Ledge_Brick"
    },
    {
      "x": -4,
      "y": 1,
      "z": 3,
      "name": "Furniture_Temple_Light_Table",
      "rotation": 1
    },
    {
      "x": -4,
      "y": 2,
      "z": 3,
      "name": "Block_Spawner_Block",
      "components": {
        "Components": {
          "PlacedByInteraction": {
            "WhoPlacedUuid": {
              "$binary": "L6LzkYSjQOWrksT02Y12sg==",
              "$type": "04"
            }
          },
          "BlockSpawner": {
            "BlockSpawnerId": "RobotCity"
          }
        }
      },
      "rotation": 2
    },
    {
      "x": -4,
      "y": 4,
      "z": 3,
      "name": "Rock_Marble_Brick_Smooth"
    },
    {
      "x": -4,
      "y": 5,
      "z": 3,
      "name": "Rock_Ledge_Brick"
    },
    {
      "x": -4,
      "y": 6,
      "z": 3,
      "name": "Cloth_Block_Wool_White"
    },
    {
      "x": -4,
      "y": 7,
      "z": 3,
      "name": "Cloth_Block_Wool_White"
    },
    {
      "x": -4,
      "y": 8,
      "z": 3,
      "name": "Cloth_Block_Wool_White"
    },
    {
      "x": -4,
      "y": 10,
      "z": 3,
      "name": "Rock_Ledge_Brick_Smooth"
    },
    {
      "x": -4,
      "y": 0,
      "z": 4,
      "name": "Rock_Ledge_Brick"
    },
    {
      "x": -4,
      "y": 1,
      "z": 4,
      "name": "Cloth_Block_Wool_White"
    },
    {
      "x": -4,
      "y": 2,
      "z": 4,
      "name": "Cloth_Block_Wool_White"
    },
    {
      "x": -4,
      "y": 3,
      "z": 4,
      "name": "Cloth_Block_Wool_White"
    },
    {
      "x": -4,
      "y": 4,
      "z": 4,
      "name": "Rock_Marble_Brick_Smooth"
    },
    {
      "x": -4,
      "y": 5,
      "z": 4,
      "name": "Rock_Ledge_Brick"
    },
    {
      "x": -4,
      "y": 6,
      "z": 4,
      "name": "Cloth_Block_Wool_White"
    },
    {
      "x": -4,
      "y": 7,
      "z": 4,
      "name": "Cloth_Block_Wool_White"
    },
    {
      "x": -4,
      "y": 8,
      "z": 4,
      "name": "Cloth_Block_Wool_White"
    },
    {
      "x": -4,
      "y": 10,
      "z": 4,
      "name": "Rock_Ledge_Brick_Smooth"
    },
    {
      "x": -4,
      "y": 0,
      "z": 5,
      "name": "Rock_Ledge_Brick"
    },
    {
      "x": -4,
      "y": 1,
      "z": 5,
      "name": "Rock_Ledge_Brick_Smooth"
    },
    {
      "x": -4,
      "y": 2,
      "z": 5,
      "name": "Rock_Ledge_Brick_Smooth"
    },
    {
      "x": -4,
      "y": 3,
      "z": 5,
      "name": "Rock_Ledge_Brick_Smooth"
    },
    {
      "x": -4,
      "y": 4,
      "z": 5,
      "name": "Rock_Ledge_Brick_Smooth"
    },
    {
      "x": -4,
      "y": 5,
      "z": 5,
      "name": "Rock_Ledge_Brick"
    },
    {
      "x": -4,
      "y": 6,
      "z": 5,
      "name": "Cloth_Block_Wool_White"
    },
    {
      "x": -4,
      "y": 7,
      "z": 5,
      "name": "Cloth_Block_Wool_White"
    },
    {
      "x": -4,
      "y": 8,
      "z": 5,
      "name": "Cloth_Block_Wool_White"
    },
    {
      "x": -4,
      "y": 9,
      "z": 5,
      "name": "Rock_Ledge_Brick_Smooth"
    },
    {
      "x": -4,
      "y": 10,
      "z": 5,
      "name": "Rock_Ledge_Brick_Smooth"
    },
    {
      "x": -4,
      "y": 0,
      "z": 6,
      "name": "Rock_Ledge_Brick"
    },
    {
      "x": -4,
      "y": 1,
      "z": 6,
      "name": "Deco_Trash_Pile_Large"
    },
    {
      "x": -4,
      "y": 2,
      "z": 6,
      "name": "Deco_Trash"
    },
    {
      "x": -4,
      "y": 5,
      "z": 6,
      "name": "Rock_Ledge_Brick_Smooth"
    },
    {
      "x": -4,
      "y": 6,
      "z": 6,
      "name": "Rock_Ledge_Brick_Smooth"
    },
    {
      "x": -4,
      "y": 7,
      "z": 6,
      "name": "Rock_Ledge_Brick_Stairs"
    },
    {
      "x": -4,
      "y": 8,
      "z": 6,
      "name": "Rock_Ledge_Brick_Smooth"
    },
    {
      "x": -4,
      "y": 0,
      "z": 7,
      "name": "Rock_Ledge_Brick"
    },
    {
      "x": -4,
      "y": 5,
      "z": 7,
      "name": "Rock_Ledge_Brick_Smooth"
    },
    {
      "x": -3,
      "y": 8,
      "z": -5,
      "name": "Rock_Ledge_Brick_Smooth"
    },
    {
      "x": -3,
      "y": 0,
      "z": -4,
      "name": "Rock_Ledge_Brick"
    },
    {
      "x": -3,
      "y": 8,
      "z": -4,
      "name": "Rock_Ledge_Brick_Smooth"
    },
    {
      "x": -3,
      "y": 9,
      "z": -4,
      "name": "Rock_Ledge_Brick_Smooth"
    },
    {
      "x": -3,
      "y": 10,
      "z": -4,
      "name": "Rock_Ledge_Brick_Smooth"
    },
    {
      "x": -3,
      "y": 0,
      "z": -3,
      "name": "Rock_Ledge_Brick"
    },
    {
      "x": -3,
      "y": 8,
      "z": -3,
      "name": "Rock_Ledge_Brick_Smooth"
    },
    {
      "x": -3,
      "y": 10,
      "z": -3,
      "name": "Rock_Ledge_Brick_Smooth"
    },
    {
      "x": -3,
      "y": 0,
      "z": -2,
      "name": "Rock_Ledge_Brick"
    },
    {
      "x": -3,
      "y": 1,
      "z": -2,
      "name": "*Furniture_Temple_Light_Door_State_Definitions_CloseDoorOut",
      "rotation": 2
    },
    {
      "x": -3,
      "y": 2,
      "z": -2,
      "name": "*Furniture_Temple_Light_Door_State_Definitions_CloseDoorOut",
      "filler": 1024,
      "rotation": 2
    },
    {
      "x": -3,
      "y": 3,
      "z": -2,
      "name": "Rock_Ledge_Brick_Smooth"
    },
    {
      "x": -3,
      "y": 7,
      "z": -2,
      "name": "Rock_Ledge_Brick_Smooth"
    },
    {
      "x": -3,
      "y": 10,
      "z": -2,
      "name": "Rock_Ledge_Brick_Smooth"
    },
    {
      "x": -3,
      "y": 0,
      "z": -1,
      "name": "Rock_Ledge_Brick"
    },
    {
      "x": -3,
      "y": 4,
      "z": -1,
      "name": "Rock_Marble_Brick_Smooth"
    },
    {
      "x": -3,
      "y": 5,
      "z": -1,
      "name": "YellowLED"
    },
    {
      "x": -3,
      "y": 6,
      "z": -1,
      "name": "Rock_Marble_Brick_Smooth"
    },
    {
      "x": -3,
      "y": 10,
      "z": -1,
      "name": "Rock_Ledge_Brick_Smooth"
    },
    {
      "x": -3,
      "y": 0,
      "z": 0,
      "name": "Rock_Ledge_Brick"
    },
    {
      "x": -3,
      "y": 4,
      "z": 0,
      "name": "Rock_Marble_Brick_Smooth"
    },
    {
      "x": -3,
      "y": 5,
      "z": 0,
      "name": "Rock_Ledge_Brick"
    },
    {
      "x": -3,
      "y": 6,
      "z": 0,
      "name": "Cloth_Block_Wool_White"
    },
    {
      "x": -3,
      "y": 7,
      "z": 0,
      "name": "Cloth_Block_Wool_White"
    },
    {
      "x": -3,
      "y": 8,
      "z": 0,
      "name": "Cloth_Block_Wool_White"
    },
    {
      "x": -3,
      "y": 10,
      "z": 0,
      "name": "Rock_Ledge_Brick_Smooth"
    },
    {
      "x": -3,
      "y": 0,
      "z": 1,
      "name": "Rock_Ledge_Brick"
    },
    {
      "x": -3,
      "y": 4,
      "z": 1,
      "name": "Rock_Marble_Brick_Smooth"
    },
    {
      "x": -3,
      "y": 5,
      "z": 1,
      "name": "Rock_Ledge_Brick"
    },
    {
      "x": -3,
      "y": 6,
      "z": 1,
      "name": "Furniture_Crude_Bed",
      "components": {
        "Components": {
          "PlacedByInteraction": {
            "WhoPlacedUuid": {
              "$binary": "L6LzkYSjQOWrksT02Y12sg==",
              "$type": "04"
            }
          },
          "RespawnBlock": {}
        }
      },
      "rotation": 1
    },
    {
      "x": -3,
      "y": 9,
      "z": 1,
      "name": "Rock_Marble_Brick_Smooth"
    },
    {
      "x": -3,
      "y": 10,
      "z": 1,
      "name": "Rock_Ledge_Brick_Smooth"
    },
    {
      "x": -3,
      "y": 0,
      "z": 2,
      "name": "Rock_Ledge_Brick"
    },
    {
      "x": -3,
      "y": 1,
      "z": 2,
      "name": "Furniture_Temple_Light_Table",
      "filler": 993,
      "rotation": 1
    },
    {
      "x": -3,
      "y": 4,
      "z": 2,
      "name": "BlueLED"
    },
    {
      "x": -3,
      "y": 5,
      "z": 2,
      "name": "Rock_Ledge_Brick"
    },
    {
      "x": -3,
      "y": 6,
      "z": 2,
      "name": "Block_Spawner_Block",
      "components": {
        "Components": {
          "PlacedByInteraction": {
            "WhoPlacedUuid": {
              "$binary": "L6LzkYSjQOWrksT02Y12sg==",
              "$type": "04"
            }
          },
          "BlockSpawner": {
            "BlockSpawnerId": "RobotCity"
          }
        }
      },
      "rotation": 1
    },
    {
      "x": -3,
      "y": 9,
      "z": 2,
      "name": "Rock_Marble_Brick_Smooth"
    },
    {
      "x": -3,
      "y": 10,
      "z": 2,
      "name": "Rock_Ledge_Brick_Smooth"
    },
    {
      "x": -3,
      "y": 0,
      "z": 3,
      "name": "Rock_Ledge_Brick"
    },
    {
      "x": -3,
      "y": 1,
      "z": 3,
      "name": "Furniture_Temple_Light_Table",
      "filler": 1,
      "rotation": 1
    },
    {
      "x": -3,
      "y": 4,
      "z": 3,
      "name": "Rock_Marble_Brick_Smooth"
    },
    {
      "x": -3,
      "y": 5,
      "z": 3,
      "name": "Rock_Ledge_Brick"
    },
    {
      "x": -3,
      "y": 6,
      "z": 3,
      "name": "Furniture_Temple_Light_Table",
      "filler": 992,
      "rotation": 1
    },
    {
      "x": -3,
      "y": 9,
      "z": 3,
      "name": "Rock_Marble_Brick_Smooth"
    },
    {
      "x": -3,
      "y": 10,
      "z": 3,
      "name": "Rock_Ledge_Brick_Smooth"
    },
    {
      "x": -3,
      "y": 0,
      "z": 4,
      "name": "Rock_Ledge_Brick"
    },
    {
      "x": -3,
      "y": 1,
      "z": 4,
      "name": "Cloth_Block_Wool_White"
    },
    {
      "x": -3,
      "y": 2,
      "z": 4,
      "name": "Cloth_Block_Wool_White"
    },
    {
      "x": -3,
      "y": 3,
      "z": 4,
      "name": "Cloth_Block_Wool_White"
    },
    {
      "x": -3,
      "y": 4,
      "z": 4,
      "name": "Rock_Marble_Brick_Smooth"
    },
    {
      "x": -3,
      "y": 5,
      "z": 4,
      "name": "Rock_Ledge_Brick"
    },
    {
      "x": -3,
      "y": 6,
      "z": 4,
      "name": "Furniture_Temple_Light_Table",
      "rotation": 1
    },
    {
      "x": -3,
      "y": 9,
      "z": 4,
      "name": "Rock_Marble_Brick_Smooth"
    },
    {
      "x": -3,
      "y": 10,
      "z": 4,
      "name": "Rock_Ledge_Brick_Smooth"
    },
    {
      "x": -3,
      "y": 0,
      "z": 5,
      "name": "Rock_Ledge_Brick"
    },
    {
      "x": -3,
      "y": 1,
      "z": 5,
      "name": "Rock_Ledge_Brick_Smooth"
    },
    {
      "x": -3,
      "y": 2,
      "z": 5,
      "name": "Rock_Ledge_Brick_Smooth"
    },
    {
      "x": -3,
      "y": 3,
      "z": 5,
      "name": "Rock_Ledge_Brick_Smooth"
    },
    {
      "x": -3,
      "y": 4,
      "z": 5,
      "name": "Rock_Ledge_Brick_Smooth"
    },
    {
      "x": -3,
      "y": 5,
      "z": 5,
      "name": "Rock_Ledge_Brick"
    },
    {
      "x": -3,
      "y": 6,
      "z": 5,
      "name": "Cloth_Block_Wool_White"
    },
    {
      "x": -3,
      "y": 7,
      "z": 5,
      "name": "Cloth_Block_Wool_White"
    },
    {
      "x": -3,
      "y": 8,
      "z": 5,
      "name": "Cloth_Block_Wool_White"
    },
    {
      "x": -3,
      "y": 9,
      "z": 5,
      "name": "Rock_Ledge_Brick_Smooth"
    },
    {
      "x": -3,
      "y": 10,
      "z": 5,
      "name": "Rock_Ledge_Brick_Smooth"
    },
    {
      "x": -3,
      "y": 0,
      "z": 6,
      "name": "Rock_Ledge_Brick"
    },
    {
      "x": -3,
      "y": 5,
      "z": 6,
      "name": "Rock_Ledge_Brick_Smooth"
    },
    {
      "x": -3,
      "y": 6,
      "z": 6,
      "name": "Rock_Ledge_Brick_Smooth"
    },
    {
      "x": -3,
      "y": 7,
      "z": 6,
      "name": "Rock_Ledge_Brick_Stairs"
    },
    {
      "x": -3,
      "y": 8,
      "z": 6,
      "name": "Rock_Ledge_Brick_Smooth"
    },
    {
      "x": -3,
      "y": 0,
      "z": 7,
      "name": "Rock_Ledge_Brick"
    },
    {
      "x": -3,
      "y": 5,
      "z": 7,
      "name": "Rock_Ledge_Brick_Smooth"
    },
    {
      "x": -2,
      "y": 8,
      "z": -5,
      "name": "Rock_Ledge_Brick_Smooth"
    },
    {
      "x": -2,
      "y": 0,
      "z": -4,
      "name": "Rock_Ledge_Brick"
    },
    {
      "x": -2,
      "y": 8,
      "z": -4,
      "name": "Rock_Ledge_Brick_Smooth"
    },
    {
      "x": -2,
      "y": 9,
      "z": -4,
      "name": "Rock_Ledge_Brick_Smooth"
    },
    {
      "x": -2,
      "y": 10,
      "z": -4,
      "name": "Rock_Ledge_Brick_Smooth"
    },
    {
      "x": -2,
      "y": 0,
      "z": -3,
      "name": "Rock_Ledge_Brick"
    },
    {
      "x": -2,
      "y": 8,
      "z": -3,
      "name": "Rock_Ledge_Brick_Smooth"
    },
    {
      "x": -2,
      "y": 10,
      "z": -3,
      "name": "Rock_Ledge_Brick_Smooth"
    },
    {
      "x": -2,
      "y": 0,
      "z": -2,
      "name": "Rock_Ledge_Brick"
    },
    {
      "x": -2,
      "y": 1,
      "z": -2,
      "name": "Rock_Ledge_Brick_Smooth"
    },
    {
      "x": -2,
      "y": 2,
      "z": -2,
      "name": "Rock_Ledge_Brick_Smooth"
    },
    {
      "x": -2,
      "y": 3,
      "z": -2,
      "name": "Rock_Ledge_Brick_Smooth"
    },
    {
      "x": -2,
      "y": 7,
      "z": -2,
      "name": "Rock_Ledge_Brick_Smooth"
    },
    {
      "x": -2,
      "y": 10,
      "z": -2,
      "name": "Rock_Ledge_Brick_Smooth"
    },
    {
      "x": -2,
      "y": 0,
      "z": -1,
      "name": "Rock_Ledge_Brick"
    },
    {
      "x": -2,
      "y": 1,
      "z": -1,
      "name": "Cloth_Block_Wool_White"
    },
    {
      "x": -2,
      "y": 2,
      "z": -1,
      "name": "Cloth_Block_Wool_White"
    },
    {
      "x": -2,
      "y": 3,
      "z": -1,
      "name": "Cloth_Block_Wool_White"
    },
    {
      "x": -2,
      "y": 4,
      "z": -1,
      "name": "Rock_Marble_Brick_Smooth"
    },
    {
      "x": -2,
      "y": 5,
      "z": -1,
      "name": "Rock_Marble_Brick_Smooth"
    },
    {
      "x": -2,
      "y": 6,
      "z": -1,
      "name": "Rock_Marble_Brick_Smooth"
    },
    {
      "x": -2,
      "y": 10,
      "z": -1,
      "name": "Rock_Ledge_Brick_Smooth"
    },
    {
      "x": -2,
      "y": 0,
      "z": 0,
      "name": "Rock_Ledge_Brick"
    },
    {
      "x": -2,
      "y": 4,
      "z": 0,
      "name": "Rock_Marble_Brick_Smooth"
    },
    {
      "x": -2,
      "y": 5,
      "z": 0,
      "name": "Rock_Ledge_Brick"
    },
    {
      "x": -2,
      "y": 6,
      "z": 0,
      "name": "Cloth_Block_Wool_White"
    },
    {
      "x": -2,
      "y": 7,
      "z": 0,
      "name": "Cloth_Block_Wool_White"
    },
    {
      "x": -2,
      "y": 8,
      "z": 0,
      "name": "Cloth_Block_Wool_White"
    },
    {
      "x": -2,
      "y": 10,
      "z": 0,
      "name": "Rock_Ledge_Brick_Smooth"
    },
    {
      "x": -2,
      "y": 0,
      "z": 1,
      "name": "Rock_Ledge_Brick"
    },
    {
      "x": -2,
      "y": 4,
      "z": 1,
      "name": "Rock_Marble_Brick_Smooth"
    },
    {
      "x": -2,
      "y": 5,
      "z": 1,
      "name": "Rock_Ledge_Brick"
    },
    {
      "x": -2,
      "y": 6,
      "z": 1,
      "name": "Furniture_Crude_Bed",
      "filler": 1,
      "rotation": 1
    },
    {
      "x": -2,
      "y": 9,
      "z": 1,
      "name": "Rock_Marble_Brick_Smooth"
    },
    {
      "x": -2,
      "y": 10,
      "z": 1,
      "name": "Rock_Ledge_Brick_Smooth"
    },
    {
      "x": -2,
      "y": 0,
      "z": 2,
      "name": "Rock_Ledge_Brick"
    },
    {
      "x": -2,
      "y": 1,
      "z": 2,
      "name": "Furniture_Village_Bed",
      "filler": 30,
      "rotation": 3
    },
    {
      "x": -2,
      "y": 2,
      "z": 2,
      "name": "Furniture_Village_Bed",
      "filler": 1054,
      "rotation": 3
    },
    {
      "x": -2,
      "y": 4,
      "z": 2,
      "name": "Rock_Marble_Brick_Smooth"
    },
    {
      "x": -2,
      "y": 5,
      "z": 2,
      "name": "Rock_Ledge_Brick"
    },
    {
      "x": -2,
      "y": 9,
      "z": 2,
      "name": "BlueLED"
    },
    {
      "x": -2,
      "y": 10,
      "z": 2,
      "name": "Rock_Ledge_Brick_Smooth"
    },
    {
      "x": -2,
      "y": 0,
      "z": 3,
      "name": "Rock_Ledge_Brick"
    },
    {
      "x": -2,
      "y": 1,
      "z": 3,
      "name": "Furniture_Village_Bed",
      "filler": 62,
      "rotation": 3
    },
    {
      "x": -2,
      "y": 2,
      "z": 3,
      "name": "Furniture_Village_Bed",
      "filler": 1086,
      "rotation": 3
    },
    {
      "x": -2,
      "y": 4,
      "z": 3,
      "name": "Rock_Marble_Brick_Smooth"
    },
    {
      "x": -2,
      "y": 5,
      "z": 3,
      "name": "Rock_Ledge_Brick"
    },
    {
      "x": -2,
      "y": 6,
      "z": 3,
      "name": "Furniture_Temple_Light_Table",
      "filler": 993,
      "rotation": 1
    },
    {
      "x": -2,
      "y": 9,
      "z": 3,
      "name": "Rock_Marble_Brick_Smooth"
    },
    {
      "x": -2,
      "y": 10,
      "z": 3,
      "name": "Rock_Ledge_Brick_Smooth"
    },
    {
      "x": -2,
      "y": 0,
      "z": 4,
      "name": "Rock_Ledge_Brick"
    },
    {
      "x": -2,
      "y": 1,
      "z": 4,
      "name": "Cloth_Block_Wool_White"
    },
    {
      "x": -2,
      "y": 2,
      "z": 4,
      "name": "Cloth_Block_Wool_White"
    },
    {
      "x": -2,
      "y": 3,
      "z": 4,
      "name": "Cloth_Block_Wool_White"
    },
    {
      "x": -2,
      "y": 4,
      "z": 4,
      "name": "Rock_Marble_Brick_Smooth"
    },
    {
      "x": -2,
      "y": 5,
      "z": 4,
      "name": "Rock_Ledge_Brick"
    },
    {
      "x": -2,
      "y": 6,
      "z": 4,
      "name": "Furniture_Temple_Light_Table",
      "filler": 1,
      "rotation": 1
    },
    {
      "x": -2,
      "y": 9,
      "z": 4,
      "name": "Rock_Marble_Brick_Smooth"
    },
    {
      "x": -2,
      "y": 10,
      "z": 4,
      "name": "Rock_Ledge_Brick_Smooth"
    },
    {
      "x": -2,
      "y": 0,
      "z": 5,
      "name": "Rock_Ledge_Brick"
    },
    {
      "x": -2,
      "y": 1,
      "z": 5,
      "name": "Rock_Ledge_Brick_Smooth"
    },
    {
      "x": -2,
      "y": 2,
      "z": 5,
      "name": "Rock_Ledge_Brick_Smooth"
    },
    {
      "x": -2,
      "y": 3,
      "z": 5,
      "name": "Rock_Ledge_Brick_Smooth"
    },
    {
      "x": -2,
      "y": 4,
      "z": 5,
      "name": "Rock_Ledge_Brick_Smooth"
    },
    {
      "x": -2,
      "y": 5,
      "z": 5,
      "name": "Rock_Ledge_Brick"
    },
    {
      "x": -2,
      "y": 6,
      "z": 5,
      "name": "Cloth_Block_Wool_White"
    },
    {
      "x": -2,
      "y": 7,
      "z": 5,
      "name": "Cloth_Block_Wool_White"
    },
    {
      "x": -2,
      "y": 8,
      "z": 5,
      "name": "Cloth_Block_Wool_White"
    },
    {
      "x": -2,
      "y": 9,
      "z": 5,
      "name": "Rock_Ledge_Brick_Smooth"
    },
    {
      "x": -2,
      "y": 10,
      "z": 5,
      "name": "Rock_Ledge_Brick_Smooth"
    },
    {
      "x": -2,
      "y": 0,
      "z": 6,
      "name": "Rock_Ledge_Brick"
    },
    {
      "x": -2,
      "y": 1,
      "z": 6,
      "name": "Deco_Trash_Pile_Large"
    },
    {
      "x": -2,
      "y": 5,
      "z": 6,
      "name": "Rock_Ledge_Brick_Smooth"
    },
    {
      "x": -2,
      "y": 6,
      "z": 6,
      "name": "Rock_Ledge_Brick_Smooth"
    },
    {
      "x": -2,
      "y": 7,
      "z": 6,
      "name": "Rock_Ledge_Brick_Stairs"
    },
    {
      "x": -2,
      "y": 8,
      "z": 6,
      "name": "Rock_Ledge_Brick_Smooth"
    },
    {
      "x": -2,
      "y": 0,
      "z": 7,
      "name": "Rock_Ledge_Brick"
    },
    {
      "x": -2,
      "y": 5,
      "z": 7,
      "name": "Rock_Ledge_Brick_Smooth"
    },
    {
      "x": -1,
      "y": 8,
      "z": -5,
      "name": "Rock_Ledge_Brick_Smooth"
    },
    {
      "x": -1,
      "y": 0,
      "z": -4,
      "name": "Rock_Ledge_Brick"
    },
    {
      "x": -1,
      "y": 8,
      "z": -4,
      "name": "Rock_Ledge_Brick_Smooth"
    },
    {
      "x": -1,
      "y": 9,
      "z": -4,
      "name": "Rock_Ledge_Brick_Smooth"
    },
    {
      "x": -1,
      "y": 10,
      "z": -4,
      "name": "Rock_Ledge_Brick_Smooth"
    },
    {
      "x": -1,
      "y": 0,
      "z": -3,
      "name": "Rock_Ledge_Brick"
    },
    {
      "x": -1,
      "y": 8,
      "z": -3,
      "name": "Rock_Ledge_Brick_Smooth"
    },
    {
      "x": -1,
      "y": 10,
      "z": -3,
      "name": "Rock_Ledge_Brick_Smooth"
    },
    {
      "x": -1,
      "y": 0,
      "z": -2,
      "name": "Rock_Ledge_Brick"
    },
    {
      "x": -1,
      "y": 1,
      "z": -2,
      "name": "Soil_Clay_Smooth_Black"
    },
    {
      "x": -1,
      "y": 2,
      "z": -2,
      "name": "Soil_Clay_Smooth_Black"
    },
    {
      "x": -1,
      "y": 3,
      "z": -2,
      "name": "Soil_Clay_Smooth_Black"
    },
    {
      "x": -1,
      "y": 4,
      "z": -2,
      "name": "Soil_Clay_Smooth_Black"
    },
    {
      "x": -1,
      "y": 5,
      "z": -2,
      "name": "Soil_Clay_Smooth_Black"
    },
    {
      "x": -1,
      "y": 6,
      "z": -2,
      "name": "Soil_Clay_Smooth_Black"
    },
    {
      "x": -1,
      "y": 7,
      "z": -2,
      "name": "Soil_Clay_Smooth_Black"
    },
    {
      "x": -1,
      "y": 10,
      "z": -2,
      "name": "Rock_Ledge_Brick_Smooth"
    },
    {
      "x": -1,
      "y": 0,
      "z": -1,
      "name": "Rock_Ledge_Brick"
    },
    {
      "x": -1,
      "y": 1,
      "z": -1,
      "name": "Cloth_Block_Wool_White"
    },
    {
      "x": -1,
      "y": 2,
      "z": -1,
      "name": "Cloth_Block_Wool_White"
    },
    {
      "x": -1,
      "y": 3,
      "z": -1,
      "name": "Cloth_Block_Wool_White"
    },
    {
      "x": -1,
      "y": 4,
      "z": -1,
      "name": "Rock_Marble_Brick_Smooth"
    },
    {
      "x": -1,
      "y": 5,
      "z": -1,
      "name": "Rock_Ledge_Brick"
    },
    {
      "x": -1,
      "y": 10,
      "z": -1,
      "name": "Rock_Ledge_Brick_Smooth"
    },
    {
      "x": -1,
      "y": 0,
      "z": 0,
      "name": "Rock_Ledge_Brick"
    },
    {
      "x": -1,
      "y": 4,
      "z": 0,
      "name": "Rock_Marble_Brick_Smooth"
    },
    {
      "x": -1,
      "y": 5,
      "z": 0,
      "name": "Rock_Ledge_Brick"
    },
    {
      "x": -1,
      "y": 6,
      "z": 0,
      "name": "Cloth_Block_Wool_White"
    },
    {
      "x": -1,
      "y": 7,
      "z": 0,
      "name": "Cloth_Block_Wool_White"
    },
    {
      "x": -1,
      "y": 8,
      "z": 0,
      "name": "Cloth_Block_Wool_White"
    },
    {
      "x": -1,
      "y": 10,
      "z": 0,
      "name": "Rock_Ledge_Brick_Smooth"
    },
    {
      "x": -1,
      "y": 0,
      "z": 1,
      "name": "Rock_Ledge_Brick"
    },
    {
      "x": -1,
      "y": 4,
      "z": 1,
      "name": "BlueLED"
    },
    {
      "x": -1,
      "y": 5,
      "z": 1,
      "name": "Rock_Ledge_Brick"
    },
    {
      "x": -1,
      "y": 9,
      "z": 1,
      "name": "Rock_Marble_Brick_Smooth"
    },
    {
      "x": -1,
      "y": 10,
      "z": 1,
      "name": "Rock_Ledge_Brick_Smooth"
    },
    {
      "x": -1,
      "y": 0,
      "z": 2,
      "name": "Rock_Ledge_Brick"
    },
    {
      "x": -1,
      "y": 1,
      "z": 2,
      "name": "Furniture_Village_Bed",
      "filler": 31,
      "rotation": 3
    },
    {
      "x": -1,
      "y": 2,
      "z": 2,
      "name": "Furniture_Village_Bed",
      "filler": 1055,
      "rotation": 3
    },
    {
      "x": -1,
      "y": 4,
      "z": 2,
      "name": "Rock_Marble_Brick_Smooth"
    },
    {
      "x": -1,
      "y": 5,
      "z": 2,
      "name": "Rock_Ledge_Brick"
    },
    {
      "x": -1,
      "y": 9,
      "z": 2,
      "name": "Rock_Marble_Brick_Smooth"
    },
    {
      "x": -1,
      "y": 10,
      "z": 2,
      "name": "Rock_Ledge_Brick_Smooth"
    },
    {
      "x": -1,
      "y": 0,
      "z": 3,
      "name": "Rock_Ledge_Brick"
    },
    {
      "x": -1,
      "y": 1,
      "z": 3,
      "name": "Furniture_Village_Bed",
      "filler": 63,
      "rotation": 3
    },
    {
      "x": -1,
      "y": 2,
      "z": 3,
      "name": "Furniture_Village_Bed",
      "filler": 1087,
      "rotation": 3
    },
    {
      "x": -1,
      "y": 4,
      "z": 3,
      "name": "Rock_Marble_Brick_Smooth"
    },
    {
      "x": -1,
      "y": 5,
      "z": 3,
      "name": "Rock_Ledge_Brick"
    },
    {
      "x": -1,
      "y": 9,
      "z": 3,
      "name": "BlueLED"
    },
    {
      "x": -1,
      "y": 10,
      "z": 3,
      "name": "Rock_Ledge_Brick_Smooth"
    },
    {
      "x": -1,
      "y": 0,
      "z": 4,
      "name": "Rock_Ledge_Brick"
    },
    {
      "x": -1,
      "y": 1,
      "z": 4,
      "name": "Cloth_Block_Wool_White"
    },
    {
      "x": -1,
      "y": 2,
      "z": 4,
      "name": "Cloth_Block_Wool_White"
    },
    {
      "x": -1,
      "y": 3,
      "z": 4,
      "name": "Cloth_Block_Wool_White"
    },
    {
      "x": -1,
      "y": 4,
      "z": 4,
      "name": "Rock_Marble_Brick_Smooth"
    },
    {
      "x": -1,
      "y": 5,
      "z": 4,
      "name": "Rock_Ledge_Brick"
    },
    {
      "x": -1,
      "y": 6,
      "z": 4,
      "name": "Furniture_Temple_Light_Stool",
      "rotation": 2
    },
    {
      "x": -1,
      "y": 9,
      "z": 4,
      "name": "Rock_Marble_Brick_Smooth"
    },
    {
      "x": -1,
      "y": 10,
      "z": 4,
      "name": "Rock_Ledge_Brick_Smooth"
    },
    {
      "x": -1,
      "y": 0,
      "z": 5,
      "name": "Rock_Ledge_Brick"
    },
    {
      "x": -1,
      "y": 1,
      "z": 5,
      "name": "Rock_Ledge_Brick_Smooth"
    },
    {
      "x": -1,
      "y": 2,
      "z": 5,
      "name": "Rock_Ledge_Brick_Smooth"
    },
    {
      "x": -1,
      "y": 3,
      "z": 5,
      "name": "Rock_Ledge_Brick_Smooth"
    },
    {
      "x": -1,
      "y": 4,
      "z": 5,
      "name": "Rock_Ledge_Brick_Smooth"
    },
    {
      "x": -1,
      "y": 5,
      "z": 5,
      "name": "Rock_Ledge_Brick"
    },
    {
      "x": -1,
      "y": 6,
      "z": 5,
      "name": "Cloth_Block_Wool_White"
    },
    {
      "x": -1,
      "y": 7,
      "z": 5,
      "name": "Cloth_Block_Wool_White"
    },
    {
      "x": -1,
      "y": 8,
      "z": 5,
      "name": "Cloth_Block_Wool_White"
    },
    {
      "x": -1,
      "y": 9,
      "z": 5,
      "name": "Rock_Ledge_Brick_Smooth"
    },
    {
      "x": -1,
      "y": 10,
      "z": 5,
      "name": "Rock_Ledge_Brick_Smooth"
    },
    {
      "x": -1,
      "y": 0,
      "z": 6,
      "name": "Rock_Ledge_Brick"
    },
    {
      "x": -1,
      "y": 5,
      "z": 6,
      "name": "Rock_Ledge_Brick_Smooth"
    },
    {
      "x": -1,
      "y": 6,
      "z": 6,
      "name": "Rock_Ledge_Brick_Smooth"
    },
    {
      "x": -1,
      "y": 7,
      "z": 6,
      "name": "Rock_Ledge_Brick_Stairs"
    },
    {
      "x": -1,
      "y": 8,
      "z": 6,
      "name": "Rock_Ledge_Brick_Smooth"
    },
    {
      "x": -1,
      "y": 0,
      "z": 7,
      "name": "Rock_Ledge_Brick"
    },
    {
      "x": -1,
      "y": 5,
      "z": 7,
      "name": "Rock_Ledge_Brick_Smooth"
    },
    {
      "x": 0,
      "y": 0,
      "z": -5,
      "name": "Rock_Ledge_Brick"
    },
    {
      "x": 0,
      "y": 8,
      "z": -5,
      "name": "Rock_Ledge_Brick_Smooth"
    },
    {
      "x": 0,
      "y": 0,
      "z": -4,
      "name": "Rock_Ledge_Brick"
    },
    {
      "x": 0,
      "y": 8,
      "z": -4,
      "name": "Rock_Ledge_Brick_Smooth"
    },
    {
      "x": 0,
      "y": 9,
      "z": -4,
      "name": "Rock_Ledge_Brick_Smooth"
    },
    {
      "x": 0,
      "y": 10,
      "z": -4,
      "name": "Rock_Ledge_Brick_Smooth"
    },
    {
      "x": 0,
      "y": 0,
      "z": -3,
      "name": "Rock_Ledge_Brick"
    },
    {
      "x": 0,
      "y": 1,
      "z": -3,
      "name": "Soil_Clay_Smooth_Black"
    },
    {
      "x": 0,
      "y": 2,
      "z": -3,
      "name": "YellowLED"
    },
    {
      "x": 0,
      "y": 3,
      "z": -3,
      "name": "YellowLED"
    },
    {
      "x": 0,
      "y": 4,
      "z": -3,
      "name": "YellowLED"
    },
    {
      "x": 0,
      "y": 5,
      "z": -3,
      "name": "YellowLED"
    },
    {
      "x": 0,
      "y": 6,
      "z": -3,
      "name": "YellowLED"
    },
    {
      "x": 0,
      "y": 7,
      "z": -3,
      "name": "Soil_Clay_Smooth_Black"
    },
    {
      "x": 0,
      "y": 8,
      "z": -3,
      "name": "Rock_Ledge_Brick_Smooth"
    },
    {
      "x": 0,
      "y": 10,
      "z": -3,
      "name": "Rock_Ledge_Brick_Smooth"
    },
    {
      "x": 0,
      "y": 0,
      "z": -2,
      "name": "Rock_Ledge_Brick"
    },
    {
      "x": 0,
      "y": 1,
      "z": -2,
      "name": "Survival_Trap_Spike_Iron"
    },
    {
      "x": 0,
      "y": 2,
      "z": -2,
      "name": "Survival_Trap_Spike_Iron",
      "rotation": 5
    },
    {
      "x": 0,
      "y": 10,
      "z": -2,
      "name": "Rock_Ledge_Brick_Smooth"
    },
    {
      "x": 0,
      "y": 0,
      "z": -1,
      "name": "Rock_Ledge_Brick"
    },
    {
      "x": 0,
      "y": 1,
      "z": -1,
      "name": "Cloth_Block_Wool_White"
    },
    {
      "x": 0,
      "y": 2,
      "z": -1,
      "name": "Cloth_Block_Wool_White"
    },
    {
      "x": 0,
      "y": 3,
      "z": -1,
      "name": "Cloth_Block_Wool_White"
    },
    {
      "x": 0,
      "y": 4,
      "z": -1,
      "name": "Rock_Marble_Brick_Smooth"
    },
    {
      "x": 0,
      "y": 5,
      "z": -1,
      "name": "Rock_Ledge_Brick"
    },
    {
      "x": 0,
      "y": 10,
      "z": -1,
      "name": "Rock_Ledge_Brick_Smooth"
    },
    {
      "x": 0,
      "y": 0,
      "z": 0,
      "name": "Rock_Ledge_Brick"
    },
    {
      "x": 0,
      "y": 1,
      "z": 0,
      "name": "Furniture_Temple_Light_Wardrobe",
      "filler": 992,
      "rotation": 3
    },
    {
      "x": 0,
      "y": 2,
      "z": 0,
      "name": "Furniture_Temple_Light_Wardrobe",
      "filler": 2016,
      "rotation": 3
    },
    {
      "x": 0,
      "y": 4,
      "z": 0,
      "name": "Rock_Marble_Brick_Smooth"
    },
    {
      "x": 0,
      "y": 5,
      "z": 0,
      "name": "Rock_Ledge_Brick"
    },
    {
      "x": 0,
      "y": 6,
      "z": 0,
      "name": "Cloth_Block_Wool_White"
    },
    {
      "x": 0,
      "y": 7,
      "z": 0,
      "name": "Cloth_Block_Wool_White"
    },
    {
      "x": 0,
      "y": 8,
      "z": 0,
      "name": "Cloth_Block_Wool_White"
    },
    {
      "x": 0,
      "y": 10,
      "z": 0,
      "name": "Rock_Ledge_Brick_Smooth"
    },
    {
      "x": 0,
      "y": 0,
      "z": 1,
      "name": "Rock_Ledge_Brick"
    },
    {
      "x": 0,
      "y": 1,
      "z": 1,
      "name": "Furniture_Temple_Light_Wardrobe",
      "rotation": 3
    },
    {
      "x": 0,
      "y": 2,
      "z": 1,
      "name": "Furniture_Temple_Light_Wardrobe",
      "filler": 1024,
      "rotation": 3
    },
    {
      "x": 0,
      "y": 4,
      "z": 1,
      "name": "Rock_Marble_Brick_Smooth"
    },
    {
      "x": 0,
      "y": 5,
      "z": 1,
      "name": "Rock_Ledge_Brick"
    },
    {
      "x": 0,
      "y": 6,
      "z": 1,
      "name": "Furniture_Temple_Light_Wardrobe",
      "filler": 992,
      "rotation": 3
    },
    {
      "x": 0,
      "y": 7,
      "z": 1,
      "name": "Furniture_Temple_Light_Wardrobe",
      "filler": 2016,
      "rotation": 3
    },
    {
      "x": 0,
      "y": 9,
      "z": 1,
      "name": "Rock_Marble_Brick_Smooth"
    },
    {
      "x": 0,
      "y": 10,
      "z": 1,
      "name": "Rock_Ledge_Brick_Smooth"
    },
    {
      "x": 0,
      "y": 0,
      "z": 2,
      "name": "Rock_Ledge_Brick"
    },
    {
      "x": 0,
      "y": 1,
      "z": 2,
      "name": "Furniture_Village_Bed",
      "components": {
        "Components": {
          "PlacedByInteraction": {
            "WhoPlacedUuid": {
              "$binary": "L6LzkYSjQOWrksT02Y12sg==",
              "$type": "04"
            }
          },
          "RespawnBlock": {}
        }
      },
      "rotation": 3
    },
    {
      "x": 0,
      "y": 2,
      "z": 2,
      "name": "Furniture_Village_Bed",
      "filler": 1024,
      "rotation": 3
    },
    {
      "x": 0,
      "y": 4,
      "z": 2,
      "name": "Rock_Marble_Brick_Smooth"
    },
    {
      "x": 0,
      "y": 5,
      "z": 2,
      "name": "Rock_Ledge_Brick"
    },
    {
      "x": 0,
      "y": 6,
      "z": 2,
      "name": "Furniture_Temple_Light_Wardrobe",
      "rotation": 3
    },
    {
      "x": 0,
      "y": 7,
      "z": 2,
      "name": "Furniture_Temple_Light_Wardrobe",
      "filler": 1024,
      "rotation": 3
    },
    {
      "x": 0,
      "y": 9,
      "z": 2,
      "name": "Rock_Marble_Brick_Smooth"
    },
    {
      "x": 0,
      "y": 10,
      "z": 2,
      "name": "Rock_Ledge_Brick_Smooth"
    },
    {
      "x": 0,
      "y": 0,
      "z": 3,
      "name": "Rock_Ledge_Brick"
    },
    {
      "x": 0,
      "y": 1,
      "z": 3,
      "name": "Furniture_Village_Bed",
      "filler": 32,
      "rotation": 3
    },
    {
      "x": 0,
      "y": 2,
      "z": 3,
      "name": "Furniture_Village_Bed",
      "filler": 1056,
      "rotation": 3
    },
    {
      "x": 0,
      "y": 4,
      "z": 3,
      "name": "Rock_Marble_Brick_Smooth"
    },
    {
      "x": 0,
      "y": 5,
      "z": 3,
      "name": "Rock_Ledge_Brick"
    },
    {
      "x": 0,
      "y": 9,
      "z": 3,
      "name": "Rock_Marble_Brick_Smooth"
    },
    {
      "x": 0,
      "y": 10,
      "z": 3,
      "name": "Rock_Ledge_Brick_Smooth"
    },
    {
      "x": 0,
      "y": 0,
      "z": 4,
      "name": "Rock_Ledge_Brick"
    },
    {
      "x": 0,
      "y": 1,
      "z": 4,
      "name": "Cloth_Block_Wool_White"
    },
    {
      "x": 0,
      "y": 2,
      "z": 4,
      "name": "Cloth_Block_Wool_White"
    },
    {
      "x": 0,
      "y": 3,
      "z": 4,
      "name": "Cloth_Block_Wool_White"
    },
    {
      "x": 0,
      "y": 4,
      "z": 4,
      "name": "Rock_Marble_Brick_Smooth"
    },
    {
      "x": 0,
      "y": 5,
      "z": 4,
      "name": "Rock_Ledge_Brick"
    },
    {
      "x": 0,
      "y": 9,
      "z": 4,
      "name": "Rock_Marble_Brick_Smooth"
    },
    {
      "x": 0,
      "y": 10,
      "z": 4,
      "name": "Rock_Ledge_Brick_Smooth"
    },
    {
      "x": 0,
      "y": 0,
      "z": 5,
      "name": "Rock_Ledge_Brick"
    },
    {
      "x": 0,
      "y": 1,
      "z": 5,
      "name": "Rock_Ledge_Brick_Smooth"
    },
    {
      "x": 0,
      "y": 2,
      "z": 5,
      "name": "Rock_Ledge_Brick_Smooth"
    },
    {
      "x": 0,
      "y": 3,
      "z": 5,
      "name": "Rock_Ledge_Brick_Smooth"
    },
    {
      "x": 0,
      "y": 4,
      "z": 5,
      "name": "Rock_Ledge_Brick_Smooth"
    },
    {
      "x": 0,
      "y": 5,
      "z": 5,
      "name": "Rock_Ledge_Brick"
    },
    {
      "x": 0,
      "y": 6,
      "z": 5,
      "name": "Cloth_Block_Wool_White"
    },
    {
      "x": 0,
      "y": 7,
      "z": 5,
      "name": "Cloth_Block_Wool_White"
    },
    {
      "x": 0,
      "y": 8,
      "z": 5,
      "name": "Cloth_Block_Wool_White"
    },
    {
      "x": 0,
      "y": 9,
      "z": 5,
      "name": "Rock_Ledge_Brick_Smooth"
    },
    {
      "x": 0,
      "y": 10,
      "z": 5,
      "name": "Rock_Ledge_Brick_Smooth"
    },
    {
      "x": 0,
      "y": 0,
      "z": 6,
      "name": "Rock_Ledge_Brick"
    },
    {
      "x": 0,
      "y": 5,
      "z": 6,
      "name": "Rock_Ledge_Brick_Smooth"
    },
    {
      "x": 0,
      "y": 6,
      "z": 6,
      "name": "Rock_Ledge_Brick_Smooth"
    },
    {
      "x": 0,
      "y": 7,
      "z": 6,
      "name": "Rock_Ledge_Brick_Stairs"
    },
    {
      "x": 0,
      "y": 8,
      "z": 6,
      "name": "Rock_Ledge_Brick_Smooth"
    },
    {
      "x": 0,
      "y": 0,
      "z": 7,
      "name": "Rock_Ledge_Brick"
    },
    {
      "x": 0,
      "y": 1,
      "z": 7,
      "name": "Rock_Ledge_Brick_Pillar_Base"
    },
    {
      "x": 0,
      "y": 2,
      "z": 7,
      "name": "Rock_Ledge_Brick_Pillar_Base",
      "rotation": 8
    },
    {
      "x": 0,
      "y": 3,
      "z": 7,
      "name": "Rock_Ledge_Brick_Pillar_Base"
    },
    {
      "x": 0,
      "y": 4,
      "z": 7,
      "name": "Rock_Ledge_Brick_Pillar_Base",
      "rotation": 8
    },
    {
      "x": 0,
      "y": 5,
      "z": 7,
      "name": "Rock_Ledge_Brick_Smooth"
    },
    {
      "x": 1,
      "y": 0,
      "z": -5,
      "name": "Rock_Ledge_Brick"
    },
    {
      "x": 1,
      "y": 8,
      "z": -5,
      "name": "Rock_Ledge_Brick_Smooth"
    },
    {
      "x": 1,
      "y": 0,
      "z": -4,
      "name": "Rock_Ledge_Brick"
    },
    {
      "x": 1,
      "y": 1,
      "z": -4,
      "name": "Soil_Clay_Smooth_Black"
    },
    {
      "x": 1,
      "y": 2,
      "z": -4,
      "name": "Soil_Clay_Smooth_Black"
    },
    {
      "x": 1,
      "y": 3,
      "z": -4,
      "name": "Soil_Clay_Smooth_Black"
    },
    {
      "x": 1,
      "y": 4,
      "z": -4,
      "name": "Soil_Clay_Smooth_Black"
    },
    {
      "x": 1,
      "y": 5,
      "z": -4,
      "name": "Soil_Clay_Smooth_Black"
    },
    {
      "x": 1,
      "y": 6,
      "z": -4,
      "name": "Soil_Clay_Smooth_Black"
    },
    {
      "x": 1,
      "y": 7,
      "z": -4,
      "name": "Soil_Clay_Smooth_Black"
    },
    {
      "x": 1,
      "y": 8,
      "z": -4,
      "name": "Rock_Ledge_Brick_Smooth"
    },
    {
      "x": 1,
      "y": 9,
      "z": -4,
      "name": "Rock_Ledge_Brick_Smooth"
    },
    {
      "x": 1,
      "y": 10,
      "z": -4,
      "name": "Rock_Ledge_Brick_Smooth"
    },
    {
      "x": 1,
      "y": 0,
      "z": -3,
      "name": "Rock_Ledge_Brick"
    },
    {
      "x": 1,
      "y": 1,
      "z": -3,
      "name": "Soil_Clay_Smooth_Black"
    },
    {
      "x": 1,
      "y": 2,
      "z": -3,
      "name": "Soil_Clay_Smooth_Black"
    },
    {
      "x": 1,
      "y": 3,
      "z": -3,
      "name": "Soil_Clay_Smooth_Black"
    },
    {
      "x": 1,
      "y": 4,
      "z": -3,
      "name": "Soil_Clay_Smooth_Black"
    },
    {
      "x": 1,
      "y": 5,
      "z": -3,
      "name": "Soil_Clay_Smooth_Black"
    },
    {
      "x": 1,
      "y": 6,
      "z": -3,
      "name": "Soil_Clay_Smooth_Black"
    },
    {
      "x": 1,
      "y": 7,
      "z": -3,
      "name": "Soil_Clay_Smooth_Black"
    },
    {
      "x": 1,
      "y": 8,
      "z": -3,
      "name": "Rock_Ledge_Brick_Smooth"
    },
    {
      "x": 1,
      "y": 10,
      "z": -3,
      "name": "Rock_Ledge_Brick_Smooth"
    },
    {
      "x": 1,
      "y": 0,
      "z": -2,
      "name": "Rock_Ledge_Brick"
    },
    {
      "x": 1,
      "y": 1,
      "z": -2,
      "name": "Survival_Trap_Spike_Iron"
    },
    {
      "x": 1,
      "y": 2,
      "z": -2,
      "name": "Survival_Trap_Spike_Iron",
      "rotation": 7
    },
    {
      "x": 1,
      "y": 10,
      "z": -2,
      "name": "Rock_Ledge_Brick_Smooth"
    },
    {
      "x": 1,
      "y": 0,
      "z": -1,
      "name": "Rock_Ledge_Brick"
    },
    {
      "x": 1,
      "y": 1,
      "z": -1,
      "name": "Cloth_Block_Wool_White"
    },
    {
      "x": 1,
      "y": 2,
      "z": -1,
      "name": "Cloth_Block_Wool_White"
    },
    {
      "x": 1,
      "y": 3,
      "z": -1,
      "name": "Cloth_Block_Wool_White"
    },
    {
      "x": 1,
      "y": 4,
      "z": -1,
      "name": "Rock_Marble_Brick_Smooth"
    },
    {
      "x": 1,
      "y": 5,
      "z": -1,
      "name": "Rock_Ledge_Brick"
    },
    {
      "x": 1,
      "y": 10,
      "z": -1,
      "name": "Rock_Ledge_Brick_Smooth"
    },
    {
      "x": 1,
      "y": 0,
      "z": 0,
      "name": "Rock_Ledge_Brick"
    },
    {
      "x": 1,
      "y": 1,
      "z": 0,
      "name": "Cloth_Block_Wool_White"
    },
    {
      "x": 1,
      "y": 2,
      "z": 0,
      "name": "Cloth_Block_Wool_White"
    },
    {
      "x": 1,
      "y": 3,
      "z": 0,
      "name": "Cloth_Block_Wool_White"
    },
    {
      "x": 1,
      "y": 4,
      "z": 0,
      "name": "Rock_Marble_Brick_Smooth"
    },
    {
      "x": 1,
      "y": 5,
      "z": 0,
      "name": "Rock_Ledge_Brick"
    },
    {
      "x": 1,
      "y": 6,
      "z": 0,
      "name": "Cloth_Block_Wool_White"
    },
    {
      "x": 1,
      "y": 7,
      "z": 0,
      "name": "Cloth_Block_Wool_White"
    },
    {
      "x": 1,
      "y": 8,
      "z": 0,
      "name": "Cloth_Block_Wool_White"
    },
    {
      "x": 1,
      "y": 10,
      "z": 0,
      "name": "Rock_Ledge_Brick_Smooth"
    },
    {
      "x": 1,
      "y": 0,
      "z": 1,
      "name": "Rock_Ledge_Brick"
    },
    {
      "x": 1,
      "y": 1,
      "z": 1,
      "name": "Cloth_Block_Wool_White"
    },
    {
      "x": 1,
      "y": 2,
      "z": 1,
      "name": "Cloth_Block_Wool_White"
    },
    {
      "x": 1,
      "y": 3,
      "z": 1,
      "name": "Cloth_Block_Wool_White"
    },
    {
      "x": 1,
      "y": 4,
      "z": 1,
      "name": "Rock_Marble_Brick_Smooth"
    },
    {
      "x": 1,
      "y": 5,
      "z": 1,
      "name": "Rock_Ledge_Brick"
    },
    {
      "x": 1,
      "y": 6,
      "z": 1,
      "name": "Cloth_Block_Wool_White"
    },
    {
      "x": 1,
      "y": 7,
      "z": 1,
      "name": "Cloth_Block_Wool_White"
    },
    {
      "x": 1,
      "y": 8,
      "z": 1,
      "name": "Cloth_Block_Wool_White"
    },
    {
      "x": 1,
      "y": 10,
      "z": 1,
      "name": "Rock_Ledge_Brick_Smooth"
    },
    {
      "x": 1,
      "y": 0,
      "z": 2,
      "name": "Rock_Ledge_Brick"
    },
    {
      "x": 1,
      "y": 1,
      "z": 2,
      "name": "Cloth_Block_Wool_White"
    },
    {
      "x": 1,
      "y": 2,
      "z": 2,
      "name": "Cloth_Block_Wool_White"
    },
    {
      "x": 1,
      "y": 3,
      "z": 2,
      "name": "Cloth_Block_Wool_White"
    },
    {
      "x": 1,
      "y": 4,
      "z": 2,
      "name": "Rock_Marble_Brick_Smooth"
    },
    {
      "x": 1,
      "y": 5,
      "z": 2,
      "name": "Rock_Ledge_Brick"
    },
    {
      "x": 1,
      "y": 6,
      "z": 2,
      "name": "Cloth_Block_Wool_White"
    },
    {
      "x": 1,
      "y": 7,
      "z": 2,
      "name": "Cloth_Block_Wool_White"
    },
    {
      "x": 1,
      "y": 8,
      "z": 2,
      "name": "Cloth_Block_Wool_White"
    },
    {
      "x": 1,
      "y": 9,
      "z": 2,
      "name": "Rock_Ledge_Brick_Smooth"
    },
    {
      "x": 1,
      "y": 10,
      "z": 2,
      "name": "Rock_Ledge_Brick_Smooth"
    },
    {
      "x": 1,
      "y": 0,
      "z": 3,
      "name": "Rock_Ledge_Brick"
    },
    {
      "x": 1,
      "y": 1,
      "z": 3,
      "name": "Cloth_Block_Wool_White"
    },
    {
      "x": 1,
      "y": 2,
      "z": 3,
      "name": "Cloth_Block_Wool_White"
    },
    {
      "x": 1,
      "y": 3,
      "z": 3,
      "name": "Cloth_Block_Wool_White"
    },
    {
      "x": 1,
      "y": 4,
      "z": 3,
      "name": "Rock_Marble_Brick_Smooth"
    },
    {
      "x": 1,
      "y": 5,
      "z": 3,
      "name": "Rock_Ledge_Brick"
    },
    {
      "x": 1,
      "y": 6,
      "z": 3,
      "name": "*Furniture_Temple_Light_Door_State_Definitions_CloseDoorIn",
      "rotation": 3
    },
    {
      "x": 1,
      "y": 7,
      "z": 3,
      "name": "*Furniture_Temple_Light_Door_State_Definitions_CloseDoorIn",
      "filler": 1024,
      "rotation": 3
    },
    {
      "x": 1,
      "y": 8,
      "z": 3,
      "name": "Cloth_Block_Wool_White"
    },
    {
      "x": 1,
      "y": 10,
      "z": 3,
      "name": "Rock_Ledge_Brick_Smooth"
    },
    {
      "x": 1,
      "y": 0,
      "z": 4,
      "name": "Rock_Ledge_Brick"
    },
    {
      "x": 1,
      "y": 1,
      "z": 4,
      "name": "Cloth_Block_Wool_White"
    },
    {
      "x": 1,
      "y": 2,
      "z": 4,
      "name": "Cloth_Block_Wool_White"
    },
    {
      "x": 1,
      "y": 3,
      "z": 4,
      "name": "Cloth_Block_Wool_White"
    },
    {
      "x": 1,
      "y": 4,
      "z": 4,
      "name": "Rock_Marble_Brick_Smooth"
    },
    {
      "x": 1,
      "y": 5,
      "z": 4,
      "name": "Rock_Ledge_Brick"
    },
    {
      "x": 1,
      "y": 6,
      "z": 4,
      "name": "*Furniture_Temple_Light_Door_State_Definitions_CloseDoorOut",
      "rotation": 1
    },
    {
      "x": 1,
      "y": 7,
      "z": 4,
      "name": "*Furniture_Temple_Light_Door_State_Definitions_CloseDoorOut",
      "filler": 1024,
      "rotation": 1
    },
    {
      "x": 1,
      "y": 8,
      "z": 4,
      "name": "Cloth_Block_Wool_White"
    },
    {
      "x": 1,
      "y": 10,
      "z": 4,
      "name": "Rock_Ledge_Brick_Smooth"
    },
    {
      "x": 1,
      "y": 0,
      "z": 5,
      "name": "Rock_Ledge_Brick"
    },
    {
      "x": 1,
      "y": 1,
      "z": 5,
      "name": "Rock_Ledge_Brick_Smooth"
    },
    {
      "x": 1,
      "y": 2,
      "z": 5,
      "name": "Rock_Ledge_Brick_Smooth"
    },
    {
      "x": 1,
      "y": 3,
      "z": 5,
      "name": "Rock_Ledge_Brick_Smooth"
    },
    {
      "x": 1,
      "y": 4,
      "z": 5,
      "name": "Rock_Ledge_Brick_Smooth"
    },
    {
      "x": 1,
      "y": 5,
      "z": 5,
      "name": "Rock_Ledge_Brick"
    },
    {
      "x": 1,
      "y": 6,
      "z": 5,
      "name": "Cloth_Block_Wool_White"
    },
    {
      "x": 1,
      "y": 7,
      "z": 5,
      "name": "Cloth_Block_Wool_White"
    },
    {
      "x": 1,
      "y": 8,
      "z": 5,
      "name": "Cloth_Block_Wool_White"
    },
    {
      "x": 1,
      "y": 9,
      "z": 5,
      "name": "Rock_Ledge_Brick_Smooth"
    },
    {
      "x": 1,
      "y": 10,
      "z": 5,
      "name": "Rock_Ledge_Brick_Smooth"
    },
    {
      "x": 1,
      "y": 0,
      "z": 6,
      "name": "Rock_Ledge_Brick"
    },
    {
      "x": 1,
      "y": 5,
      "z": 6,
      "name": "Rock_Ledge_Brick_Smooth"
    },
    {
      "x": 1,
      "y": 6,
      "z": 6,
      "name": "Rock_Ledge_Brick_Smooth"
    },
    {
      "x": 1,
      "y": 7,
      "z": 6,
      "name": "Rock_Ledge_Brick_Stairs"
    },
    {
      "x": 1,
      "y": 8,
      "z": 6,
      "name": "Rock_Ledge_Brick_Smooth"
    },
    {
      "x": 1,
      "y": 0,
      "z": 7,
      "name": "Rock_Ledge_Brick"
    },
    {
      "x": 2,
      "y": 0,
      "z": -6,
      "name": "Rock_Ledge_Brick"
    },
    {
      "x": 2,
      "y": 0,
      "z": -5,
      "name": "Rock_Ledge_Brick"
    },
    {
      "x": 2,
      "y": 8,
      "z": -5,
      "name": "Rock_Ledge_Brick_Smooth"
    },
    {
      "x": 2,
      "y": 0,
      "z": -4,
      "name": "Rock_Ledge_Brick"
    },
    {
      "x": 2,
      "y": 1,
      "z": -4,
      "name": "Rock_Ledge_Brick_Smooth"
    },
    {
      "x": 2,
      "y": 2,
      "z": -4,
      "name": "Rock_Ledge_Brick_Smooth"
    },
    {
      "x": 2,
      "y": 3,
      "z": -4,
      "name": "Rock_Ledge_Brick_Smooth"
    },
    {
      "x": 2,
      "y": 7,
      "z": -4,
      "name": "Rock_Ledge_Brick_Smooth"
    },
    {
      "x": 2,
      "y": 8,
      "z": -4,
      "name": "Rock_Ledge_Brick_Smooth"
    },
    {
      "x": 2,
      "y": 9,
      "z": -4,
      "name": "Rock_Ledge_Brick_Smooth"
    },
    {
      "x": 2,
      "y": 10,
      "z": -4,
      "name": "Rock_Ledge_Brick_Smooth"
    },
    {
      "x": 2,
      "y": 0,
      "z": -3,
      "name": "Rock_Ledge_Brick"
    },
    {
      "x": 2,
      "y": 1,
      "z": -3,
      "name": "Rock_Ledge_Brick"
    },
    {
      "x": 2,
      "y": 2,
      "z": -3,
      "name": "Rock_Ledge_Brick"
    },
    {
      "x": 2,
      "y": 3,
      "z": -3,
      "name": "Rock_Ledge_Brick"
    },
    {
      "x": 2,
      "y": 4,
      "z": -3,
      "name": "Rock_Ledge_Brick_Smooth"
    },
    {
      "x": 2,
      "y": 5,
      "z": -3,
      "name": "Rock_Ledge_Brick_Smooth"
    },
    {
      "x": 2,
      "y": 6,
      "z": -3,
      "name": "Rock_Ledge_Brick_Smooth"
    },
    {
      "x": 2,
      "y": 7,
      "z": -3,
      "name": "Rock_Ledge_Brick_Smooth"
    },
    {
      "x": 2,
      "y": 8,
      "z": -3,
      "name": "Rock_Ledge_Brick_Smooth"
    },
    {
      "x": 2,
      "y": 10,
      "z": -3,
      "name": "Rock_Ledge_Brick_Smooth"
    },
    {
      "x": 2,
      "y": 0,
      "z": -2,
      "name": "Rock_Ledge_Brick"
    },
    {
      "x": 2,
      "y": 1,
      "z": -2,
      "name": "Rock_Ledge_Brick"
    },
    {
      "x": 2,
      "y": 2,
      "z": -2,
      "name": "Rock_Ledge_Brick"
    },
    {
      "x": 2,
      "y": 3,
      "z": -2,
      "name": "Rock_Ledge_Brick"
    },
    {
      "x": 2,
      "y": 4,
      "z": -2,
      "name": "Rock_Ledge_Brick"
    },
    {
      "x": 2,
      "y": 5,
      "z": -2,
      "name": "YellowLED"
    },
    {
      "x": 2,
      "y": 6,
      "z": -2,
      "name": "Rock_Ledge_Brick"
    },
    {
      "x": 2,
      "y": 7,
      "z": -2,
      "name": "Rock_Ledge_Brick"
    },
    {
      "x": 2,
      "y": 8,
      "z": -2,
      "name": "Rock_Ledge_Brick_Smooth"
    },
    {
      "x": 2,
      "y": 10,
      "z": -2,
      "name": "Rock_Ledge_Brick_Smooth"
    },
    {
      "x": 2,
      "y": 0,
      "z": -1,
      "name": "Rock_Ledge_Brick"
    },
    {
      "x": 2,
      "y": 1,
      "z": -1,
      "name": "Rock_Ledge_Brick"
    },
    {
      "x": 2,
      "y": 2,
      "z": -1,
      "name": "Rock_Ledge_Brick"
    },
    {
      "x": 2,
      "y": 3,
      "z": -1,
      "name": "Rock_Ledge_Brick"
    },
    {
      "x": 2,
      "y": 4,
      "z": -1,
      "name": "Rock_Ledge_Brick"
    },
    {
      "x": 2,
      "y": 5,
      "z": -1,
      "name": "YellowLED"
    },
    {
      "x": 2,
      "y": 6,
      "z": -1,
      "name": "Rock_Ledge_Brick"
    },
    {
      "x": 2,
      "y": 7,
      "z": -1,
      "name": "Rock_Ledge_Brick"
    },
    {
      "x": 2,
      "y": 8,
      "z": -1,
      "name": "Rock_Ledge_Brick_Smooth"
    },
    {
      "x": 2,
      "y": 10,
      "z": -1,
      "name": "Rock_Ledge_Brick_Smooth"
    },
    {
      "x": 2,
      "y": 0,
      "z": 0,
      "name": "Rock_Ledge_Brick"
    },
    {
      "x": 2,
      "y": 1,
      "z": 0,
      "name": "Rock_Ledge_Brick"
    },
    {
      "x": 2,
      "y": 2,
      "z": 0,
      "name": "Rock_Ledge_Brick"
    },
    {
      "x": 2,
      "y": 3,
      "z": 0,
      "name": "Rock_Ledge_Brick"
    },
    {
      "x": 2,
      "y": 4,
      "z": 0,
      "name": "Rock_Ledge_Brick"
    },
    {
      "x": 2,
      "y": 5,
      "z": 0,
      "name": "YellowLED"
    },
    {
      "x": 2,
      "y": 6,
      "z": 0,
      "name": "Rock_Ledge_Brick"
    },
    {
      "x": 2,
      "y": 7,
      "z": 0,
      "name": "Rock_Ledge_Brick"
    },
    {
      "x": 2,
      "y": 8,
      "z": 0,
      "name": "Rock_Ledge_Brick_Smooth"
    },
    {
      "x": 2,
      "y": 10,
      "z": 0,
      "name": "Rock_Ledge_Brick_Smooth"
    },
    {
      "x": 2,
      "y": 0,
      "z": 1,
      "name": "Rock_Ledge_Brick"
    },
    {
      "x": 2,
      "y": 1,
      "z": 1,
      "name": "YellowLED"
    },
    {
      "x": 2,
      "y": 2,
      "z": 1,
      "name": "YellowLED"
    },
    {
      "x": 2,
      "y": 3,
      "z": 1,
      "name": "YellowLED"
    },
    {
      "x": 2,
      "y": 4,
      "z": 1,
      "name": "YellowLED"
    },
    {
      "x": 2,
      "y": 5,
      "z": 1,
      "name": "YellowLED"
    },
    {
      "x": 2,
      "y": 6,
      "z": 1,
      "name": "YellowLED"
    },
    {
      "x": 2,
      "y": 7,
      "z": 1,
      "name": "YellowLED"
    },
    {
      "x": 2,
      "y": 8,
      "z": 1,
      "name": "Rock_Ledge_Brick_Smooth"
    },
    {
      "x": 2,
      "y": 10,
      "z": 1,
      "name": "Rock_Ledge_Brick_Smooth"
    },
    {
      "x": 2,
      "y": 0,
      "z": 2,
      "name": "Rock_Ledge_Brick"
    },
    {
      "x": 2,
      "y": 1,
      "z": 2,
      "name": "Rock_Ledge_Brick"
    },
    {
      "x": 2,
      "y": 2,
      "z": 2,
      "name": "Rock_Ledge_Brick"
    },
    {
      "x": 2,
      "y": 3,
      "z": 2,
      "name": "Rock_Ledge_Brick"
    },
    {
      "x": 2,
      "y": 4,
      "z": 2,
      "name": "Rock_Ledge_Brick"
    },
    {
      "x": 2,
      "y": 5,
      "z": 2,
      "name": "Rock_Ledge_Brick"
    },
    {
      "x": 2,
      "y": 6,
      "z": 2,
      "name": "Rock_Ledge_Brick_Smooth"
    },
    {
      "x": 2,
      "y": 7,
      "z": 2,
      "name": "Rock_Ledge_Brick_Smooth"
    },
    {
      "x": 2,
      "y": 8,
      "z": 2,
      "name": "Rock_Ledge_Brick_Smooth"
    },
    {
      "x": 2,
      "y": 10,
      "z": 2,
      "name": "Rock_Ledge_Brick_Smooth"
    },
    {
      "x": 2,
      "y": 0,
      "z": 3,
      "name": "Rock_Ledge_Brick"
    },
    {
      "x": 2,
      "y": 5,
      "z": 3,
      "name": "Rock_Ledge_Brick"
    },
    {
      "x": 2,
      "y": 8,
      "z": 3,
      "name": "Rock_Ledge_Brick_Smooth"
    },
    {
      "x": 2,
      "y": 10,
      "z": 3,
      "name": "Rock_Ledge_Brick_Smooth"
    },
    {
      "x": 2,
      "y": 0,
      "z": 4,
      "name": "Rock_Ledge_Brick"
    },
    {
      "x": 2,
      "y": 1,
      "z": 4,
      "name": "Rock_Marble_Brick_Smooth"
    },
    {
      "x": 2,
      "y": 2,
      "z": 4,
      "name": "Rock_Marble_Brick_Smooth"
    },
    {
      "x": 2,
      "y": 3,
      "z": 4,
      "name": "Rock_Marble_Brick_Smooth"
    },
    {
      "x": 2,
      "y": 5,
      "z": 4,
      "name": "Rock_Ledge_Brick"
    },
    {
      "x": 2,
      "y": 8,
      "z": 4,
      "name": "Rock_Ledge_Brick_Smooth"
    },
    {
      "x": 2,
      "y": 10,
      "z": 4,
      "name": "Rock_Ledge_Brick_Smooth"
    },
    {
      "x": 2,
      "y": 4,
      "z": 5,
      "name": "Rock_Ledge_Brick_Smooth"
    },
    {
      "x": 2,
      "y": 5,
      "z": 5,
      "name": "YellowLED"
    },
    {
      "x": 2,
      "y": 6,
      "z": 5,
      "name": "Rock_Ledge_Brick"
    },
    {
      "x": 2,
      "y": 7,
      "z": 5,
      "name": "Rock_Ledge_Brick"
    },
    {
      "x": 2,
      "y": 9,
      "z": 5,
      "name": "Rock_Ledge_Brick_Smooth"
    },
    {
      "x": 2,
      "y": 10,
      "z": 5,
      "name": "Rock_Ledge_Brick_Smooth"
    },
    {
      "x": 2,
      "y": 8,
      "z": 6,
      "name": "Rock_Ledge_Brick_Smooth"
    },
    {
      "x": 3,
      "y": 0,
      "z": -6,
      "name": "Rock_Ledge_Brick"
    },
    {
      "x": 3,
      "y": 0,
      "z": -5,
      "name": "Rock_Ledge_Brick"
    },
    {
      "x": 3,
      "y": 8,
      "z": -5,
      "name": "Rock_Ledge_Brick_Smooth"
    },
    {
      "x": 3,
      "y": 0,
      "z": -4,
      "name": "Rock_Ledge_Brick"
    },
    {
      "x": 3,
      "y": 1,
      "z": -4,
      "name": "*Furniture_Temple_Light_Door_State_Definitions_CloseDoorIn"
    },
    {
      "x": 3,
      "y": 2,
      "z": -4,
      "name": "*Furniture_Temple_Light_Door_State_Definitions_CloseDoorIn",
      "filler": 1024
    },
    {
      "x": 3,
      "y": 3,
      "z": -4,
      "name": "Rock_Ledge_Brick_Smooth"
    },
    {
      "x": 3,
      "y": 7,
      "z": -4,
      "name": "Rock_Ledge_Brick_Smooth"
    },
    {
      "x": 3,
      "y": 8,
      "z": -4,
      "name": "Rock_Ledge_Brick_Smooth"
    },
    {
      "x": 3,
      "y": 9,
      "z": -4,
      "name": "Rock_Ledge_Brick_Smooth"
    },
    {
      "x": 3,
      "y": 10,
      "z": -4,
      "name": "Rock_Ledge_Brick_Smooth"
    },
    {
      "x": 3,
      "y": 0,
      "z": -3,
      "name": "Rock_Ledge_Brick"
    },
    {
      "x": 3,
      "y": 4,
      "z": -3,
      "name": "Rock_Ledge_Brick_Smooth"
    },
    {
      "x": 3,
      "y": 5,
      "z": -3,
      "name": "Rock_Ledge_Brick_Smooth"
    },
    {
      "x": 3,
      "y": 6,
      "z": -3,
      "name": "Rock_Ledge_Brick_Smooth"
    },
    {
      "x": 3,
      "y": 7,
      "z": -3,
      "name": "Rock_Ledge_Brick_Smooth"
    },
    {
      "x": 3,
      "y": 8,
      "z": -3,
      "name": "Rock_Ledge_Brick_Smooth"
    },
    {
      "x": 3,
      "y": 10,
      "z": -3,
      "name": "Rock_Ledge_Brick_Smooth"
    },
    {
      "x": 3,
      "y": 0,
      "z": -2,
      "name": "Rock_Ledge_Brick"
    },
    {
      "x": 3,
      "y": 1,
      "z": -2,
      "name": "Rock_Ledge_Brick_Stairs",
      "rotation": 2
    },
    {
      "x": 3,
      "y": 8,
      "z": -2,
      "name": "Rock_Ledge_Brick_Smooth"
    },
    {
      "x": 3,
      "y": 10,
      "z": -2,
      "name": "Rock_Ledge_Brick_Smooth"
    },
    {
      "x": 3,
      "y": 0,
      "z": -1,
      "name": "Rock_Ledge_Brick"
    },
    {
      "x": 3,
      "y": 1,
      "z": -1,
      "name": "Rock_Ledge_Brick"
    },
    {
      "x": 3,
      "y": 2,
      "z": -1,
      "name": "Rock_Ledge_Brick_Stairs",
      "rotation": 2
    },
    {
      "x": 3,
      "y": 8,
      "z": -1,
      "name": "Rock_Ledge_Brick_Smooth"
    },
    {
      "x": 3,
      "y": 10,
      "z": -1,
      "name": "Rock_Ledge_Brick_Smooth"
    },
    {
      "x": 3,
      "y": 0,
      "z": 0,
      "name": "Rock_Ledge_Brick"
    },
    {
      "x": 3,
      "y": 1,
      "z": 0,
      "name": "Rock_Ledge_Brick"
    },
    {
      "x": 3,
      "y": 2,
      "z": 0,
      "name": "Rock_Ledge_Brick"
    },
    {
      "x": 3,
      "y": 3,
      "z": 0,
      "name": "Rock_Ledge_Brick_Stairs",
      "rotation": 2
    },
    {
      "x": 3,
      "y": 8,
      "z": 0,
      "name": "Rock_Ledge_Brick_Smooth"
    },
    {
      "x": 3,
      "y": 10,
      "z": 0,
      "name": "Rock_Ledge_Brick_Smooth"
    },
    {
      "x": 3,
      "y": 0,
      "z": 1,
      "name": "Rock_Ledge_Brick"
    },
    {
      "x": 3,
      "y": 1,
      "z": 1,
      "name": "Rock_Ledge_Brick"
    },
    {
      "x": 3,
      "y": 2,
      "z": 1,
      "name": "Rock_Ledge_Brick"
    },
    {
      "x": 3,
      "y": 3,
      "z": 1,
      "name": "Rock_Ledge_Brick"
    },
    {
      "x": 3,
      "y": 4,
      "z": 1,
      "name": "Rock_Ledge_Brick_Stairs",
      "rotation": 2
    },
    {
      "x": 3,
      "y": 8,
      "z": 1,
      "name": "Rock_Ledge_Brick_Smooth"
    },
    {
      "x": 3,
      "y": 10,
      "z": 1,
      "name": "Rock_Ledge_Brick_Smooth"
    },
    {
      "x": 3,
      "y": 0,
      "z": 2,
      "name": "Rock_Ledge_Brick"
    },
    {
      "x": 3,
      "y": 1,
      "z": 2,
      "name": "Rock_Ledge_Brick"
    },
    {
      "x": 3,
      "y": 2,
      "z": 2,
      "name": "Rock_Ledge_Brick"
    },
    {
      "x": 3,
      "y": 3,
      "z": 2,
      "name": "Rock_Ledge_Brick"
    },
    {
      "x": 3,
      "y": 4,
      "z": 2,
      "name": "Rock_Ledge_Brick"
    },
    {
      "x": 3,
      "y": 5,
      "z": 2,
      "name": "Rock_Ledge_Brick_Stairs",
      "rotation": 2
    },
    {
      "x": 3,
      "y": 8,
      "z": 2,
      "name": "Rock_Ledge_Brick_Smooth"
    },
    {
      "x": 3,
      "y": 10,
      "z": 2,
      "name": "Rock_Ledge_Brick_Smooth"
    },
    {
      "x": 3,
      "y": 0,
      "z": 3,
      "name": "Rock_Ledge_Brick"
    },
    {
      "x": 3,
      "y": 5,
      "z": 3,
      "name": "Rock_Ledge_Brick"
    },
    {
      "x": 3,
      "y": 8,
      "z": 3,
      "name": "Rock_Ledge_Brick_Smooth"
    },
    {
      "x": 3,
      "y": 10,
      "z": 3,
      "name": "Rock_Ledge_Brick_Smooth"
    },
    {
      "x": 3,
      "y": 0,
      "z": 4,
      "name": "Rock_Ledge_Brick"
    },
    {
      "x": 3,
      "y": 1,
      "z": 4,
      "name": "Rock_Marble_Brick_Smooth"
    },
    {
      "x": 3,
      "y": 2,
      "z": 4,
      "name": "Rock_Marble_Brick_Smooth"
    },
    {
      "x": 3,
      "y": 3,
      "z": 4,
      "name": "Rock_Marble_Brick_Smooth"
    },
    {
      "x": 3,
      "y": 5,
      "z": 4,
      "name": "Rock_Ledge_Brick"
    },
    {
      "x": 3,
      "y": 8,
      "z": 4,
      "name": "Rock_Ledge_Brick_Smooth"
    },
    {
      "x": 3,
      "y": 10,
      "z": 4,
      "name": "Rock_Ledge_Brick_Smooth"
    },
    {
      "x": 3,
      "y": 4,
      "z": 5,
      "name": "Rock_Ledge_Brick_Smooth"
    },
    {
      "x": 3,
      "y": 5,
      "z": 5,
      "name": "YellowLED"
    },
    {
      "x": 3,
      "y": 6,
      "z": 5,
      "name": "Rock_Ledge_Brick"
    },
    {
      "x": 3,
      "y": 7,
      "z": 5,
      "name": "Rock_Ledge_Brick"
    },
    {
      "x": 3,
      "y": 9,
      "z": 5,
      "name": "Rock_Ledge_Brick_Smooth"
    },
    {
      "x": 3,
      "y": 10,
      "z": 5,
      "name": "Rock_Ledge_Brick_Smooth"
    },
    {
      "x": 3,
      "y": 8,
      "z": 6,
      "name": "Rock_Ledge_Brick_Smooth"
    },
    {
      "x": 4,
      "y": 0,
      "z": -6,
      "name": "Rock_Ledge_Brick"
    },
    {
      "x": 4,
      "y": 0,
      "z": -5,
      "name": "Rock_Ledge_Brick"
    },
    {
      "x": 4,
      "y": 8,
      "z": -5,
      "name": "Rock_Ledge_Brick_Smooth"
    },
    {
      "x": 4,
      "y": 0,
      "z": -4,
      "name": "Rock_Ledge_Brick"
    },
    {
      "x": 4,
      "y": 1,
      "z": -4,
      "name": "*Furniture_Temple_Light_Door_State_Definitions_CloseDoorOut",
      "rotation": 2
    },
    {
      "x": 4,
      "y": 2,
      "z": -4,
      "name": "*Furniture_Temple_Light_Door_State_Definitions_CloseDoorOut",
      "filler": 1024,
      "rotation": 2
    },
    {
      "x": 4,
      "y": 3,
      "z": -4,
      "name": "Rock_Ledge_Brick_Smooth"
    },
    {
      "x": 4,
      "y": 7,
      "z": -4,
      "name": "Rock_Ledge_Brick_Smooth"
    },
    {
      "x": 4,
      "y": 8,
      "z": -4,
      "name": "Rock_Ledge_Brick_Smooth"
    },
    {
      "x": 4,
      "y": 9,
      "z": -4,
      "name": "Rock_Ledge_Brick_Smooth"
    },
    {
      "x": 4,
      "y": 10,
      "z": -4,
      "name": "Rock_Ledge_Brick_Smooth"
    },
    {
      "x": 4,
      "y": 0,
      "z": -3,
      "name": "Rock_Ledge_Brick"
    },
    {
      "x": 4,
      "y": 4,
      "z": -3,
      "name": "Rock_Ledge_Brick_Smooth"
    },
    {
      "x": 4,
      "y": 5,
      "z": -3,
      "name": "Rock_Ledge_Brick_Smooth"
    },
    {
      "x": 4,
      "y": 6,
      "z": -3,
      "name": "Rock_Ledge_Brick_Smooth"
    },
    {
      "x": 4,
      "y": 7,
      "z": -3,
      "name": "Rock_Ledge_Brick_Smooth"
    },
    {
      "x": 4,
      "y": 8,
      "z": -3,
      "name": "Rock_Ledge_Brick_Smooth"
    },
    {
      "x": 4,
      "y": 10,
      "z": -3,
      "name": "Rock_Ledge_Brick_Smooth"
    },
    {
      "x": 4,
      "y": 0,
      "z": -2,
      "name": "Rock_Ledge_Brick"
    },
    {
      "x": 4,
      "y": 1,
      "z": -2,
      "name": "Rock_Ledge_Brick_Stairs",
      "rotation": 2
    },
    {
      "x": 4,
      "y": 8,
      "z": -2,
      "name": "Rock_Ledge_Brick_Smooth"
    },
    {
      "x": 4,
      "y": 10,
      "z": -2,
      "name": "Rock_Ledge_Brick_Smooth"
    },
    {
      "x": 4,
      "y": 0,
      "z": -1,
      "name": "Rock_Ledge_Brick"
    },
    {
      "x": 4,
      "y": 1,
      "z": -1,
      "name": "Rock_Ledge_Brick"
    },
    {
      "x": 4,
      "y": 2,
      "z": -1,
      "name": "Rock_Ledge_Brick_Stairs",
      "rotation": 2
    },
    {
      "x": 4,
      "y": 8,
      "z": -1,
      "name": "Rock_Ledge_Brick_Smooth"
    },
    {
      "x": 4,
      "y": 10,
      "z": -1,
      "name": "Rock_Ledge_Brick_Smooth"
    },
    {
      "x": 4,
      "y": 0,
      "z": 0,
      "name": "Rock_Ledge_Brick"
    },
    {
      "x": 4,
      "y": 1,
      "z": 0,
      "name": "Rock_Ledge_Brick"
    },
    {
      "x": 4,
      "y": 2,
      "z": 0,
      "name": "Rock_Ledge_Brick"
    },
    {
      "x": 4,
      "y": 3,
      "z": 0,
      "name": "Rock_Ledge_Brick_Stairs",
      "rotation": 2
    },
    {
      "x": 4,
      "y": 8,
      "z": 0,
      "name": "Rock_Ledge_Brick_Smooth"
    },
    {
      "x": 4,
      "y": 10,
      "z": 0,
      "name": "Rock_Ledge_Brick_Smooth"
    },
    {
      "x": 4,
      "y": 0,
      "z": 1,
      "name": "Rock_Ledge_Brick"
    },
    {
      "x": 4,
      "y": 1,
      "z": 1,
      "name": "Rock_Ledge_Brick"
    },
    {
      "x": 4,
      "y": 2,
      "z": 1,
      "name": "Rock_Ledge_Brick"
    },
    {
      "x": 4,
      "y": 3,
      "z": 1,
      "name": "Rock_Ledge_Brick"
    },
    {
      "x": 4,
      "y": 4,
      "z": 1,
      "name": "Rock_Ledge_Brick_Stairs",
      "rotation": 2
    },
    {
      "x": 4,
      "y": 8,
      "z": 1,
      "name": "Rock_Ledge_Brick_Smooth"
    },
    {
      "x": 4,
      "y": 10,
      "z": 1,
      "name": "Rock_Ledge_Brick_Smooth"
    },
    {
      "x": 4,
      "y": 0,
      "z": 2,
      "name": "Rock_Ledge_Brick"
    },
    {
      "x": 4,
      "y": 1,
      "z": 2,
      "name": "Rock_Ledge_Brick"
    },
    {
      "x": 4,
      "y": 2,
      "z": 2,
      "name": "Rock_Ledge_Brick"
    },
    {
      "x": 4,
      "y": 3,
      "z": 2,
      "name": "Rock_Ledge_Brick"
    },
    {
      "x": 4,
      "y": 4,
      "z": 2,
      "name": "Rock_Ledge_Brick"
    },
    {
      "x": 4,
      "y": 5,
      "z": 2,
      "name": "Rock_Ledge_Brick_Stairs",
      "rotation": 2
    },
    {
      "x": 4,
      "y": 8,
      "z": 2,
      "name": "Rock_Ledge_Brick_Smooth"
    },
    {
      "x": 4,
      "y": 10,
      "z": 2,
      "name": "Rock_Ledge_Brick_Smooth"
    },
    {
      "x": 4,
      "y": 0,
      "z": 3,
      "name": "Rock_Ledge_Brick"
    },
    {
      "x": 4,
      "y": 5,
      "z": 3,
      "name": "Rock_Ledge_Brick"
    },
    {
      "x": 4,
      "y": 8,
      "z": 3,
      "name": "Rock_Ledge_Brick_Smooth"
    },
    {
      "x": 4,
      "y": 10,
      "z": 3,
      "name": "Rock_Ledge_Brick_Smooth"
    },
    {
      "x": 4,
      "y": 0,
      "z": 4,
      "name": "Rock_Ledge_Brick"
    },
    {
      "x": 4,
      "y": 1,
      "z": 4,
      "name": "Rock_Marble_Brick_Smooth"
    },
    {
      "x": 4,
      "y": 2,
      "z": 4,
      "name": "Rock_Marble_Brick_Smooth"
    },
    {
      "x": 4,
      "y": 3,
      "z": 4,
      "name": "Rock_Marble_Brick_Smooth"
    },
    {
      "x": 4,
      "y": 5,
      "z": 4,
      "name": "Rock_Ledge_Brick"
    },
    {
      "x": 4,
      "y": 8,
      "z": 4,
      "name": "Rock_Ledge_Brick_Smooth"
    },
    {
      "x": 4,
      "y": 10,
      "z": 4,
      "name": "Rock_Ledge_Brick_Smooth"
    },
    {
      "x": 4,
      "y": 4,
      "z": 5,
      "name": "Rock_Ledge_Brick_Smooth"
    },
    {
      "x": 4,
      "y": 5,
      "z": 5,
      "name": "YellowLED"
    },
    {
      "x": 4,
      "y": 6,
      "z": 5,
      "name": "Rock_Ledge_Brick"
    },
    {
      "x": 4,
      "y": 7,
      "z": 5,
      "name": "Rock_Ledge_Brick"
    },
    {
      "x": 4,
      "y": 9,
      "z": 5,
      "name": "Rock_Ledge_Brick_Smooth"
    },
    {
      "x": 4,
      "y": 10,
      "z": 5,
      "name": "Rock_Ledge_Brick_Smooth"
    },
    {
      "x": 4,
      "y": 8,
      "z": 6,
      "name": "Rock_Ledge_Brick_Smooth"
    },
    {
      "x": 5,
      "y": 0,
      "z": -6,
      "name": "Rock_Ledge_Brick"
    },
    {
      "x": 5,
      "y": 0,
      "z": -5,
      "name": "Rock_Ledge_Brick"
    },
    {
      "x": 5,
      "y": 8,
      "z": -5,
      "name": "Rock_Ledge_Brick_Smooth"
    },
    {
      "x": 5,
      "y": 0,
      "z": -4,
      "name": "Rock_Ledge_Brick"
    },
    {
      "x": 5,
      "y": 1,
      "z": -4,
      "name": "Rock_Ledge_Brick_Smooth"
    },
    {
      "x": 5,
      "y": 2,
      "z": -4,
      "name": "Rock_Ledge_Brick_Smooth"
    },
    {
      "x": 5,
      "y": 3,
      "z": -4,
      "name": "Rock_Ledge_Brick_Smooth"
    },
    {
      "x": 5,
      "y": 7,
      "z": -4,
      "name": "Rock_Ledge_Brick_Smooth"
    },
    {
      "x": 5,
      "y": 8,
      "z": -4,
      "name": "Rock_Ledge_Brick_Smooth"
    },
    {
      "x": 5,
      "y": 9,
      "z": -4,
      "name": "Rock_Ledge_Brick_Smooth"
    },
    {
      "x": 5,
      "y": 10,
      "z": -4,
      "name": "Rock_Ledge_Brick_Smooth"
    },
    {
      "x": 5,
      "y": 0,
      "z": -3,
      "name": "Rock_Ledge_Brick"
    },
    {
      "x": 5,
      "y": 1,
      "z": -3,
      "name": "Rock_Ledge_Brick_Smooth"
    },
    {
      "x": 5,
      "y": 2,
      "z": -3,
      "name": "Rock_Ledge_Brick_Smooth"
    },
    {
      "x": 5,
      "y": 3,
      "z": -3,
      "name": "Rock_Ledge_Brick_Smooth"
    },
    {
      "x": 5,
      "y": 4,
      "z": -3,
      "name": "Rock_Ledge_Brick_Smooth"
    },
    {
      "x": 5,
      "y": 5,
      "z": -3,
      "name": "Rock_Ledge_Brick_Smooth"
    },
    {
      "x": 5,
      "y": 6,
      "z": -3,
      "name": "Rock_Ledge_Brick_Smooth"
    },
    {
      "x": 5,
      "y": 7,
      "z": -3,
      "name": "Rock_Ledge_Brick_Smooth"
    },
    {
      "x": 5,
      "y": 8,
      "z": -3,
      "name": "Rock_Ledge_Brick_Smooth"
    },
    {
      "x": 5,
      "y": 10,
      "z": -3,
      "name": "Rock_Ledge_Brick_Smooth"
    },
    {
      "x": 5,
      "y": 0,
      "z": -2,
      "name": "Rock_Ledge_Brick"
    },
    {
      "x": 5,
      "y": 1,
      "z": -2,
      "name": "Rock_Ledge_Brick_Smooth"
    },
    {
      "x": 5,
      "y": 2,
      "z": -2,
      "name": "Rock_Ledge_Brick_Smooth"
    },
    {
      "x": 5,
      "y": 3,
      "z": -2,
      "name": "Rock_Ledge_Brick_Smooth"
    },
    {
      "x": 5,
      "y": 4,
      "z": -2,
      "name": "Rock_Ledge_Brick_Smooth"
    },
    {
      "x": 5,
      "y": 5,
      "z": -2,
      "name": "Rock_Ledge_Brick_Smooth"
    },
    {
      "x": 5,
      "y": 6,
      "z": -2,
      "name": "Rock_Ledge_Brick_Smooth"
    },
    {
      "x": 5,
      "y": 7,
      "z": -2,
      "name": "Rock_Ledge_Brick_Smooth"
    },
    {
      "x": 5,
      "y": 8,
      "z": -2,
      "name": "Rock_Ledge_Brick_Smooth"
    },
    {
      "x": 5,
      "y": 10,
      "z": -2,
      "name": "Rock_Ledge_Brick_Smooth"
    },
    {
      "x": 5,
      "y": 0,
      "z": -1,
      "name": "Rock_Ledge_Brick"
    },
    {
      "x": 5,
      "y": 1,
      "z": -1,
      "name": "Rock_Marble_Brick_Smooth"
    },
    {
      "x": 5,
      "y": 2,
      "z": -1,
      "name": "Rock_Ledge_Brick_Smooth"
    },
    {
      "x": 5,
      "y": 3,
      "z": -1,
      "name": "Rock_Ledge_Brick_Smooth"
    },
    {
      "x": 5,
      "y": 4,
      "z": -1,
      "name": "Rock_Ledge_Brick_Smooth"
    },
    {
      "x": 5,
      "y": 5,
      "z": -1,
      "name": "Rock_Ledge_Brick_Smooth"
    },
    {
      "x": 5,
      "y": 6,
      "z": -1,
      "name": "Rock_Ledge_Brick_Smooth"
    },
    {
      "x": 5,
      "y": 7,
      "z": -1,
      "name": "Rock_Ledge_Brick_Smooth"
    },
    {
      "x": 5,
      "y": 8,
      "z": -1,
      "name": "Rock_Ledge_Brick_Smooth"
    },
    {
      "x": 5,
      "y": 10,
      "z": -1,
      "name": "Rock_Ledge_Brick_Smooth"
    },
    {
      "x": 5,
      "y": 0,
      "z": 0,
      "name": "Rock_Ledge_Brick"
    },
    {
      "x": 5,
      "y": 1,
      "z": 0,
      "name": "Rock_Marble_Brick_Smooth"
    },
    {
      "x": 5,
      "y": 2,
      "z": 0,
      "name": "Rock_Marble_Brick_Smooth"
    },
    {
      "x": 5,
      "y": 3,
      "z": 0,
      "name": "Rock_Ledge_Brick_Smooth"
    },
    {
      "x": 5,
      "y": 4,
      "z": 0,
      "name": "Rock_Ledge_Brick_Smooth"
    },
    {
      "x": 5,
      "y": 5,
      "z": 0,
      "name": "Rock_Ledge_Brick_Smooth"
    },
    {
      "x": 5,
      "y": 6,
      "z": 0,
      "name": "Rock_Ledge_Brick_Smooth"
    },
    {
      "x": 5,
      "y": 7,
      "z": 0,
      "name": "Rock_Ledge_Brick_Smooth"
    },
    {
      "x": 5,
      "y": 8,
      "z": 0,
      "name": "Rock_Ledge_Brick_Smooth"
    },
    {
      "x": 5,
      "y": 10,
      "z": 0,
      "name": "Rock_Ledge_Brick_Smooth"
    },
    {
      "x": 5,
      "y": 0,
      "z": 1,
      "name": "Rock_Ledge_Brick"
    },
    {
      "x": 5,
      "y": 1,
      "z": 1,
      "name": "Rock_Marble_Brick_Smooth"
    },
    {
      "x": 5,
      "y": 2,
      "z": 1,
      "name": "Rock_Marble_Brick_Smooth"
    },
    {
      "x": 5,
      "y": 3,
      "z": 1,
      "name": "Rock_Marble_Brick_Smooth"
    },
    {
      "x": 5,
      "y": 4,
      "z": 1,
      "name": "Rock_Ledge_Brick_Smooth"
    },
    {
      "x": 5,
      "y": 5,
      "z": 1,
      "name": "Rock_Ledge_Brick_Smooth"
    },
    {
      "x": 5,
      "y": 6,
      "z": 1,
      "name": "Rock_Ledge_Brick_Smooth"
    },
    {
      "x": 5,
      "y": 7,
      "z": 1,
      "name": "Rock_Ledge_Brick_Smooth"
    },
    {
      "x": 5,
      "y": 8,
      "z": 1,
      "name": "Rock_Ledge_Brick_Smooth"
    },
    {
      "x": 5,
      "y": 10,
      "z": 1,
      "name": "Rock_Ledge_Brick_Smooth"
    },
    {
      "x": 5,
      "y": 0,
      "z": 2,
      "name": "Rock_Ledge_Brick"
    },
    {
      "x": 5,
      "y": 1,
      "z": 2,
      "name": "Rock_Marble_Brick_Smooth"
    },
    {
      "x": 5,
      "y": 2,
      "z": 2,
      "name": "Rock_Marble_Brick_Smooth"
    },
    {
      "x": 5,
      "y": 3,
      "z": 2,
      "name": "Rock_Marble_Brick_Smooth"
    },
    {
      "x": 5,
      "y": 4,
      "z": 2,
      "name": "Rock_Ledge_Brick_Smooth"
    },
    {
      "x": 5,
      "y": 5,
      "z": 2,
      "name": "Rock_Ledge_Brick_Smooth"
    },
    {
      "x": 5,
      "y": 6,
      "z": 2,
      "name": "Rock_Ledge_Brick_Smooth"
    },
    {
      "x": 5,
      "y": 7,
      "z": 2,
      "name": "Rock_Ledge_Brick_Smooth"
    },
    {
      "x": 5,
      "y": 8,
      "z": 2,
      "name": "Rock_Ledge_Brick_Smooth"
    },
    {
      "x": 5,
      "y": 10,
      "z": 2,
      "name": "Rock_Ledge_Brick_Smooth"
    },
    {
      "x": 5,
      "y": 0,
      "z": 3,
      "name": "Rock_Ledge_Brick"
    },
    {
      "x": 5,
      "y": 1,
      "z": 3,
      "name": "Rock_Marble_Brick_Smooth"
    },
    {
      "x": 5,
      "y": 2,
      "z": 3,
      "name": "Rock_Marble_Brick_Smooth"
    },
    {
      "x": 5,
      "y": 3,
      "z": 3,
      "name": "Rock_Marble_Brick_Smooth"
    },
    {
      "x": 5,
      "y": 4,
      "z": 3,
      "name": "Rock_Ledge_Brick_Smooth"
    },
    {
      "x": 5,
      "y": 5,
      "z": 3,
      "name": "Rock_Ledge_Brick_Smooth"
    },
    {
      "x": 5,
      "y": 6,
      "z": 3,
      "name": "Rock_Ledge_Brick_Smooth"
    },
    {
      "x": 5,
      "y": 7,
      "z": 3,
      "name": "Rock_Ledge_Brick_Smooth"
    },
    {
      "x": 5,
      "y": 8,
      "z": 3,
      "name": "Rock_Ledge_Brick_Smooth"
    },
    {
      "x": 5,
      "y": 10,
      "z": 3,
      "name": "Rock_Ledge_Brick_Smooth"
    },
    {
      "x": 5,
      "y": 0,
      "z": 4,
      "name": "Rock_Ledge_Brick"
    },
    {
      "x": 5,
      "y": 1,
      "z": 4,
      "name": "Rock_Marble_Brick_Smooth"
    },
    {
      "x": 5,
      "y": 2,
      "z": 4,
      "name": "Rock_Marble_Brick_Smooth"
    },
    {
      "x": 5,
      "y": 3,
      "z": 4,
      "name": "Rock_Marble_Brick_Smooth"
    },
    {
      "x": 5,
      "y": 4,
      "z": 4,
      "name": "Rock_Ledge_Brick_Smooth"
    },
    {
      "x": 5,
      "y": 5,
      "z": 4,
      "name": "Rock_Ledge_Brick_Smooth"
    },
    {
      "x": 5,
      "y": 6,
      "z": 4,
      "name": "Rock_Ledge_Brick_Smooth"
    },
    {
      "x": 5,
      "y": 7,
      "z": 4,
      "name": "Rock_Ledge_Brick_Smooth"
    },
    {
      "x": 5,
      "y": 8,
      "z": 4,
      "name": "Rock_Ledge_Brick_Smooth"
    },
    {
      "x": 5,
      "y": 10,
      "z": 4,
      "name": "Rock_Ledge_Brick_Smooth"
    },
    {
      "x": 5,
      "y": 4,
      "z": 5,
      "name": "Rock_Ledge_Brick_Smooth"
    },
    {
      "x": 5,
      "y": 5,
      "z": 5,
      "name": "YellowLED"
    },
    {
      "x": 5,
      "y": 6,
      "z": 5,
      "name": "Rock_Ledge_Brick"
    },
    {
      "x": 5,
      "y": 7,
      "z": 5,
      "name": "Rock_Ledge_Brick"
    },
    {
      "x": 5,
      "y": 9,
      "z": 5,
      "name": "Rock_Ledge_Brick_Smooth"
    },
    {
      "x": 5,
      "y": 10,
      "z": 5,
      "name": "Rock_Ledge_Brick_Smooth"
    },
    {
      "x": 5,
      "y": 8,
      "z": 6,
      "name": "Rock_Ledge_Brick_Smooth"
    },
    {
      "x": 6,
      "y": 0,
      "z": -6,
      "name": "Rock_Ledge_Brick"
    },
    {
      "x": 6,
      "y": 0,
      "z": -5,
      "name": "Rock_Ledge_Brick"
    },
    {
      "x": 6,
      "y": 8,
      "z": -5,
      "name": "Rock_Ledge_Brick_Smooth"
    },
    {
      "x": 6,
      "y": 0,
      "z": -4,
      "name": "Rock_Ledge_Brick"
    },
    {
      "x": 6,
      "y": 1,
      "z": -4,
      "name": "Rock_Ledge_Brick_Smooth"
    },
    {
      "x": 6,
      "y": 2,
      "z": -4,
      "name": "Rock_Ledge_Brick_Smooth"
    },
    {
      "x": 6,
      "y": 3,
      "z": -4,
      "name": "Rock_Ledge_Brick_Smooth"
    },
    {
      "x": 6,
      "y": 4,
      "z": -4,
      "name": "Rock_Ledge_Brick_Smooth"
    },
    {
      "x": 6,
      "y": 5,
      "z": -4,
      "name": "Rock_Ledge_Brick_Smooth"
    },
    {
      "x": 6,
      "y": 6,
      "z": -4,
      "name": "Rock_Ledge_Brick_Smooth"
    },
    {
      "x": 6,
      "y": 7,
      "z": -4,
      "name": "Rock_Ledge_Brick_Smooth"
    },
    {
      "x": 6,
      "y": 8,
      "z": -4,
      "name": "Rock_Ledge_Brick_Smooth"
    },
    {
      "x": 6,
      "y": 9,
      "z": -4,
      "name": "Rock_Ledge_Brick_Smooth"
    },
    {
      "x": 6,
      "y": 10,
      "z": -4,
      "name": "Rock_Ledge_Brick_Smooth"
    },
    {
      "x": 6,
      "y": 4,
      "z": -3,
      "name": "Rock_Ledge_Brick_Smooth"
    },
    {
      "x": 6,
      "y": 5,
      "z": -3,
      "name": "YellowLED"
    },
    {
      "x": 6,
      "y": 6,
      "z": -3,
      "name": "Rock_Ledge_Brick"
    },
    {
      "x": 6,
      "y": 7,
      "z": -3,
      "name": "Rock_Ledge_Brick"
    },
    {
      "x": 6,
      "y": 8,
      "z": -3,
      "name": "Rock_Ledge_Brick_Smooth"
    },
    {
      "x": 6,
      "y": 9,
      "z": -3,
      "name": "Rock_Ledge_Brick_Smooth"
    },
    {
      "x": 6,
      "y": 10,
      "z": -3,
      "name": "Rock_Ledge_Brick_Smooth"
    },
    {
      "x": 6,
      "y": 4,
      "z": -2,
      "name": "Rock_Ledge_Brick_Smooth"
    },
    {
      "x": 6,
      "y": 5,
      "z": -2,
      "name": "YellowLED"
    },
    {
      "x": 6,
      "y": 6,
      "z": -2,
      "name": "Rock_Ledge_Brick"
    },
    {
      "x": 6,
      "y": 7,
      "z": -2,
      "name": "Rock_Ledge_Brick"
    },
    {
      "x": 6,
      "y": 8,
      "z": -2,
      "name": "Rock_Ledge_Brick_Smooth"
    },
    {
      "x": 6,
      "y": 9,
      "z": -2,
      "name": "Rock_Ledge_Brick_Smooth"
    },
    {
      "x": 6,
      "y": 10,
      "z": -2,
      "name": "Rock_Ledge_Brick_Smooth"
    },
    {
      "x": 6,
      "y": 4,
      "z": -1,
      "name": "Rock_Ledge_Brick_Smooth"
    },
    {
      "x": 6,
      "y": 5,
      "z": -1,
      "name": "YellowLED"
    },
    {
      "x": 6,
      "y": 6,
      "z": -1,
      "name": "Rock_Ledge_Brick"
    },
    {
      "x": 6,
      "y": 7,
      "z": -1,
      "name": "Rock_Ledge_Brick"
    },
    {
      "x": 6,
      "y": 8,
      "z": -1,
      "name": "Rock_Ledge_Brick_Smooth"
    },
    {
      "x": 6,
      "y": 9,
      "z": -1,
      "name": "Rock_Ledge_Brick_Smooth"
    },
    {
      "x": 6,
      "y": 10,
      "z": -1,
      "name": "Rock_Ledge_Brick_Smooth"
